Workbook

Sheet Page 1
A1: अर्थसंकल्पीय अंदाजपत्रक सन 2026-2027 (प्रपत्र ड)
A2: मागणी क्र.सी- 1- लेखाशिर्ष 20530387
A3: अपर आयुक्त (सा.प्र.) कोकण विभाग | O3: (आकडे हजारात)
A4: अ. क्र. | B4: वर्ग | C4: पद | D4: मंजूर पदे | E4: मंजूर पदे | F4: विशेष वेतन | G4: मुळ वेतन | H4: ग्रेड वेतन | I4: एकूण | J4: महागाई भत्ता 70% | K4: स्थानिक पुरक भत्ता | L4: घर भाडे भत्ता | M4: वाहन भत्ता | N4: धूलाई भत्ता | O4: रोख भत्ता | P4: चप्पल भत्ता/ इतर | Q4: एकूण
D5: 2025-26 | E5: 2026-27
C6: स्थायी
A7: 1 | B7: वर्ग-1 व 2 | C7: विभागीय आयुक्त | D7: 1 | E7: 1 | F7: 0 | G7: 2171 | H7: 0 | I7: =SUM(G7:H7) -> 2171 | J7: =ROUND(I7*0.7,0) -> 1520 | K7: 4 | L7: 0 | M7: 0 | N7: 0 | O7: 0 | P7: 0 | Q7: =SUM(F7+I7+J7+K7+L7+M7+N7+O7+P7) -> 3695
C8: अपर आयुक्त | D8: 1 | E8: 1 | F8: 0 | G8: 1849 | H8: 0 | I8: =SUM(G8:H8) -> 1849 | J8: =ROUND(I8*0.7,0) -> 1294 | K8: 4 | L8: 555 | M8: 0 | N8: 0 | O8: 0 | P8: 0 | Q8: =SUM(F8+I8+J8+K8+L8+M8+N8+O8+P8) -> 3702
C9: तहसिलदार | D9: 3 | E9: 3 | F9: 0 | G9: 2218 | H9: 0 | I9: =SUM(G9:H9) -> 2218 | J9: =ROUND(I9*0.7,0) -> 1553 | K9: 11 | L9: 451 | M9: 129 | N9: 0 | O9: 0 | P9: 0 | Q9: =SUM(F9+I9+J9+K9+L9+M9+N9+O9+P9) -> 4362
C10: नायब तहसिलदार | D10: 2 | E10: 2 | F10: 0 | G10: 1333 | H10: 0 | I10: =SUM(G10:H10) -> 1333 | J10: =ROUND(I10*0.7,0) -> 933 | K10: 7 | L10: 400 | M10: 65 | N10: 0 | O10: 0 | P10: 0 | Q10: =SUM(F10+I10+J10+K10+L10+M10+N10+O10+P10) -> 2738
C11: एकूण (वर्ग-1 व 2) | D11: =D7+D8+D9+D10 -> 7 | E11: =E7+E8+E9+E10 -> 7 | F11: =F7+F8+F9+F10 -> 0 | G11: =G7+G8+G9+G10 -> 7571 | H11: 0 | I11: =I7+I8+I9+I10 -> 7571 | J11: =J7+J8+J9+J10 -> 5300 | K11: =K7+K8+K9+K10 -> 26 | L11: =L7+L8+L9+L10 -> 1406 | M11: =M7+M8+M9+M10 -> 194 | N11: =N7+N8+N9+N10 -> 0 | O11: =O7+O8+O9+O10 -> 0 | P11: =P7+P8+P9+P10 -> 0 | Q11: =Q7+Q8+Q9+Q10 -> 14497
A12: 2 | B12: वर्ग-3 | C12: लघुलेखक (उच्च) | D12: 1 | E12: 1 | F12: 0 | G12: 774 | H12: 0 | I12: =SUM(G12:H12) -> 774 | J12: =ROUND(I12*0.7,0) -> 542 | K12: 4 | L12: =ROUND(I12*0.3,0) -> 232 | M12: 32 | N12: 0 | O12: 0 | P12: 0 | Q12: =SUM(F12+I12+J12+K12+L12+M12+N12+O12+P12) -> 1584
C13: अव्वल कारकून | D13: 22 | E13: 22 | F13: 0 | G13: 11846 | H13: 0 | I13: =SUM(G13:H13) -> 11846 | J13: =ROUND(I13*0.7,0) -> 8292 | K13: 79 | L13: 2574 | M13: 713 | N13: 0 | O13: 0 | P13: 0 | Q13: =SUM(F13+I13+J13+K13+L13+M13+N13+O13+P13) -> 23504
C14: लिपिक-टंकलेखक | D14: 18 | E14: 18 | F14: 0 | G14: 6878 | H14: 0 | I14: =SUM(G14:H14) -> 6878 | J14: =ROUND(I14*0.7,0) -> 4815 | K14: 65 | L14: 1751 | M14: 562 | N14: 0 | O14: 0 | P14: 0 | Q14: =SUM(F14+I14+J14+K14+L14+M14+N14+O14+P14) -> 14071
C15: एकूण (वर्ग-3) | D15: =D12+D13+D14 -> 41 | E15: =E12+E13+E14 -> 41 | F15: =F12+F13+F14 -> 0 | G15: =G12+G13+G14 -> 19498 | H15: =H12+H13+H14 -> 0 | I15: =I12+I13+I14 -> 19498 | J15: =SUM(J12:J14) -> 13649 | K15: =K12+K13+K14 -> 148 | L15: =L12+L13+L14 -> 4557 | M15: =M12+M13+M14 -> 1307 | N15: =N12+N13+N14 -> 0 | O15: =O12+O13+O14 -> 0 | P15: =P12+P13+P14 -> 0 | Q15: =Q12+Q13+Q14 -> 39159
A16: 3 | B16: वर्ग-4 | C16: शिपाई/नाईक/हवालदार | D16: 18 | E16: 18 | F16: 0 | G16: 6892 | H16: 0 | I16: =SUM(G16:H16) -> 6892 | J16: =ROUND(I16*0.7,0) -> 4824 | K16: 73 | L16: 1646 | M16: 505 | N16: 54 | O16: 0 | P16: 0 | Q16: =SUM(F16+I16+J16+K16+L16+M16+N16+O16+P16) -> 13994
C17: एकूण (वर्ग-4) | D17: =D16 -> 18 | E17: =E16 -> 18 | F17: =F16 -> 0 | G17: =G16 -> 6892 | H17: =H16 -> 0 | I17: =I16 -> 6892 | J17: =J16 -> 4824 | K17: =K16 -> 73 | ... Q17: =Q16 -> 13994
A18: स्थायी एकूण (वर्ग-1,2,3 व 4) | D18: =D11+D15+D17 -> 66 | E18: =E11+E15+E17 -> 66 | F18: =F11+F15+F17 -> 0 | G18: =G11+G15+G17 -> 33961 | H18: =H11+H15+H17 -> 0 | I18: =I11+I15+I17 -> 33961 | J18: =J11+J15+J17 -> 23773 | K18: =K11+K15+K17 -> 247 | ... Q18: =Q11+Q15+Q17 -> 67650
A20: अर्थसंकल्पीय अंदाजपत्रक सन 2026-2027
A21: मागणी क्र.सी- 1- लेखाशिर्ष 20530387
A22: अपर आयुक्त (सा.प्र.) कोकण विभाग | O22: (आकडे हजारात)
A23: अ. क्र. | B23: वर्ग | C23: पद | D23: मंजूर पदे | E23: मंजूर पदे | F23: विशेष वेतन | G23: मुळ वेतन | H23: ग्रेड वेतन | I23: एकूण | J23: महागाई भत्ता 70% | K23: स्थानिक पुरक भत्ता | L23: घर भाडे भत्ता | M23: वाहन भत्ता | N23: धूलाई भत्ता | O23: रोख भत्ता | P23: चप्पल भत्ता/ इतर | Q23: एकूण
D24: 2025-26 | E24: 2026-27
C25: अस्थायी
A26: 1 | B26: वर्ग-1 व 2 | C26: उपआयुक्त | D26: 2 | E26: 2 | F26: 0 | G26: 3248 | H26: 0 | I26: =SUM(G26:H26) -> 3248 | J26: =ROUND(I26*0.7,0) -> 2274 | K26: 7 | L26: 974 | M26: 0 | N26: 0 | O26: 0 | P26: 0 | Q26: =SUM(F26+I26+J26+K26+L26+M26+N26+O26+P26) -> 6503
C27: उपजिल्हाधिकारी | D27: 1 | E27: 1 | F27: 0 | G27: 1205 | H27: 0 | I27: =SUM(G27:H27) -> 1205 | J27: =ROUND(I27*0.7,0) -> 844 | K27: 4 | L27: 361 | M27: 65 | N27: 0 | O27: 0 | P27: 0 | Q27: =SUM(F27+I27+J27+K27+L27+M27+N27+O27+P27) -> 2479
C28: सहायक संचालक नगररचना (नगररचनाकार) | D28: 1 | E28: 1 | F28: 0 | G28: 1115 | H28: 0 | I28: =SUM(G28:H28) -> 1115 | J28: =ROUND(I28*0.7,0) -> 781 | K28: 4 | L28: 334 | M28: 65 | N28: 0 | O28: 0 | P28: 0 | Q28: =SUM(F28+I28+J28+K28+L28+M28+N28+O28+P28) -> 2299
C29: सहाय्यक संचालक | D29: 1 | E29: 1 | F29: 0 | G29: 979 | H29: 0 | I29: =SUM(G29:H29) -> 979 | J29: =ROUND(I29*0.7,0) -> 685 | K29: 4 | L29: 294 | M29: 65 | N29: 0 | O29: 0 | P29: 0 | Q29: =SUM(F29+I29+J29+K29+L29+M29+N29+O29+P29) -> 2027
C30: नायब तहसिलदार | D30: 3 | E30: 3 | F30: 0 | G30: 1938 | H30: 0 | I30: =SUM(G30:H30) -> 1938 | J30: =ROUND(I30*0.7,0) -> 1357 | K30: 11 | L30: =ROUND(I30*0.3,0) -> 581 | M30: 97 | N30: 0 | O30: 0 | P30: 0 | Q30: =SUM(F30+I30+J30+K30+L30+M30+N30+O30+P30) -> 3984
C31: नायब तहसिलदार (उल्हासनगर) | D31: 1 | E31: 1 | F31: 0 | G31: 675 | H31: 0 | I31: =SUM(G31:H31) -> 675 | J31: =ROUND(I31*0.7,0) -> 473 | K31: 3 | L31: 202 | M31: 32 | N31: 0 | O31: 0 | P31: 0 | Q31: =SUM(F31+I31+J31+K31+L31+M31+N31+O31+P31) -> 1385
C32: लेखाधिकारी | D32: 1 | E32: 1 | F32: 0 | G32: 870 | H32: 0 | I32: =SUM(G32:H32) -> 870 | J32: =ROUND(I32*0.7,0) -> 609 | K32: 4 | L32: 261 | M32: 65 | N32: 0 | O32: 0 | P32: 0 | Q32: =SUM(F32+I32+J32+K32+L32+M32+N32+O32+P32) -> 1809
C33: रचना सहायक | D33: 1 | E33: 1 | F33: 0 | G33: 487 | H33: 0 | I33: =SUM(G33:H33) -> 487 | J33: =ROUND(I33*0.7,0) -> 341 | K33: 3 | L33: =ROUND(I33*0.3,0) -> 146 | M33: 32 | N33: 0 | O33: 0 | P33: 0 | Q33: =SUM(F33+I33+J33+K33+L33+M33+N33+O33+P33) -> 1009
C34: सहाय्यक लेखाधिकारी | D34: 1 | E34: 1 | F34: 0 | G34: 512 | H34: 0 | I34: =SUM(G34:H34) -> 512 | J34: =ROUND(I34*0.7,0) -> 358 | K34: 3 | L34: =ROUND(I34*0.3,0) -> 154 | M34: 32 | N34: 0 | O34: 0 | P34: 0 | Q34: =SUM(F34+I34+J34+K34+L34+M34+N34+O34+P34) -> 1059
C35: विधी अधिकारी (मानधन) | D35: 1 | E35: 1 | F35: 0 | G35: 0 | H35: 0 | I35: =SUM(G35:H35) -> 0 | J35: =ROUND(I35*0.7,0) -> 0 | K35: 0 | L35: 0 | M35: 0 | N35: 0 | O35: 0 | P35: 0 | Q35: =SUM(F35+I35+J35+K35+L35+M35+N35+O35+P35) -> 0
C36: एकूण (वर्ग-1 व 2) | D36: =D26+D27+D28+D29+D30+D31+D32+D33+D34+D35 -> 13 | E36: =E26+E27+E28+E29+E30+E31+E32+E33+E34+E35 -> 13 | F36: =F26+F27+F28+F29+F30+F31+F32+F33+F34+F35 -> 0 | G36: =G26+G27+G28+G29+G30+G31+G32+G33+G34+G35 -> 11029 | H36: =H26+H27+H28+H29+H30+H31+H32+H33+H34+H35 -> 0 | I36: =I26+I27+I28+I29+I30+I31+I32+I33+I34+I35 -> 11029 | J36: =J26+J27+J28+J29+J30+J31+J32+J33+J34+J35 -> 7722 | K36: =K26+K27+K28+K29+K30+K31+K32+K33+K34+K35 -> 43 | ... Q36: =Q26+Q27+Q28+Q29+Q30+Q31+Q32+Q33+Q34+Q35 -> 22554
A37: 2 | B37: वर्ग-3 | C37: उपलेखापाल | D37: 1 | E37: 1 | F37: 0 | G37: 534 | H37: 0 | I37: =SUM(G37:H37) -> 534 | J37: =ROUND(I37*0.7,0) -> 374 | K37: 4 | L37: =ROUND(I37*0.3,0) -> 160 | M37: 33 | N37: 0 | O37: 0 | P37: 0 | Q37: =SUM(F37+I37+J37+K37+L37+M37+N37+O37+P37) -> 1105
C38: लघुलेखक (निवड श्रेणी) | D38: 1 | E38: 1 | F38: 0 | G38: 1259 | H38: 0 | I38: =SUM(G38:H38) -> 1259 | J38: =ROUND(I38*0.7,0) -> 881 | K38: 3 | L38: =ROUND(I38*0.3,0) -> 378 | M38: 33 | N38: 0 | O38: 0 | P38: 0 | Q38: =SUM(F38+I38+J38+K38+L38+M38+N38+O38+P38) -> 2554
C39: लघुलेखक (निम्न) | D39: 2 | E39: 2 | F39: 0 | G39: 1495 | H39: 0 | I39: =SUM(G39:H39) -> 1495 | J39: =ROUND(I39*0.7,0) -> 1047 | K39: 7 | L39: =ROUND(I39*0.3,0) -> 449 | M39: 97 | N39: 0 | O39: 0 | P39: 0 | Q39: =SUM(F39+I39+J39+K39+L39+M39+N39+O39+P39) -> 3095
C40: लघुलेखक (उ.वि.उल्हासनगर) | D40: 1 | E40: 1 | F40: 0 | G40: 473 | H40: 0 | I40: =SUM(G40:H40) -> 473 | J40: =ROUND(I40*0.7,0) -> 331 | K40: 3 | L40: =ROUND(I40*0.3,0) -> 142 | M40: 32 | N40: 0 | O40: 0 | P40: 0 | Q40: =SUM(F40+I40+J40+K40+L40+M40+N40+O40+P40) -> 981
C41: लघु टंकलेखक | D41: 1 | E41: 1 | F41: 0 | G41: 312 | H41: 0 | I41: =SUM(G41:H41) -> 312 | J41: =ROUND(I41*0.7,0) -> 218 | K41: 4 | L41: =ROUND(I41*0.3,0) -> 94 | M41: 32 | N41: 0 | O41: 0 | P41: 0 | Q41: =SUM(F41+I41+J41+K41+L41+M41+N41+O41+P41) -> 660
...

Sheet Page 2
A1: अर्थसंकल्पीय अंदाजपत्रक सन 2026-2027(प्रपत्र क)
A2: मागणी क्र.सी- 1- लेखाशिर्ष 20530387
A3: (आकडे हजारात)
A4: जिल्हा | B4: स्थायी पदे
C5: भरलेली पदे | G5: रिक्त पदे | K5: एकूण
A6: अपर आयुक्त (सा.प्र.) | B6: वर्ग | C6: वर्ग-1 व 2 | D6: वर्ग-3 | E6: वर्ग-4 | F6: एकूण | G6: वर्ग-1 व 2 | H6: वर्ग-3 | I6: वर्ग-4 | J6: एकूण | K6: एकूण
B7: पदे | C7: 6 | D7: 40 | E7: 14 | F7: =SUM(C7:E7) -> 60 | G7: 1 | H7: 1 | I7: 4 | J7: =SUM(G7:I7) -> 6 | K7: =SUM(J7,F7) -> 66
B8: वेतन | C8: 6877 | D8: 19056 | E8: 6098 | F8: =SUM(C8:E8) -> 32031 | G8: 695 | H8: 442 | I8: 793 | J8: =SUM(G8:I8) -> 1930 | K8: =SUM(J8,F8) -> 33961
B9: ग्रेड पे | C9: 0 | D9: 0 | E9: 0 | F9: =SUM(C9:E9) -> 0 | G9: 0 | H9: 0 | I9: 0 | J9: =SUM(G9:I9) -> 0 | K9: =SUM(J9,F9) -> 0
B10: एकूण | C10: =SUM(C8:C9) -> 6877 | D10: =SUM(D8:D9) -> 19056 | E10: =SUM(E8:E9) -> 6098 | F10: =SUM(C10:E10) -> 32031 | G10: =SUM(G8:G9) -> 695 | H10: =SUM(H8:H9) -> 442 | I10: =SUM(I8:I9) -> 793 | J10: =SUM(J8:J9) -> 1930 | K10: =SUM(K8:K9) -> 33961
B11: विशेष वेतन | C11: 0 | D11: 0 | E11: 0 | F11: =SUM(C11:E11) -> 0 | G11: 0 | H11: 0 | I11: 0 | J11: =SUM(G11:I11) -> 0 | K11: =SUM(J11,F11) -> 0
B12: महा.भत्ता | C12: 4814 | D12: 13339 | E12: 4269 | F12: =SUM(C12:E12) -> 22422 | G12: 486 | H12: 309 | I12: 556 | J12: =SUM(G12:I12) -> 1351 | K12: =SUM(J12,F12) -> 23773
B13: स्था.पु.भ. | C13: 22 | D13: 144 | E13: 59 | F13: =SUM(C13:E13) -> 225 | G13: 4 | H13: 4 | I13: 14 | J13: =SUM(G13:I13) -> 22 | K13: =SUM(J13,F13) -> 247
B14: घरभाडे | C14: 1197 | D14: 4424 | E14: 1408 | F14: =SUM(C14:E14) -> 7029 | G14: 209 | H14: 133 | I14: 238 | J14: =SUM(G14:I14) -> 580 | K14: =SUM(J14,F14) -> 7609
B15: प्रवास भत्ता | C15: 162 | D15: 1275 | E15: 457 | F15: =SUM(C15:E15) -> 1894 | G15: 32 | H15: 32 | I15: 48 | J15: =SUM(G15:I15) -> 112 | K15: =SUM(J15,F15) -> 2006
B16: इतर | C16: 0 | D16: 0 | E16: 42 | F16: =SUM(C16:E16) -> 42 | G16: 0 | H16: 0 | I16: 12 | J16: =SUM(G16:I16) -> 12 | K16: =SUM(J16,F16) -> 54
B17: एकूण | C17: =SUM(C10:C16) -> 13072 | D17: =SUM(D10:D16) -> 38238 | E17: =SUM(E10:E16) -> 12333 | F17: =SUM(F10:F16) -> 63643 | G17: =SUM(G10:G16) -> 1426 | H17: =SUM(H10:H16) -> 920 | I17: =SUM(I10:I16) -> 1661 | J17: =SUM(J10:J16) -> 4007 | K17: =SUM(K10:K16) -> 67650
A19: जिल्हा | B19: अस्थायी पदे | M19: सर्व वर्ग पदे
C20: भरलेली पदे | G20: रिक्त पदे | K20: एकूण | M20: वर्ग | N20: स्थायी पदे | O20: अस्थायी पदे | P20: एकूण
A21: अपर आयुक्त (सा.प्र.) | B21: वर्ग | C21: वर्ग-1 व 2 | D21: वर्ग-3 | E21: वर्ग-4 | F21: एकूण | G21: वर्ग-1 व 2 | H21: वर्ग-3 | I21: वर्ग-4 | J21: एकूण | K21: एकूण | M21: पदे | N21: =K7 -> 66 | O21: =K22 -> 59 | P21: =SUM(N21:O21) -> 125
B22: पदे | C22: 9 | D22: 9 | E22: 12 | F22: =SUM(C22:E22) -> 30 | G22: 4 | H22: 12 | I22: 13 | J22: =SUM(G22:I22) -> 29 | K22: =SUM(J22,F22) -> 59 | M22: वेतन | N22: =K8 -> 33961 | O22: =K23 -> 27282 | P22: =SUM(N22:O22) -> 61243
B23: वेतन | C23: 8764 | D23: 5719 | E23: 4408 | F23: =SUM(C23:E23) -> 18891 | G23: 2265 | H23: 3290 | I23: 2836 | J23: =SUM(G23:I23) -> 8391 | K23: =SUM(J23,F23) -> 27282 | M23: ग्रेड पे | N23: =K9 -> 0 | O23: =K24 -> 0 | P23: =SUM(N23:O23) -> 0
B24: ग्रेड पे | C24: 0 | D24: 0 | E24: 0 | F24: =SUM(C24:E24) -> 0 | G24: 0 | H24: 0 | I24: 0 | J24: =SUM(G24:I24) -> 0 | K24: =SUM(J24,F24) -> 0 | M24: एकूण | N24: =K10 -> 33961 | O24: =K25 -> 27282 | P24: =SUM(P22:P23) -> 61243
B25: एकूण | C25: =SUM(C23:C24) -> 8764 | D25: =SUM(D23:D24) -> 5719 | E25: =SUM(E23:E24) -> 4408 | F25: =SUM(C25:E25) -> 18891 | G25: =SUM(G23:G24) -> 2265 | H25: =SUM(H23:H24) -> 3290 | I25: =SUM(I23:I24) -> 2836 | J25: =SUM(J23:J24) -> 8391 | K25: =SUM(K23:K24) -> 27282 | M25: विशेष वेतन | N25: =K11 -> 0 | O25: =K26 -> 0 | P25: =SUM(N25:O25) -> 0
B26: विशेष वेतन | C26: 0 | D26: 0 | E26: 0 | F26: =SUM(C26:E26) -> 0 | G26: 0 | H26: 0 | I26: 0 | J26: =SUM(G26:I26) -> 0 | K26: =SUM(J26,F26) -> 0 | M26: महा.भत्ता | N26: =K12 -> 23773 | O26: =K27 -> 19099 | P26: =SUM(N26:O26) -> 42872
B27: महा.भत्ता | C27: 6136 | D27: 4003 | E27: 3086 | F27: =SUM(C27:E27) -> 13225 | G27: 1586 | H27: 2302 | I27: 1986 | J27: =SUM(G27:I27) -> 5874 | K27: =SUM(J27,F27) -> 19099 | M27: स्था.पु.भ. | N27: =K13 -> 247 | O27: =K28 -> 208 | P27: =SUM(N27:O27) -> 455
B28: स्था.पु.भ. | C28: 32 | D28: 32 | E28: 43 | F28: =SUM(C28:E28) -> 107 | G28: 11 | H28: 43 | I28: 47 | J28: =SUM(G28:I28) -> 101 | K28: =SUM(J28,F28) -> 208 | M28: घरभाडे | N28: =K14 -> 7609 | O28: =K29 -> 7593 | P28: =SUM(N28:O28) -> 15202
B29: घरभाडे | C29: 2629 | D29: 1402 | E29: 1044 | F29: =SUM(C29:E29) -> 5075 | G29: 680 | H29: 987 | I29: 851 | J29: =SUM(G29:I29) -> 2518 | K29: =SUM(J29,F29) -> 7593 | M29: प्रवास भत्ता | N29: =K15 -> 2006 | O29: =K30 -> 1506 | P29: =SUM(N29:O29) -> 3512
B30: प्रवास भत्ता | C30: 324 | D30: 324 | E30: 307 | F30: =SUM(C30:E30) -> 955 | G30: 129 | H30: 205 | I30: 217 | J30: =SUM(G30:I30) -> 551 | K30: =SUM(J30,F30) -> 1506 | M30: इतर | N30: =K16 -> 54 | O30: =K31 -> 87 | P30: =SUM(N30:O30) -> 141
B31: इतर | C31: 0 | D31: 12 | E31: 36 | F31: =SUM(C31:E31) -> 48 | G31: 0 | H31: 0 | I31: 39 | J31: =SUM(G31:I31) -> 39 | K31: =SUM(J31,F31) -> 87 | M31: एकूण | N31: =SUM(N24:N30) -> 67650 | O31: =SUM(O24:O30) -> 55775 | P31: =SUM(P24:P30) -> 123425
B32: एकूण | C32: =SUM(C25:C31) -> 17885 | D32: =SUM(D25:D31) -> 11492 | E32: =SUM(E25:E31) -> 8924 | F32: =SUM(F25:F31) -> 38301 | G32: =SUM(G25:G31) -> 4671 | H32: =SUM(H25:H31) -> 6827 | I32: =SUM(I25:I31) -> 5976 | J32: =SUM(J25:J31) -> 17474 | K32: =SUM(K25:K31) -> 55775
A34: अर्थसंकल्पीय अंदाजपत्रक सन 2026-2027(प्रपत्र क)
A35: मागणी क्र.सी- 1- लेखाशिर्ष 20530387
A36: (आकडे हजारात)
A37: विभाग | B37: स्थायी पदे
C38: भरलेली पदे | G38: रिक्त पदे | K38: एकूण
A39: कोकण विभाग | B39: वर्ग | C39: वर्ग-1 व 2 | D39: वर्ग-3 | E39: वर्ग-4 | F39: एकूण | G39: वर्ग-1 व 2 | H39: वर्ग-3 | I39: वर्ग-4 | J39: एकूण | K39: एकूण
B40: पदे | C40: =C7 -> 6 | D40: =D7 -> 40 | E40: =E7 -> 14 | F40: =F7 -> 60 | G40: =G7 -> 1 | H40: =H7 -> 1 | I40: =I7 -> 4 | J40: =J7 -> 6 | K40: =K7 -> 66
B41: वेतन | C41: =C8 -> 6877 | D41: =D8 -> 19056 | E41: =E8 -> 6098 | F41: =F8 -> 32031 | G41: =G8 -> 695 | H41: =H8 -> 442 | I41: =I8 -> 793 | J41: =J8 -> 1930 | K41: =K8 -> 33961
B42: ग्रेड पे | C42: =C9 -> 0 | D42: =D9 -> 0 | E42: =E9 -> 0 | F42: =F9 -> 0 | G42: =G9 -> 0 | H42: =H9 -> 0 | I42: =I9 -> 0 | J42: =J9 -> 0 | K42: =K9 -> 0
...

Sheet Page 3
A1: अर्थसंकल्पीय अंदाजपत्रक सन 2026-2027(प्रपत्र ब)
A2: मागणी क्र.सी- 1- लेखाशिर्ष 20530387
A3: मंजूर पदे
A4: अ.क्र. | B4: वर्ग | C4: स्थायी | E4: अस्थायी | G4: एकूण
C5: भरलेली पदे | D5: रिक्त पदे | E5: भरलेली पदे | F5: रिक्त पदे
A6: 1 | B6: 1 | C6: 4 | D6: 1 | E6: 4 | F6: 1 | G6: =SUM(C6:F6) -> 10
A7: 2 | B7: 2 | C7: 2 | D7: 0 | E7: 5 | F7: 3 | G7: =SUM(C7:F7) -> 10
A8: 3 | B8: 3 | C8: 40 | D8: 1 | E8: 9 | F8: 12 | G8: =SUM(C8:F8) -> 62
A9: 4 | B9: 4 | C9: 14 | D9: 4 | E9: 12 | F9: 13 | G9: =SUM(C9:F9) -> 43
A10: -- | B10: एकूण | C10: =SUM(C6:C9) -> 60 | D10: =SUM(D6:D9) -> 6 | E10: =SUM(E6:E9) -> 30 | F10: =SUM(F6:F9) -> 29 | G10: =SUM(G6:G9) -> 125
F13: (आकडे हजारात)
A14: अ.क्र. | B14: जिल्हा / विभाग | C14: वैद्यकिय खर्च | D14: उत्सव/सण अग्रिम | E14: स्वग्राम/महाराष्ट्र दर्शन | F14: NPS | G14: इतर | H14: एकूण
A15: 1 | B15: अपर आयुक्त (सा.प्र.) | C15: 3000 | D15: 1300 | E15: 250 | F15: 7763 | G15: 8000 | H15: =SUM(C15:G15) -> 20313
A17: अर्थसंकल्पीय अंदाजपत्रक सन 2026-2027(प्रपत्र ब)
A18: मागणी क्र.सी- 1- लेखाशिर्ष 20530387
A19: मंजूर पदे
A20: अ.क्र. | B20: वर्ग | C20: स्थायी | E20: अस्थायी | G20: एकूण
C21: भरलेली पदे | D21: रिक्त पदे | E21: भरलेली पदे | F21: रिक्त पदे
A22: 1 | B22: 1 | C22: =C6 -> 4 | D22: =D6 -> 1 | E22: =E6 -> 4 | F22: =F6 -> 1 | G22: =G6 -> 10
A23: 2 | B23: 2 | C23: =C7 -> 2 | D23: =D7 -> 0 | E23: =E7 -> 5 | F23: =F7 -> 3 | G23: =G7 -> 10
A24: 3 | B24: 3 | C24: =C8 -> 40 | D24: =D8 -> 1 | E24: =E8 -> 9 | F24: =F8 -> 12 | G24: =G8 -> 62
A25: 4 | B25: 4 | C25: =C9 -> 14 | D25: =D9 -> 4 | E25: =E9 -> 12 | F25: =F9 -> 13 | G25: =G9 -> 43
A26: -- | B26: एकूण | C26: =SUM(C22:C25) -> 60 | D26: =SUM(D22:D25) -> 6 | E26: =SUM(E22:E25) -> 30 | F26: =SUM(F22:F25) -> 29 | G26: =SUM(G22:G25) -> 125
F29: (आकडे हजारात)
A30: अ.क्र. | B30: जिल्हा / विभाग | C30: वैद्यकिय खर्च | D30: उत्सव/सण अग्रिम | E30: स्वग्राम/महाराष्ट्र दर्शन | F30: NPS | G30: इतर | H30: एकूण
A31: 1 | B31: कोकण विभाग | C31: =C15 -> 3000 | D31: =D15 -> 1300 | E31: =E15 -> 250 | F31: =F15 -> 7763 | G31: =G15 -> 8000 | H31: =SUM(C31:G31) -> 20313
F35: सहाय्यक संचालक(लेखा)कोकण विभाग

Sheet Page 4
A1: अर्थसंकल्पीय अंदाजपत्रक सन 2026-2027(प्रपत्र अ)
A2: मागणी क्र.सी- 1- लेखाशिर्ष 20530387
A3: अपर आयुक्त (सा.प्र.) कोकण विभाग | L3: (आकडे हजारात)
A4: अ. क्र. | B4: लेख्याची प्राथमिक आणि दुय्यम युनिट | C4: प्रत्यक्ष रक्कमा (खर्च) | F4: अर्थसंकल्पीय अंदाज | G4: सुधारीत अंदाज | H4: अर्थसंकल्पीय अंदाज 2026-2027 | L4: मागील वर्षाच्या प्रत्यक्ष रक्कमा आणि चालु वर्षाच्या अर्थसंकल्पीय अंदाजाची तुलना करता आगामी वर्षासाठीच्या अंदाजातील वाढ किंवा घट यांच्या संबंधातील स्पष्टीकरणे.
C5: 2022-2023 | D5: 2023-2024 | E5: 2024-2025 | F5: 2025-2026 | G5: 2025-2026 | H5: प्राकक्लन (एस्टिमेटिंग) अधिका-याचा | I5: नियंत्रक अधिका-यांचा | J5: प्रशासकीय विभागाचा | K5: वित्त विभागाचा
A6: 1 | B6: 2 | C6: 3 | D6: 4 | E6: 5 | F6: 6 | G6: 7 | H6: 8 | I6: 9 | J6: 10 | K6: 11 | L6: 12
A7: 1 | B7: 01- वेतन | C7: 94361 | D7: 98690 | E7: 109877 | F7: 136100 | G7: 136100 | H7: 143738 | I7: 0 | J7: 0 | K7: 0 | L7: (1) अधिकारी व कर्मचारी यांचे सातव्या वेतन आयोगानुसार वेतन व भत्ते अदा करण्याकरीता. वेळोवेळी होणारी वेतनवाढ व महागाई भत्ता दराप्रमाणे वाढीव अनुदान मिळणेस विनंती आहे. (2) प्रतिक्षाधीन कालावधीचे वेतन, आश्वासित प्रगती योजनेच्या लाभाचे वेतन व अतिरिक्त कार्यभाराचे विशेष वेतन इ.साठी आवश्यकता आहे.
A8: 2 | B8: 03- अति. भत्ता | C8: 17 | D8: 29 | E8: 41 | F8: 150 | G8: 150 | H8: 150 | I8: 0 | J8: 0 | K8: 0 | L8: शासनाने ठरवून दिलेल्या वाढीव महसूल उद्दिष्ट पुर्ततेबाबत वाहन चालकांना मा.आयुक्त, उपआयुक्त या दर्जाच्या अधिकाऱ्यांसोबत फिरती करावी लागते.
A9: 3 | B9: 06- दूरध्वनी, वीज,पाणी व शुल्क | C9: 3650 | D9: 3836 | E9: 3360 | F9: 4300 | G9: 4300 | H9: 5790 | I9: 0 | J9: 0 | K9: 0 | L9: (1) या बाबीखाली जिल्हा कार्यालयाशी मोठया प्रमाणावर संपर्क साधण्यासाठी, इंटरनेटसाठी दूरध्वनीचा वापर करावा लागतो. (2) मुंबई येथील विभागीय आयुक्त कार्यालयातील वीज देयक अदा करणेसाठी अनुदानाची आवश्यकता आहे. (3) कोकण भवन इमारतीच्या पाण्याचे पंप,उद्ववाहने, प्रसाधन गृहे, चौक, पॅसेज, छन्नमार्ग, आवारातील लाईटस् यासाठी लागणाच्या वीजेची देयके भरण्यासाठी दर महा अंदाजे रक्कम रु. 3,00,000/- प्रमाणे वार्षिक रक्कम रु.42,00,000/- वाढीव अनुदानाची गरज आहे. हॉटलाईन टेलिफोन करीता अंदाजित 90,000/- अनुदानाची आवश्यकता आहे. (4) कोकण भवन इमारतीचे पाणी देयक भरणेसाठी वार्षिक अंदाजे र.रु.12,00,000/- इतक्या अनुदानाची आवश्यकता आहे. (5) विजेचे वाढलेले दर व पाणी पट्टीची वाढीव देयके यासाठी वाढीव अनुदानाची आवश्यकता आहे.
A10: 4 | B10: 10- कंत्राटी सेवा | C10: 19040 | D10: 13219 | E10: 3420 | F10: 16000 | G10: 16000 | H10: 17600 | I10: 0 | J10: 0 | K10: 0 | L10: (1) कोंकण भवन इमारतीची साफसफाई यांत्रिकी पध्दतीने करणेच्या कामासाठी अंदाजित रक्कम रूपये 1,70,00,000/- एवढया रकमेची आवश्यकता आहे. (2) शासन, वित्त विभाग, शासन परिपत्रक क्र : संकीर्ण-2019/ प्र.क्र.22 /कोषा प्रशा-4 दि.13/08/2020 अन्वये विधी अधिकारी या (कंत्राटी)पदाच्या मानधना करीता र.रू.6,00,000/- तरतुद करण्यात आली आहे.
A11: 5 | B11: 11- देशांतर्गत प्रवास खर्च | C11: 89 | D11: 303 | E11: 301 | F11: 500 | G11: 500 | H11: 500 | I11: 0 | J11: 0 | K11: 0 | L11: कार्यालयीन अधिकारी/कर्मचारी यांच्या प्रवास खर्चाकरीता
A12: 6 | B12: 13- कार्यालयीन खर्च | C12: 3283 | D12: 4254 | E12: 2282 | F12: 4500 | G12: 4500 | H12: 4700 | I12: 0 | J12: 0 | K12: 0 | L12: (1) कार्यालयीन खर्चासाठी स्टेशनरी, जडसंग्रह वस्तु,झेरॉक्स व इतर खर्च, विविध प्रकारच्या बैठका आयोजीत करण्याकरीता, निवासी दुरध्वनी देयके, वाहन खरेदी, छपाई खर्च अदा करण्याकरीता अंदाजित र.रु.44,10,000/-ची आवश्यकता आहे. (2) कोंकण भवन प्रशासकीय इमारतीवर दररोज राष्ट्रध्वज लावणेकामी व ध्वजदोरी खरेदी करणेकरीता अंदाजित रक्कम रुपये 1,90,000/- एवढया रकमेची तरतूद आवश्यक आहे. (3) विद्युत साहित्याची खरेदी, जंयती दिनाचे कार्यक्रम, टीसीएल पावडरची खरेदी व इतर कार्यालयीन खर्चाकरीता अंदाजित र.रु.1,00,000/- अ‍नुदान आवश्यक आहे.
A13: 7 | B13: 14- भाडेपट्टी व कर | C13: 92 | D13: 310 | E13: 761 | F13: 500 | G13: 500 | H13: 400 | I13: 0 | J13: 0 | K13: 0 | L13: विभागीय आयुक्त कार्यालयाच्या हिश्याचा वार्षिक मालमत्ता कर देयक भरणे करीता अनुदान आवश्यक आहे.
A14: 8 | B14: 16- प्रकाशने | C14: 0 | D14: 0 | E14: 0 | F14: 1 | G14: 1 | H14: 150 | I14: 0 | J14: 0 | K14: 0 | L14: विविध प्रकारच्या छपाईच्या देयक प्रदाणाकरीता नवीन बाब निर्माण करण्यासाठी टोकन रक्कमेची आवश्यकता आहे.
A15: 9 | B15: 17- संगणक खर्च | C15: 215 | D15: 355 | E15: 583 | F15: 700 | G15: 700 | H15: 1200 | I15: 0 | J15: 0 | K15: 0 | L15: संगणक, टोनर रिफिलींग / देखभाल, इतर दुरुस्तीसाठी अंदाजे र.रू.8,00,000/- तसेच, नवीन संगणक व प्रिंटर्स खरेदीसाठी अंदाजे र.रू.4,00,000/- ची आवश्यकता आहे.
A16: 10 | B16: 20- इतर प्रशासकीय खर्च | C16: 0 | D16: 0 | E16: 0 | F16: 1 | G16: 1 | H16: 50 | I16: 0 | J16: 0 | K16: 0 | L16: विविध प्रकारच्या बैठकाया कार्यालयात आयोजीत केल्या जातात त्यावेळी उपस्थिताकरीता चहा/नास्ता मागविण्यात येता त्याच्या खर्चासाठी देयक प्रदाणाकरीता नवीन बाब निर्माण करण्यासाठी टोकन रक्कमेची आवश्यकता आहे.
A17: 11 | B17: 24- इंधन खर्च | C17: 0 | D17: 0 | E17: 160 | F17: 225 | G17: 225 | H17: 600 | I17: 0 | J17: 0 | K17: 0 | L17: 4 वाहनांकरीता पेट्रोल व डिझेल खर्चे
A18: 12 | B18: 26- जाहिरात व प्रसिध्दी खर्च | C18: 0 | D18: 0 | E18: 0 | F18: 1 | G18: 1 | H18: 100 | I18: 0 | J18: 0 | K18: 0 | L18: जाहिरात प्रसिध्द करण्याकरीता आवश्यक खर्च नवीन बाब निर्माण करण्यासाठी टोकन रक्कमेची आवश्यकता आहे.
... A21: 15 | B21: 51- मोटार वाहने | C21: 0 | D21: 0 | E21: 0 | F21: 21 | G21: 21 | H21: 200 | I21: 0 | J21: 0 | K21: 0 | L21: वाहन दुरस्ती करीता
A22: -- | B22: एकूण | C22: =SUM(C7:C21) -> 120747 | D22: =SUM(D7:D21) -> 120996 | E22: =SUM(E7:E21) -> 120785 | F22: =SUM(F7:F21) -> 163000 | G22: =SUM(G7:G21) -> 163000 | H22: =SUM(H7:H21) -> 175188 | I22: =SUM(I7:I21) -> 0 | J22: =SUM(J7:J21) -> 0 | K22: =SUM(K7:K21) -> 0
A24: अर्थसंकल्पीय अंदाजपत्रक सन 2026-2027(प्रपत्र अ)
A25: मागणी क्र.सी- 1- लेखाशिर्ष 20530387
A26: कोकण विभाग | L26: (आकडे हजारात)
A27: अ. क्र. | B27: लेख्याची प्राथमिक आणि दुय्यम युनिट | C27: प्रत्यक्ष रक्कमा (खर्च) | F27: अर्थसंकल्पीय अंदाज | G27: सुधारीत अंदाज | H27: अर्थसंकल्पीय अंदाज 2026-2027 | L27: मागील वर्षाच्या प्रत्यक्ष रक्कमा आणि चालु वर्षाच्या अर्थसंकल्पीय अंदाजाची तुलना करता आगामी वर्षासाठीच्या अंदाजातील वाढ किंवा घट यांच्या संबंधातील स्पष्टीकरणे.
C28: 2021-2022 | D28: 2022-2023 | E28: 2023-2024 | F28: 2024-2025 | G28: 2024-2025 | H28: प्राकक्लन (एस्टिमेटिंग) अधिका-याचा | I28: नियंत्रक अधिका-यांचा | J28: प्रशासकीय विभागाचा | K28: वित्त विभागाचा
A29: 1 | B29: 2 | C29: 3 | D29: 4 | E29: 5 | F29: 6 | G29: 7 | H29: 8 | I29: 9 | J29: 10 | K29: 11 | L29: 12
A30: 1 | B30: 01- वेतन | C30: =C7 -> 94361 | D30: =D7 -> 98690 | E30: =E7 -> 109877 | F30: =F7 -> 136100 | G30: =G7 -> 136100 | H30: =H7 -> 143738 | I30: =I7 -> 0 | J30: =J7 -> 0 | K30: =K7 -> 0 | L30: (1) अधिकारी व कर्मचारी यांचे सातव्या वेतन आयोगानुसार वेतन व भत्ते अदा करण्याकरीता. वेळोवेळी होणारी वेतनवाढ व महागाई भत्ता दराप्रमाणे वाढीव अनुदान मिळणेस विनंती आहे. (2) प्रतिक्षाधीन कालावधीचे वेतन, आश्वासित प्रगती योजनेच्या लाभाचे वेतन व अतिरिक्त कार्यभाराचे विशेष वेतन इ.साठी आवश्यकता आहे.
A31: 2 | B31: 03- अति. भत्ता | C31: =C8 -> 17 | D31: =D8 -> 29 | E31: =E8 -> 41 | F31: =F8 -> 150 | G31: =G8 -> 150 | H31: =H8 -> 150 | I31: =I8 -> 0 | J31: =J8 -> 0 | K31: =K8 -> 0 | L31: शासनाने ठरवून दिलेल्या वाढीव महसूल उद्दिष्ट पुर्ततेबाबत वाहन चालकांना मा.आयुक्त, उपआयुक्त या दर्जाच्या अधिकाऱ्यांसोबत फिरती करावी लागते.
A32: 3 | B32: 06- दूरध्वनी, वीज,पाणी व शुल्क | C32: =C9 -> 3650 | D32: =D9 -> 3836 | E32: =E9 -> 3360 | F32: =F9 -> 4300 | G32: =G9 -> 4300 | H32: =H9 -> 5790 | I32: =I9 -> 0 | J32: =J9 -> 0 | K32: =K9 -> 0 | L32: (1) या बाबीखाली जिल्हा कार्यालयाशी मोठया प्रमाणावर संपर्क साधण्यासाठी, इंटरनेटसाठी दूरध्वनीचा वापर करावा लागतो. (2) मुंबई येथील विभागीय आयुक्त कार्यालयातील वीज देयक अदा करणेसाठी अनुदानाची आवश्यकता आहे. (3) कोकण भवन इमारतीच्या पाण्याचे पंप,उद्ववाहने, प्रसाधन गृहे, चौक, पॅसेज, छन्नमार्ग, आवारातील लाईटस् यासाठी लागणाच्या वीजेची देयके भरण्यासाठी दर महा अंदाजे रक्कम रु. 3,00,000/- प्रमाणे वार्षिक रक्कम रु.42,00,000/- वाढीव अनुदानाची गरज आहे. हॉटलाईन टेलिफोन करीता अंदाजित 90,000/- अनुदानाची आवश्यकता आहे. (4) कोकण भवन इमारतीचे पाणी देयक भरणेसाठी वार्षिक अंदाजे र.रु.12,00,000/- इतक्या अनुदानाची आवश्यकता आहे. (5) विजेचे वाढलेले दर व पाणी पट्टीची वाढीव देयके यासाठी वाढीव अनुदानाची आवश्यकता आहे.
A33: 4 | B33: 10- कंत्राटी सेवा | C33: =C10 -> 19040 | D33: =D10 -> 13219 | E33: =E10 -> 3420 | F33: =F10 -> 16000 | G33: =G10 -> 16000 | H33: =H10 -> 17600 | I33: =I10 -> 0 | J33: =J10 -> 0 | K33: =K10 -> 0 | L33: (1) कोंकण भवन इमारतीची साफसफाई यांत्रिकी पध्दतीने करणेच्या कामासाठी अंदाजित रक्कम रूपये 1,70,00,000/- एवढया रकमेची आवश्यकता आहे. (2) शासन, वित्त विभाग, शासन परिपत्रक क्र : संकीर्ण-2019/ प्र.क्र.22 /कोषा प्रशा-4 दि.13/08/2020 अन्वये विधी अधिकारी या (कंत्राटी)पदाच्या मानधना करीता र.रू.6,00,000/- तरतुद करण्यात आली आहे.
A34: 5 | B34: 11- देशांतर्गत प्रवास खर्च | C34: =C11 -> 89 | D34: =D11 -> 303 | E34: =E11 -> 301 | F34: =F11 -> 500 | G34: =G11 -> 500 | H34: =H11 -> 500 | I34: =I11 -> 0 | J34: =J11 -> 0 | K34: =K11 -> 0 | L34: कार्यालयीन अधिकारी/कर्मचारी यांच्या प्रवास खर्चाकरीता
A35: 6 | B35: 13- कार्यालयीन खर्च | C35: =C12 -> 3283 | D35: =D12 -> 4254 | E35: =E12 -> 2282 | F35: =F12 -> 4500 | G35: =G12 -> 4500 | H35: =H12 -> 4700 | I35: =I12 -> 0 | J35: =J12 -> 0 | K35: =K12 -> 0 | L35: (1) कार्यालयीन खर्चासाठी स्टेशनरी, जडसंग्रह वस्तु,झेरॉक्स व इतर खर्च, विविध प्रकारच्या बैठका आयोजीत करण्याकरीता, निवासी दुरध्वनी देयके, वाहन खरेदी, छपाई खर्च अदा करण्याकरीता अंदाजित र.रु.44,10,000/-ची आवश्यकता आहे. (2) कोंकण भवन प्रशासकीय इमारतीवर दररोज राष्ट्रध्वज लावणेकामी व ध्वजदोरी खरेदी करणेकरीता अंदाजित रक्कम रुपये 1,90,000/- एवढया रकमेची तरतूद आवश्यक आहे. (3) विद्युत साहित्याची खरेदी, जंयती दिनाचे कार्यक्रम, टीसीएल पावडरची खरेदी व इतर कार्यालयीन खर्चाकरीता अंदाजित र.रु.1,00,000/- अ‍नुदान आवश्यक आहे.
A36: 7 | B36: 14- भाडेपट्टी व कर | C36: =C13 -> 92 | D36: =D13 -> 310 | E36: =E13 -> 761 | F36: =F13 -> 500 | G36: =G13 -> 500 | H36: =H13 -> 400 | I36: =I13 -> 0 | J36: =J13 -> 0 | K36: =K13 -> 0 | L36: विभागीय आयुक्त कार्यालयाच्या हिश्याचा वार्षिक मालमत्ता कर देयक भरणे करीता अनुदान आवश्यक आहे.
A37: 8 | B37: 16- प्रकाशने | C37: =C14 -> 0 | D37: =D14 -> 0 | E37: =E14 -> 0 | F37: =F14 -> 1 | G37: =G14 -> 1 | H37: =H14 -> 150 | I37: =I14 -> 0 | J37: =J14 -> 0 | K37: =K14 -> 0 | L37: विविध प्रकारच्या छपाईच्या देयक प्रदाणाकरीता नवीन बाब निर्माण करण्यासाठी टोकन रक्कमेची आवश्यकता आहे.
A38: 9 | B38: 17- संगणक खर्च | C38: =C15 -> 215 | D38: =D15 -> 355 | E38: =E15 -> 583 | F38: =F15 -> 700 | G38: =G15 -> 700 | H38: =H15 -> 1200 | I38: =I15 -> 0 | J38: =J15 -> 0 | K38: =K15 -> 0 | L38: संगणक, टोनर रिफिलींग / देखभाल, इतर दुरुस्तीसाठी अंदाजे र.रू.8,00,000/- तसेच, नवीन संगणक व प्रिंटर्स खरेदीसाठी अंदाजे र.रू.4,00,000/- ची आवश्यकता आहे.
A39: 10 | B39: 20- इतर प्रशासकीय खर्च | C39: =C16 -> 0 | D39: =D16 -> 0 | E39: =E16 -> 0 | F39: =F16 -> 1 | G39: =G16 -> 1 | H39: =H16 -> 50 | I39: =I16 -> 0 | J39: =J16 -> 0 | K39: =K16 -> 0 | L39: विविध प्रकारच्या बैठकाया कार्यालयात आयोजीत केल्या जातात त्यावेळी उपस्थिताकरीता चहा/नास्ता मागविण्यात येता त्याच्या खर्चासाठी देयक प्रदाणाकरीता नवीन बाब निर्माण करण्यासाठी टोकन रक्कमेची आवश्यकता आहे.
A40: 11 | B40: 24- इंधन खर्च | C40: =C17 -> 0 | D40: =D17 -> 0 | E40: =E17 -> 160 | F40: =F17 -> 225 | G40: =G17 -> 225 | H40: =H17 -> 600 | I40: =I17 -> 0 | J40: =J17 -> 0 | K40: =K17 -> 0 | L40: 4 वाहनांकरीता पेट्रोल व डिझेल खर्चे
A41: 12 | B41: 26- जाहिरात व प्रसिध्दी खर्च | C41: =C18 -> 0 | D41: =D18 -> 0 | E41: =E18 -> 0 | F41: =F18 -> 1 | G41: =G18 -> 1 | H41: =H18 -> 100 | I41: =I18 -> 0 | J41: =J18 -> 0 | K41: =K18 -> 0 | L41: जाहिरात प्रसिध्द करण्याकरीता आवश्यक खर्च नवीन बाब निर्माण करण्यासाठी टोकन रक्कमेची आवश्यकता आहे.
... A44: 15 | B44: 51- मोटार वाहने | C44: =C21 -> 0 | D44: =D21 -> 0 | E44: =E21 -> 0 | F44: =F21 -> 21 | G44: =G21 -> 21 | H44: =H21 -> 200 | I44: =I21 -> 0 | J44: =J21 -> 0 | K44: =K21 -> 0 | L44: वाहन दुरस्ती करीता
A45: -- | B45: एकूण | C45: =SUM(C30:C44) -> 120747 | D45: =SUM(D30:D44) -> 120996 | E45: =SUM(E30:E44) -> 120785 | F45: =SUM(F30:F44) -> 163000 | G45: =SUM(G30:G44) -> 163000 | H45: =SUM(H30:H44) -> 175188 | I45: =SUM(I30:I44) -> 0 | J45: =SUM(J30:J44) -> 0 | K45: =SUM(K30:K44) -> 0
...

Sheet Page 5
A1: अर्थसंकल्पीय अंदाजपत्रक सन 2026-2027
A2: मागणी क्र.सी- 1- लेखाशिर्ष 20530387
A3: कोकण विभाग | L3: (आकडे हजारात)
A4: अ. क्र. | B4: लेख्याची प्राथमिक आणि दुय्यम युनिट | C4: प्रत्यक्ष रक्कमा (खर्च) | F4: अर्थसंकल्पीय अंदाज | G4: सुधारीत अंदाज | H4: अर्थसंकल्पीय अंदाज 2026-2027 | L4: मागील वर्षाच्या प्रत्यक्ष रक्कमा आणि चालु वर्षाच्या अर्थसंकल्पीय अंदाजाची तुलना करता आगामी वर्षासाठीच्या अंदाजातील वाढ किंवा घट यांच्या संबंधातील स्पष्टीकरणे
C5: 2022-2023 | D5: 2023-2024 | E5: 2024-2025 | F5: 2025-2026 | G5: 2025-2026 | H5: प्राकक्लन (एस्टिमेटिंग) अधिका-याचा | I5: नियंत्रक अधिका-यांचा | J5: प्रशासकीय विभागाचा | K5: वित्त विभागाचा
A6: 1 | B6: 2 | C6: 3 | D6: 4 | E6: 5 | F6: 6 | G6: 7 | H6: 8 | I6: 9 | J6: 10 | K6: 11 | L6: 12
A7: 1 | B7: 01- वेतन | C7: ='Page 4'!C30 -> 94361 | D7: ='Page 4'!D30 -> 98690 | E7: ='Page 4'!E30 -> 109877 | F7: ='Page 4'!F30 -> 136100 | G7: ='Page 4'!G30 -> 136100 | H7: 0 | I7: ='Page 4'!H30 -> 143738 | J7: ='Page 4'!J30 -> 0 | K7: ='Page 4'!K30 -> 0 | L7: (1) अधिकारी व कर्मचारी यांचे सातव्या वेतन आयोगानुसार वेतन व भत्ते अदा करण्याकरीता. वेळोवेळी होणारी वेतनवाढ व महागाई भत्ता दराप्रमाणे वाढीव अनुदान मिळणेस विनंती आहे. (2) प्रतिक्षाधीन कालावधीचे वेतन, आश्वासित प्रगती योजनेच्या लाभाचे वेतन व अतिरिक्त कार्यभाराचे विशेष वेतन इ.साठी आवश्यकता आहे.
A8: 2 | B8: 03-अति. भत्ता | C8: ='Page 4'!C31 -> 17 | D8: ='Page 4'!D31 -> 29 | E8: ='Page 4'!E31 -> 41 | F8: ='Page 4'!F31 -> 150 | G8: ='Page 4'!G31 -> 150 | H8: 0 | I8: ='Page 4'!H31 -> 150 | J8: ='Page 4'!J31 -> 0 | K8: ='Page 4'!K31 -> 0 | L8: शासनाने ठरवून दिलेल्या वाढीव महसूल उद्दिष्ट पुर्ततेबाबत वाहन चालकांना मा.आयुक्त, उपआयुक्त या दर्जाच्या अधिकाऱ्यांसोबत फिरती करावी लागते.
A9: 3 | B9: 06- दूरध्वनी, वीज,पाणी व शुल्क | C9: ='Page 4'!C32 -> 3650 | D9: ='Page 4'!D32 -> 3836 | E9: ='Page 4'!E32 -> 3360 | F9: ='Page 4'!F32 -> 4300 | G9: ='Page 4'!G32 -> 4300 | H9: 0 | I9: ='Page 4'!H32 -> 5790 | J9: ='Page 4'!J32 -> 0 | K9: ='Page 4'!K32 -> 0 | L9: (1) या बाबीखाली जिल्हा कार्यालयाशी मोठया प्रमाणावर संपर्क साधण्यासाठी, इंटरनेटसाठी दूरध्वनीचा वापर करावा लागतो. (2) मुंबई येथील विभागीय आयुक्त कार्यालयातील वीज देयक अदा करणेसाठी अनुदानाची आवश्यकता आहे. (3) कोकण भवन इमारतीच्या पाण्याचे पंप,उद्ववाहने, प्रसाधन गृहे, चौक, पॅसेज, छन्नमार्ग, आवारातील लाईटस् यासाठी लागणाच्या वीजेची देयके भरण्यासाठी दर महा अंदाजे रक्कम रु. 2,50,000/- प्रमाणे वार्षिक रक्कम रु.30,00,000/- वाढीव अनुदानाची गरज आहे. (4) कोकण भवन इमारतीचे पाणी देयक भरणेसाठी वार्षिक र.रु.2,50,000/- इतक्या अनुदानाची आवश्यकता आहे. (5) विजेचे वाढलेले दर व पाणी पट्टीची वाढीव देयके यासाठी वाढीव अनुदानाची आवश्यकता आहे.
A10: 4 | B10: 10- कंत्राटी सेवा | C10: ='Page 4'!C33 -> 19040 | D10: ='Page 4'!D33 -> 13219 | E10: ='Page 4'!E33 -> 3420 | F10: ='Page 4'!F33 -> 16000 | G10: ='Page 4'!G33 -> 16000 | H10: 0 | I10: ='Page 4'!H33 -> 17600 | J10: ='Page 4'!J33 -> 0 | K10: ='Page 4'!K33 -> 0 | L10: (1) कोंकण भवन इमारतीची साफसफाई यांत्रिकी पध्दतीने करणेच्या कामासाठी अंदाजित रक्कम रूपये 1,50,00,000/- एवढया रकमेची आवश्यकता आहे. (2) शासन, वित्त विभाग, शासन परिपत्रक क्र : संकीर्ण-2019/ प्र.क्र.22 /कोषा प्रशा-4 दि.13/08/2020 अन्वये विधी अधिकारी या (कंत्राटी)पदाच्या मानधना करीता र.रू.4,20,000/- तरतुद करण्यात आली आहे.
A11: 5 | B11: 11- देशांतर्गत प्रवास खर्च | C11: ='Page 4'!C34 -> 89 | D11: ='Page 4'!D34 -> 303 | E11: ='Page 4'!E34 -> 301 | F11: ='Page 4'!F34 -> 500 | G11: ='Page 4'!G34 -> 500 | H11: 0 | I11: ='Page 4'!H34 -> 500 | J11: ='Page 4'!J34 -> 0 | K11: ='Page 4'!K34 -> 0 | L11: कार्यालयीन अधिकारी/कर्मचारी यांच्या प्रवास खर्चाकरीता
A12: 6 | B12: 13- कार्यालयीन खर्च | C12: ='Page 4'!C35 -> 3283 | D12: ='Page 4'!D35 -> 4254 | E12: ='Page 4'!E35 -> 2282 | F12: ='Page 4'!F35 -> 4500 | G12: ='Page 4'!G35 -> 4500 | H12: 0 | I12: ='Page 4'!H35 -> 4700 | J12: ='Page 4'!J35 -> 0 | K12: ='Page 4'!K35 -> 0 | L12: (1) कार्यालयीन खर्चासाठी स्टेशनरी, जडसंग्रह वस्तु,झेरॉक्स व इतर खर्च, विविध प्रकारच्या बैठका आयोजीत करण्याकरीता, निवासी दुरध्वनी देयके अदा करण्याकरीता र.रु.46,50,000/-ची आवश्यकता आहे. (2) कोंकण भवन प्रशासकीय इमारतीवर दररोज राष्ट्रध्वज लावणेकामी व ध्वजदोरी खरेदी करणेकरीता अंदाजित रक्कम रुपये 2,25,000/- एवढया रकमेची तरतूद आवश्यक आहे. (3) विद्युत साहित्याची खरेदी, जंयती दिनाचे कार्यक्रम, टीसीएल पावडरची खरेदी व इतर कार्यालयीन खर्चाकरीता अंदाजित र.रु.1,00,000/- अ‍नुदान आवश्यक आहे.
A13: 7 | B13: 14- भाडेपट्टी व कर | C13: ='Page 4'!C36 -> 92 | D13: ='Page 4'!D36 -> 310 | E13: ='Page 4'!E36 -> 761 | F13: ='Page 4'!F36 -> 500 | G13: ='Page 4'!G36 -> 500 | H13: 0 | I13: ='Page 4'!H36 -> 400 | J13: ='Page 4'!J36 -> 0 | K13: ='Page 4'!K36 -> 0 | L13: विभागीय आयुक्त कार्यालयाच्या हिश्याचा वार्षिक मालमत्ता कर देयक भरणे करीता अनुदान आवश्यक आहे.
A14: 8 | B14: 16- प्रकाशने | C14: ='Page 4'!C37 -> 0 | D14: ='Page 4'!D37 -> 0 | E14: ='Page 4'!E37 -> 0 | F14: ='Page 4'!F37 -> 1 | G14: ='Page 4'!G37 -> 1 | H14: 0 | I14: ='Page 4'!H37 -> 150 | J14: ='Page 4'!J37 -> 0 | K14: ='Page 4'!K37 -> 0 | L14: विविध प्रकारच्या छपाईच्या देयक प्रदाणाकरीता नवीन बाब निर्माण करण्यासाठी टोकन रक्कमेची आवश्यकता आहे.
A15: 9 | B15: 17- संगणक खर्च | C15: ='Page 4'!C38 -> 215 | D15: ='Page 4'!D38 -> 355 | E15: ='Page 4'!E38 -> 583 | F15: ='Page 4'!F38 -> 700 | G15: ='Page 4'!G38 -> 700 | H15: 0 | I15: ='Page 4'!H38 -> 1200 | J15: ='Page 4'!J38 -> 0 | K15: ='Page 4'!K38 -> 0 | L15: संगणक, टोनर रिफिलींग / देखभाल दुरुस्तीसाठी र.रू.8,00,000/- तसेच, नवीन संगणक व प्रिंटर्स खरेदीसाठी अंदाजे र.रू.4,00,000/- ची आवश्यकता आहे.
A16: 10 | B16: 20- इतर प्रशासकीय खर्च | C16: ='Page 4'!C39 -> 0 | D16: ='Page 4'!D39 -> 0 | E16: ='Page 4'!E39 -> 0 | F16: ='Page 4'!F39 -> 1 | G16: ='Page 4'!G39 -> 1 | H16: 0 | I16: ='Page 4'!H39 -> 50 | J16: ='Page 4'!J39 -> 0 | K16: ='Page 4'!K39 -> 0 | L16: विविध प्रकारच्या बैठकाया कार्यालयात आयोजीत केल्या जातात त्यावेळी उपस्थिताकरीता चहा/नास्ता मागविण्यात येता त्याच्या खर्चासाठी देयक प्रदाणाकरीता नवीन बाब निर्माण करण्यासाठी टोकन रक्कमेची आवश्यकता आहे.
A17: 11 | B17: 24- इंधन खर्च | C17: ='Page 4'!C40 -> 0 | D17: ='Page 4'!D40 -> 0 | E17: ='Page 4'!E40 -> 160 | F17: ='Page 4'!F40 -> 225 | G17: ='Page 4'!G40 -> 225 | H17: 0 | I17: ='Page 4'!H40 -> 600 | J17: ='Page 4'!J40 -> 0 | K17: ='Page 4'!K40 -> 0 | L17: 4 वाहनांकरीता पेट्रोल व डिझेल खर्चे
A18: 12 | B18: 26- जाहिरात व प्रसिध्दी खर्च | C18: ='Page 4'!C41 -> 0 | D18: ='Page 4'!D41 -> 0 | E18: ='Page 4'!E41 -> 0 | F18: ='Page 4'!F41 -> 1 | G18: ='Page 4'!G41 -> 1 | H18: 0 | I18: ='Page 4'!H41 -> 100 | J18: ='Page 4'!J41 -> 0 | K18: ='Page 4'!K41 -> 0 | L18: जाहिरात प्रसिध्द करण्याकरीता आवश्यक खर्च नवीन बाब निर्माण करण्यासाठी टोकन रक्कमेची आवश्यकता आहे.
A19: 13 | B19: 27-लहान बांधकामे | C19: ='Page 4'!C42 -> 0 | D19: ='Page 4'!D42 -> 0 | E19: ='Page 4'!E42 -> 0 | F19: ='Page 4'!F42 -> 0 | G19: ='Page 4'!G42 -> 0 | H19: 0 | I19: ='Page 4'!H42 -> 0 | J19: ='Page 4'!J42 -> 0 | K19: ='Page 4'!K42 -> 0 | L19: -
A20: 14 | B20: 50-इतर खर्च | C20: ='Page 4'!C43 -> 0 | D20: ='Page 4'!D43 -> 0 | E20: ='Page 4'!E43 -> 0 | F20: ='Page 4'!F43 -> 1 | G20: ='Page 4'!G43 -> 1 | H20: 0 | I20: ='Page 4'!H43 -> 10 | J20: ='Page 4'!J44 -> 0 | K20: ='Page 4'!K44 -> 0 | L20: उपरोक्तबाबी व्यतिरिक्त या कार्यालयात करण्यात येणाऱ्या खर्चा करीता नवीन बाब निर्माण करण्यासाठी टोकन रक्कमेची आवश्यकता आहे.
A21: 15 | B21: 51- मोटार वाहने | C21: ='Page 4'!C44 -> 0 | D21: ='Page 4'!D44 -> 0 | E21: ='Page 4'!E44 -> 0 | F21: ='Page 4'!F44 -> 21 | G21: ='Page 4'!G44 -> 21 | H21: 0 | I21: ='Page 4'!H44 -> 200 | J21: ='Page 4'!J45 -> 0 | K21: ='Page 4'!K45 -> 0 | L21: वाहन दुरस्ती करीता
A22: -- | B22: एकूण | C22: =SUM(C7:C21) -> 120747 | D22: =SUM(D7:D21) -> 120996 | E22: =SUM(E7:E21) -> 120785 | F22: =SUM(F7:F21) -> 163000 | G22: =SUM(G7:G21) -> 163000 | H22: =SUM(H7:H21) -> 0 | I22: =SUM(I7:I21) -> 175188 | J22: =SUM(J7:J21) -> 0 | K22: =SUM(K7:K21) -> 0 | L22: --
J26: सहाय्यक संचालक(लेखा)कोकण विभाग

Sheet Table-D
A2: जोडपत्र "ड"
A5: अर्थसंकल्पीय अंदाजपत्रक सन 2026-2027
A6: मागणी क्र.सी- 1- लेखाशिर्ष 20530387
A8: संवर्गनिहाय माहिती
A10: अ.क्र. | B10: संवर्ग | C10: मंजूर पदे | E10: भरलेली पदे | G10: रिक्त पदे
C11: स्थायी | D11: अस्थायी | E11: स्थायी | F11: अस्थायी | G11: स्थायी | H11: अस्थायी
A12: 1 | B12: वर्ग-1 | C12: =E12+G12 -> 5 | D12: =F12+H12 -> 5 | E12: 4 | F12: 4 | G12: 1 | H12: 1
A13: 2 | B13: वर्ग-2 | C13: =E13+G13 -> 2 | D13: =F13+H13 -> 8 | E13: 2 | F13: 5 | G13: 0 | H13: 3
A14: 3 | B14: वर्ग-3 | C14: =E14+G14 -> 41 | D14: =F14+H14 -> 21 | E14: 40 | F14: 9 | G14: 1 | H14: 12
A15: 4 | B15: वर्ग-4 | C15: =E15+G15 -> 18 | D15: 24 | E15: 14 | F15: 12 | G15: 4 | H15: 13
A16: -- | B16: एकूण | C16: =C12+C13+C14+C15 -> 66 | D16: =D12+D13+D14+D15 -> 58 | E16: =E12+E13+E14+E15 -> 60 | F16: =F12+F13+F14+F15 -> 30 | G16: =G12+G13+G14+G15 -> 6 | H16: =H12+H13+H14+H15 -> 29
E20: सहाय्यक संचालक(लेखा)कोकण विभाग
