Workbook

Sheet Page 1
A1: प्रपत्र - ड - अर्थसंकल्पीय अंदाजपत्रक सन 2021-2022
A2: मागणी क्र.सी- 1- लेखाशिर्ष 2029 0262
A3: जिल्हा मुंबई शहर | O3: (आकडे हजारात)
A4: अ क्र | B4: वर्ग | C4: पद | D4: मंजूर पदे | E4: मंजूर पदे | F4: विशेष वेतन | G4: मुळ वेतन | H4: ग्रेड वेतन | I4: एकूण | J4: महागाई भत्ता 25% | K4: स्थानिक पुरक भत्ता | L4: घर भाडे भत्ता | M4: वाहन भत्ता | N4: धूलाई भत्ता | O4: रोख भत्ता | P4: चप्पल भत्ता/ इतर | Q4: एकूण
D5: 2020-2021 | E5: 2021-2022
C6: स्थायी
A7: 1 | B7: वर्ग-3 | C7: अव्वल कारकून | I7: 0 | J7: 0 | Q7: 0
C8: लिपिक | I8: 0 | J8: 0 | Q8: 0
C9: एकुण | D9: 0 | E9: 0 | F9: 0 | G9: 0 | H9: 0 | I9: 0 | J9: 0 | K9: 0 | L9: 0 | M9: 0 | N9: 0 | O9: 0 | P9: 0 | Q9: 0
A11: अ.क्र. | B11: वर्ग | C11: पद | D11: मंजूर पदे | E11: मंजूर पदे | F11: विशेष वेतन | G11: मुळ वेतन | H11: ग्रेड वेतन | I11: एकूण | J11: महागाई भत्ता 25% | K11: स्थानिक पुरक भत्ता | L11: घर भाडे भत्ता | M11: वाहन भत्ता | N11: धूलाई भत्ता | O11: रोख भत्ता | P11: चप्पल भत्ता/ इतर | Q11: एकूण
D12: 2020-2021 | E12: 2021-2022
C13: अस्थायी | I13: 0 | J13: 0 | Q13: 0
C14: निरंक | D14: 0 | E14: 0 | F14: 0 | G14: 0 | H14: 0 | I14: 0 | J14: 0 | K14: 0 | L14: 0 | M14: 0 | N14: 0 | O14: 0 | P14: 0 | Q14: 0
A16: =$A$1 -> प्रपत्र - ड - अर्थसंकल्पीय अंदाजपत्रक सन 2021-2022
A17: मागणी क्र.सी- 1- लेखाशिर्ष 2029 0262
A18: जिल्हा मुंबई उपनगर | O18: (आकडे हजारात)
A19: अ क्र | B19: वर्ग | C19: पद | D19: मंजूर पदे | E19: मंजूर पदे | F19: विशेष वेतन | G19: मुळ वेतन | H19: ग्रेड वेतन | I19: एकूण | J19: महागाई भत्ता 25% | K19: स्थानिक पुरक भत्ता | L19: घर भाडे भत्ता | M19: वाहन भत्ता | N19: धूलाई भत्ता | O19: रोख भत्ता | P19: चप्पल भत्ता/ इतर | Q19: एकूण
D20: 2020-2021 | E20: 2021-2022
C21: स्थायी
A22: 1 | B22: वर्ग-3 | C22: अव्वल कारकून | I22: 0 | J22: 0 | Q22: 0
C23: लिपिक | I23: 0 | J23: 0 | Q23: 0
C24: एकुण | D24: 0 | E24: 0 | F24: 0 | G24: 0 | H24: 0 | I24: 0 | J24: 0 | K24: 0 | L24: 0 | M24: 0 | N24: 0 | O24: 0 | P24: 0 | Q24: 0
A26: अ.क्र. | B26: वर्ग | C26: पद | D26: मंजूर पदे | E26: मंजूर पदे | F26: विशेष वेतन | G26: मुळ वेतन | H26: ग्रेड वेतन | I26: एकूण | J26: महागाई भत्ता 25% | K26: स्थानिक पुरक भत्ता | L26: घर भाडे भत्ता | M26: वाहन भत्ता | N26: धूलाई भत्ता | O26: रोख भत्ता | P26: चप्पल भत्ता/ इतर | Q26: एकूण
D27: 2020-2021 | E27: 2021-2022
C28: अस्थायी | I28: 0 | J28: 0 | Q28: 0
C29: निरंक | D29: 0 | E29: 0 | F29: 0 | G29: 0 | H29: 0 | I29: 0 | J29: 0 | K29: 0 | L29: 0 | M29: 0 | N29: 0 | O29: 0 | P29: 0 | Q29: 0
A31: =$A$1 -> प्रपत्र - ड - अर्थसंकल्पीय अंदाजपत्रक सन 2021-2022
A32: मागणी क्र.सी- 1- लेखाशिर्ष 2029 0262
A33: जिल्हा ठाणे | O33: (आकडे हजारात)
A34: अ क्र | B34: वर्ग | C34: पद | D34: मंजूर पदे | E34: मंजूर पदे | F34: विशेष वेतन | G34: मुळ वेतन | H34: ग्रेड वेतन | I34: एकूण | J34: महागाई भत्ता 25% | K34: स्थानिक पुरक भत्ता | L34: घर भाडे भत्ता | M34: वाहन भत्ता | N34: धूलाई भत्ता | O34: रोख भत्ता | P34: चप्पल भत्ता/ इतर | Q34: एकूण
D35: 2020-2021 | E35: 2021-2022
C36: स्थायी
A37: 1 | B37: वर्ग-3 | C37: अव्वल कारकून | D37: 1 | E37: 1 | F37: 0 | G37: 446 | H37: 0 | I37: =SUM(G37:H37) -> 446 | J37: =ROUND(I37*0.25, 0) -> 112 | K37: 4 | L37: 120 | M37: 5 | N37: 0 | O37: 0 | P37: 0 | Q37: =SUM(I37:P37)+F37 -> 687
C38: लिपिक | D38: 1 | E38: 1 | F38: 0 | G38: 192 | H38: 0 | I38: =SUM(G38:H38) -> 192 | J38: =ROUND(I38*0.25, 0) -> 48 | K38: 4 | L38: 52 | M38: 5 | N38: 0 | O38: 0 | P38: 0 | Q38: =SUM(I38:P38)+F38 -> 301
C39: एकुण | D39: =SUM(D37:D38) -> 2 | E39: =SUM(E37:E38) -> 2 | F39: =SUM(F37:F38) -> 0 | G39: =SUM(G37:G38) -> 638 | H39: =SUM(H37:H38) -> 0 | I39: =SUM(I37:I38) -> 638 | J39: =SUM(J37:J38) -> 160 | K39: =SUM(K37:K38) -> 8 | ... Q39: =SUM(Q37:Q38) -> 988
A41: अ.क्र. | B41: वर्ग | C41: पद | D41: मंजूर पदे | E41: मंजूर पदे | F41: विशेष वेतन | G41: मुळ वेतन | H41: ग्रेड वेतन | I41: एकूण | J41: महागाई भत्ता 25% | K41: स्थानिक पुरक भत्ता | L41: घर भाडे भत्ता | M41: वाहन भत्ता | N41: धूलाई भत्ता | O41: रोख भत्ता | P41: चप्पल भत्ता/ इतर | Q41: एकूण
D42: 2020-2021 | E42: 2021-2022
C43: अस्थायी | D43: 0 | E43: 0 | F43: 0 | G43: 0 | H43: 0 | I43: 0 | J43: 0 | K43: 0 | L43: 0 | M43: 0 | N43: 0 | O43: 0 | P43: 0 | Q43: 0
C44: निरंक | D44: 0 | E44: 0 | F44: 0 | G44: 0 | H44: 0 | I44: 0 | J44: 0 | K44: 0 | L44: 0 | M44: 0 | N44: 0 | O44: 0 | P44: 0 | Q44: 0
A45: =$A$1 -> प्रपत्र - ड - अर्थसंकल्पीय अंदाजपत्रक सन 2021-2022
...

Sheet Page 2
A1: प्रपत्र - क - अर्थसंकल्पीय अंदाजपत्रक सन 2021-2022
A2: मागणी क्र.सी- 1- लेखाशिर्ष 2029 0262
A3: (आकडे हजारात)
A4: जिल्हा | B4: स्थायी पदे
C5: भरलेली पदे | G5: रिक्त पदे | K5: एकुण
A6: मुंबई शहर | B6: वर्ग | C6: वर्ग-1 व 2 | D6: वर्ग-3 | E6: वर्ग-4 | F6: एकुण | G6: वर्ग-1 व 2 | H6: वर्ग-3 | I6: वर्ग-4 | J6: एकुण | K6: एकुण
B7: पदे | F7: =SUM(C7:E7) -> 0 | J7: =SUM(G7:I7) -> 0 | K7: {=SUM(G7:I7+C7:E7)} -> 0
B8: वेतन | F8: 0 | J8: 0 | K8: 0
B9: ग्रेड पे | F9: 0 | J9: 0 | K9: 0
B10: एकुण | C10: 0 | D10: 0 | E10: 0 | F10: 0 | G10: 0 | H10: 0 | I10: 0 | J10: 0 | K10: 0
B11: विशेष वेतन | F11: 0 | J11: 0 | K11: 0
B12: महा.भत्ता | F12: 0 | J12: 0 | K12: 0
B13: स्था.पु.भ. | F13: 0 | J13: 0 | K13: 0
B14: घरभाडे | F14: 0 | J14: 0 | K14: 0
B15: प्रवास भत्ता | F15: 0 | J15: 0 | K15: 0
B16: इतर | F16: 0 | J16: 0 | K16: 0
B17: एकुण | C17: 0 | D17: 0 | E17: 0 | F17: 0 | G17: 0 | H17: 0 | I17: 0 | J17: 0 | K17: 0
A19: जिल्हा | B19: अस्थायी पदे | M19: सर्व वर्ग पदे
C20: भरलेली पदे | G20: रिक्त पदे | K20: एकुण | M20: वर्ग | N20: स्थायी पदे | O20: अस्थायी पदे | P20: एकुण
A21: मुंबई शहर | B21: वर्ग | C21: वर्ग-1 व 2 | D21: वर्ग-3 | E21: वर्ग-4 | F21: एकुण | G21: वर्ग-1 व 2 | H21: वर्ग-3 | I21: वर्ग-4 | J21: एकुण | M21: पदे | N21: =K8 -> 0 | O21: =K22 -> 0 | P21: =SUM(N21:O21) -> 0
B22: पदे | F22: =SUM(C22:E22) -> 0 | J22: =SUM(G22:I22) -> 0 | K22: {=SUM(G22:I22+C22:E22)} -> 0 | M22: वेतन | N22: 0 | O22: 0 | P22: 0
B23: वेतन | F23: 0 | J23: 0 | K23: 0 | M23: ग्रेड पे | N23: 0 | O23: 0 | P23: 0
B24: ग्रेड पे | F24: 0 | J24: 0 | K24: 0 | M24: एकुण | N24: 0 | O24: 0 | P24: 0
B25: एकुण | C25: 0 | D25: 0 | E25: 0 | F25: 0 | G25: 0 | H25: 0 | I25: 0 | J25: 0 | K25: 0 | M25: महा.भत्ता | N25: 0 | O25: 0 | P25: 0
B26: विशेष वेतन | F26: 0 | J26: 0 | K26: 0 | M26: विशेष वेतन | N26: 0 | O26: 0 | P26: 0
B27: महा.भत्ता | F27: 0 | J27: 0 | K27: 0 | M27: स्था.पु.भ. | N27: 0 | O27: 0 | P27: 0
B28: स्था.पु.भ. | F28: 0 | J28: 0 | K28: 0 | M28: घरभाडे | N28: 0 | O28: 0 | P28: 0
B29: घरभाडे | F29: 0 | J29: 0 | K29: 0 | M29: प्रवास भत्ता | N29: 0 | O29: 0 | P29: 0
B30: प्रवास भत्ता | F30: 0 | J30: 0 | K30: 0 | M30: इतर | N30: 0 | O30: 0 | P30: 0
B31: इतर | F31: 0 | J31: 0 | K31: 0 | M31: एकुण | N31: 0 | O31: 0 | P31: 0
B32: एकुण | C32: 0 | D32: 0 | E32: 0 | F32: 0 | G32: 0 | H32: 0 | I32: 0 | J32: 0 | K32: 0
A33: =$A$1 -> प्रपत्र - क - अर्थसंकल्पीय अंदाजपत्रक सन 2021-2022
A34: मागणी क्र.सी- 1- लेखाशिर्ष 2029 0262
A35: (आकडे हजारात)
A36: जिल्हा | B36: स्थायी पदे
C37: भरलेली पदे | G37: रिक्त पदे | K37: एकुण
A38: मुंबई उपनगर | B38: वर्ग | C38: वर्ग-1 व 2 | D38: वर्ग-3 | E38: वर्ग-4 | F38: एकुण | G38: वर्ग-1 व 2 | H38: वर्ग-3 | I38: वर्ग-4 | J38: एकुण | K38: एकुण
B39: पदे | F39: =SUM(C39:E39) -> 0 | J39: =SUM(G39:I39) -> 0 | K39: {=SUM(G39:I39 + C39:E39)} -> 0
B40: वेतन | F40: 0 | J40: 0 | K40: 0
B41: ग्रेड पे | F41: 0 | J41: 0 | K41: 0
...

Sheet Page 3
A1: प्रपत्र - ब - अर्थसंकल्पीय अंदाजपत्रक सन 2021-2022
A2: मागणी क्र.सी- 1- लेखाशिर्ष 2029 0262
A3: मंजुर पदे
A4: अ.क्र. | B4: वर्ग | C4: स्थायी | E4: अस्थायी | G4: एकुण
C5: भरलेली पदे | D5: रिक्त पदे | E5: भरलेली पदे | F5: रिक्त पदे
A6: 1 | B6: 1 | G6: 0
A7: 2 | B7: 2 | G7: 0
A8: 3 | B8: 3 | G8: 0
A9: 4 | B9: 4 | G9: 0
A10: एकुण | C10: 0 | D10: 0 | E10: 0 | F10: 0 | G10: 0
F13: ( आकडे हजारात)
A14: अ.क्र. | B14: जिल्हा / विभाग | C14: वैद्यकिय खर्च | D14: उत्सव/सण अग्रिम | E14: स्वग्राम/महाराष्ट्र दर्शन | F14: 7 व्या वेतन आयोग फरक | G14: एनपीएस | H14: इतर | I14: एकुण
A15: 1 | B15: मुंबई शहर | H15: 0 | I15: =SUM(C15:H15) -> 0
A17: =$A$1 -> प्रपत्र - ब - अर्थसंकल्पीय अंदाजपत्रक सन 2021-2022
A18: मागणी क्र.सी- 1- लेखाशिर्ष 2029 0262
A19: मंजुर पदे
A20: अ.क्र. | B20: वर्ग | C20: स्थायी | E20: अस्थायी | G20: एकुण
C21: भरलेली पदे | D21: रिक्त पदे | E21: भरलेली पदे | F21: रिक्त पदे
A22: 1 | B22: 1 | G22: 0
A23: 2 | B23: 2 | G23: 0
A24: 3 | B24: 3 | G24: 0
A25: 4 | B25: 4 | G25: 0
A26: एकुण | C26: 0 | D26: 0 | E26: 0 | F26: 0 | G26: 0
F29: ( आकडे हजारात)
A30: अ.क्र. | B30: जिल्हा / विभाग | C30: वैद्यकिय खर्च | D30: उत्सव/सण अग्रिम | E30: स्वग्राम/महाराष्ट्र दर्शन | F30: 7 व्या वेतन आयोग फरक | G30: एनपीएस | H30: इतर | I30: एकुण
A31: 1 | B31: मुंबई उपनगर | H31: 0 | I31: =SUM(C31:H31) -> 0
A33: =$A$1 -> प्रपत्र - ब - अर्थसंकल्पीय अंदाजपत्रक सन 2021-2022
A34: मागणी क्र.सी- 1- लेखाशिर्ष 2029 0262
A35: मंजुर पदे
A36: अ.क्र. | B36: वर्ग | C36: स्थायी | E36: अस्थायी | G36: एकुण
C37: भरलेली पदे | D37: रिक्त पदे | E37: भरलेली पदे | F37: रिक्त पदे
A38: 1 | B38: 1 | C38: 0 | D38: 0 | E38: 0 | F38: 0 | G38: =SUM(C38:F38) -> 0
A39: 2 | B39: 2 | C39: 0 | D39: 0 | E39: 0 | F39: 0 | G39: =SUM(C39:F39) -> 0
A40: 3 | B40: 3 | C40: 0 | D40: 2 | E40: 0 | F40: 0 | G40: =SUM(C40:F40) -> 2
A41: 4 | B41: 4 | C41: 0 | D41: 0 | E41: 0 | F41: 0 | G41: =SUM(C41:F41) -> 0
A42: एकुण | C42: =SUM(C38:C41) -> 0 | D42: =SUM(D38:D41) -> 2 | E42: =SUM(E38:E41) -> 0 | F42: =SUM(F38:F41) -> 0 | G42: =SUM(G38:G41) -> 2
F45: ( आकडे हजारात)
A46: अ.क्र. | B46: जिल्हा / विभाग | C46: वैद्यकिय खर्च | D46: उत्सव/सण अग्रिम | E46: स्वग्राम/महाराष्ट्र दर्शन | F46: 7 व्या वेतन आयोग फरक | G46: एनपीएस | H46: इतर | I46: एकुण
A47: 1 | B47: ठाणे | C47: 300 | D47: 25 | E47: 25 | F47: 200 | G47: 50 | H47: 0 | I47: =SUM(C47:H47) -> 600
A48: =$A$1 -> प्रपत्र - ब - अर्थसंकल्पीय अंदाजपत्रक सन 2021-2022
...

Sheet Page 4
A1: प्रपत्र - अ - अर्थसंकल्पीय अंदाजपत्रक सन 2021-2022
A2: मागणी क्र.सी- 1- लेखाशिर्ष 2029 0262
A3: जिल्हा मुंबई शहर | L3: (आकडे हजारात)
A4: अ. क्र | B4: लेख्याची प्राथमिक आणि दुय्यम युनिट | C4: प्रत्यक्ष रक्कमा (खर्च) | F4: अर्थसंकल्पीय अंदाज | G4: सुधारीत अंदाज 2020-2021 | H4: अर्थसंकल्पीय अंदाज 2021-2022 | L4: मागील वर्षाच्या प्रत्यक्ष रक्कमा आणि चालु वर्षाच्या अर्थसंकल्पीय अंदाजाची तुलना करता आगामी वर्षासाठीच्या अंदाजातील वाढ किंवा घट यांच्या संबधातील स्पष्टीकरणे.
C5: 2017-2018 | D5: 2018-2019 | E5: 2019-2020 | F5: 2020-2021 | H5: प्राकक्लन (एस्टिमेटिंग) अधिका-याचा | I5: नियंत्रक अधिका-यांचा | J5: प्रशासकीय विभागाचा | K5: वित्त विभागाचा
A6: 1 | B6: 2 | C6: 3 | D6: 4 | E6: 5 | F6: 6 | G6: 7 | H6: 8 | I6: 9 | J6: 10 | K6: 11 | L6: 12
A7: 1 | B7: 01- वेतन
A8: 2 | B8: 03 अति.भत्ता
A9: 3 | B9: 06- दूरध्वनी वीज,पाणी व शुल्क
A10: 4 | B10: 11- देशातंर्गत प्रवास खर्च
A11: 4 | B11: 13- कार्यालयीन खर्च
A12: 5 | B12: 14-भाडेपटटी व कर
A13: 7 | B13: 17- संगणक खर्च
A14: 8 | B14: 26- जाहीरात व प्रसिध्दी खर्च
A15: 9 | B15: 51- मोटार वाहने
B16: एकुण | C16: 0 | D16: 0 | E16: 0 | F16: 0 | G16: 0 | H16: 0 | I16: 0 | J16: 0 | K16: 0
A18: =$A$1 -> प्रपत्र - अ - अर्थसंकल्पीय अंदाजपत्रक सन 2021-2022
A19: मागणी क्र.सी- 1- लेखाशिर्ष 2029 0262
A20: जिल्हा मुंबई उपनगर | L20: (आकडे हजारात)
A21: अ. क्र | B21: लेख्याची प्राथमिक आणि दुय्यम युनिट | C21: प्रत्यक्ष रक्कमा (खर्च) | F21: अर्थसंकल्पीय अंदाज | G21: सुधारीत अंदाज 2020-2021 | H21: अर्थसंकल्पीय अंदाज 2021-2022 | L21: मागील वर्षाच्या प्रत्यक्ष रक्कमा आणि चालु वर्षाच्या अर्थसंकल्पीय अंदाजाची तुलना करता आगामी वर्षासाठीच्या अंदाजातील वाढ किंवा घट यांच्या संबधातील स्पष्टीकरणे.
C22: 2017-2018 | D22: 2018-2019 | E22: 2019-2020 | F22: 2020-2021 | H22: प्राकक्लन (एस्टिमेटिंग) अधिका-याचा | I22: नियंत्रक अधिका-यांचा | J22: प्रशासकीय विभागाचा | K22: वित्त विभागाचा
A23: 1 | B23: 2 | C23: 3 | D23: 4 | E23: 5 | F23: 6 | G23: 7 | H23: 8 | I23: 9 | J23: 10 | K23: 11 | L23: 12
A24: 1 | B24: 01- वेतन
A25: 2 | B25: 03 अति.भत्ता
A26: 3 | B26: 06- दूरध्वनी वीज,पाणी व शुल्क
A27: 4 | B27: 11- देशातंर्गत प्रवास खर्च
A28: 4 | B28: 13- कार्यालयीन खर्च
A29: 5 | B29: 14-भाडेपटटी व कर
A30: 7 | B30: 17- संगणक खर्च
A31: 8 | B31: 26- जाहीरात व प्रसिध्दी खर्च
A32: 9 | B32: 51- मोटार वाहने
B33: एकुण | C33: 0 | D33: 0 | E33: 0 | F33: 0 | G33: 0 | H33: 0 | I33: 0 | J33: 0 | K33: 0 | L33: 0
A35: =$A$1 -> प्रपत्र - अ - अर्थसंकल्पीय अंदाजपत्रक सन 2021-2022
A36: मागणी क्र.सी- 1- लेखाशिर्ष 2029 0262
A37: जिल्हा ठाणे | L37: (आकडे हजारात)
A38: अ. क्र | B38: लेख्याची प्राथमिक आणि दुय्यम युनिट | C38: प्रत्यक्ष रक्कमा (खर्च) | F38: अर्थसंकल्पीय अंदाज | G38: सुधारीत अंदाज 2020-2021 | H38: अर्थसंकल्पीय अंदाज 2021-2022 | L38: मागील वर्षाच्या प्रत्यक्ष रक्कमा आणि चालु वर्षाच्या अर्थसंकल्पीय अंदाजाची तुलना करता आगामी वर्षासाठीच्या अंदाजातील वाढ किंवा घट यांच्या संबधातील स्पष्टीकरणे.
C39: 2017-2018 | D39: 2018-2019 | E39: 2019-2020 | F39: 2020-2021 | H39: प्राकक्लन (एस्टिमेटिंग) अधिका-याचा | I39: नियंत्रक अधिका-यांचा | J39: प्रशासकीय विभागाचा | K39: वित्त विभागाचा
A40: 1 | B40: 2 | C40: 3 | D40: 4 | E40: 5 | F40: 6 | G40: 7 | H40: 8 | I40: 9 | J40: 10 | K40: 11 | L40: 12
A41: 1 | B41: 01- वेतन | C41: 23 | D41: 317 | E41: 430 | F41: 1288 | G41: 1400 | H41: 1588
A42: 2 | B42: 03 अति.भत्ता | C42: 0 | D42: 0 | E42: 0 | F42: 0 | G42: 0 | H42: 0
...

Sheet Page 5
A1: ='Page 4'!A136 -> प्रपत्र - अ - अर्थसंकल्पीय अंदाजपत्रक सन 2021-2022
A2: मागणी क्र.सी- 1- लेखाशिर्ष 2029 0262
A3: कोकण विभाग | L3: (आकडे हजारात)
A4: अ. क्र | B4: लेख्याची प्राथमिक आणि दुय्यम युनिट | C4: ='Page 4'!C139 -> प्रत्यक्ष रक्कमा (खर्च) | F4: ='Page 4'!F139 -> अर्थसंकल्पीय अंदाज | G4: ='Page 4'!G139 -> सुधारीत अंदाज 2020-2021 | H4: ='Page 4'!H139 -> अर्थसंकल्पीय अंदाज 2021-2022 | L4: मागील वर्षाच्या प्रत्यक्ष रक्कमा आणि चालु वर्षाच्या अर्थसंकल्पीय अंदाजाची तुलना करता आगामी वर्षासाठीच्या अंदाजातील वाढ किंवा घट यांच्या संबधातील स्पष्टीकरणे.
C5: ='Page 4'!C140 -> 2017-2018 | D5: ='Page 4'!D140 -> 2018-2019 | E5: ='Page 4'!E140 -> 2019-2020 | F5: ='Page 4'!F140 -> 2020-2021 | H5: ='Page 4'!H140 -> प्राकक्लन (एस्टिमेटिंग) अधिका-याचा | I5: ='Page 4'!I140 -> नियंत्रक अधिका-यांचा | J5: ='Page 4'!J140 -> प्रशासकीय विभागाचा | K5: ='Page 4'!K140 -> वित्त विभागाचा
A6: 1 | B6: 2 | C6: 3 | D6: 4 | E6: 5 | F6: 6 | G6: 7 | H6: 8 | I6: 9 | J6: 10 | K6: 11 | L6: 12
A7: 1 | B7: 01- वेतन | C7: ='Page 4'!C142 -> 6877 | D7: ='Page 4'!D142 -> 7619 | E7: ='Page 4'!E142 -> 9680 | F7: ='Page 4'!F142 -> 17661 | G7: ='Page 4'!G142 -> 11067 | I7: ='Page 4'!H142 -> 17003 | L7: 01- वेतन:- या बाबीखाली चालु महागाई भत्ता दर आकारणी 25% प्रमाणे विचारात घेवून केली आहे. वेळोवेळी होणारी वेतनवाढ व महागाई भत्ता दराप्रमाणे वाढीव अनुदान मिळणेस विनंती आहे.
A8: 2 | B8: 03 अति.भत्ता | C8: ='Page 4'!C143 -> 0 | D8: ='Page 4'!D143 -> 0 | E8: ='Page 4'!E143 -> 0 | F8: ='Page 4'!F143 -> 0 | G8: ='Page 4'!G143 -> 0 | I8: ='Page 4'!H143 -> 0
A9: 3 | B9: 06- दूरध्वनी वीज,पाणी व शुल्क | C9: ='Page 4'!C144 -> 17 | D9: ='Page 4'!D144 -> 12 | E9: ='Page 4'!E144 -> 0 | F9: ='Page 4'!F144 -> 350 | G9: ='Page 4'!G144 -> 310 | I9: ='Page 4'!H144 -> 310 | L9: 06- दूरध्वनी, वीज पाणी व शुल्क:- तगाई आस्थापनाकडील कार्यालये व मुख्यालये यामध्ये दुरध्वनी खर्च तसेच वाढीव दराची वीज देयके अदा करणेकामी जादा अनुदानाची आवश्यकता आहे.
A10: 4 | B10: 11- देशातंर्गत प्रवास खर्च | C10: ='Page 4'!C145 -> 10 | D10: ='Page 4'!D145 -> 43 | E10: ='Page 4'!E145 -> 37 | F10: ='Page 4'!F145 -> 430 | G10: ='Page 4'!G145 -> 375 | I10: ='Page 4'!H145 -> 385 | L10: 11- देशातंर्गत प्रवास खर्च:- तगाई आस्थापना कार्यालया कडील कराव्या लागलेल्या फिरती बदली प्रवासभत्ता दैनिकभत्ता इत्यादीसाठी वाढीव महागाई दराच्या आधारावर जादा अनुदानाची आवश्यकता आहे.
A11: 5 | B11: 13- कार्यालयीन खर्च | C11: ='Page 4'!C146 -> 218 | D11: ='Page 4'!D146 -> 246 | E11: ='Page 4'!E146 -> 231 | F11: ='Page 4'!F146 -> 701 | G11: ='Page 4'!G146 -> 541 | I11: ='Page 4'!H146 -> 601 | L11: 13- कार्यालयीन खर्च :- सदर बाबीखाली कार्या.खर्चासाठी स्टेशनरी, जडसंग्रह वस्तु, झेरॉक्स यांच्या वाढीव दरामुळे तसेच अधिका-या यांच्या साठी उपलब्ध असलेल्या शासकीय वाहनांची देखभाल, दुरुस्ती, पेट्रोल व डिझेल यांचे वाढीव दर यामुळे कार्यालयीन खर्च मोठया प्रमाणावर वाढला आहे. त्यामुळे वाढीव अनुदानाची मागणी केली आहे.
A12: 6 | B12: 14-भाडेपटटी व कर | C12: ='Page 4'!C147 -> 0 | D12: ='Page 4'!D147 -> 0 | E12: ='Page 4'!E147 -> 0 | F12: ='Page 4'!F147 -> 0 | G12: ='Page 4'!G147 -> 0 | I12: ='Page 4'!H147 -> 0
A13: 7 | B13: 17- संगणक खर्च | C13: ='Page 4'!C148 -> 21 | D13: ='Page 4'!D148 -> 34 | E13: ='Page 4'!E148 -> 32 | F13: ='Page 4'!F148 -> 290 | G13: ='Page 4'!G148 -> 235 | I13: ='Page 4'!H148 -> 255 | L13: 17- संगणक खर्च :- सदर बाबीखाली सन 2010-2011 पासून मागणी करण्यात येत आहे. सदर उपशिर्षाखाली तगाई आस्थापनाकडील कार्यालयास पाठवावयाचे नियतकालीके अहवाल तयार करणे इ. कार्यालयीन कामे संगणकावर करावी लागतात. 2013-14 वित्‍त्तीय वर्षात सदर लेखाशिर्षातंर्गत नवीन बाब निर्माण करण्यांत आली आहे. मात्र अत्यल्प अनुदान उपलब्ध करुन देण्यांत आले. सबब या वित्तीय वर्षात सदर अनुदानाची तरतूद होण्यास विनंती आहे.
A14: 8 | B14: 26- जाहीरात व प्रसिध्दी खर्च | C14: ='Page 4'!C149 -> 0 | D14: ='Page 4'!D149 -> 0 | E14: ='Page 4'!E149 -> 0 | F14: ='Page 4'!F149 -> 0 | G14: ='Page 4'!G149 -> 0 | I14: ='Page 4'!H149 -> 0
A15: 9 | B15: 51- मोटार वाहने | C15: ='Page 4'!C150 -> 0 | D15: ='Page 4'!D150 -> 0 | E15: ='Page 4'!E150 -> 0 | F15: ='Page 4'!F150 -> 0 | G15: ='Page 4'!G150 -> 0 | I15: ='Page 4'!H150 -> 0
B16: एकुण | C16: =SUM(C7:C15) -> 7143 | D16: =SUM(D7:D15) -> 7954 | E16: =SUM(E7:E15) -> 9980 | F16: =SUM(F7:F15) -> 19432 | G16: =SUM(G7:G15) -> 12528 | H16: =SUM(H7:H15) -> 0 | I16: =SUM(I7:I15) -> 18554 | J16: =SUM(J7:J15) -> 0 | K16: =SUM(K7:K15) -> 0
L18: (विनिता भूमकर)
L19: सहाय्यक संचालक(लेखा) कोकण विभाग

Sheet 4-12 TO 7-12 MES
A1: 2018-2019
A2: 4/2018-7/2018 Monthly Expenditure 20290262
C3: Mcity | D3: MSD | E3: PAO | F3: THANE | G3: PALGHAR | H3: RAIGAD | I3: RATNAGIRI | J3: SINDHUDURG | K3: DIV COMM | L3: AG | M3: TOTAL
A4: 1 | B4: Salary | C4: 0 | D4: 0 | E4: =SUM(C4:D4) -> 0 | F4: 94 | G4: 317 | H4: 1194 | I4: 175 | J4: 140 | K4: 0 | L4: =SUM(F4:K4) -> 1920 | M4: =SUM(L4,E4) -> 1920
A5: 6 | B5: ELCT/WAT/TEL | E5: =SUM(C5:D5) -> 0 | L5: =SUM(F5:K5) -> 0 | M5: =SUM(L5,E5) -> 0
A6: 11 | B6: TE | E6: =SUM(C6:D6) -> 0 | L6: =SUM(F6:K6) -> 0 | M6: =SUM(L6,E6) -> 0
A7: 13 | B7: OE | E7: =SUM(C7:D7) -> 0 | L7: =SUM(F7:K7) -> 0 | M7: =SUM(L7,E7) -> 0
A8: 14 | B8: Property Tax | E8: =SUM(C8:D8) -> 0 | L8: =SUM(F8:K8) -> 0 | M8: =SUM(L8,E8) -> 0
A9: 17 | B9: Computer | E9: =SUM(C9:D9) -> 0 | L9: =SUM(F9:K9) -> 0 | M9: =SUM(L9,E9) -> 0
A10: 26 | B10: Advertisement & Publicity | E10: =SUM(C10:D10) -> 0 | L10: =SUM(F10:K10) -> 0 | M10: =SUM(L10,E10) -> 0
A11: 51 | B11: Motor Car | E11: =SUM(C11:D11) -> 0 | L11: =SUM(F11:K11) -> 0 | M11: =SUM(L11,E11) -> 0
C12: =SUM(C4:C11) -> 0 | D12: =SUM(D4:D11) -> 0 | E12: =SUM(E4:E11) -> 0 | F12: =SUM(F4:F11) -> 94 | G12: =SUM(G4:G11) -> 317 | H12: =SUM(H4:H11) -> 1194 | I12: =SUM(I4:I11) -> 175 | J12: =SUM(J4:J11) -> 140 | ... M12: =SUM(M4:M11) -> 1920
K15: (विनिता भूमकर)
K16: सहाय्यक संचालक(लेखा) कोकण विभाग

Sheet jodpatra D
A1: जोडपत्र-ड
A2: अर्थसंकल्पीय अंदाजपत्रक सन 2021-2022
A3: मागणी क्र.सी-1 2029 जमीन महसूल (20290262)
A4: कोकण विभाग संगर्व निहाय पदांची माहिती
A5: अ.क्र. | B5: संवर्ग | C5: मंजूर पदे | E5: भरलेली पदे | G5: रिक्त पदे
C6: स्थायी | D6: अस्थायी | E6: स्थायी | F6: अस्थायी | G6: स्थायी | H6: अस्थायी
A7: 1 | B7: वर्ग-1 | C7: 0 | D7: 0 | E7: =SUM('Page 3'!C132) -> 0 | F7: =SUM('Page 3'!E132) -> 0 | G7: =SUM('Page 3'!D132) -> 0 | H7: =SUM('Page 3'!F132) -> 0
A8: 2 | B8: वर्ग-2 | C8: 0 | D8: 0 | E8: =SUM('Page 3'!C133) -> 0 | F8: =SUM('Page 3'!E133) -> 0 | G8: =SUM('Page 3'!D133) -> 0 | H8: =SUM('Page 3'!F133) -> 0
A9: 3 | B9: वर्ग-3 | C9: =SUM('Page 1'!E129) -> 31 | D9: 0 | E9: =SUM('Page 3'!C134) -> 14 | F9: =SUM('Page 3'!E134) -> 0 | G9: =SUM('Page 3'!D134) -> 17 | H9: =SUM('Page 3'!F134) -> 0
A10: 4 | B10: वर्ग-4 | C10: 0 | D10: 0 | E10: =SUM('Page 3'!C135) -> 0 | F10: =SUM('Page 3'!E135) -> 0 | G10: =SUM('Page 3'!D135) -> 0 | H10: =SUM('Page 3'!F135) -> 0
B11: एकूण | C11: =SUM(C7:C10) -> 31 | D11: =SUM(D7:D10) -> 0 | E11: =SUM(E7:E10) -> 14 | F11: =SUM(F7:F10) -> 0 | G11: =SUM(G7:G10) -> 17 | H11: =SUM(H7:H10) -> 0
F14: (विनिता भूमकर)
F15: सहाय्यक संचालक(लेखा) कोकण विभाग

Sheet Sheet1
A1: अर्थसंकल्पीय अंदाजपत्रक सन 2016-2017 (जिल्हानिहाय)
A2: मागणी क्र.सी-1- लेखाशिर्ष : 20290262
A3: (आकडे हजारात)
A4: अ. क्र. | B4: उपलेखाशिर्ष | C4: मुंबई शहर | D4: मुंबई उपनगर | E4: ठाणे | F4: पालघर | G4: रायगड | H4: रत्नागिरी | I4: सिंधुदुर्ग | J4: मा.उप आयुक्त (सा.प्र.) | K4: एकूण
A5: 1 | B5: 01- वेतन | C5: =SUM('Page 4'!H7) -> 0 | D5: =SUM('Page 4'!H24) -> 0 | E5: =SUM('Page 4'!H41) -> 1588 | F5: =SUM('Page 4'!H57) -> 2430 | G5: =SUM('Page 4'!H74) -> 9693 | H5: =SUM('Page 4'!H91) -> 2760 | I5: =SUM('Page 4'!H108) -> 532 | J5: =SUM('Page 4'!H125) -> 0 | K5: =SUM(C5:J5) -> 17003
A6: 2 | B6: 03- अति.भत्ता | C6: =SUM('Page 4'!H8) -> 0 | D6: =SUM('Page 4'!H25) -> 0 | E6: =SUM('Page 4'!H42) -> 0 | F6: =SUM('Page 4'!H58) -> 0 | G6: =SUM('Page 4'!H75) -> 0 | H6: =SUM('Page 4'!H92) -> 0 | I6: =SUM('Page 4'!H109) -> 0 | J6: =SUM('Page 4'!H126) -> 0 | K6: =SUM(C6:J6) -> 0
A7: 3 | B7: 06- दूरध्वनी वीज,पाणी व शुल्क | C7: =SUM('Page 4'!H9) -> 0 | D7: =SUM('Page 4'!H26) -> 0 | E7: =SUM('Page 4'!H43) -> 60 | F7: =SUM('Page 4'!H59) -> 0 | G7: =SUM('Page 4'!H76) -> 250 | H7: =SUM('Page 4'!H93) -> 0 | I7: =SUM('Page 4'!H110) -> 0 | J7: =SUM('Page 4'!H127) -> 0 | K7: =SUM(C7:J7) -> 310
A8: 4 | B8: 11- देशातंर्गत प्रवास खर्च | C8: =SUM('Page 4'!H10) -> 0 | D8: =SUM('Page 4'!H27) -> 0 | E8: =SUM('Page 4'!H44) -> 60 | F8: =SUM('Page 4'!H60) -> 5 | G8: =SUM('Page 4'!H77) -> 280 | H8: =SUM('Page 4'!H94) -> 10 | I8: =SUM('Page 4'!H111) -> 30 | J8: =SUM('Page 4'!H128) -> 0 | K8: =SUM(C8:J8) -> 385
A9: 5 | B9: 13- कार्यालयीन खर्च | C9: =SUM('Page 4'!H11) -> 0 | D9: =SUM('Page 4'!H28) -> 0 | E9: =SUM('Page 4'!H45) -> 61 | F9: =SUM('Page 4'!H61) -> 50 | G9: =SUM('Page 4'!H78) -> 400 | H9: =SUM('Page 4'!H95) -> 50 | I9: =SUM('Page 4'!H112) -> 40 | J9: =SUM('Page 4'!H129) -> 0 | K9: =SUM(C9:J9) -> 601
A10: 6 | B10: 14-भाडेपट्टी व कर | C10: =SUM('Page 4'!H12) -> 0 | D10: =SUM('Page 4'!H29) -> 0 | E10: =SUM('Page 4'!H46) -> 0 | F10: =SUM('Page 4'!H62) -> 0 | G10: =SUM('Page 4'!H79) -> 0 | H10: =SUM('Page 4'!H96) -> 0 | I10: =SUM('Page 4'!H113) -> 0 | J10: =SUM('Page 4'!H130) -> 0 | K10: =SUM(C10:J10) -> 0
A11: 8 | B11: 17- संगणक खर्च | C11: =SUM('Page 4'!H13) -> 0 | D11: =SUM('Page 4'!H30) -> 0 | E11: =SUM('Page 4'!H47) -> 70 | F11: =SUM('Page 4'!H63) -> 15 | G11: =SUM('Page 4'!H80) -> 150 | H11: =SUM('Page 4'!H97) -> 20 | I11: =SUM('Page 4'!H114) -> 0 | J11: =SUM('Page 4'!H131) -> 0 | K11: =SUM(C11:J11) -> 255
A12: 9 | B12: 26- जाहीरात व प्रसिध्दी खर्च | C12: =SUM('Page 4'!H14) -> 0 | D12: =SUM('Page 4'!H31) -> 0 | E12: =SUM('Page 4'!H48) -> 0 | F12: =SUM('Page 4'!H64) -> 0 | G12: =SUM('Page 4'!H81) -> 0 | H12: =SUM('Page 4'!H98) -> 0 | I12: =SUM('Page 4'!H115) -> 0 | J12: =SUM('Page 4'!H132) -> 0 | K12: =SUM(C12:J12) -> 0
A13: 10 | B13: 51-मोटार वाहने | C13: =SUM('Page 4'!H15) -> 0 | D13: =SUM('Page 4'!H32) -> 0 | E13: =SUM('Page 4'!H49) -> 0 | F13: =SUM('Page 4'!H65) -> 0 | G13: =SUM('Page 4'!H82) -> 0 | H13: =SUM('Page 4'!H99) -> 0 | I13: =SUM('Page 4'!H116) -> 0 | J13: =SUM('Page 4'!H133) -> 0 | K13: =SUM(C13:J13) -> 0
A14: एकूण | C14: =SUM(C5:C13) -> 0 | D14: =SUM(D5:D13) -> 0 | E14: =SUM(E5:E13) -> 1839 | F14: =SUM(F5:F13) -> 2500 | G14: =SUM(G5:G13) -> 10773 | H14: =SUM(H5:H13) -> 2840 | I14: =SUM(I5:I13) -> 602 | J14: =SUM(J5:J13) -> 0 | K14: =SUM(K5:K13) -> 18554
A16: प्रपत्र - अ - अर्थसंकल्पीय अंदाजपत्रक सन 2018-2019
A17: मागणी क्र.सी-1- लेखाशिर्ष : 20290262
A18: (आकडे हजारात)
A19: अ. क्र. | B19: उपलेखाशिर्ष | C19: मुंबई शहर | D19: मुंबई उपनगर | E19: ठाणे | F19: पालघर | G19: रायगड | H19: रत्नागिरी | I19: सिंधुदुर्ग | J19: मा.उप आयुक्त (सा.प्र.) | K19: एकूण
A20: 1 | B20: 01- वेतन | C20: =SUM((C5/K5)*100) -> 0 | D20: =SUM((D5/K5)*100) -> 0 | E20: =SUM((E5/K5)*100) -> 9.3395283 | F20: =SUM((F5/K5)*100) -> 14.291596 | G20: =SUM((G5/K5)*100) -> 57.007587 | H20: =SUM((H5/K5)*100) -> 16.23243 | I20: =SUM((I5/K5)*100) -> 3.1288596 | J20: =SUM((J5/K5)*100) -> 0 | K20: 11845 | L20: =SUM(C20:J20) -> 100
A21: 2 | B21: 03- अति.भत्ता | C21: =SUM((C6/K6)*100) -> #DIV/0! | D21: =SUM((D6/K6)*100) -> #DIV/0! | E21: =SUM((E6/K6)*100) -> #DIV/0! | F21: =SUM((F6/K6)*100) -> #DIV/0! | G21: =SUM((G6/K6)*100) -> #DIV/0! | H21: =SUM((H6/K6)*100) -> #DIV/0! | I21: =SUM((I6/K6)*100) -> #DIV/0! | J21: =SUM((J6/K6)*100) -> #DIV/0! | K21: 0 | L21: =SUM(C21:J21) -> #DIV/0!
A22: 3 | B22: 06- दूरध्वनी वीज,पाणी व शुल्क | C22: =SUM((C7/K7)*100) -> 0 | D22: =SUM((D7/K7)*100) -> 0 | E22: =SUM((E7/K7)*100) -> 19.354839 | F22: =SUM((F7/K7)*100) -> 0 | G22: =SUM((G7/K7)*100) -> 80.645161 | H22: =SUM((H7/K7)*100) -> 0 | I22: =SUM((I7/K7)*100) -> 0 | J22: =SUM((J7/K7)*100) -> 0 | K22: 330 | L22: =SUM(C22:J22) -> 100
A23: 4 | B23: 11- देशातंर्गत प्रवास खर्च | C23: =SUM((C8/K8)*100) -> 0 | D23: =SUM((D8/K8)*100) -> 0 | E23: =SUM((E8/K8)*100) -> 15.584416 | F23: =SUM((F8/K8)*100) -> 1.2987013 | G23: =SUM((G8/K8)*100) -> 72.727273 | H23: =SUM((H8/K8)*100) -> 2.5974026 | I23: =SUM((I8/K8)*100) -> 7.7922078 | J23: =SUM((J8/K8)*100) -> 0 | K23: 420 | L23: =SUM(C23:J23) -> 100
A24: 5 | B24: 13- कार्यालयीन खर्च | C24: =SUM((C9/K9)*100) -> 0 | D24: =SUM((D9/K9)*100) -> 0 | E24: =SUM((E9/K9)*100) -> 10.14975 | F24: =SUM((F9/K9)*100) -> 8.3194676 | G24: =SUM((G9/K9)*100) -> 66.55574 | H24: =SUM((H9/K9)*100) -> 8.3194676 | I24: =SUM((I9/K9)*100) -> 6.655574 | J24: =SUM((J9/K9)*100) -> 0 | K24: 650 | L24: =SUM(C24:J24) -> 100
A25: 6 | B25: 14-भाडेपट्टी व कर | C25: =SUM((C10/K10)*100) -> #DIV/0! | D25: =SUM((D10/K10)*100) -> #DIV/0! | E25: =SUM((E10/K10)*100) -> #DIV/0! | F25: =SUM((F10/K10)*100) -> #DIV/0! | G25: =SUM((G10/K10)*100) -> #DIV/0! | H25: =SUM((H10/K10)*100) -> #DIV/0! | I25: =SUM((I10/K10)*100) -> #DIV/0! | J25: =SUM((J10/K10)*100) -> #DIV/0! | K25: 0 | L25: =SUM(C25:J25) -> #DIV/0!
A26: 7 | B26: 17- संगणक खर्च | C26: =SUM((C11/K11)*100) -> 0 | D26: =SUM((D11/K11)*100) -> 0 | E26: =SUM((E11/K11)*100) -> 27.45098 | F26: =SUM((F11/K11)*100) -> 5.8823529 | G26: =SUM((G11/K11)*100) -> 58.823529 | H26: =SUM((H11/K11)*100) -> 7.8431373 | I26: =SUM((I11/K11)*100) -> 0 | J26: =SUM((J11/K11)*100) -> 0 | K26: 280 | L26: =SUM(C26:J26) -> 100
A27: 8 | B27: 26- जाहीरात व प्रसिध्दी खर्च | C27: =SUM((C12/K12)*100) -> #DIV/0! | D27: =SUM((D12/K12)*100) -> #DIV/0! | E27: =SUM((E12/K12)*100) -> #DIV/0! | F27: =SUM((F12/K12)*100) -> #DIV/0! | G27: =SUM((G12/K12)*100) -> #DIV/0! | H27: =SUM((H12/K12)*100) -> #DIV/0! | I27: =SUM((I12/K12)*100) -> #DIV/0! | J27: =SUM((J12/K12)*100) -> #DIV/0! | K27: 0 | L27: =SUM(C27:J27) -> #DIV/0!
A28: 9 | B28: 51-मोटार वाहने | C28: =SUM((C13/K13)*100) -> #DIV/0! | D28: =SUM((D13/K13)*100) -> #DIV/0! | E28: =SUM((E13/K13)*100) -> #DIV/0! | F28: =SUM((F13/K13)*100) -> #DIV/0! | G28: =SUM((G13/K13)*100) -> #DIV/0! | H28: =SUM((H13/K13)*100) -> #DIV/0! | I28: =SUM((I13/K13)*100) -> #DIV/0! | J28: =SUM((J13/K13)*100) -> #DIV/0! | K28: 0 | L28: =SUM(C28:J28) -> #DIV/0!
A29: एकूण | C29: =SUM((C14/K14)*100) -> 0 | D29: =SUM((D14/K14)*100) -> 0 | E29: =SUM((E14/K14)*100) -> 9.9116094 | F29: =SUM((F14/K14)*100) -> 13.474183 | G29: =SUM((G14/K14)*100) -> 58.062951 | H29: =SUM((H14/K14)*100) -> 15.306672 | I29: =SUM((I14/K14)*100) -> 3.2445834 | J29: =SUM((J14/K14)*100) -> 0 | K29: =SUM(K20:K28) -> 13525 | L29: =SUM(C29:J29) -> 100
