Workbook

Sheet Page 1
A1: अर्थसंकल्पीय अंदाजपत्रक सन 2026-2027 (प्रपत्र ड)
A2: मागणी क्र.सी- 1- लेखाशिर्ष 20530313
A3: जिल्हा मुंबई शहर | O3: (आकडे हजारात)
A4: अ. क्र. | B4: वर्ग | C4: पद | D4: मंजूर पदे | E4: मंजूर पदे | F4: विशेष वेतन | G4: मुळ वेतन | H4: ग्रेड वेतन | I4: एकूण | J4: महागाई भत्ता 70% | K4: स्थानिक पुरक भत्ता | L4: घर भाडे भत्ता | M4: वाहन भत्ता/ कायम प्रवास भत्ता | N4: धूलाई भत्ता | O4: रोख भत्ता | P4: चप्पल भत्ता/ इतर | Q4: एकूण
D5: 2025-26 | E5: 2026-27
C6: स्थायी
A7: 1 | B7: वर्ग-3 | C7: तलाठी | D7: 0 | E7: 0 | F7: 0 | G7: 0 | H7: 0 | I7: =SUM(G7:H7) -> 0 | J7: =ROUND(I7*1.6,0) -> 0 | K7: 0 | L7: 0 | M7: 0 | N7: 0 | O7: 0 | P7: 0 | Q7: =SUM(F7+I7+J7+K7+L7+M7+N7+O7+P7) -> 0
A8: 2 | B8: वर्ग-4 | C8: कोतवाल | D8: 0 | E8: 0 | F8: 0 | G8: 0 | H8: 0 | I8: =SUM(G8:H8) -> 0 | J8: 0 | K8: 0 | L8: 0 | M8: 0 | N8: 0 | O8: 0 | P8: 0 | Q8: =SUM(F8+I8+J8+K8+L8+M8+N8+O8+P8) -> 0
A9: -- | B9: -- | C9: एकूण | D9: =SUM(D7:D8) -> 0 | E9: =SUM(E7:E8) -> 0 | F9: =SUM(F7:F8) -> 0 | G9: =SUM(G7:G8) -> 0 | H9: =SUM(H7:H8) -> 0 | I9: =SUM(I7:I8) -> 0 | J9: =SUM(J7:J8) -> 0 | K9: =SUM(K7:K8) -> 0 | ... Q9: =SUM(Q7:Q8) -> 0
A11: अर्थसंकल्पीय अंदाजपत्रक सन 2026-2027 (प्रपत्र ड)
A12: मागणी क्र.सी- 1- लेखाशिर्ष 20530313
A13: जिल्हा मुंबई शहर | O13: (आकडे हजारात)
A14: अ. क्र. | B14: वर्ग | C14: पद | D14: मंजूर पदे | E14: मंजूर पदे | F14: विशेष वेतन | G14: मुळ वेतन | H14: ग्रेड वेतन | I14: एकूण | J14: महागाई भत्ता 70% | K14: स्थानिक पुरक भत्ता | L14: घर भाडे भत्ता | M14: वाहन भत्ता/ कायम प्रवास भत्ता | N14: धूलाई भत्ता | O14: रोख भत्ता | P14: चप्पल भत्ता/ इतर | Q14: एकूण
D15: 2025-26 | E15: 2026-27
C16: अस्थायी
A17: 1 | B17: वर्ग-3 | C17: तलाठी | D17: 19 | E17: 19 | F17: 0 | G17: 6402 | H17: 0 | I17: =SUM(G17:H17) -> 6402 | J17: 4482 | K17: 46 | L17: 1920 | M17: 616 | N17: 0 | O17: 0 | P17: 285 | Q17: =SUM(F17+I17+J17+K17+L17+M17+N17+O17+P17) -> 13751
A18: 2 | B18: वर्ग-4 | C18: कोतवाल | D18: 0 | E18: 0 | F18: 0 | G18: 0 | H18: 0 | I18: =SUM(G18:H18) -> 0 | J18: 0 | K18: 0 | L18: 0 | M18: 0 | N18: 0 | O18: 0 | P18: 0 | Q18: =SUM(F18+I18+J18+K18+L18+M18+N18+O18+P18) -> 0
A19: -- | B19: -- | C19: एकूण | D19: =SUM(D17:D18) -> 19 | E19: =SUM(E17:E18) -> 19 | F19: =SUM(F17:F18) -> 0 | G19: =SUM(G17:G18) -> 6402 | H19: =SUM(H17:H18) -> 0 | I19: =SUM(I17:I18) -> 6402 | J19: =SUM(J17:J18) -> 4482 | K19: =SUM(K17:K18) -> 46 | ... Q19: =SUM(Q17:Q18) -> 13751
A21: अर्थसंकल्पीय अंदाजपत्रक सन 2026-2027 (प्रपत्र ड)
A22: मागणी क्र.सी- 1- लेखाशिर्ष 20530313
A23: जिल्हा मुंबई उपनगर | O23: (आकडे हजारात)
A24: अ. क्र. | B24: वर्ग | C24: पद | D24: मंजूर पदे | E24: मंजूर पदे | F24: विशेष वेतन | G24: मुळ वेतन | H24: ग्रेड वेतन | I24: एकूण | J24: महागाई भत्ता 70% | K24: स्थानिक पुरक भत्ता | L24: घर भाडे भत्ता | M24: वाहन भत्ता/ कायम प्रवास भत्ता | N24: धूलाई भत्ता | O24: रोख भत्ता | P24: चप्पल भत्ता/ इतर | Q24: एकूण
D25: 2025-26 | E25: 2026-27
C26: स्थायी
A27: 1 | B27: वर्ग-3 | C27: तलाठी | D27: 18 | E27: 18 | F27: 0 | G27: 10815 | H27: 0 | I27: =SUM(G27:H27) -> 10815 | J27: =ROUND(I27*0.7,0) -> 7571 | K27: 62 | L27: 3245 | M27: 769 | N27: 0 | O27: 0 | P27: 141 | Q27: =SUM(F27+I27+J27+K27+L27+M27+N27+O27+P27) -> 22603
A28: 2 | B28: वर्ग-4 | C28: कोतवाल | D28: 41 | E28: 41 | F28: 0 | G28: 9401 | H28: 0 | I28: =SUM(G28:H28) -> 9401 | J28: 0 | K28: 0 | L28: 0 | M28: 0 | N28: 0 | O28: 0 | P28: 0 | Q28: =SUM(F28+I28+J28+K28+L28+M28+N28+O28+P28) -> 9401
A29: -- | B29: -- | C29: एकूण | D29: =SUM(D27:D28) -> 59 | E29: =SUM(E27:E28) -> 59 | F29: =SUM(F27:F28) -> 0 | G29: =SUM(G27:G28) -> 20216 | H29: =SUM(H27:H28) -> 0 | I29: =SUM(I27:I28) -> 20216 | J29: =SUM(J27:J28) -> 7571 | K29: =SUM(K27:K28) -> 62 | ... Q29: =SUM(Q27:Q28) -> 32004
A31: अर्थसंकल्पीय अंदाजपत्रक सन 2026-2027 (प्रपत्र ड)
A32: मागणी क्र.सी- 1- लेखाशिर्ष 20530313
A33: जिल्हा मुंबई उपनगर | O33: (आकडे हजारात)
A34: अ. क्र. | B34: वर्ग | C34: पद | D34: मंजूर पदे | E34: मंजूर पदे | F34: विशेष वेतन | G34: मुळ वेतन | H34: ग्रेड वेतन | I34: एकूण | J34: महागाई भत्ता 70% | K34: स्थानिक पुरक भत्ता | L34: घर भाडे भत्ता | M34: वाहन भत्ता/ कायम प्रवास भत्ता | N34: धूलाई भत्ता | O34: रोख भत्ता | P34: चप्पल भत्ता/ इतर | Q34: एकूण
D35: 2025-26 | E35: 2026-27
C36: अस्थायी
A37: 1 | B37: वर्ग-3 | C37: तलाठी | D37: 68 | E37: 68 | F37: 0 | G37: 42708 | H37: 0 | I37: =SUM(G37:H37) -> 42708 | J37: =ROUND(I37*0.7,0) -> 29896 | K37: 186 | L37: 12812 | M37: 3066 | P37: 333 | Q37: =SUM(F37+I37+J37+K37+L37+M37+N37+O37+P37) -> 89001
A38: 2 | B38: वर्ग-4 | C38: कोतवाल | D38: 0 | E38: 0 | F38: 0 | G38: 0 | H38: 0 | I38: =SUM(G38:H38) -> 0 | J38: 0 | K38: 0 | L38: 0 | M38: 0 | N38: 0 | O38: 0 | P38: 0 | Q38: =SUM(F38+I38+J38+K38+L38+M38+N38+O38+P38) -> 0
A39: -- | B39: -- | C39: एकूण | D39: =SUM(D37:D38) -> 68 | E39: =SUM(E37:E38) -> 68 | F39: =SUM(F37:F38) -> 0 | G39: =SUM(G37:G38) -> 42708 | H39: =SUM(H37:H38) -> 0 | I39: =SUM(I37:I38) -> 42708 | J39: =SUM(J37:J38) -> 29896 | K39: =SUM(K37:K38) -> 186 | ... Q39: =SUM(Q37:Q38) -> 89001
A41: अर्थसंकल्पीय अंदाजपत्रक सन 2026-2027 (प्रपत्र ड)
A42: मागणी क्र.सी- 1- लेखाशिर्ष 20530313
A43: जिल्हा ठाणे | O43: (आकडे हजारात)
A44: अ. क्र. | B44: वर्ग | C44: पद | D44: मंजूर पदे | E44: मंजूर पदे | F44: विशेष वेतन | G44: मुळ वेतन | H44: ग्रेड वेतन | I44: एकूण | J44: महागाई भत्ता 70% | K44: स्थानिक पुरक भत्ता | L44: घर भाडे भत्ता | M44: वाहन भत्ता/ कायम प्रवास भत्ता | N44: धूलाई भत्ता | O44: रोख भत्ता | P44: चप्पल भत्ता/ इतर | Q44: एकूण
...

Sheet Page 2
A1: अर्थसंकल्पीय अंदाजपत्रक सन 2026-2027 (प्रपत्र क)
A2: मागणी क्र.सी- 1- लेखाशिर्ष 20530313
A3: (आकडे हजारात)
A4: जिल्हा | B4: स्थायी पदे
C5: भरलेली पदे | G5: रिक्त पदे | K5: एकूण
A6: मुंबई शहर | B6: वर्ग | C6: वर्ग-1 व 2 | D6: वर्ग-3 | E6: वर्ग-4 | F6: एकूण | G6: वर्ग-1 व 2 | H6: वर्ग-3 | I6: वर्ग-4 | J6: एकूण | K6: एकूण
B7: पदे | C7: 0 | D7: 0 | E7: 0 | F7: =SUM(C7:E7) -> 0 | G7: 0 | H7: 0 | I7: 0 | J7: =SUM(G7:I7) -> 0 | K7: =SUM(J7,F7) -> 0
B8: वेतन | C8: 0 | D8: 0 | E8: 0 | F8: =SUM(C8:E8) -> 0 | G8: 0 | H8: 0 | I8: 0 | J8: =SUM(G8:I8) -> 0 | K8: =SUM(J8,F8) -> 0
B9: ग्रेड पे | C9: 0 | D9: 0 | E9: 0 | F9: =SUM(C9:E9) -> 0 | G9: 0 | H9: 0 | I9: 0 | J9: =SUM(G9:I9) -> 0 | K9: =SUM(J9,F9) -> 0
B10: एकूण | C10: =SUM(C8:C9) -> 0 | D10: =SUM(D8:D9) -> 0 | E10: =SUM(E8:E9) -> 0 | F10: =SUM(C10:E10) -> 0 | G10: =SUM(G8:G9) -> 0 | H10: =SUM(H8:H9) -> 0 | I10: =SUM(I8:I9) -> 0 | J10: =SUM(J8:J9) -> 0 | K10: =SUM(K8:K9) -> 0
B11: विशेष वेतन | C11: 0 | D11: 0 | E11: 0 | F11: =SUM(C11:E11) -> 0 | G11: 0 | H11: 0 | I11: 0 | J11: =SUM(G11:I11) -> 0 | K11: =SUM(J11,F11) -> 0
B12: महा.भत्ता | C12: 0 | D12: 0 | E12: 0 | F12: =SUM(C12:E12) -> 0 | G12: 0 | H12: 0 | I12: 0 | J12: =SUM(G12:I12) -> 0 | K12: =SUM(J12,F12) -> 0
B13: स्था.पु.भ. | C13: 0 | D13: 0 | E13: 0 | F13: =SUM(C13:E13) -> 0 | G13: 0 | H13: 0 | I13: 0 | J13: =SUM(G13:I13) -> 0 | K13: =SUM(J13,F13) -> 0
B14: घरभाडे | C14: 0 | D14: 0 | E14: 0 | F14: =SUM(C14:E14) -> 0 | G14: 0 | H14: 0 | I14: 0 | J14: =SUM(G14:I14) -> 0 | K14: =SUM(J14,F14) -> 0
B15: प्रवास भत्ता/कायम प्रवास भत्ता | C15: 0 | D15: 0 | E15: 0 | F15: =SUM(C15:E15) -> 0 | G15: 0 | H15: 0 | I15: 0 | J15: =SUM(G15:I15) -> 0 | K15: =SUM(J15,F15) -> 0
B16: इतर | C16: 0 | D16: 0 | E16: 0 | F16: =SUM(C16:E16) -> 0 | G16: 0 | H16: 0 | I16: 0 | J16: =SUM(G16:I16) -> 0 | K16: =SUM(J16,F16) -> 0
B17: एकूण | C17: =SUM(C10:C16) -> 0 | D17: =SUM(D10:D16) -> 0 | E17: =SUM(E10:E16) -> 0 | F17: =SUM(F10:F16) -> 0 | G17: =SUM(G10:G16) -> 0 | H17: =SUM(H10:H16) -> 0 | I17: =SUM(I10:I16) -> 0 | J17: =SUM(J10:J16) -> 0 | K17: =SUM(K10:K16) -> 0
A19: जिल्हा | B19: अस्थायी पदे | M19: सर्व वर्ग पदे
C20: भरलेली पदे | G20: रिक्त पदे | K20: एकूण | M20: वर्ग | N20: स्थायी पदे | O20: अस्थायी पदे | P20: एकूण
A21: मुंबई शहर | B21: वर्ग | C21: वर्ग-1 व 2 | D21: वर्ग-3 | E21: वर्ग-4 | F21: एकूण | G21: वर्ग-1 व 2 | H21: वर्ग-3 | I21: वर्ग-4 | J21: एकूण | K21: एकूण | M21: पदे | N21: =K7 -> 0 | O21: =K22 -> 19 | P21: =SUM(N21:O21) -> 19
B22: पदे | C22: 0 | D22: 17 | E22: 0 | F22: =SUM(C22:E22) -> 17 | G22: 0 | H22: 2 | I22: 0 | J22: =SUM(G22:I22) -> 2 | K22: =SUM(J22,F22) -> 19 | M22: वेतन | N22: =K8 -> 0 | O22: =K23 -> 6402 | P22: =SUM(N22:O22) -> 6402
B23: वेतन | C23: 0 | D23: 5771 | E23: 0 | F23: =SUM(C23:E23) -> 5771 | G23: 0 | H23: 631 | I23: 0 | J23: =SUM(G23:I23) -> 631 | K23: =SUM(J23,F23) -> 6402 | M23: ग्रेड पे | N23: =K9 -> 0 | O23: =K24 -> 0 | P23: =SUM(N23:O23) -> 0
B24: ग्रेड पे | C24: 0 | D24: 0 | E24: 0 | F24: =SUM(C24:E24) -> 0 | G24: 0 | H24: 0 | I24: 0 | J24: =SUM(G24:I24) -> 0 | K24: =SUM(J24,F24) -> 0 | M24: एकूण | N24: =K10 -> 0 | O24: =K25 -> 6402 | P24: =SUM(N24:O24) -> 6402
B25: एकूण | C25: =SUM(C23:C24) -> 0 | D25: =SUM(D23:D24) -> 5771 | E25: =SUM(E23:E24) -> 0 | F25: =SUM(C25:E25) -> 5771 | G25: =SUM(G23:G24) -> 0 | H25: =SUM(H23:H24) -> 631 | I25: =SUM(I23:I24) -> 0 | J25: =SUM(J23:J24) -> 631 | K25: =SUM(K23:K24) -> 6402 | M25: महा.भत्ता | N25: =K12 -> 0 | O25: =K27 -> 4482 | P25: =SUM(N25:O25) -> 4482
B26: विशेष वेतन | C26: 0 | D26: 0 | E26: 0 | F26: =SUM(C26:E26) -> 0 | G26: 0 | H26: 0 | I26: 0 | J26: =SUM(G26:I26) -> 0 | K26: =SUM(J26,F26) -> 0 | M26: विशेष वेतन | N26: =$K$11 -> 0 | O26: =SUM(K26) -> 0 | P26: =SUM(N26:O26) -> 0
B27: महा.भत्ता | C27: 0 | D27: 4040 | E27: 0 | F27: =SUM(C27:E27) -> 4040 | G27: 0 | H27: 442 | I27: 0 | J27: =SUM(G27:I27) -> 442 | K27: =SUM(J27,F27) -> 4482 | M27: स्था.पु.भ. | N27: =K13 -> 0 | O27: =K28 -> 46 | P27: =SUM(N27:O27) -> 46
B28: स्था.पु.भ. | C28: 0 | D28: 41 | E28: 0 | F28: =SUM(C28:E28) -> 41 | G28: 0 | H28: 5 | I28: 0 | J28: =SUM(G28:I28) -> 5 | K28: =SUM(J28,F28) -> 46 | M28: घरभाडे | N28: =K14 -> 0 | O28: =K29 -> 1920 | P28: =SUM(N28:O28) -> 1920
B29: घरभाडे | C29: 0 | D29: 1731 | E29: 0 | F29: =SUM(C29:E29) -> 1731 | G29: 0 | H29: 189 | I29: 0 | J29: =SUM(G29:I29) -> 189 | K29: =SUM(J29,F29) -> 1920 | M29: प्रवास भत्ता/कायम प्रवास भत्ता | N29: =K15 -> 0 | O29: =K30 -> 616 | P29: =SUM(N29:O29) -> 616
B30: प्रवास भत्ता/कायम प्रवास भत्ता | C30: 0 | D30: 551 | E30: 0 | F30: =SUM(C30:E30) -> 551 | G30: 0 | H30: 65 | I30: 0 | J30: =SUM(G30:I30) -> 65 | K30: =SUM(J30,F30) -> 616 | M30: इतर | N30: =K16 -> 0 | O30: =K31 -> 285 | P30: =SUM(N30:O30) -> 285
B31: इतर | C31: 0 | D31: 255 | E31: 0 | F31: =SUM(C31:E31) -> 255 | G31: 0 | H31: 30 | I31: 0 | J31: =SUM(G31:I31) -> 30 | K31: =SUM(J31,F31) -> 285 | M31: एकूण | N31: =SUM(N24:N30) -> 0 | O31: =SUM(O24:O30) -> 13751 | P31: =SUM(P24:P30) -> 13751
B32: एकूण | C32: =SUM(C25:C31) -> 0 | D32: =SUM(D25:D31) -> 12389 | E32: =SUM(E25:E31) -> 0 | F32: =SUM(F25:F31) -> 12389 | G32: =SUM(G25:G31) -> 0 | H32: =SUM(H25:H31) -> 1362 | I32: =SUM(I25:I31) -> 0 | J32: =SUM(J25:J31) -> 1362 | K32: =SUM(K25:K31) -> 13751
A34: अर्थसंकल्पीय अंदाजपत्रक सन 2026-2027 (प्रपत्र क)
A35: मागणी क्र.सी- 1- लेखाशिर्ष 20530313
A36: (आकडे हजारात)
A37: जिल्हा | B37: स्थायी पदे
C38: भरलेली पदे | G38: रिक्त पदे | K38: एकूण
A39: मुंबई उपनगर | B39: वर्ग | C39: वर्ग-1 व 2 | D39: वर्ग-3 | E39: वर्ग-4 | F39: एकूण | G39: वर्ग-1 व 2 | H39: वर्ग-3 | I39: वर्ग-4 | J39: एकूण | K39: एकूण
B40: पदे | C40: 0 | D40: 18 | E40: 31 | F40: =SUM(C40:E40) -> 49 | G40: 0 | H40: 0 | I40: 10 | J40: =SUM(G40:I40) -> 10 | K40: =SUM(J40,F40) -> 59
B41: वेतन | C41: 0 | D41: 10815 | E41: 7601 | F41: =SUM(C41:E41) -> 18416 | G41: 0 | H41: 0 | I41: 1800 | J41: =SUM(G41:I41) -> 1800 | K41: =SUM(J41,F41) -> 20216
B42: ग्रेड पे | C42: 0 | D42: 0 | E42: 0 | F42: =SUM(C42:E42) -> 0 | G42: 0 | H42: 0 | I42: 0 | J42: =SUM(G42:I42) -> 0 | K42: =SUM(J42,F42) -> 0
...

Sheet Page 3
A1: अर्थसंकल्पीय अंदाजपत्रक सन 2026-2027 (प्रपत्र ब)
A2: मागणी क्र.सी- 1- लेखाशिर्ष 20530313
A3: मंजूर पदे
A4: अ.क्र. | B4: वर्ग | C4: स्थायी | E4: अस्थायी | G4: एकूण
C5: भरलेली पदे | D5: रिक्त पदे | E5: भरलेली पदे | F5: रिक्त पदे
A6: 1 | B6: 1 | C6: 0 | D6: 0 | E6: 0 | F6: 0 | G6: =SUM(C6:F6) -> 0
A7: 2 | B7: 2 | C7: 0 | D7: 0 | E7: 0 | F7: 0 | G7: =SUM(C7:F7) -> 0
A8: 3 | B8: 3 | C8: 0 | D8: 0 | E8: 17 | F8: 2 | G8: =SUM(C8:F8) -> 19
A9: 4 | B9: 4 | C9: 0 | D9: 0 | E9: 0 | F9: 0 | G9: =SUM(C9:F9) -> 0
A10: -- | B10: एकूण | C10: =SUM(C6:C9) -> 0 | D10: =SUM(D6:D9) -> 0 | E10: =SUM(E6:E9) -> 17 | F10: =SUM(F6:F9) -> 2 | G10: =SUM(G6:G9) -> 19
F13: (आकडे हजारात)
A14: अ.क्र. | B14: जिल्हा / विभाग | C14: वैद्यकिय खर्च | D14: उत्सव/सण अग्रिम | E14: स्वग्राम/महाराष्ट्र दर्शन | F14: NPS | G14: इतर | H14: एकूण
A15: 1 | B15: मुंबई शहर | C15: 400 | D15: 238 | E15: 120 | F15: 2200 | G15: 0 | H15: =SUM(C15:G15) -> 2958
A17: अर्थसंकल्पीय अंदाजपत्रक सन 2026-2027 (प्रपत्र ब)
A18: मागणी क्र.सी- 1- लेखाशिर्ष 20530313
A19: मंजूर पदे
A20: अ.क्र. | B20: वर्ग | C20: स्थायी | E20: अस्थायी | G20: एकूण
C21: भरलेली पदे | D21: रिक्त पदे | E21: भरलेली पदे | F21: रिक्त पदे
A22: 1 | B22: 1 | C22: 0 | D22: 0 | E22: 0 | F22: 0 | G22: =SUM(C22:F22) -> 0
A23: 2 | B23: 2 | C23: 0 | D23: 0 | E23: 0 | F23: 0 | G23: =SUM(C23:F23) -> 0
A24: 3 | B24: 3 | C24: 18 | D24: 0 | E24: 57 | F24: 11 | G24: =SUM(C24:F24) -> 86
A25: 4 | B25: 4 | C25: 31 | D25: 10 | E25: 0 | F25: 0 | G25: =SUM(C25:F25) -> 41
A26: -- | B26: एकूण | C26: =SUM(C22:C25) -> 49 | D26: =SUM(D22:D25) -> 10 | E26: =SUM(E22:E25) -> 57 | F26: =SUM(F22:F25) -> 11 | G26: =SUM(G22:G25) -> 127
F29: (आकडे हजारात)
A30: अ.क्र. | B30: जिल्हा / विभाग | C30: वैद्यकिय खर्च | D30: उत्सव/सण अग्रिम | E30: स्वग्राम/महाराष्ट्र दर्शन | F30: NPS | G30: इतर | H30: एकूण
A31: 1 | B31: मुंबई उपनगर | C31: 4800 | D31: 878 | E31: 600 | F31: 4494 | G31: 1000 | H31: =SUM(C31:G31) -> 11772
A33: अर्थसंकल्पीय अंदाजपत्रक सन 2026-2027 (प्रपत्र ब)
A34: मागणी क्र.सी- 1- लेखाशिर्ष 20530313
A35: मंजूर पदे
A36: अ.क्र. | B36: वर्ग | C36: स्थायी | E36: अस्थायी | G36: एकूण
C37: भरलेली पदे | D37: रिक्त पदे | E37: भरलेली पदे | F37: रिक्त पदे
A38: 1 | B38: 1 | C38: 0 | D38: 0 | E38: 0 | F38: 0 | G38: =SUM(C38:F38) -> 0
A39: 2 | B39: 2 | C39: 0 | D39: 0 | E39: 0 | F39: 0 | G39: =SUM(C39:F39) -> 0
A40: 3 | B40: 3 | C40: 114 | D40: 23 | E40: 127 | F40: 4 | G40: =SUM(C40:F40) -> 268
A41: 4 | B41: 4 | C41: 155 | D41: 0 | E41: 0 | F41: 0 | G41: =SUM(C41:F41) -> 155
A42: -- | B42: एकूण | C42: =SUM(C38:C41) -> 269 | D42: =SUM(D38:D41) -> 23 | E42: =SUM(E38:E41) -> 127 | F42: =SUM(F38:F41) -> 4 | G42: =SUM(G38:G41) -> 423
F45: (आकडे हजारात)
A46: अ.क्र. | B46: जिल्हा / विभाग | C46: वैद्यकिय खर्च | D46: उत्सव/सण अग्रिम | E46: स्वग्राम/महाराष्ट्र दर्शन | F46: NPS | G46: इतर | H46: एकूण
A47: 1 | B47: ठाणे | C47: 1000 | D47: 2000 | E47: 100 | F47: 0 | G47: 2000 | H47: =SUM(C47:G47) -> 5100
A49: अर्थसंकल्पीय अंदाजपत्रक सन 2026-2027 (प्रपत्र ब)
...

Sheet Page 4
A1: अर्थसंकल्पीय अंदाजपत्रक सन 2026-2027 (प्रपत्र अ)
A2: मागणी क्र.सी- 1- लेखाशिर्ष 20530313
A3: जिल्हा मुंबई शहर | L3: (आकडे हजारात)
A4: अ. क्र. | B4: लेख्याची प्राथमिक आणि दुय्यम युनिट | C4: प्रत्यक्ष रक्कमा (खर्च) | F4: अर्थसंकल्पीय अंदाज | G4: सुधारीत अंदाज | H4: अर्थसंकल्पीय अंदाज 2026-2027 | L4: मागील वर्षाच्या प्रत्यक्ष रक्कमा आणि चालु वर्षाच्या अर्थसंकल्पीय अंदाजाची तुलना करता आगामी वर्षासाठीच्या अंदाजातील वाढ किंवा घट यांच्या संबंधातील स्पष्टीकरणे.
C5: 2022-2023 | D5: 2023-2024 | E5: 2024-2025 | F5: 2025-2026 | G5: 2025-2026 | H5: प्राकक्लन (एस्टिमेटिंग) अधिका-याचा | I5: नियंत्रक अधिका-यांचा | J5: प्रशासकीय विभागाचा | K5: वित्त विभागाचा
A6: 1 | B6: 2 | C6: 3 | D6: 4 | E6: 5 | F6: 6 | G6: 7 | H6: 8 | I6: 9 | J6: 10 | K6: 11 | L6: 12
A7: 1 | B7: 01- वेतन | C7: 0 | D7: 0 | E7: 5802 | F7: 12010 | G7: 12010 | H7: 16709 | I7: 0 | J7: 0 | K7: 0
A8: 2 | B8: 03 अति.भत्ता | C8: 0 | D8: 0 | E8: 0 | F8: 0 | G8: 0 | H8: 0 | I8: 0 | J8: 0 | K8: 0
A9: 3 | B9: 06- दूरध्वनी, वीज,पाणी व शुल्क | C9: 0 | D9: 0 | E9: 9 | F9: 95 | G9: 95 | H9: 600 | I9: 0 | J9: 0 | K9: 0
A10: 4 | B10: 10- कंत्राटी सेवा | C10: 0 | D10: 0 | E10: 0 | F10: 0 | G10: 0 | H10: 0 | I10: 0 | J10: 0 | K10: 0
A11: 5 | B11: 11- देशांतर्गत प्रवास खर्च | C11: 0 | D11: 0 | E11: 0 | F11: 80 | G11: 80 | H11: 100 | I11: 0 | J11: 0 | K11: 0
A12: 6 | B12: 13- कार्यालयीन खर्च | C12: 0 | D12: 0 | E12: 28 | F12: 41 | G12: 41 | H12: 300 | I12: 0 | J12: 0 | K12: 0
A13: 7 | B13: 14- भाडेपट्टी व कर | C13: 0 | D13: 0 | E13: 0 | F13: 0 | G13: 0 | H13: 0 | I13: 0 | J13: 0 | K13: 0
A14: 8 | B14: 16- प्रकाशने | C14: 0 | D14: 0 | E14: 0 | F14: 0 | G14: 0 | H14: 0 | I14: 0 | J14: 0 | K14: 0
A15: 9 | B15: 17- संगणक खर्च | C15: 0 | D15: 0 | E15: 0 | F15: 0 | G15: 0 | H15: 200 | I15: 0 | J15: 0 | K15: 0
A16: 10 | B16: 20- इतर प्रशासकीय खर्च | C16: 0 | D16: 0 | E16: 0 | F16: 0 | G16: 0 | H16: 0 | I16: 0 | J16: 0 | K16: 0
A17: 11 | B17: 26- जाहीरात व प्रसिध्दी खर्च | C17: 0 | D17: 0 | E17: 0 | F17: 0 | G17: 0 | H17: 0 | I17: 0 | J17: 0 | K17: 0
A18: 12 | B18: 50- इतर खर्च | C18: 0 | D18: 0 | E18: 0 | F18: 0 | G18: 0 | H18: 0 | I18: 0 | J18: 0 | K18: 0
A19: 13 | B19: 51- मोटार वाहने | C19: 0 | D19: 0 | E19: 0 | F19: 0 | G19: 0 | H19: 0 | I19: 0 | J19: 0 | K19: 0
A20: -- | B20: एकूण | C20: =SUM(C7:C19) -> 0 | D20: =SUM(D7:D19) -> 0 | E20: =SUM(E7:E19) -> 5839 | F20: =SUM(F7:F19) -> 12226 | G20: =SUM(G7:G19) -> 12226 | H20: =SUM(H7:H19) -> 17909 | I20: =SUM(I7:I19) -> 0 | J20: =SUM(J7:J19) -> 0 | K20: =SUM(K7:K19) -> 0
A22: अर्थसंकल्पीय अंदाजपत्रक सन 2026-2027 (प्रपत्र अ)
A23: मागणी क्र.सी- 1- लेखाशिर्ष 20530313
A24: जिल्हा मुंबई उपनगर | L24: (आकडे हजारात)
A25: अ. क्र. | B25: लेख्याची प्राथमिक आणि दुय्यम युनिट | C25: प्रत्यक्ष रक्कमा (खर्च) | F25: अर्थसंकल्पीय अंदाज | G25: सुधारीत अंदाज | H25: अर्थसंकल्पीय अंदाज 2026-2027 | L25: मागील वर्षाच्या प्रत्यक्ष रक्कमा आणि चालु वर्षाच्या अर्थसंकल्पीय अंदाजाची तुलना करता आगामी वर्षासाठीच्या अंदाजातील वाढ किंवा घट यांच्या संबंधातील स्पष्टीकरणे.
C26: 2022-2023 | D26: 2023-2024 | E26: 2024-2025 | F26: 2025-2026 | G26: 2025-2026 | H26: प्राकक्लन (एस्टिमेटिंग) अधिका-याचा | I26: नियंत्रक अधिका-यांचा | J26: प्रशासकीय विभागाचा | K26: वित्त विभागाचा
A27: 1 | B27: 2 | C27: 3 | D27: 4 | E27: 5 | F27: 6 | G27: 7 | H27: 8 | I27: 9 | J27: 10 | K27: 11 | L27: 12
A28: 1 | B28: 01- वेतन | C28: 38040 | D28: 36819 | E28: 57985 | F28: 81135 | G28: 81135 | H28: 132777 | I28: 0 | J28: 0 | K28: 0
A29: 2 | B29: 03 अति.भत्ता | C29: 0 | D29: 0 | E29: 0 | F29: 0 | G29: 0 | H29: 0 | I29: 0 | J29: 0 | K29: 0
A30: 3 | B30: 06- दूरध्वनी, वीज,पाणी व शुल्क | C30: 9 | D30: 0 | E30: 16 | F30: 40 | G30: 40 | H30: 40 | I30: 0 | J30: 0 | K30: 0
A31: 4 | B31: 10- कंत्राटी सेवा | C31: 0 | D31: 0 | E31: 0 | F31: 0 | G31: 0 | H31: 0 | I31: 0 | J31: 0 | K31: 0
A32: 5 | B32: 11- देशांतर्गत प्रवास खर्च | C32: 0 | D32: 0 | E32: 0 | F32: 60 | G32: 60 | H32: 60 | I32: 0 | J32: 0 | K32: 0
A33: 6 | B33: 13- कार्यालयीन खर्च | C33: 118 | D33: 99 | E33: 0 | F33: 374 | G33: 374 | H33: 375 | I33: 0 | J33: 0 | K33: 0
A34: 7 | B34: 14- भाडेपट्टी व कर | C34: 0 | D34: 0 | E34: 0 | F34: 48 | G34: 0 | H34: 0 | I34: 0 | J34: 0 | K34: 0
A35: 8 | B35: 16- प्रकाशने | C35: 0 | D35: 0 | E35: 0 | F35: 1 | G35: 1 | H35: 0 | I35: 0 | J35: 0 | K35: 0
A36: 9 | B36: 17- संगणक खर्च | C36: 16 | D36: 18 | E36: 22 | F36: 70 | G36: 70 | H36: 70 | I36: 0 | J36: 0 | K36: 0
A37: 10 | B37: 20- इतर प्रशासकीय खर्च | C37: 0 | D37: 0 | E37: 0 | F37: 0 | G37: 0 | H37: 0 | I37: 0 | J37: 0 | K37: 0
A38: 11 | B38: 26- जाहीरात व प्रसिध्दी खर्च | C38: 0 | D38: 0 | E38: 0 | F38: 0 | G38: 0 | H38: 0 | I38: 0 | J38: 0 | K38: 0
A39: 12 | B39: 50- इतर खर्च | C39: 0 | D39: 0 | E39: 0 | F39: 0 | G39: 0 | H39: 0 | I39: 0 | J39: 0 | K39: 0
A40: 13 | B40: 51- मोटार वाहने | C40: 0 | D40: 0 | E40: 0 | F40: 0 | G40: 0 | H40: 0 | I40: 0 | J40: 0 | K40: 0
A41: -- | B41: एकूण | C41: =SUM(C28:C40) -> 38183 | D41: =SUM(D28:D40) -> 36936 | E41: =SUM(E28:E40) -> 58023 | F41: =SUM(F28:F40) -> 81728 | G41: =SUM(G28:G40) -> 81680 | H41: =SUM(H28:H40) -> 133322 | I41: =SUM(I28:I40) -> 0 | J41: =SUM(J28:J40) -> 0 | K41: =SUM(K28:K40) -> 0
...

Sheet Page 5
A1: अर्थसंकल्पीय अंदाजपत्रक सन 2026-2027
A2: मागणी क्र.सी- 1- लेखाशिर्ष 20530313
A3: कोकण विभाग | L3: (आकडे हजारात)
A4: अ. क्र. | B4: लेख्याची प्राथमिक आणि दुय्यम युनिट | C4: प्रत्यक्ष रक्कमा (खर्च) | F4: अर्थसंकल्पीय अंदाज | G4: सुधारीत अंदाज | H4: अर्थसंकल्पीय अंदाज 2026-2027 | L4: मागील वर्षाच्या प्रत्यक्ष रक्कमा आणि चालु वर्षाच्या अर्थसंकल्पीय अंदाजाची तुलना करता आगामी वर्षासाठीच्या अंदाजातील वाढ किंवा घट यांच्या संबंधातील स्पष्टीकरणे
C5: 2022-2023 | D5: 2023-2024 | E5: 2024-2025 | F5: 2025-2026 | G5: 2025-2026 | H5: प्राकक्लन (एस्टिमेटिंग) अधिका-याचा | I5: नियंत्रक अधिका-यांचा | J5: प्रशासकीय विभागाचा | K5: वित्त विभागाचा
A6: 1 | B6: 2 | C6: 3 | D6: 4 | E6: 5 | F6: 6 | G6: 7 | H6: 8 | I6: 9 | J6: 10 | K6: 11 | L6: 12
A7: 1 | B7: 01- वेतन | C7: ='Page 4'!C175 -> 995380 | D7: ='Page 4'!D175 -> 975544 | E7: ='Page 4'!E175 -> 1192342 | F7: ='Page 4'!F175 -> 1753800 | G7: ='Page 4'!G175 -> 2012015 | H7: 0 | I7: ='Page 4'!H175 -> 2500240 | J7: 0 | K7: 0 | L7: 01- वेतन:- या बाबीखाली सातवा वेतन आयोग फरक, चालु महागाई भत्ता दर आकारणी 70% प्रमाणे विचारात घेवून केली आहे. वेळोवेळी होणारी वेतनवाढ व महागाई भत्ता दराप्रमाणे वाढीव अनुदान मिळणेस विनंती आहे.
A8: 2 | B8: 03- अति.भत्ता | C8: ='Page 4'!C176 -> 0 | D8: ='Page 4'!D176 -> 0 | E8: ='Page 4'!E176 -> 0 | F8: 0 | G8: 0 | H8: 0 | I8: ='Page 4'!H176 -> 0 | J8: 0 | K8: 0 | L8: --
A9: 3 | B9: 06- दूरध्वनी, वीज,पाणी व शुल्क | C9: ='Page 4'!C177 -> 504 | D9: ='Page 4'!D177 -> 392 | E9: ='Page 4'!E177 -> 475 | F9: ='Page 4'!F177 -> 900 | G9: ='Page 4'!G177 -> 2825 | H9: 0 | I9: ='Page 4'!H177 -> 5980 | J9: 0 | K9: 0 | L9: 06- दूरध्वनी, वीज पाणी व शुल्क:- या बाबीखाली विभागात शासनाने ठरवून दिलेल्या जमीन महसूल कर वसुलीच्या वाढीव उद्दिष्टपूर्तता बाबत जिल्हा कार्यालयाशी मोठया प्रमाणावर संपर्क साधण्यासाठी दूरध्वनीचा वापर, वीजेचे वाढलेले दर व पाणी पट्टीची वाढीव देयके यासाठी वाढीव अनुदानाची गरज आहे.
A10: 4 | B10: 10- कंत्राटी सेवा | C10: ='Page 4'!C178 -> 0 | D10: ='Page 4'!D178 -> 0 | E10: ='Page 4'!E178 -> 16362 | F10: ='Page 4'!F178 -> 0 | G10: ='Page 4'!G178 -> 0 | I10: ='Page 4'!H178 -> 62602 | L10: 10- कंत्राटी सेवा:- विभागीय आयुक्त कोकण विभाग यांचे अधिनस्त सर्व तलाठी कार्यालयांतील कंत्राटी पध्दतीने विविध सेवा देणा-या कर्मचा-यांची देयके अदा करण्याकरीता रक्कमेची आवश्यक आहे.
A11: 5 | B11: 11- देशांतर्गत प्रवास खर्च | C11: ='Page 4'!C179 -> 754 | D11: ='Page 4'!D179 -> 1057 | E11: ='Page 4'!E179 -> 1193 | F11: ='Page 4'!F179 -> 4500 | G11: ='Page 4'!G179 -> 4980 | H11: 0 | I11: ='Page 4'!H179 -> 6055 | J11: 0 | K11: 0 | L11: 11- देशांतर्गत प्रवास खर्च:- 1)सदर बाबीखाली शासनाने ठरवून दिलेल्या जमीन महसूल कर वसुलीच्या वाढीव उद्दिष्टपूर्तताबाबत वाढीव फिरती कराव्या लागत असल्याने प्रवास खर्च अनुदानाची मागणी केली आहे. 2)तसेच संभाव्य बदली प्रवास भत्ता अदा करणेकरीता अनुदानाची आवश्यकता आहे.
A12: 6 | B12: 13- कार्यालयीन खर्च | C12: ='Page 4'!C180 -> 3029 | D12: ='Page 4'!D180 -> 3627 | E12: ='Page 4'!E180 -> 3353 | F12: ='Page 4'!F180 -> 4500 | G12: ='Page 4'!G180 -> 6925 | H12: 0 | I12: ='Page 4'!H180 -> 9698 | J12: 0 | K12: 0 | L12: 13- कार्यालयीन खर्च:- सदर बाबीखाली कार्या.खर्चसाठी स्टेशनरी, जडसंग्रह वस्तु, झेरॉक्स यांच्या वाढीव दरामुळे कार्यालयीन खर्च मोठया प्रमाणावर वाढला आहे. त्यामुळे अनुदानाची मागणी केली आहे.
A13: 7 | B13: 14- भाडेपट्टी व कर | C13: ='Page 4'!C181 -> 3095 | D13: ='Page 4'!D181 -> 3822 | E13: ='Page 4'!E181 -> 3525 | F13: ='Page 4'!F181 -> 5200 | G13: ='Page 4'!G181 -> 18224 | H13: 0 | I13: ='Page 4'!H181 -> 27460 | J13: 0 | K13: 0 | L13: 14- भाडेपट्टी व कर:- (1)महसूल व वन विभाग शासन निर्णय क्र.भाडेवाढ/2011/प्र.क्र.282/ई-10, दि.05/06/2013 अन्वये ग्रामीण भागातील तलाठी सज्जावरील तलाठी कार्यालयासाठी खाजगी जागा भाडयाने घेतल्यास त्या जागेचे सुधारीत भाडे दरमहा रु.1,000/- व शहरी भागातील तलाठी सज्जावरील तलाठी कार्यालयासाठी खाजगी जागा भाडयाने घेतल्यास त्या जागेचे भाडे दरमहा रु.2,000/- इतके मंजूर करण्यात आले आहे.विभागीय आयुक्त, कोकण विभाग यांचे कार्यालयाकडून सन 2015-16 पासून सातत्याने अनुदान मागणी महसूल व वन विभागास सादर करण्यात येत आहे. अर्थसंकल्पीय अंदाजपत्रकाद्वारे सदर अनुदानाची मागणी करण्यात येत आहे.
A14: 8 | B14: 16- प्रकाशने | C14: ='Page 4'!C182 -> 0 | D14: ='Page 4'!D182 -> 0 | E14: ='Page 4'!E182 -> 0 | F14: ='Page 4'!F182 -> 1 | G14: ='Page 4'!G182 -> 51 | I14: ='Page 4'!H182 -> 50 | L14: 16- प्रकाशने:- विभागीय आयुक्त कोकण विभाग यांचे अधिनस्त सर्व तलाठी कार्यालयांतील विविध प्रकारच्या छपाईची देयके अदा करण्याकरीता रक्कमेची आवश्यक आहे.
A15: 9 | B15: 17- संगणक खर्च | C15: ='Page 4'!C183 -> 511 | D15: ='Page 4'!D183 -> 626 | E15: ='Page 4'!E183 -> 346 | F15: ='Page 4'!F183 -> 1247 | G15: ='Page 4'!G183 -> 7760 | H15: 0 | I15: ='Page 4'!H183 -> 10320 | J15: 0 | K15: 0 | L15: 17- संगणक खर्च :- सदर उपशिर्षाखाली जमीन महसूल कर वसुली उद्दिष्ठपूर्तता बाबत शासनास पाठवावयाचे नियतकालीके अहवाल तयार करणे इ. कार्यालयीन कामे संगणकावर करावी लागतात. यास्तव शासनाने लॅपटॉप पुरविले आहेत. मात्र देखभाल खर्चासाठी अनुदान प्राप्त होत नसल्याने अडचणी निर्माण होत आहेत. त्यामुळे संगणक खर्च अनुदान मंजूर होणेस विनंती आहे.
A16: 10 | B16: 20- इतर प्रशासकीय खर्च | C16: ='Page 4'!C184 -> 0 | D16: ='Page 4'!D184 -> 0 | E16: ='Page 4'!E184 -> 0 | F16: ='Page 4'!F184 -> 0 | G16: ='Page 4'!G184 -> 0 | I16: ='Page 4'!H184 -> 0
A17: 11 | B17: 26- जाहीरात व प्रसिध्दी खर्च | C17: ='Page 4'!C185 -> 0 | D17: ='Page 4'!D185 -> 0 | E17: ='Page 4'!E185 -> 0 | F17: ='Page 4'!F185 -> 1 | G17: ='Page 4'!G185 -> 50 | H17: 0 | I17: ='Page 4'!H185 -> 265 | J17: 0 | K17: 0 | L17: 26-जाहीरात व प्रसिध्दी खर्च:- जिल्हाधिकारी कार्यालयांचे आवश्यकतेप्रमाणे अनुदान मंजूर होणेंस विनंती आहे.
A18: 12 | B18: 50- इतर खर्च | C18: ='Page 4'!C186 -> 0 | D18: ='Page 4'!D186 -> 0 | E18: ='Page 4'!E186 -> 0 | F18: ='Page 4'!F186 -> 1 | G18: ='Page 4'!G186 -> 100 | H18: 0 | I18: ='Page 4'!H186 -> 200 | J18: 0 | K18: 0 | L18: 50- इतर खर्च:- विभागीय आयुक्त कार्यालयाचे सादर अंदाजपत्रकामध्ये नमूद बाबींव्यतिरिक्त विभागीय आयुक्त कार्यालयात करण्यात येणा-या खर्चाकरीता रक्कमेची आवश्यक आहे.
A19: 13 | B19: 51- मोटार वाहने | C19: ='Page 4'!C187 -> 0 | D19: ='Page 4'!D187 -> 0 | E19: ='Page 4'!E187 -> 0 | F19: 0 | G19: ='Page 4'!G187 -> 0 | H19: 0 | I19: ='Page 4'!H187 -> 0 | J19: 0 | K19: 0 | L19: --
A20: -- | B20: एकूण | C20: =SUM(C7:C19) -> 1003273 | D20: =SUM(D7:D19) -> 985068 | E20: =SUM(E7:E19) -> 1217596 | F20: =SUM(F7:F19) -> 1770150 | G20: =SUM(G7:G19) -> 2052930 | H20: =SUM(H7:H19) -> 0 | I20: =SUM(I7:I19) -> 2622870 | J20: =SUM(J7:J19) -> 0 | K20: =SUM(K7:K19) -> 0 | L20: --
J24: सहाय्यक संचालक(लेखा)कोकण विभाग

Sheet Distrs.wise Abstract
A1: अर्थसंकल्पीय अंदाजपत्रक सन 2026-2027 (जिल्हानिहाय)
A2: मागणी क्र.सी-1- लेखाशिर्ष : 20530313
A3: (आकडे हजारात)
A4: अ. क्र. | B4: उपलेखाशिर्ष | C4: मुंबई शहर | D4: मुंबई उपनगर | E4: ठाणे | F4: पालघर | G4: रायगड | H4: रत्नागिरी | I4: सिंधुदुर्ग | J4: एकूण
A5: 1 | B5: 01- वेतन | C5: ='Page 4'!H7 -> 16709 | D5: ='Page 4'!H28 -> 132777 | E5: ='Page 4'!H49 -> 267076 | F5: ='Page 4'!H70 -> 475929 | G5: ='Page 4'!H91 -> 515590 | H5: ='Page 4'!H112 -> 692381 | I5: ='Page 4'!H133 -> 399778 | J5: =C5+D5+E5+F5+G5+H5+I5 -> 2500240
A6: 2 | B6: 03 अति.भत्ता | C6: ='Page 4'!H8 -> 0 | D6: ='Page 4'!H29 -> 0 | E6: ='Page 4'!H50 -> 0 | F6: ='Page 4'!H71 -> 0 | G6: ='Page 4'!H92 -> 0 | H6: ='Page 4'!H113 -> 0 | I6: ='Page 4'!H134 -> 0 | J6: =C6+D6+E6+F6+G6+H6+I6 -> 0
A7: 3 | B7: 06- दूरध्वनी, वीज,पाणी व शुल्क | C7: ='Page 4'!H9 -> 600 | D7: ='Page 4'!H30 -> 40 | E7: ='Page 4'!H51 -> 420 | F7: ='Page 4'!H72 -> 1000 | G7: ='Page 4'!H93 -> 1690 | H7: ='Page 4'!H114 -> 2100 | I7: ='Page 4'!H135 -> 130 | J7: =C7+D7+E7+F7+G7+H7+I7 -> 5980
A8: 4 | B8: 10- कंत्राटी सेवा | C8: ='Page 4'!H10 -> 0 | D8: ='Page 4'!H31 -> 0 | E8: ='Page 4'!H52 -> 11563 | F8: ='Page 4'!H73 -> 51039 | G8: ='Page 4'!H94 -> 0 | H8: ='Page 4'!H115 -> 0 | I8: ='Page 4'!H136 -> 0 | J8: =C8+D8+E8+F8+G8+H8+I8 -> 62602
A9: 5 | B9: 11- देशांतर्गत प्रवास खर्च | C9: ='Page 4'!H11 -> 100 | D9: ='Page 4'!H32 -> 60 | E9: ='Page 4'!H53 -> 220 | F9: ='Page 4'!H74 -> 1500 | G9: ='Page 4'!H95 -> 2275 | H9: ='Page 4'!H116 -> 800 | I9: ='Page 4'!H137 -> 1100 | J9: =C9+D9+E9+F9+G9+H9+I9 -> 6055
A10: 6 | B10: 13- कार्यालयीन खर्च | C10: ='Page 4'!H12 -> 300 | D10: ='Page 4'!H33 -> 375 | E10: ='Page 4'!H54 -> 750 | F10: ='Page 4'!H75 -> 1500 | G10: ='Page 4'!H96 -> 3003 | H10: ='Page 4'!H117 -> 3000 | I10: ='Page 4'!H138 -> 770 | J10: =C10+D10+E10+F10+G10+H10+I10 -> 9698
A11: 7 | B11: 14- भाडेपट्टी व कर | C11: ='Page 4'!H13 -> 0 | D11: ='Page 4'!H34 -> 0 | E11: ='Page 4'!H55 -> 2650 | F11: ='Page 4'!H76 -> 3500 | G11: ='Page 4'!H97 -> 6710 | H11: ='Page 4'!H118 -> 12500 | I11: ='Page 4'!H139 -> 2100 | J11: =C11+D11+E11+F11+G11+H11+I11 -> 27460
A12: 8 | B12: 16- प्रकाशने | C12: ='Page 4'!H14 -> 0 | D12: ='Page 4'!H35 -> 0 | E12: ='Page 4'!H56 -> 0 | F12: ='Page 4'!H77 -> 0 | G12: ='Page 4'!H98 -> 0 | H12: ='Page 4'!H119 -> 50 | I12: ='Page 4'!H140 -> 0 | J12: =C12+D12+E12+F12+G12+H12+I12 -> 50
A13: 9 | B13: 17- संगणक खर्च | C13: ='Page 4'!H15 -> 200 | D13: ='Page 4'!H36 -> 70 | E13: ='Page 4'!H57 -> 5000 | F13: ='Page 4'!H78 -> 1000 | G13: ='Page 4'!H99 -> 1950 | H13: ='Page 4'!H120 -> 2000 | I13: ='Page 4'!H141 -> 100 | J13: =C13+D13+E13+F13+G13+H13+I13 -> 10320
A14: 10 | B14: 20- इतर प्रशासकीय खर्च | C14: ='Page 4'!H16 -> 0 | D14: ='Page 4'!H37 -> 0 | E14: ='Page 4'!H58 -> 0 | F14: ='Page 4'!H79 -> 0 | G14: ='Page 4'!H100 -> 0 | H14: ='Page 4'!H121 -> 0 | I14: ='Page 4'!H142 -> 0 | J14: =C14+D14+E14+F14+G14+H14+I14 -> 0
A15: 11 | B15: 26- जाहीरात व प्रसिध्दी खर्च | C15: ='Page 4'!H17 -> 0 | D15: ='Page 4'!H38 -> 0 | E15: ='Page 4'!H59 -> 0 | F15: ='Page 4'!H80 -> 0 | G15: ='Page 4'!H101 -> 195 | H15: ='Page 4'!H122 -> 70 | I15: ='Page 4'!H143 -> 0 | J15: =C15+D15+E15+F15+G15+H15+I15 -> 265
A16: 12 | B16: 50- इतर खर्च | C16: ='Page 4'!H18 -> 0 | D16: ='Page 4'!H39 -> 0 | E16: ='Page 4'!H60 -> 0 | F16: ='Page 4'!H81 -> 0 | G16: ='Page 4'!H102 -> 0 | H16: ='Page 4'!H123 -> 200 | I16: ='Page 4'!H144 -> 0 | J16: =C16+D16+E16+F16+G16+H16+I16 -> 200
A17: 13 | B17: 51- मोटार वाहने | C17: ='Page 4'!H19 -> 0 | D17: ='Page 4'!H40 -> 0 | E17: ='Page 4'!H61 -> 0 | F17: ='Page 4'!H82 -> 0 | G17: ='Page 4'!H103 -> 0 | H17: ='Page 4'!H124 -> 0 | I17: ='Page 4'!H145 -> 0 | J17: =C17+D17+E17+F17+G17+H17+I17 -> 0
A18: एकूण | C18: =C5+C6+C7+C9+C10+C11+C13+C15+C16+C17 -> 17909 | D18: =D5+D6+D7+D9+D10+D11+D13+D15+D16+D17 -> 133322 | E18: =E5+E6+E7+E9+E10+E11+E13+E15+E16+E17 -> 276116 | F18: =F5+F6+F7+F9+F10+F11+F13+F15+F16+F17 -> 484429 | G18: =G5+G6+G7+G9+G10+G11+G13+G15+G16+G17 -> 531413 | H18: =H5+H6+H7+H9+H10+H11+H13+H15+H16+H17 -> 713051 | I18: =I5+I6+I7+I9+I10+I11+I13+I15+I16+I17 -> 403978 | J18: =J5+J6+J7+J9+J10+J11+J12+J13+J15+J16+J17 -> 2560268

Sheet Table-D
A2: जोडपत्र "ड"
A5: अर्थसंकल्पीय अंदाजपत्रक सन 2026-2027
A6: मागणी क्र.सी- 1- लेखाशिर्ष 20530313
A8: संवर्गनिहाय माहिती
A10: अ.क्र. | B10: संवर्ग | C10: मंजूर पदे | E10: भरलेली पदे | G10: रिक्त पदे
C11: स्थायी | D11: अस्थायी | E11: स्थायी | F11: अस्थायी | G11: स्थायी | H11: अस्थायी
A12: 1 | B12: वर्ग-1 | C12: =E12+G12 -> 0 | D12: =F12+H12 -> 0 | E12: 0 | F12: 0 | G12: 0 | H12: 0
A13: 2 | B13: वर्ग-2 | C13: =E13+G13 -> 0 | D13: =F13+H13 -> 0 | E13: 0 | F13: 0 | G13: 0 | H13: 0
A14: 3 | B14: वर्ग-3 | C14: =E14+G14 -> 1014 | D14: =F14+H14 -> 980 | E14: 855 | F14: 687 | G14: 159 | H14: 293
A15: 4 | B15: वर्ग-4 | C15: =E15+G15 -> 1355 | D15: =F15+H15 -> 0 | E15: 1068 | F15: 0 | G15: 287 | H15: 0
A16: -- | B16: एकूण | C16: =C12+C13+C14+C15 -> 2369 | D16: =D12+D13+D14+D15 -> 980 | E16: =E12+E13+E14+E15 -> 1923 | F16: =F12+F13+F14+F15 -> 687 | G16: =G12+G13+G14+G15 -> 446 | H16: =H12+H13+H14+H15 -> 293
E20: सहाय्यक संचालक(लेखा)कोकण विभाग
