Workbook

Sheet Page 1
A1: अर्थसंकल्पीय अंदाजपत्रक सन 2020-2021
A2: मागणी क्र.सी- 1- लेखाशिर्ष 20530162
A3: जिल्हा मुंबई शहर | O3: (आकडे हजारात)
A4: अ. क्र. | B4: वर्ग | C4: पद | D4: मंजूर पदे | E4: मंजूर पदे | F4: विशेष वेतन | G4: मुळ वेतन | H4: ग्रेड वेतन | I4: एकूण | J4: महागाई भत्ता 70% | K4: स्थानिक पुरक भत्ता | L4: घर भाडे भत्ता | M4: वाहन भत्ता | N4: धूलाई भत्ता | O4: रोख भत्ता | P4: चप्पल भत्ता/ इतर | Q4: एकूण
D5: 2023-24 | E5: 2024-25
C6: स्थायी
A7: 1 | B7: वर्ग-1 व 2 | C7: उपविभागीय अधिकारी | D7: 0 | E7: 0 | F7: 0 | G7: 0 | H7: 0 | I7: =SUM(G7:H7) -> 0 | J7: =ROUND(I7*1.6,0) -> 0 | K7: 0 | L7: 0 | M7: 0 | N7: 0 | O7: 0 | P7: 0 | Q7: =SUM(F7+I7+J7+K7+L7+M7+N7+O7+P7) -> 0
C8: नायब तहसिलदार | D8: 0 | E8: 0 | F8: 0 | G8: 0 | H8: 0 | I8: =SUM(G8:H8) -> 0 | J8: =ROUND(I8*1.6,0) -> 0 | K8: 0 | L8: 0 | M8: 0 | N8: 0 | O8: 0 | P8: 0 | Q8: =SUM(F8+I8+J8+K8+L8+M8+N8+O8+P8) -> 0
A9: 2 | B9: वर्ग-3 | C9: लघुलेखक (नि.श्रे.) | D9: 0 | E9: 0 | F9: 0 | G9: 0 | H9: 0 | I9: =SUM(G9:H9) -> 0 | J9: =ROUND(I9*1.6,0) -> 0 | K9: 0 | L9: 0 | M9: 0 | N9: 0 | O9: 0 | P9: 0 | Q9: =SUM(F9+I9+J9+K9+L9+M9+N9+O9+P9) -> 0
C10: अव्वल कारकून | D10: 0 | E10: 0 | F10: 0 | G10: 0 | H10: 0 | I10: =SUM(G10:H10) -> 0 | J10: =ROUND(I10*1.6,0) -> 0 | K10: 0 | L10: 0 | M10: 0 | N10: 0 | O10: 0 | P10: 0 | Q10: =SUM(F10+I10+J10+K10+L10+M10+N10+O10+P10) -> 0
C11: लिपिक | D11: 0 | E11: 0 | F11: 0 | G11: 0 | H11: 0 | I11: =SUM(G11:H11) -> 0 | J11: =ROUND(I11*1.6,0) -> 0 | K11: 0 | L11: 0 | M11: 0 | N11: 0 | O11: 0 | P11: 0 | Q11: =SUM(F11+I11+J11+K11+L11+M11+N11+O11+P11) -> 0
C12: वाहन चालक | D12: 0 | E12: 0 | F12: 0 | G12: 0 | H12: 0 | I12: =SUM(G12:H12) -> 0 | J12: =ROUND(I12*1.6,0) -> 0 | K12: 0 | L12: 0 | M12: 0 | N12: 0 | O12: 0 | P12: 0 | Q12: =SUM(F12+I12+J12+K12+L12+M12+N12+O12+P12) -> 0
A13: 3 | B13: वर्ग-4 | C13: शिपाई | D13: 0 | E13: 0 | F13: 0 | G13: 0 | H13: 0 | I13: =SUM(G13:H13) -> 0 | J13: =ROUND(I13*1.6,0) -> 0 | K13: 0 | L13: 0 | M13: 0 | N13: 0 | O13: 0 | P13: 0 | Q13: =SUM(F13+I13+J13+K13+L13+M13+N13+O13+P13) -> 0
A14: -- | B14: -- | C14: एकूण | D14: =SUM(D7:D13) -> 0 | E14: =SUM(E7:E13) -> 0 | F14: =SUM(F7:F13) -> 0 | G14: =SUM(G7:G13) -> 0 | H14: =SUM(H7:H13) -> 0 | I14: =SUM(I7:I13) -> 0 | J14: =SUM(J7:J13) -> 0 | K14: =SUM(K7:K13) -> 0 | ... Q14: =SUM(Q7:Q13) -> 0
A16: अर्थसंकल्पीय अंदाजपत्रक सन 2020-2021
A17: मागणी क्र.सी- 1- लेखाशिर्ष 20530162
A18: जिल्हा मुंबई शहर | O18: (आकडे हजारात)
A19: अ. क्र. | B19: वर्ग | C19: पद | D19: मंजूर पदे | E19: मंजूर पदे | F19: विशेष वेतन | G19: मुळ वेतन | H19: ग्रेड वेतन | I19: एकूण | J19: महागाई भत्ता 70% | K19: स्थानिक पुरक भत्ता | L19: घर भाडे भत्ता | M19: वाहन भत्ता | N19: धूलाई भत्ता | O19: रोख भत्ता | P19: चप्पल भत्ता/ इतर | Q19: एकूण
D20: 2023-24 | E20: 2024-25
C21: अस्थायी
A22: 1 | B22: वर्ग-1 व 2 | C22: उपविभागीय अधिकारी | D22: 0 | E22: 0 | F22: 0 | G22: 0 | H22: 0 | I22: =SUM(G22:H22) -> 0 | J22: =ROUND(I22*1.6,0) -> 0 | K22: 0 | L22: 0 | M22: 0 | N22: 0 | O22: 0 | P22: 0 | Q22: =SUM(F22+I22+J22+K22+L22+M22+N22+O22+P22) -> 0
C23: नायब तहसिलदार | D23: 0 | E23: 0 | F23: 0 | G23: 0 | H23: 0 | I23: =SUM(G23:H23) -> 0 | J23: =ROUND(I23*1.6,0) -> 0 | K23: 0 | L23: 0 | M23: 0 | N23: 0 | O23: 0 | P23: 0 | Q23: =SUM(F23+I23+J23+K23+L23+M23+N23+O23+P23) -> 0
A24: 2 | B24: वर्ग-3 | C24: लघुलेखक (नि.श्रे.) | D24: 0 | E24: 0 | F24: 0 | G24: 0 | H24: 0 | I24: =SUM(G24:H24) -> 0 | J24: =ROUND(I24*1.6,0) -> 0 | K24: 0 | L24: 0 | M24: 0 | N24: 0 | O24: 0 | P24: 0 | Q24: =SUM(F24+I24+J24+K24+L24+M24+N24+O24+P24) -> 0
C25: अव्वल कारकून | D25: 0 | E25: 0 | F25: 0 | G25: 0 | H25: 0 | I25: =SUM(G25:H25) -> 0 | J25: =ROUND(I25*1.6,0) -> 0 | K25: 0 | L25: 0 | M25: 0 | N25: 0 | O25: 0 | P25: 0 | Q25: =SUM(F25+I25+J25+K25+L25+M25+N25+O25+P25) -> 0
C26: लिपिक | D26: 0 | E26: 0 | F26: 0 | G26: 0 | H26: 0 | I26: =SUM(G26:H26) -> 0 | J26: =ROUND(I26*1.6,0) -> 0 | K26: 0 | L26: 0 | M26: 0 | N26: 0 | O26: 0 | P26: 0 | Q26: =SUM(F26+I26+J26+K26+L26+M26+N26+O26+P26) -> 0
C27: वाहन चालक | D27: 0 | E27: 0 | F27: 0 | G27: 0 | H27: 0 | I27: =SUM(G27:H27) -> 0 | J27: =ROUND(I27*1.6,0) -> 0 | K27: 0 | L27: 0 | M27: 0 | N27: 0 | O27: 0 | P27: 0 | Q27: =SUM(F27+I27+J27+K27+L27+M27+N27+O27+P27) -> 0
A28: 3 | B28: वर्ग-4 | C28: शिपाई | D28: 0 | E28: 0 | F28: 0 | G28: 0 | H28: 0 | I28: =SUM(G28:H28) -> 0 | J28: =ROUND(I28*1.6,0) -> 0 | K28: 0 | L28: 0 | M28: 0 | N28: 0 | O28: 0 | P28: 0 | Q28: =SUM(F28+I28+J28+K28+L28+M28+N28+O28+P28) -> 0
A29: -- | B29: -- | C29: एकूण | D29: =SUM(D22:D28) -> 0 | E29: =SUM(E22:E28) -> 0 | F29: =SUM(F22:F28) -> 0 | G29: =SUM(G22:G28) -> 0 | H29: =SUM(H22:H28) -> 0 | I29: =SUM(I22:I28) -> 0 | J29: =SUM(J22:J28) -> 0 | K29: =SUM(K22:K28) -> 0 | ... Q29: =SUM(Q22:Q28) -> 0
A31: अर्थसंकल्पीय अंदाजपत्रक सन 2026-2027 (प्रपत्र ड)
A32: मागणी क्र.सी- 1- लेखाशिर्ष 20530162
A33: जिल्हा मुंबई उपनगर | O33: (आकडे हजारात)
A34: अ. क्र. | B34: वर्ग | C34: पद | D34: मंजूर पदे | E34: मंजूर पदे | F34: विशेष वेतन | G34: मुळ वेतन | H34: ग्रेड वेतन | I34: एकूण | J34: महागाई भत्ता 70% | K34: स्थानिक पुरक भत्ता | L34: घर भाडे भत्ता | M34: वाहन भत्ता | N34: धूलाई भत्ता | O34: रोख भत्ता | P34: चप्पल भत्ता/ इतर | Q34: एकूण
D35: 2025-26 | E35: 2026-27
C36: स्थायी
A37: 1 | B37: वर्ग-1 व 2 | C37: उपविभागीय अधिकारी | D37: 1 | E37: 1 | F37: 0 | G37: 1304 | H37: 0 | I37: =SUM(G37:H37) -> 1304 | J37: =ROUND(I37*0.7,0) -> 913 | K37: 4 | L37: 391 | M37: 36 | N37: 0 | O37: 0 | P37: 0 | Q37: =SUM(F37+I37+J37+K37+L37+M37+N37+O37+P37) -> 2648
C38: नायब तहसिलदार | D38: 0 | E38: 0 | F38: 0 | G38: 0 | H38: 0 | I38: =SUM(G38:H38) -> 0 | J38: =ROUND(I38*0.7,0) -> 0 | K38: 0 | L38: =ROUND(I38*0.27,0) -> 0 | M38: 0 | N38: 0 | O38: 0 | P38: 0 | Q38: =SUM(F38+I38+J38+K38+L38+M38+N38+O38+P38) -> 0
A39: 2 | B39: वर्ग-3 | C39: लघुलेखक (नि.श्रे.) | D39: 0 | E39: 0 | F39: 0 | G39: 0 | H39: 0 | I39: =SUM(G39:H39) -> 0 | J39: =ROUND(I39*0.7,0) -> 0 | K39: 0 | L39: =ROUND(I39*0.27,0) -> 0 | M39: 0 | N39: 0 | O39: 0 | P39: 0 | Q39: =SUM(F39+I39+J39+K39+L39+M39+N39+O39+P39) -> 0
C40: सहायक महसूल अधिकारी | D40: 0 | E40: 0 | F40: 0 | G40: 0 | H40: 0 | I40: =SUM(G40:H40) -> 0 | J40: =ROUND(I40*0.7,0) -> 0 | K40: 0 | L40: =ROUND(I40*0.27,0) -> 0 | M40: 0 | N40: 0 | O40: 0 | P40: 0 | Q40: =SUM(F40+I40+J40+K40+L40+M40+N40+O40+P40) -> 0
C41: महसूल सहायक | D41: 2 | E41: 2 | F41: 0 | G41: 568 | H41: 0 | I41: =SUM(G41:H41) -> 568 | J41: =ROUND(I41*0.7,0) -> 398 | K41: 4 | L41: 170 | M41: 24 | N41: 0 | O41: 0 | P41: 0 | Q41: =SUM(F41+I41+J41+K41+L41+M41+N41+O41+P41) -> 1164
C42: वाहन चालक | D42: 0 | E42: 0 | F42: 0 | G42: 0 | H42: 0 | I42: =SUM(G42:H42) -> 0 | J42: =ROUND(I42*0.7,0) -> 0 | K42: 0 | L42: =ROUND(I42*0.27,0) -> 0 | M42: 0 | N42: 0 | O42: 0 | P42: 0 | Q42: =SUM(F42+I42+J42+K42+L42+M42+N42+O42+P42) -> 0
...

Sheet Page 2
A1: अर्थसंकल्पीय अंदाजपत्रक सन 2026-2027 (प्रपत्र क)
A2: मागणी क्र.सी- 1- लेखाशिर्ष 20530162
A3: (आकडे हजारात)
A4: जिल्हा | B4: स्थायी पदे
C5: भरलेली पदे | G5: रिक्त पदे | K5: एकूण
A6: मुंबई शहर | B6: वर्ग | C6: वर्ग-1 व 2 | D6: वर्ग-3 | E6: वर्ग-4 | F6: एकूण | G6: वर्ग-1 व 2 | H6: वर्ग-3 | I6: वर्ग-4 | J6: एकूण | K6: एकूण
B7: पदे | C7: 0 | D7: 0 | E7: 0 | F7: =SUM(C7:E7) -> 0 | G7: 0 | H7: 0 | I7: 0 | J7: =SUM(G7:I7) -> 0 | K7: =SUM(J7,F7) -> 0
B8: वेतन | C8: 0 | D8: 0 | E8: 0 | F8: =SUM(C8:E8) -> 0 | G8: 0 | H8: 0 | I8: 0 | J8: =SUM(G8:I8) -> 0 | K8: =SUM(J8,F8) -> 0
B9: ग्रेड पे | C9: 0 | D9: 0 | E9: 0 | F9: =SUM(C9:E9) -> 0 | G9: 0 | H9: 0 | I9: 0 | J9: =SUM(G9:I9) -> 0 | K9: =SUM(J9,F9) -> 0
B10: एकूण | C10: =SUM(C8:C9) -> 0 | D10: =SUM(D8:D9) -> 0 | E10: =SUM(E8:E9) -> 0 | F10: =SUM(C10:E10) -> 0 | G10: =SUM(G8:G9) -> 0 | H10: =SUM(H8:H9) -> 0 | I10: =SUM(I8:I9) -> 0 | J10: =SUM(J8:J9) -> 0 | K10: =SUM(K8:K9) -> 0
B11: विशेष वेतन | C11: 0 | D11: 0 | E11: 0 | F11: =SUM(C11:E11) -> 0 | G11: 0 | H11: 0 | I11: 0 | J11: =SUM(G11:I11) -> 0 | K11: =SUM(J11,F11) -> 0
B12: महा.भत्ता | C12: 0 | D12: 0 | E12: 0 | F12: =SUM(C12:E12) -> 0 | G12: 0 | H12: 0 | I12: 0 | J12: =SUM(G12:I12) -> 0 | K12: =SUM(J12,F12) -> 0
B13: स्था.पु.भ. | C13: 0 | D13: 0 | E13: 0 | F13: =SUM(C13:E13) -> 0 | G13: 0 | H13: 0 | I13: 0 | J13: =SUM(G13:I13) -> 0 | K13: =SUM(J13,F13) -> 0
B14: घरभाडे | C14: 0 | D14: 0 | E14: 0 | F14: =SUM(C14:E14) -> 0 | G14: 0 | H14: 0 | I14: 0 | J14: =SUM(G14:I14) -> 0 | K14: =SUM(J14,F14) -> 0
B15: प्रवास भत्ता | C15: 0 | D15: 0 | E15: 0 | F15: =SUM(C15:E15) -> 0 | G15: 0 | H15: 0 | I15: 0 | J15: =SUM(G15:I15) -> 0 | K15: =SUM(J15,F15) -> 0
B16: इतर | C16: 0 | D16: 0 | E16: 0 | F16: =SUM(C16:E16) -> 0 | G16: 0 | H16: 0 | I16: 0 | J16: =SUM(G16:I16) -> 0 | K16: =SUM(J16,F16) -> 0
B17: एकूण | C17: =SUM(C10:C16) -> 0 | D17: =SUM(D10:D16) -> 0 | E17: =SUM(E10:E16) -> 0 | F17: =SUM(F10:F16) -> 0 | G17: =SUM(G10:G16) -> 0 | H17: =SUM(H10:H16) -> 0 | I17: =SUM(I10:I16) -> 0 | J17: =SUM(J10:J16) -> 0 | K17: =SUM(K10:K16) -> 0
A19: जिल्हा | B19: अस्थायी पदे | M19: सर्व वर्ग पदे
C20: भरलेली पदे | G20: रिक्त पदे | K20: एकूण | M20: वर्ग | N20: स्थायी पदे | O20: अस्थायी पदे | P20: एकूण
A21: मुंबई शहर | B21: वर्ग | C21: वर्ग-1 व 2 | D21: वर्ग-3 | E21: वर्ग-4 | F21: एकूण | G21: वर्ग-1 व 2 | H21: वर्ग-3 | I21: वर्ग-4 | J21: एकूण | K21: एकूण | M21: पदे | N21: =K7 -> 0 | O21: =K22 -> 0 | P21: =SUM(N21:O21) -> 0
B22: पदे | C22: 0 | D22: 0 | E22: 0 | F22: =SUM(C22:E22) -> 0 | G22: 0 | H22: 0 | I22: 0 | J22: =SUM(G22:I22) -> 0 | K22: =SUM(J22,F22) -> 0 | M22: वेतन | N22: =K8 -> 0 | O22: =K23 -> 0 | P22: =SUM(N22:O22) -> 0
B23: वेतन | C23: 0 | D23: 0 | E23: 0 | F23: =SUM(C23:E23) -> 0 | G23: 0 | H23: 0 | I23: 0 | J23: =SUM(G23:I23) -> 0 | K23: =SUM(J23,F23) -> 0 | M23: ग्रेड पे | N23: =K9 -> 0 | O23: =K24 -> 0 | P23: =SUM(N23:O23) -> 0
B24: ग्रेड पे | C24: 0 | D24: 0 | E24: 0 | F24: =SUM(C24:E24) -> 0 | G24: 0 | H24: 0 | I24: 0 | J24: =SUM(G24:I24) -> 0 | K24: =SUM(J24,F24) -> 0 | M24: एकूण | N24: =K10 -> 0 | O24: =K25 -> 0 | P24: =SUM(N24:O24) -> 0
B25: एकूण | C25: =SUM(C23:C24) -> 0 | D25: =SUM(D23:D24) -> 0 | E25: =SUM(E23:E24) -> 0 | F25: =SUM(C25:E25) -> 0 | G25: =SUM(G23:G24) -> 0 | H25: =SUM(H23:H24) -> 0 | I25: =SUM(I23:I24) -> 0 | J25: =SUM(J23:J24) -> 0 | K25: =SUM(K23:K24) -> 0 | M25: महा.भत्ता | N25: =K12 -> 0 | O25: =K27 -> 0 | P25: =SUM(N25:O25) -> 0
B26: विशेष वेतन | C26: 0 | D26: 0 | E26: 0 | F26: =SUM(C26:E26) -> 0 | G26: 0 | H26: 0 | I26: 0 | J26: =SUM(G26:I26) -> 0 | K26: =SUM(J26,F26) -> 0 | M26: विशेष वेतन | N26: =$K$11 -> 0 | O26: =SUM(K26) -> 0 | P26: =SUM(N26:O26) -> 0
B27: महा.भत्ता | C27: 0 | D27: 0 | E27: 0 | F27: =SUM(C27:E27) -> 0 | G27: 0 | H27: 0 | I27: 0 | J27: =SUM(G27:I27) -> 0 | K27: =SUM(J27,F27) -> 0 | M27: स्था.पु.भ. | N27: =K13 -> 0 | O27: =K28 -> 0 | P27: =SUM(N27:O27) -> 0
B28: स्था.पु.भ. | C28: 0 | D28: 0 | E28: 0 | F28: =SUM(C28:E28) -> 0 | G28: 0 | H28: 0 | I28: 0 | J28: =SUM(G28:I28) -> 0 | K28: =SUM(J28,F28) -> 0 | M28: घरभाडे | N28: =K14 -> 0 | O28: =K29 -> 0 | P28: =SUM(N28:O28) -> 0
B29: घरभाडे | C29: 0 | D29: 0 | E29: 0 | F29: =SUM(C29:E29) -> 0 | G29: 0 | H29: 0 | I29: 0 | J29: =SUM(G29:I29) -> 0 | K29: =SUM(J29,F29) -> 0 | M29: प्रवास भत्ता | N29: =K15 -> 0 | O29: =K30 -> 0 | P29: =SUM(N29:O29) -> 0
B30: प्रवास भत्ता | C30: 0 | D30: 0 | E30: 0 | F30: =SUM(C30:E30) -> 0 | G30: 0 | H30: 0 | I30: 0 | J30: =SUM(G30:I30) -> 0 | K30: =SUM(J30,F30) -> 0 | M30: इतर | N30: =K16 -> 0 | O30: =K31 -> 0 | P30: =SUM(N30:O30) -> 0
B31: इतर | C31: 0 | D31: 0 | E31: 0 | F31: =SUM(C31:E31) -> 0 | G31: 0 | H31: 0 | I31: 0 | J31: =SUM(G31:I31) -> 0 | K31: =SUM(J31,F31) -> 0 | M31: एकूण | N31: =SUM(N24:N30) -> 0 | O31: =SUM(O24:O30) -> 0 | P31: =SUM(P24:P30) -> 0
B32: एकूण | C32: =SUM(C25:C31) -> 0 | D32: =SUM(D25:D31) -> 0 | E32: =SUM(E25:E31) -> 0 | F32: =SUM(F25:F31) -> 0 | G32: =SUM(G25:G31) -> 0 | H32: =SUM(H25:H31) -> 0 | I32: =SUM(I25:I31) -> 0 | J32: =SUM(J25:J31) -> 0 | K32: =SUM(K25:K31) -> 0
A34: अर्थसंकल्पीय अंदाजपत्रक सन 2026-2027 (प्रपत्र क)
A35: मागणी क्र.सी- 1- लेखाशिर्ष 20530162
A36: (आकडे हजारात)
A37: जिल्हा | B37: स्थायी पदे
C38: भरलेली पदे | G38: रिक्त पदे | K38: एकूण
A39: मुंबई उपनगर | B39: वर्ग | C39: वर्ग-1 व 2 | D39: वर्ग-3 | E39: वर्ग-4 | F39: एकूण | G39: वर्ग-1 व 2 | H39: वर्ग-3 | I39: वर्ग-4 | J39: एकूण | K39: एकूण
B40: पदे | C40: 1 | D40: 2 | E40: 1 | F40: =SUM(C40:E40) -> 4 | G40: 0 | H40: 0 | I40: 1 | J40: =SUM(G40:I40) -> 1 | K40: =SUM(J40,F40) -> 5
B41: वेतन | C41: 1304 | D41: 568 | E41: 629 | F41: =SUM(C41:E41) -> 2501 | G41: 0 | H41: 0 | I41: 220 | J41: =SUM(G41:I41) -> 220 | K41: =SUM(J41,F41) -> 2721
B42: ग्रेड पे | C42: 0 | D42: 0 | E42: 0 | F42: =SUM(C42:E42) -> 0 | G42: 0 | H42: 0 | I42: 0 | J42: =SUM(G42:I42) -> 0 | K42: =SUM(J42,F42) -> 0
...

Sheet Page 3
A1: अर्थसंकल्पीय अंदाजपत्रक सन 2020-2021
A2: मागणी क्र.सी- 1- लेखाशिर्ष 20530162
A3: मंजूर पदे
A4: अ.क्र. | B4: वर्ग | C4: स्थायी | E4: अस्थायी | G4: एकूण
C5: भरलेली पदे | D5: रिक्त पदे | E5: भरलेली पदे | F5: रिक्त पदे
A6: 1 | B6: 1 | C6: 0 | D6: 0 | E6: 0 | F6: 0 | G6: =SUM(C6:F6) -> 0
A7: 2 | B7: 2 | C7: 0 | D7: 0 | E7: 0 | F7: 0 | G7: =SUM(C7:F7) -> 0
A8: 3 | B8: 3 | C8: 0 | D8: 0 | E8: 0 | F8: 0 | G8: =SUM(C8:F8) -> 0
A9: 4 | B9: 4 | C9: 0 | D9: 0 | E9: 0 | F9: 0 | G9: =SUM(C9:F9) -> 0
A10: -- | B10: एकूण | C10: =SUM(C6:C9) -> 0 | D10: =SUM(D6:D9) -> 0 | E10: =SUM(E6:E9) -> 0 | F10: =SUM(F6:F9) -> 0 | G10: =SUM(G6:G9) -> 0
F13: (आकडे हजारात)
A14: अ.क्र. | B14: जिल्हा / विभाग | C14: वैद्यकिय खर्च | D14: उत्सव/सण अग्रिम | E14: स्वग्राम/महाराष्ट्र दर्शन | F14: 6 व्या वेतन आयोग फरक | G14: इतर | H14: एकूण
A15: 1 | B15: मुंबई शहर | C15: 0 | D15: 0 | E15: 0 | F15: 0 | G15: 0 | H15: =SUM(C15:G15) -> 0
A17: अर्थसंकल्पीय अंदाजपत्रक सन 2026-2027 (प्रपत्र ब)
A18: मागणी क्र.सी- 1- लेखाशिर्ष 20530162
A19: मंजूर पदे
A20: अ.क्र. | B20: वर्ग | C20: स्थायी | E20: अस्थायी | G20: एकूण
C21: भरलेली पदे | D21: रिक्त पदे | E21: भरलेली पदे | F21: रिक्त पदे
A22: 1 | B22: 1 | C22: 1 | D22: 0 | E22: 1 | F22: 0 | G22: =SUM(C22:F22) -> 2
A23: 2 | B23: 2 | C23: 0 | D23: 0 | E23: 2 | F23: 0 | G23: =SUM(C23:F23) -> 2
A24: 3 | B24: 3 | C24: 2 | D24: 0 | E24: 6 | F24: 4 | G24: =SUM(C24:F24) -> 12
A25: 4 | B25: 4 | C25: 1 | D25: 1 | E25: 1 | F25: 1 | G25: =SUM(C25:F25) -> 4
A26: -- | B26: एकूण | C26: =SUM(C22:C25) -> 4 | D26: =SUM(D22:D25) -> 1 | E26: =SUM(E22:E25) -> 10 | F26: =SUM(F22:F25) -> 5 | G26: =SUM(G22:G25) -> 20
F29: (आकडे हजारात)
A30: अ.क्र. | B30: जिल्हा / विभाग | C30: वैद्यकिय खर्च | D30: उत्सव/सण अग्रिम | E30: स्वग्राम/महाराष्ट्र दर्शन | F30: NPS | G30: इतर | H30: एकूण
A31: 1 | B31: मुंबई उपनगर | C31: 1600 | D31: 150 | E31: 150 | F31: 500 | G31: 500 | H31: =SUM(C31:G31) -> 2900
A33: अर्थसंकल्पीय अंदाजपत्रक सन 2026-2027 (प्रपत्र ब)
A34: मागणी क्र.सी- 1- लेखाशिर्ष 20530162
A35: मंजूर पदे
A36: अ.क्र. | B36: वर्ग | C36: स्थायी | E36: अस्थायी | G36: एकूण
C37: भरलेली पदे | D37: रिक्त पदे | E37: भरलेली पदे | F37: रिक्त पदे
A38: 1 | B38: 1 | C38: 2 | D38: 0 | E38: 2 | F38: 0 | G38: =SUM(C38:F38) -> 4
A39: 2 | B39: 2 | C39: 0 | D39: 0 | E39: 4 | F39: 0 | G39: =SUM(C39:F39) -> 4
A40: 3 | B40: 3 | C40: 7 | D40: 3 | E40: 14 | F40: 0 | G40: =SUM(C40:F40) -> 24
A41: 4 | B41: 4 | C41: 4 | D41: 0 | E41: 4 | F41: 0 | G41: =SUM(C41:F41) -> 8
A42: -- | B42: एकूण | C42: =SUM(C38:C41) -> 13 | D42: =SUM(D38:D41) -> 3 | E42: =SUM(E38:E41) -> 24 | F42: =SUM(F38:F41) -> 0 | G42: =SUM(G38:G41) -> 40
F45: (आकडे हजारात)
A46: अ.क्र. | B46: जिल्हा / विभाग | C46: वैद्यकिय खर्च | D46: उत्सव/सण अग्रिम | E46: स्वग्राम/महाराष्ट्र दर्शन | F46: NPS | G46: इतर | H46: एकूण
A47: 1 | B47: ठाणे | C47: 650 | D47: 155 | E47: 100 | F47: 0 | G47: 4172 | H47: =SUM(C47:G47) -> 5077
A49: अर्थसंकल्पीय अंदाजपत्रक सन 2026-2027 (प्रपत्र ब)
...

Sheet Page 4
A1: अर्थसंकल्पीय अंदाजपत्रक सन 2020-2021
A2: मागणी क्र.सी- 1- लेखाशिर्ष 20530162
A3: जिल्हा मुंबई शहर | L3: (आकडे हजारात)
A4: अ. क्र. | B4: लेख्याची प्राथमिक आणि दुय्यम युनिट | C4: प्रत्यक्ष रक्कमा (खर्च) | F4: अर्थसंकल्पीय अंदाज | G4: सुधारीत अंदाज | H4: अर्थसंकल्पीय अंदाज 2020-2021 | L4: मागील वर्षाच्या प्रत्यक्ष रक्कमा आणि चालु वर्षाच्या अर्थसंकल्पीय अंदाजाची तुलना करता आगामी वर्षासाठीच्या अंदाजातील वाढ किंवा घट यांच्या संबंधातील स्पष्टीकरणे.
C5: 2020-2021 | D5: 2021-2022 | E5: 2022-2023 | F5: 2023-2024 | G5: 2023-2024 | H5: प्राकक्लन (एस्टिमेटिंग) अधिका-याचा | I5: नियंत्रक अधिका-यांचा | J5: प्रशासकीय विभागाचा | K5: वित्त विभागाचा
A6: 1 | B6: 2 | C6: 3 | D6: 4 | E6: 5 | F6: 6 | G6: 7 | H6: 8 | I6: 9 | J6: 10 | K6: 11 | L6: 12
A7: 1 | B7: 01- वेतन | C7: 0 | D7: 0 | E7: 0 | F7: 0 | G7: 0 | H7: 0 | I7: 0 | J7: 0 | K7: 0
A8: 2 | B8: 03- अति.भत्ता | C8: 0 | D8: 0 | E8: 0 | F8: 0 | G8: 0 | H8: 0 | I8: 0 | J8: 0 | K8: 0
A9: 3 | B9: 06- दूरध्वनी, वीज,पाणी व शुल्क | C9: 0 | D9: 0 | E9: 0 | F9: 0 | G9: 0 | H9: 0 | I9: 0 | J9: 0 | K9: 0
A10: 4 | B10: 10- कंत्राटी सेवा | C10: 0 | D10: 0 | E10: 0 | F10: 0 | G10: 0 | H10: 0 | I10: 0 | J10: 0 | K10: 0
A11: 5 | B11: 11- देशांतर्गत प्रवास खर्च | C11: 0 | D11: 0 | E11: 0 | F11: 0 | G11: 0 | H11: 0 | I11: 0 | J11: 0 | K11: 0
A12: 6 | B12: 13- कार्यालयीन खर्च | C12: 0 | D12: 0 | E12: 0 | F12: 0 | G12: 0 | H12: 0 | I12: 0 | J12: 0 | K12: 0
A13: 7 | B13: 14-भाडेपट्टी व कर | C13: 0 | D13: 0 | E13: 0 | F13: 0 | G13: 0 | H13: 0 | I13: 0 | J13: 0 | K13: 0
A14: 8 | B14: 16- प्रकाशने | C14: 0 | D14: 0 | E14: 0 | F14: 0 | G14: 0 | H14: 0 | I14: 0 | J14: 0 | K14: 0
A15: 9 | B15: 17- संगणक खर्च | C15: 0 | D15: 0 | E15: 0 | F15: 0 | G15: 0 | H15: 0 | I15: 0 | J15: 0 | K15: 0
A16: 10 | B16: 20- इतर प्रशासकीय खर्च | C16: 0 | D16: 0 | E16: 0 | F16: 0 | G16: 0 | H16: 0 | I16: 0 | J16: 0 | K16: 0
A17: 11 | B17: 24- इंधन | C17: 0 | D17: 0 | E17: 0 | F17: 0 | G17: 0 | H17: 0 | I17: 0 | J17: 0 | K17: 0
A18: 12 | B18: 26- जाहीरात व प्रसिध्दी खर्च | C18: 0 | D18: 0 | E18: 0 | F18: 0 | G18: 0 | H18: 0 | I18: 0 | J18: 0 | K18: 0
... A20: 14 | B20: 51- मोटार वाहने | C20: 0 | D20: 0 | E20: 0 | F20: 0 | G20: 0 | H20: 0 | I20: 0 | J20: 0 | K20: 0
A21: -- | B21: एकूण | C21: =SUM(C7:C20) -> 0 | D21: =SUM(D7:D20) -> 0 | E21: =SUM(E7:E20) -> 0 | F21: =SUM(F7:F20) -> 0 | G21: =SUM(G7:G20) -> 0 | H21: =SUM(H7:H20) -> 0 | I21: =SUM(I7:I20) -> 0 | J21: =SUM(J7:J20) -> 0 | K21: =SUM(K7:K20) -> 0
A23: अर्थसंकल्पीय अंदाजपत्रक सन 2026-2027 (प्रपत्र अ)
A24: मागणी क्र.सी- 1- लेखाशिर्ष 20530162
A25: जिल्हा मुंबई उपनगर | L25: (आकडे हजारात)
A26: अ. क्र. | B26: लेख्याची प्राथमिक आणि दुय्यम युनिट | C26: प्रत्यक्ष रक्कमा (खर्च) | F26: अर्थसंकल्पीय अंदाज | G26: सुधारीत अंदाज | H26: अर्थसंकल्पीय अंदाज 2026-2027 | L26: मागील वर्षाच्या प्रत्यक्ष रक्कमा आणि चालु वर्षाच्या अर्थसंकल्पीय अंदाजाची तुलना करता आगामी वर्षासाठीच्या अंदाजातील वाढ किंवा घट यांच्या संबंधातील स्पष्टीकरणे.
C27: 2022-2023 | D27: 2023-2024 | E27: 2024-2025 | F27: 2025-2026 | G27: 2025-2026 | H27: प्राकक्लन (एस्टिमेटिंग) अधिका-याचा | I27: नियंत्रक अधिका-यांचा | J27: प्रशासकीय विभागाचा | K27: वित्त विभागाचा
A28: 1 | B28: 2 | C28: 3 | D28: 4 | E28: 5 | F28: 6 | G28: 7 | H28: 8 | I28: 9 | J28: 10 | K28: 11 | L28: 12
A29: 1 | B29: 01- वेतन | C29: 12548 | D29: 12928 | E29: 15513 | F29: 28615 | G29: 28615 | H29: 28777 | I29: 0 | J29: 0 | K29: 0
A30: 2 | B30: 03- अति.भत्ता | C30: 30 | D30: 0 | E30: 38 | F30: 117 | G30: 117 | H30: 200 | I30: 0 | J30: 0 | K30: 0
A31: 3 | B31: 06- दूरध्वनी, वीज,पाणी व शुल्क | C31: 0 | D31: 59 | E31: 79 | F31: 150 | G31: 150 | H31: 200 | I31: 0 | J31: 0 | K31: 0
A32: 4 | B32: 10- कंत्राटी सेवा | C32: 0 | D32: 0 | E32: 0 | F32: 0 | G32: 0 | H32: 0 | I32: 0 | J32: 0 | K32: 0
A33: 5 | B33: 11- देशांतर्गत प्रवास खर्च | C33: 0 | D33: 0 | E33: 0 | F33: 96 | G33: 96 | H33: 96 | I33: 0 | J33: 0 | K33: 0
A34: 6 | B34: 13- कार्यालयीन खर्च | C34: 274 | D34: 759 | E34: 122 | F34: 1500 | G34: 1500 | H34: 1500 | I34: 0 | J34: 0 | K34: 0
A35: 7 | B35: 14-भाडेपट्टी व कर | C35: 0 | D35: 0 | E35: 0 | F35: 0 | G35: 0 | H35: 0 | I35: 0 | J35: 0 | K35: 0
A36: 8 | B36: 16- प्रकाशने | C36: 0 | D36: 0 | E36: 0 | F36: 1 | G36: 1 | H36: 0 | I36: 0 | J36: 0 | K36: 0
A37: 9 | B37: 17- संगणक खर्च | C37: 0 | D37: 0 | E37: 0 | F37: 50 | G37: 50 | H37: 100 | I37: 0 | J37: 0 | K37: 0
A38: 10 | B38: 20- इतर प्रशासकीय खर्च | C38: 0 | D38: 0 | E38: 0 | F38: 0 | G38: 0 | H38: 0 | I38: 0 | J38: 0 | K38: 0
A39: 11 | B39: 24- इंधन | C39: 58 | D39: 454 | E39: 316 | F39: 735 | G39: 735 | H39: 400 | I39: 0 | J39: 0 | K39: 0
A40: 12 | B40: 26- जाहीरात व प्रसिध्दी खर्च | C40: 0 | D40: 0 | E40: 0 | F40: 0 | G40: 0 | H40: 300 | I40: 0 | J40: 0 | K40: 0
... A42: 14 | B42: 51- मोटार वाहने | C42: 0 | D42: 0 | E42: 0 | F42: 0 | G42: 0 | H42: 0 | I42: 0 | J42: 0 | K42: 0
A43: -- | B43: एकूण | C43: =SUM(C29:C42) -> 12910 | D43: =SUM(D29:D42) -> 14200 | E43: =SUM(E29:E42) -> 16068 | F43: =SUM(F29:F42) -> 31264 | G43: =SUM(G29:G42) -> 31264 | H43: =SUM(H29:H42) -> 31573 | I43: =SUM(I29:I42) -> 0 | J43: =SUM(J29:J42) -> 0 | K43: =SUM(K29:K42) -> 0
...

Sheet Page 5
A1: अर्थसंकल्पीय अंदाजपत्रक सन 2026-2027
A2: मागणी क्र.सी- 1- लेखाशिर्ष 20530162
A3: कोकण विभाग | L3: (आकडे हजारात)
A4: अ. क्र. | B4: लेख्याची प्राथमिक आणि दुय्यम युनिट | C4: प्रत्यक्ष रक्कमा (खर्च) | F4: अर्थसंकल्पीय अंदाज | G4: सुधारीत अंदाज | H4: अर्थसंकल्पीय अंदाज 2026-2027 | L4: मागील वर्षाच्या प्रत्यक्ष रक्कमा आणि चालु वर्षाच्या अर्थसंकल्पीय अंदाजाची तुलना करता आगामी वर्षासाठीच्या अंदाजातील वाढ किंवा घट यांच्या संबंधातील स्पष्टीकरणे.
C5: 2022-2023 | D5: 2023-2024 | E5: 2024-2025 | F5: 2025-2026 | G5: 2025-2026 | H5: प्राकक्लन (एस्टिमेटिंग) अधिका-याचा | I5: नियंत्रक अधिका-यांचा | J5: प्रशासकीय विभागाचा | K5: वित्त विभागाचा
A6: 1 | B6: 2 | C6: 3 | D6: 4 | E6: 5 | F6: 6 | G6: 7 | H6: 8 | I6: 9 | J6: 10 | K6: 11 | L6: 12
A7: 1 | B7: 01- वेतन | C7: ='Page 4'!C183 -> 183854 | D7: ='Page 4'!D183 -> 197411 | E7: ='Page 4'!E183 -> 214250 | F7: ='Page 4'!F183 -> 320000 | G7: ='Page 4'!G183 -> 333639 | H7: 0 | I7: ='Page 4'!H183 -> 363203 | J7: ='Page 4'!J183 -> 0 | K7: ='Page 4'!K183 -> 0 | L7: 01- वेतन:- या बाबीखाली सातवा वेतन आयोग फरक, चालु महागाई भत्ता दर आकारणी 70% प्रमाणे विचारात घेवून केली आहे. वेळोवेळी होणारी वेतनवाढ व महागाई भत्ता दराप्रमाणे वाढीव अनुदान मिळणेस विनंती आहे.
A8: 2 | B8: 03 अति.भत्ता | C8: ='Page 4'!C184 -> 244 | D8: ='Page 4'!D184 -> 320 | E8: ='Page 4'!E184 -> 690 | F8: ='Page 4'!F184 -> 1700 | G8: ='Page 4'!G184 -> 2007 | H8: 0 | I8: ='Page 4'!H184 -> 2800 | J8: ='Page 4'!J184 -> 0 | K8: ='Page 4'!K184 -> 0 | L8: 03- अति. भत्ता:- विभागीय आयुक्त कोकण विभाग यांचे अधिनस्त सर्व जिल्हयांनी त्यांचेकडील मागील वर्षाच्या उपलेखाशिर्षनिहाय प्रत्यक्ष खर्चाचे अवलोकन सबब सन 2025-26 चे अंदाजपत्रकात वाढ (+) झाली आहे.
A9: 3 | B9: 06- दूरध्वनी वीज,पाणी व शुल्क | C9: ='Page 4'!C185 -> 2712 | D9: ='Page 4'!D185 -> 3369 | E9: ='Page 4'!E185 -> 3435 | F9: ='Page 4'!F185 -> 6000 | G9: ='Page 4'!G185 -> 8450 | H9: 0 | I9: ='Page 4'!H185 -> 12700 | J9: ='Page 4'!J185 -> 0 | K9: ='Page 4'!K185 -> 0 | L9: 06- दूरध्वनी, वीज पाणी व शुल्क:- या बाबीखाली विभागात शासनाने ठरवून दिलेल्या जमीन महसूल कर वसुलीच्या वाढीव उद्दिष्टपूर्तता बाबत जिल्हा कार्यालयाशी मोठया प्रमाणावर संपर्क साधण्यासाठी दूरध्वनीचा वापर, वीजेचे वाढलेले दर व पाणीपट्टीची वाढीव देयके यासाठी वाढीव अनुदानाची गरज आहे.
A10: 4 | B10: 10- कंत्राटी सेवा | C10: ='Page 4'!C186 -> 0 | D10: ='Page 4'!D186 -> 0 | E10: ='Page 4'!E186 -> 0 | F10: ='Page 4'!F186 -> 1 | G10: ='Page 4'!G186 -> 0 | H10: 0 | I10: ='Page 4'!H186 -> 0 | J10: ='Page 4'!J186 -> 0 | K10: ='Page 4'!K186 -> 0
A11: 5 | B11: 11- देशांतर्गत प्रवास खर्च | C11: ='Page 4'!C187 -> 551 | D11: ='Page 4'!D187 -> 980 | E11: ='Page 4'!E187 -> 1091 | F11: ='Page 4'!F187 -> 4500 | G11: ='Page 4'!G187 -> 4557 | H11: 0 | I11: ='Page 4'!H187 -> 4766 | J11: ='Page 4'!J187 -> 0 | K11: ='Page 4'!K187 -> 0 | L11: 11- देशांतर्गत प्रवास खर्च:- 1)सदर बाबीखाली शासनाने ठरवून दिलेल्या जमीन महसूल कर वसुलीच्या वाढीव उद्दिष्टपूर्तताबाबत वाढीव फिरती कराव्या लागत असल्याने प्रवास खर्च अनुदानाची मागणी केली आहे. 2)तसेच संभाव्य बदली प्रवास भत्ता अदा करणेकरीता अनुदानाची आवश्यकता आहे.
A12: 6 | B12: 13- कार्यालयीन खर्च | C12: ='Page 4'!C188 -> 10277 | D12: ='Page 4'!D188 -> 12934 | E12: ='Page 4'!E188 -> 10957 | F12: ='Page 4'!F188 -> 17500 | G12: ='Page 4'!G188 -> 18200 | H12: 0 | I12: ='Page 4'!H188 -> 21300 | J12: ='Page 4'!J188 -> 0 | K12: ='Page 4'!K188 -> 0 | L12: 13- कार्यालयीन खर्च:- सदर बाबीखाली कार्या.खर्चसाठी स्टेशनरी, जडसंग्रह वस्तु, झेरॉक्स यांच्या वाढीव दरामुळे कार्यालयीन खर्च मोठया प्रमाणावर वाढला आहे. त्यामुळे अनुदानाची मागणी केली आहे.
A13: 7 | B13: 14- भाडेपट्टी व कर | C13: ='Page 4'!C189 -> 646 | D13: ='Page 4'!D189 -> 574 | E13: ='Page 4'!E189 -> 606 | F13: ='Page 4'!F189 -> 1595 | G13: ='Page 4'!G189 -> 2490 | H13: 0 | I13: ='Page 4'!H189 -> 3630 | J13: ='Page 4'!J189 -> 0 | K13: ='Page 4'!K189 -> 0 | L13: 14-भाडेपट्टी व कर:- विभागीय आयुक्त कोकण विभाग यांचे अधिनस्त उपविभागीय अधिकारी कार्यालयाचे आवश्यकतेप्रमाणे जिल्हाधिकारी कार्यालयाकडील अंदाजपत्रकीय अनुदान मागणीनुसार अनुदान मंजूर होणेंस विनंती आहे.
A14: 8 | B14: 16- प्रकाशने | C14: ='Page 4'!C190 -> 0 | D14: ='Page 4'!D190 -> 0 | E14: ='Page 4'!E190 -> 0 | F14: ='Page 4'!F190 -> 1 | G14: ='Page 4'!G190 -> 101 | H14: 0 | I14: ='Page 4'!H190 -> 100 | J14: ='Page 4'!J190 -> 0 | K14: ='Page 4'!K190 -> 0 | L14: 16- प्रकाशने:- विभागीय आयुक्त कोकण विभाग यांचे अधिनस्त सर्व उपविभागीय अधिकारी कार्यालयांतील विविध प्रकारच्या छपाईची देयके अदा करण्याकरीता रक्कमेची आवश्यक आहे.
A15: 9 | B15: 17- संगणक खर्च | C15: ='Page 4'!C191 -> 219 | D15: ='Page 4'!D191 -> 200 | E15: ='Page 4'!E191 -> 156 | F15: ='Page 4'!F191 -> 700 | G15: ='Page 4'!G191 -> 2305 | H15: 0 | I15: ='Page 4'!H191 -> 3675 | J15: ='Page 4'!J191 -> 0 | K15: ='Page 4'!K191 -> 0 | L15: 17- संगणक खर्च :- सदर बाबीखाली दरवर्षी अंदाजपत्रकीय मागणीचे तुलनेत कमी अनुदान प्राप्त होत आहे. सदर उपशिर्षाखाली जमीन महसूल कर वसुली उद्दिष्टपूर्तता बाबत शासनास पाठवावयाचे नियतकालीके अहवाल तयार करणे इ. कार्यालयीन कामे संगणकावर करावी लागतात. त्यामुळे नवीन संगणक खरेदीकरीता संगणक खर्च अनुदान मिळणेस विनंती आहे.
A16: 10 | B16: 20- इतर प्रशासकीय खर्च | C16: ='Page 4'!C192 -> 0 | D16: ='Page 4'!D192 -> 0 | E16: ='Page 4'!E192 -> 0 | F16: ='Page 4'!F192 -> 0 | G16: ='Page 4'!G192 -> 0 | H16: 0 | I16: ='Page 4'!H192 -> 0 | J16: ='Page 4'!J192 -> 0 | K16: ='Page 4'!K192 -> 0
A17: 11 | B17: 24- इंधन खर्च | C17: ='Page 4'!C193 -> 1645 | D17: ='Page 4'!D193 -> 2717 | E17: ='Page 4'!E193 -> 2481 | F17: ='Page 4'!F193 -> 7000 | G17: ='Page 4'!G193 -> 7411 | H17: 0 | I17: ='Page 4'!H193 -> 7670 | J17: ='Page 4'!J193 -> 0 | K17: ='Page 4'!K193 -> 0 | L17: 24- इंधन खर्च :- शासनाने ठरवून दिलेल्या वाढीव महसूल उद्दिष्टपूर्तताबाबत विभागीय आयुक्त कोकण विभाग यांचे अधिनस्त एकूण 27 उपविभागीय अधिकारी यांचे विविध दौ-यासाठी त्यांचे वाहनांच्या पेट्रोल व डिझेल खर्चाकरिता अनुदान प्राप्त होणे आवश्यक आहे.
A18: 12 | B18: 26- जाहीरात व प्रसिध्दी खर्च | C18: ='Page 4'!C194 -> 0 | D18: ='Page 4'!D194 -> 0 | E18: ='Page 4'!E194 -> 0 | F18: ='Page 4'!F194 -> 1 | G18: ='Page 4'!G194 -> 920 | H18: 0 | I18: ='Page 4'!H194 -> 1570 | J18: ='Page 4'!J194 -> 0 | K18: ='Page 4'!K194 -> 0 | L18: 26-जाहीरात व प्रसिध्दी खर्च:- जिल्हाधिकारी कार्यालयांचे आवश्यकतेप्रमाणे अनुदान मंजूर होणेंस विनंती आहे.
A19: 13 | B19: 50- इतर खर्च | C19: ='Page 4'!C195 -> 0 | D19: ='Page 4'!D195 -> 0 | E19: ='Page 4'!E195 -> 0 | F19: ='Page 4'!F195 -> 1 | G19: ='Page 4'!G195 -> 600 | H19: 0 | I19: ='Page 4'!H195 -> 400 | J19: ='Page 4'!J195 -> 0 | K19: ='Page 4'!K195 -> 0 | L19: 50- इतर खर्च:- (1)जिल्हाधिकारी कार्यालयांचे आवश्यकतेप्रमाणे अनुदान मंजूर होणेंस विनंती आहे. (2)विभागीय आयुक्त कार्यालयाचे सादर अंदाजपत्रकामध्ये नमूद बाबींव्यतिरिक्त विभागीय आयुक्त कार्यालयात करण्यात येणा-या खर्चाकरीता नवीन बाब निर्माण करण्यासाठी टोकन रक्कमेची आवश्यक आहे.
A20: 14 | B20: 51- मोटार वाहने | C20: ='Page 4'!C196 -> 0 | D20: ='Page 4'!D196 -> 0 | E20: ='Page 4'!E196 -> 0 | F20: ='Page 4'!F196 -> 1 | G20: ='Page 4'!G196 -> 1071 | H20: 0 | I20: ='Page 4'!H196 -> 2320 | J20: ='Page 4'!J196 -> 0 | K20: ='Page 4'!K196 -> 0 | L20: 51-मोटार वाहने:- विभागीय आयुक्त कोकण विभाग यांचे अधिनस्त उपविभागीय अधिकारी कार्यालयांतील वाहन दुरुस्ती व देखभाल खर्चाकरीता अनुदानाची आवश्यकता आहे.
A21: -- | B21: एकूण | C21: =SUM(C7:C20) -> 200148 | D21: =SUM(D7:D20) -> 218505 | E21: =SUM(E7:E20) -> 233666 | F21: =SUM(F7:F20) -> 359000 | G21: =SUM(G7:G20) -> 381751 | H21: =SUM(H7:H20) -> 0 | I21: =SUM(I7:I20) -> 424134 | J21: =SUM(J7:J20) -> 0 | K21: =SUM(K7:K20) -> 0 | L21: --
J24: सहायक संचालक (लेखा) कोकण विभाग

Sheet Distrs.wise Abstract
A1: अर्थसंकल्पीय अंदाजपत्रक सन 2026-2027 (जिल्हानिहाय)
A2: मागणी क्र.सी-1- लेखाशिर्ष : 20530162
A3: (आकडे हजारात)
A4: अ. क्र. | B4: उपलेखाशिर्ष | C4: मुंबई उपनगर | D4: ठाणे | E4: पालघर | F4: रायगड | G4: रत्नागिरी | H4: सिंधुदुर्ग | I4: एकूण
A5: 1 | B5: 01- वेतन | C5: ='Page 4'!H29 -> 28777 | D5: ='Page 4'!H51 -> 50247 | E5: ='Page 4'!H73 -> 70827 | F5: ='Page 4'!H95 -> 94993 | G5: ='Page 4'!H117 -> 80615 | H5: ='Page 4'!H139 -> 37744 | I5: =C5+D5+E5+F5+G5+H5 -> 363203
A6: 2 | B6: 03- अति.भत्ता | C6: ='Page 4'!H30 -> 200 | D6: ='Page 4'!H52 -> 250 | E6: ='Page 4'!H74 -> 250 | F6: ='Page 4'!H96 -> 750 | G6: ='Page 4'!H118 -> 1050 | H6: ='Page 4'!H140 -> 300 | I6: =C6+D6+E6+F6+G6+H6 -> 2800
A7: 3 | B7: 06- दूरध्वनी, वीज,पाणी व शुल्क | C7: ='Page 4'!H31 -> 200 | D7: ='Page 4'!H53 -> 2700 | E7: ='Page 4'!H75 -> 2500 | F7: ='Page 4'!H97 -> 6000 | G7: ='Page 4'!H119 -> 1000 | H7: ='Page 4'!H141 -> 300 | I7: =C7+D7+E7+F7+G7+H7 -> 12700
A8: 4 | B8: 10- कंत्राटी सेवा | C8: ='[1]Page 4'!H32 -> 0 | D8: ='Page 4'!H54 -> 0 | E8: ='Page 4'!H76 -> 0 | F8: ='Page 4'!H98 -> 0 | G8: ='Page 4'!H120 -> 0 | H8: ='Page 4'!H142 -> 0 | I8: =C8+D8+E8+F8+G8+H8 -> 0
A9: 5 | B9: 11- देशांतर्गत प्रवास खर्च | C9: ='Page 4'!H33 -> 96 | D9: ='Page 4'!H55 -> 270 | E9: ='Page 4'!H77 -> 500 | F9: ='Page 4'!H99 -> 3000 | G9: ='Page 4'!H121 -> 600 | H9: ='Page 4'!H143 -> 300 | I9: =C9+D9+E9+F9+G9+H9 -> 4766
A10: 6 | B10: 13- कार्यालयीन खर्च | C10: ='Page 4'!H34 -> 1500 | D10: ='Page 4'!H56 -> 2200 | E10: ='Page 4'!H78 -> 2500 | F10: ='Page 4'!H100 -> 10000 | G10: ='Page 4'!H122 -> 3100 | H10: ='Page 4'!H144 -> 2000 | I10: =C10+D10+E10+F10+G10+H10 -> 21300
A11: 7 | B11: 14-भाडेपट्टी व कर | C11: ='Page 4'!H35 -> 0 | D11: ='Page 4'!H57 -> 200 | E11: ='Page 4'!H79 -> 1000 | F11: ='Page 4'!H101 -> 1000 | G11: ='Page 4'!H123 -> 1400 | H11: ='Page 4'!H145 -> 30 | I11: =C11+D11+E11+F11+G11+H11 -> 3630
A12: 8 | B12: 16- प्रकाशने | C12: ='[1]Page 4'!H36 -> 0 | D12: ='Page 4'!H58 -> 0 | E12: ='Page 4'!H80 -> 0 | F12: ='Page 4'!H102 -> 0 | G12: ='Page 4'!H124 -> 100 | H12: ='Page 4'!H146 -> 0 | I12: =C12+D12+E12+F12+G12+H12 -> 100
A13: 9 | B13: 17- संगणक खर्च | C13: ='Page 4'!H37 -> 100 | D13: ='Page 4'!H59 -> 1000 | E13: ='Page 4'!H81 -> 800 | F13: ='Page 4'!H103 -> 1000 | G13: ='Page 4'!H125 -> 700 | H13: ='Page 4'!H147 -> 75 | I13: =C13+D13+E13+F13+G13+H13 -> 3675
A14: 10 | B14: 20- इतर प्रशासकीय खर्च | C14: ='[1]Page 4'!H38 -> 0 | D14: ='Page 4'!H60 -> 0 | E14: ='Page 4'!H82 -> 0 | F14: ='Page 4'!H104 -> 0 | G14: ='Page 4'!H126 -> 0 | H14: ='Page 4'!H148 -> 0 | I14: =C14+D14+E14+F14+G14+H14 -> 0
A15: 11 | B15: 24- इंधन | C15: ='Page 4'!H39 -> 400 | D15: ='Page 4'!H61 -> 620 | E15: ='Page 4'!H83 -> 1500 | F15: ='Page 4'!H105 -> 3000 | G15: ='Page 4'!H127 -> 1300 | H15: ='Page 4'!H149 -> 850 | I15: =C15+D15+E15+F15+G15+H15 -> 7670
A16: 12 | B16: 26- जाहीरात व प्रसिध्दी खर्च | C16: ='Page 4'!H40 -> 300 | D16: ='Page 4'!H62 -> 320 | E16: ='Page 4'!H84 -> 600 | F16: ='Page 4'!H106 -> 250 | G16: ='Page 4'!H128 -> 100 | H16: ='Page 4'!H150 -> 0 | I16: =C16+D16+E16+F16+G16+H16 -> 1570
A17: 13 | B17: 50- इतर | C17: ='Page 4'!H41 -> 0 | D17: ='Page 4'!H63 -> 0 | E17: ='Page 4'!H85 -> 300 | F17: ='Page 4'!H107 -> 0 | G17: ='Page 4'!H129 -> 100 | H17: ='Page 4'!H151 -> 0 | I17: =C17+D17+E17+F17+G17+H17 -> 400
A18: 14 | B18: 51- मोटार वाहने | C18: ='Page 4'!H42 -> 0 | D18: ='Page 4'!H64 -> 220 | E18: ='Page 4'!H86 -> 700 | F18: ='Page 4'!H108 -> 1000 | G18: ='Page 4'!H130 -> 400 | H18: ='Page 4'!H152 -> 0 | I18: =C18+D18+E18+F18+G18+H18 -> 2320
A19: एकूण | C19: =SUM(C5:C18) -> 31573 | D19: =SUM(D5:D18) -> 58027 | E19: =SUM(E5:E18) -> 81477 | F19: =SUM(F5:F18) -> 120993 | G19: =SUM(G5:G18) -> 90465 | H19: =SUM(H5:H18) -> 41599 | I19: =SUM(I5:I18) -> 424134

Sheet Table-D
A2: जोडपत्र "ड"
A5: अर्थसंकल्पीय अंदाजपत्रक सन 2026-2027
A6: मागणी क्र.सी- 1- लेखाशिर्ष 20530162
A8: संवर्गनिहाय माहिती
A10: अ.क्र. | B10: संवर्ग | C10: मंजूर पदे | E10: भरलेली पदे | G10: रिक्त पदे
C11: स्थायी | D11: अस्थायी | E11: स्थायी | F11: अस्थायी | G11: स्थायी | H11: अस्थायी
A12: 1 | B12: वर्ग-1 | C12: =E12+G12 -> 10 | D12: =F12+H12 -> 17 | E12: 9 | F12: 16 | G12: 1 | H12: 1
A13: 2 | B13: वर्ग-2 | C13: =E13+G13 -> 0 | D13: =F13+H13 -> 27 | E13: 0 | F13: 25 | G13: 0 | H13: 2
A14: 3 | B14: वर्ग-3 | C14: =E14+G14 -> 60 | D14: =F14+H14 -> 102 | E14: 38 | F14: 75 | G14: 22 | H14: 27
A15: 4 | B15: वर्ग-4 | C15: =E15+G15 -> 22 | D15: =F15+H15 -> 32 | E15: 18 | F15: 25 | G15: 4 | H15: 7
A16: -- | B16: एकूण | C16: =C12+C13+C14+C15 -> 92 | D16: =D12+D13+D14+D15 -> 178 | E16: =E12+E13+E14+E15 -> 65 | F16: =F12+F13+F14+F15 -> 141 | G16: =G12+G13+G14+G15 -> 27 | H16: =H12+H13+H14+H15 -> 37
E20: सहायक संचालक (लेखा) कोकण विभाग
