Workbook

Sheet Page 1
A1: प्रपत्र - ड - अर्थसंकल्पीय अंदाजपत्रक सन 2021-2022
A2: मागणी क्र.सी- 1- लेखाशिर्ष 2029 0182
A3: जिल्हा मुंबई शहर | O3: (आकडे हजारात)
A4: अ क्र | B4: वर्ग | C4: पद | D4: मंजूर पदे | E4: मंजूर पदे | F4: विशेष वेतन | G4: मुळ वेतन | H4: ग्रेड वेतन | I4: एकूण | J4: महागाई भत्ता 25% | K4: स्थानिक पुरक भत्ता | L4: घर भाडे भत्ता | M4: वाहन भत्ता | N4: धूलाई भत्ता | O4: रोख भत्ता | P4: चप्पल भत्ता/ इतर | Q4: एकूण
D5: 2020-2021 | E5: 2021-2022
C6: स्थायी
A7: 1 | B7: वर्ग-3 | C7: अव्वल कारकून | I7: 0 | J7: 0 | Q7: 0
C8: लिपिक | I8: 0 | J8: 0 | Q8: 0
C9: एकूण वर्ग 3 | D9: 0 | E9: 0 | F9: 0 | G9: 0 | H9: 0 | I9: 0 | J9: 0 | K9: 0 | L9: 0 | M9: 0 | N9: 0 | O9: 0 | P9: 0 | Q9: 0
A10: 2 | B10: वर्ग-4 | C10: शिपाई | I10: 0 | J10: 0 | Q10: 0
C11: एकूण वर्ग 4 | D11: 0 | E11: 0 | F11: 0 | G11: 0 | H11: 0 | I11: 0 | J11: 0 | K11: 0 | L11: 0 | M11: 0 | N11: 0 | O11: 0 | P11: 0 | Q11: 0
C12: एकूण वर्ग 3 4 | D12: 0 | E12: 0 | F12: 0 | G12: 0 | H12: 0 | I12: 0 | J12: 0 | K12: 0 | L12: 0 | M12: 0 | N12: 0 | O12: 0 | P12: 0 | Q12: 0
A14: अ.क्र. | B14: वर्ग | C14: पद | D14: =D4 -> मंजूर पदे | E14: =E4 -> मंजूर पदे | F14: =F4 -> विशेष वेतन | G14: =G4 -> मुळ वेतन | H14: =H4 -> ग्रेड वेतन | I14: =I4 -> एकूण | J14: =J4 -> महागाई भत्ता 25% | K14: स्थानिक पुरक भत्ता | L14: घर भाडे भत्ता | M14: वाहन भत्ता | N14: धूलाई भत्ता | O14: रोख भत्ता | P14: चप्पल भत्ता/ इतर | Q14: एकूण
D15: =D5 -> 2020-2021 | E15: =E5 -> 2021-2022
C16: अस्थायी
A17: 1 | B17: वर्ग-1 व 2 | C17: उप जिल्हाधिकारी/वि.भू.अधि | I17: 0 | J17: 0 | Q17: 0
C18: नायब तहसिलदार | I18: 0 | J18: 0 | Q18: 0
C19: एकूण वर्ग 1 2 | D19: 0 | E19: 0 | F19: 0 | G19: 0 | H19: 0 | I19: 0 | J19: 0 | K19: 0 | L19: 0 | M19: 0 | N19: 0 | O19: 0 | P19: 0 | Q19: 0
A20: 2 | B20: वर्ग-3 | C20: अव्वल कारकून | I20: 0 | J20: 0 | Q20: 0
C21: उपलेखापाल | I21: 0 | J21: 0 | Q21: 0
C22: लघुलेखक | I22: 0 | J22: 0 | Q22: 0
C23: मंडळ अधिकारी | I23: 0 | J23: 0 | Q23: 0
C24: तलाठी | I24: 0 | J24: 0 | Q24: 0
C25: लिपिक | I25: 0 | J25: 0 | Q25: 0
C26: वाहन चालक | I26: 0 | J26: 0 | Q26: 0
C27: एकूण वर्ग 3 | D27: 0 | E27: 0 | F27: 0 | G27: 0 | H27: 0 | I27: 0 | J27: 0 | K27: 0 | L27: 0 | M27: 0 | N27: 0 | O27: 0 | P27: 0 | Q27: 0
A28: 3 | B28: वर्ग-4 | C28: शिपाई | I28: 0 | J28: 0 | Q28: 0
C29: पहारेकरी | I29: 0 | J29: 0 | Q29: 0
C30: एकूण वर्ग 4 | D30: 0 | E30: 0 | F30: 0 | G30: 0 | H30: 0 | I30: 0 | J30: 0 | K30: 0 | L30: 0 | M30: 0 | N30: 0 | O30: 0 | P30: 0 | Q30: 0
C31: एकूण वर्ग 1 2 3 4 | D31: 0 | E31: 0 | F31: 0 | G31: 0 | H31: 0 | I31: 0 | J31: 0 | K31: 0 | L31: 0 | M31: 0 | N31: 0 | O31: 0 | P31: 0 | Q31: 0
A33: =$A$1 -> प्रपत्र - ड - अर्थसंकल्पीय अंदाजपत्रक सन 2021-2022
A34: मागणी क्र.सी- 1- लेखाशिर्ष 2029 0182
A35: जिल्हा मुंबई उपनगर | O35: (आकडे हजारात)
A36: अ क्र | B36: वर्ग | C36: पद | D36: =D4 -> मंजूर पदे | E36: =E4 -> मंजूर पदे | F36: =F4 -> विशेष वेतन | G36: =G4 -> मुळ वेतन | H36: =H4 -> ग्रेड वेतन | I36: =I4 -> एकूण | J36: =J4 -> महागाई भत्ता 25% | K36: स्थानिक पुरक भत्ता | L36: घर भाडे भत्ता | M36: वाहन भत्ता | N36: धूलाई भत्ता | O36: रोख भत्ता | P36: चप्पल भत्ता/ इतर | Q36: एकूण
D37: =D5 -> 2020-2021 | E37: =E5 -> 2021-2022
C38: स्थायी
A39: 1 | B39: वर्ग-3 | C39: अव्वल कारकून | I39: 0 | J39: 0 | Q39: 0
C40: लिपिक | I40: 0 | J40: 0 | Q40: 0
C41: एकूण वर्ग 3 | D41: 0 | E41: 0 | F41: 0 | G41: 0 | H41: 0 | I41: 0 | J41: 0 | K41: 0 | L41: 0 | M41: 0 | N41: 0 | O41: 0 | P41: 0 | Q41: 0
A42: 2 | B42: वर्ग-4 | C42: शिपाई | I42: 0 | J42: 0 | Q42: 0
...

Sheet Page 2
A1: प्रपत्र - क - अर्थसंकल्पीय अंदाजपत्रक सन 2021-2022
A2: मागणी क्र.सी- 1- लेखाशिर्ष 2029 0182
A3: (आकडे हजारात)
A4: जिल्हा | B4: स्थायी पदे
C5: भरलेली पदे | G5: रिक्त पदे | K5: एकुण
A6: मुंबई शहर | B6: वर्ग | C6: वर्ग-1 व 2 | D6: वर्ग-3 | E6: वर्ग-4 | F6: एकुण | G6: वर्ग-1 व 2 | H6: वर्ग-3 | I6: वर्ग-4 | J6: एकुण | K6: एकुण
B7: पदे | F7: 0 | J7: 0 | K7: 0
B8: वेतन | F8: 0 | J8: 0 | K8: 0
B9: ग्रेड पे | F9: 0 | J9: 0 | K9: 0
B10: एकुण | C10: 0 | D10: 0 | E10: 0 | F10: 0 | G10: 0 | H10: 0 | I10: 0 | J10: 0 | K10: 0
B11: विशेष वेतन | F11: 0 | J11: 0 | K11: 0
B12: महा.भत्ता | F12: 0 | J12: 0 | K12: 0
B13: स्था.पु.भ. | F13: 0 | J13: 0 | K13: 0
B14: घरभाडे | F14: 0 | J14: 0 | K14: 0
B15: प्रवास भत्ता | F15: 0 | J15: 0 | K15: 0
B16: इतर | F16: 0 | J16: 0 | K16: 0
B17: एकुण | C17: 0 | D17: 0 | E17: 0 | F17: 0 | G17: 0 | H17: 0 | I17: 0 | J17: 0 | K17: 0
A19: जिल्हा | B19: अस्थायी पदे | M19: सर्व वर्ग पदे
C20: भरलेली पदे | G20: रिक्त पदे | K20: एकुण | M20: वर्ग | N20: स्थायी पदे | O20: अस्थायी पदे | P20: एकुण
A21: मुंबई शहर | B21: वर्ग | C21: वर्ग-1 व 2 | D21: वर्ग-3 | E21: वर्ग-4 | F21: एकुण | G21: वर्ग-1 व 2 | H21: वर्ग-3 | I21: वर्ग-4 | J21: एकुण | M21: पदे | N21: 0 | O21: 0 | P21: 0
B22: पदे | F22: 0 | J22: 0 | K22: 0 | M22: वेतन | N22: 0 | O22: 0 | P22: 0
B23: वेतन | F23: 0 | J23: 0 | K23: 0 | M23: ग्रेड पे | N23: 0 | O23: 0 | P23: 0
B24: ग्रेड पे | F24: 0 | J24: 0 | K24: 0 | M24: एकुण | N24: 0 | O24: 0 | P24: 0
B25: एकुण | C25: 0 | D25: 0 | E25: 0 | F25: 0 | G25: 0 | H25: 0 | I25: 0 | J25: 0 | K25: 0 | M25: महा.भत्ता | N25: 0 | O25: 0 | P25: 0
B26: विशेष वेतन | F26: 0 | J26: 0 | K26: 0 | M26: विशेष वेतन | N26: 0 | O26: 0 | P26: 0
B27: महा.भत्ता | F27: 0 | J27: 0 | K27: 0 | M27: स्था.पु.भ. | N27: 0 | O27: 0 | P27: 0
B28: स्था.पु.भ. | F28: 0 | J28: 0 | K28: 0 | M28: घरभाडे | N28: 0 | O28: 0 | P28: 0
B29: घरभाडे | F29: 0 | J29: 0 | K29: 0 | M29: प्रवास भत्ता | N29: 0 | O29: 0 | P29: 0
B30: प्रवास भत्ता | F30: 0 | J30: 0 | K30: 0 | M30: इतर | N30: 0 | O30: 0 | P30: 0
B31: इतर | F31: 0 | J31: 0 | K31: 0 | M31: एकुण | N31: 0 | O31: 0 | P31: 0
B32: एकुण | C32: 0 | D32: 0 | E32: 0 | F32: 0 | G32: 0 | H32: 0 | I32: 0 | J32: 0 | K32: 0
A33: =$A$1 -> प्रपत्र - क - अर्थसंकल्पीय अंदाजपत्रक सन 2021-2022
A34: मागणी क्र.सी- 1- लेखाशिर्ष 2029 0182
A35: (आकडे हजारात)
A36: जिल्हा | B36: स्थायी पदे
C37: भरलेली पदे | G37: रिक्त पदे | K37: एकुण
A38: मुंबई उपनगर | B38: वर्ग | C38: वर्ग-1 व 2 | D38: वर्ग-3 | E38: वर्ग-4 | F38: एकुण | G38: वर्ग-1 व 2 | H38: वर्ग-3 | I38: वर्ग-4 | J38: एकुण | K38: एकुण
B39: पदे | F39: 0 | J39: 0 | K39: 0
B40: वेतन | F40: 0 | J40: 0 | K40: 0
B41: ग्रेड पे | F41: 0 | J41: 0 | K41: 0
...

Sheet Page 3
A1: प्रपत्र - ब - अर्थसंकल्पीय अंदाजपत्रक सन 2021-2022
A2: मागणी क्र.सी- 1- लेखाशिर्ष 2029 0182
A3: मंजुर पदे
A4: अ.क्र. | B4: वर्ग | C4: स्थायी | E4: अस्थायी | G4: एकुण
C5: भरलेली पदे | D5: रिक्त पदे | E5: भरलेली पदे | F5: रिक्त पदे
A6: 1 | B6: 1 | G6: 0
A7: 2 | B7: 2 | G7: 0
A8: 3 | B8: 3 | G8: 0
A9: 4 | B9: 4 | G9: 0
A10: एकुण | C10: 0 | D10: 0 | E10: 0 | F10: 0 | G10: 0
F13: ( आकडे हजारात)
A14: अ.क्र. | B14: जिल्हा / विभाग | C14: वैद्यकिय खर्च | D14: उत्सव/सण अग्रिम | E14: स्वग्राम/महाराष्ट्र दर्शन | F14: 7 व्या वेतन आयोग फरक | G14: एनपीएस | H14: इतर | I14: एकुण
A15: 1 | B15: मुंबई शहर | I15: =SUM(C15:H15) -> 0
A17: =$A$1 -> प्रपत्र - ब - अर्थसंकल्पीय अंदाजपत्रक सन 2021-2022
A18: मागणी क्र.सी- 1- लेखाशिर्ष 2029 0182
A19: मंजुर पदे
A20: अ.क्र. | B20: वर्ग | C20: स्थायी | E20: अस्थायी | G20: एकुण
C21: भरलेली पदे | D21: रिक्त पदे | E21: भरलेली पदे | F21: रिक्त पदे
A22: 1 | B22: 1 | G22: 0
A23: 2 | B23: 2 | G23: 0
A24: 3 | B24: 3 | G24: 0
A25: 4 | B25: 4 | G25: 0
A26: एकुण | C26: 0 | D26: 0 | E26: 0 | F26: 0 | G26: 0
F29: ( आकडे हजारात)
A30: अ.क्र. | B30: जिल्हा / विभाग | C30: वैद्यकिय खर्च | D30: उत्सव/सण अग्रिम | E30: स्वग्राम/महाराष्ट्र दर्शन | F30: 7 व्या वेतन आयोग फरक | G30: एनपीएस | H30: इतर | I30: एकुण
A31: 1 | B31: मुंबई उपनगर | I31: =SUM(C31:H31) -> 0
A33: =$A$1 -> प्रपत्र - ब - अर्थसंकल्पीय अंदाजपत्रक सन 2021-2022
A34: मागणी क्र.सी- 1- लेखाशिर्ष 2029 0182
A35: मंजुर पदे
A36: अ.क्र. | B36: वर्ग | C36: स्थायी | E36: अस्थायी | G36: एकुण
C37: भरलेली पदे | D37: रिक्त पदे | E37: भरलेली पदे | F37: रिक्त पदे
A38: 1 | B38: 1 | C38: 0 | D38: 0 | E38: 2 | F38: 0 | G38: =SUM(C38:F38) -> 2
A39: 2 | B39: 2 | C39: 0 | D39: 0 | E39: 0 | F39: 0 | G39: =SUM(C39:F39) -> 0
A40: 3 | B40: 3 | C40: 0 | D40: 0 | E40: 7 | F40: 0 | G40: =SUM(C40:F40) -> 7
A41: 4 | B41: 4 | C41: 0 | D41: 0 | E41: 1 | F41: 0 | G41: =SUM(C41:F41) -> 1
A42: एकुण | C42: =SUM(C38:C41) -> 0 | D42: =SUM(D38:D41) -> 0 | E42: =SUM(E38:E41) -> 10 | F42: =SUM(F38:F41) -> 0 | G42: =SUM(G38:G41) -> 10
F45: ( आकडे हजारात)
A46: अ.क्र. | B46: जिल्हा / विभाग | C46: वैद्यकिय खर्च | D46: उत्सव/सण अग्रिम | E46: स्वग्राम/महाराष्ट्र दर्शन | F46: 7 व्या वेतन आयोग फरक | G46: एनपीएस | H46: इतर | I46: एकुण
A47: 1 | B47: ठाणे | C47: 400 | D47: 50 | E47: 40 | F47: 150 | G47: 100 | H47: 0 | I47: =SUM(C47:H47) -> 740
A48: =$A$1 -> प्रपत्र - ब - अर्थसंकल्पीय अंदाजपत्रक सन 2021-2022
...

Sheet Page 4
A1: प्रपत्र - अ - अर्थसंकल्पीय अंदाजपत्रक सन 2021-2022
A2: मागणी क्र.सी- 1- लेखाशिर्ष 2029 0182
A3: जिल्हा मुंबई शहर | L3: (आकडे हजारात)
A4: अ. क्र | B4: लेख्याची प्राथमिक आणि दुय्यम युनिट | C4: प्रत्यक्ष रक्कमा (खर्च) | F4: अर्थसंकल्पीय अंदाज | G4: सुधारीत अंदाज 2020-2021 | H4: अर्थसंकल्पीय अंदाज 2021-2022 | L4: मागील वर्षाच्या प्रत्यक्ष रक्कमा आणि चालु वर्षाच्या अर्थसंकल्पीय अंदाजाची तुलना करता आगामी वर्षासाठीच्या अंदाजातील वाढ किंवा घट यांच्या संबधातील स्पष्टीकरणे.
C5: 2017-2018 | D5: 2018-2019 | E5: 2019-2020 | F5: 2020-2021 | H5: प्राकक्लन (एस्टिमेटिंग) अधिका-याचा | I5: नियंत्रक अधिका-यांचा | J5: प्रशासकीय विभागाचा | K5: वित्त विभागाचा
A6: 1 | B6: 2 | C6: 3 | D6: 4 | E6: 5 | F6: 6 | G6: 7 | H6: 8 | I6: 9 | J6: 10 | K6: 11 | L6: 12
A7: 1 | B7: 01- वेतन
A8: 2 | B8: 03 अति.भत्ता
A9: 3 | B9: 06- दूरध्वनी वीज,पाणी व शुल्क
A10: 4 | B10: 11- देशातंर्गत प्रवास खर्च
A11: 5 | B11: 13- कार्यालयीन खर्च
A12: 6 | B12: 14-भाडेपटटी व कर
A13: 7 | B13: 16- प्रकाशने
A14: 8 | B14: 17- संगणक खर्च
A15: 9 | B15: 24- इंधन खर्च
A16: 10 | B16: 26- जाहीरात व प्रसिध्दी खर्च
B17: एकुण | C17: 0 | D17: 0 | E17: 0 | F17: 0 | G17: 0 | H17: 0 | I17: 0 | J17: 0 | K17: 0
A19: =$A$1 -> प्रपत्र - अ - अर्थसंकल्पीय अंदाजपत्रक सन 2021-2022
A20: मागणी क्र.सी- 1- लेखाशिर्ष 2029 0182
A21: जिल्हा मुंबई उपनगर | L21: (आकडे हजारात)
A22: अ. क्र | B22: लेख्याची प्राथमिक आणि दुय्यम युनिट | C22: प्रत्यक्ष रक्कमा (खर्च) | F22: अर्थसंकल्पीय अंदाज | G22: सुधारीत अंदाज 2020-2021 | H22: अर्थसंकल्पीय अंदाज 2021-2022 | L22: मागील वर्षाच्या प्रत्यक्ष रक्कमा आणि चालु वर्षाच्या अर्थसंकल्पीय अंदाजाची तुलना करता आगामी वर्षासाठीच्या अंदाजातील वाढ किंवा घट यांच्या संबधातील स्पष्टीकरणे.
C23: 2017-2018 | D23: 2018-2019 | E23: 2019-2020 | F23: 2020-2021 | H23: प्राकक्लन (एस्टिमेटिंग) अधिका-याचा | I23: नियंत्रक अधिका-यांचा | J23: प्रशासकीय विभागाचा | K23: वित्त विभागाचा
A24: 1 | B24: 2 | C24: 3 | D24: 4 | E24: 5 | F24: 6 | G24: 7 | H24: 8 | I24: 9 | J24: 10 | K24: 11 | L24: 12
A25: 1 | B25: 01- वेतन
A26: 2 | B26: 03 अति.भत्ता
A27: 3 | B27: 06- दूरध्वनी वीज,पाणी व शुल्क
A28: 4 | B28: 11- देशातंर्गत प्रवास खर्च
A29: 5 | B29: 13- कार्यालयीन खर्च
A30: 6 | B30: 14-भाडेपटटी व कर
A31: 7 | B31: 16- प्रकाशने
A32: 8 | B32: 17- संगणक खर्च
A33: 9 | B33: 24- इंधन खर्च
A34: 10 | B34: 26- जाहीरात व प्रसिध्दी खर्च
B35: एकुण | C35: 0 | D35: 0 | E35: 0 | F35: 0 | G35: 0 | H35: 0 | I35: 0 | J35: 0 | K35: 0 | L35: 0
A37: =$A$1 -> प्रपत्र - अ - अर्थसंकल्पीय अंदाजपत्रक सन 2021-2022
A38: मागणी क्र.सी- 1- लेखाशिर्ष 2029 0182
A39: जिल्हा ठाणे | L39: (आकडे हजारात)
A40: अ. क्र | B40: लेख्याची प्राथमिक आणि दुय्यम युनिट | C40: प्रत्यक्ष रक्कमा (खर्च) | F40: अर्थसंकल्पीय अंदाज | G40: सुधारीत अंदाज 2020-2021 | H40: अर्थसंकल्पीय अंदाज 2021-2022 | L40: मागील वर्षाच्या प्रत्यक्ष रक्कमा आणि चालु वर्षाच्या अर्थसंकल्पीय अंदाजाची तुलना करता आगामी वर्षासाठीच्या अंदाजातील वाढ किंवा घट यांच्या संबधातील स्पष्टीकरणे.
C41: 2017-2018 | D41: 2018-2019 | E41: 2019-2020 | F41: 2020-2021 | H41: प्राकक्लन (एस्टिमेटिंग) अधिका-याचा | I41: नियंत्रक अधिका-यांचा | J41: प्रशासकीय विभागाचा | K41: वित्त विभागाचा
A42: 1 | B42: 2 | C42: 3 | D42: 4 | E42: 5 | F42: 6 | G42: 7 | H42: 8 | I42: 9 | J42: 10 | K42: 11 | L42: 12
...

Sheet Page 5
A1: ='Page 4'!A144 -> प्रपत्र - अ - अर्थसंकल्पीय अंदाजपत्रक सन 2021-2022
A2: ='Page 4'!A145 -> मागणी क्र.सी- 1- लेखाशिर्ष 2029 0182
A3: ='Page 4'!A146 -> कोकण विभाग | L3: ='Page 4'!L146 -> (आकडे हजारात)
A4: ='Page 4'!A147 -> अ. क्र | B4: ='Page 4'!B147 -> लेख्याची प्राथमिक आणि दुय्यम युनिट | C4: ='Page 4'!C147 -> प्रत्यक्ष रक्कमा (खर्च) | F4: ='Page 4'!F147 -> अर्थसंकल्पीय अंदाज | G4: ='Page 4'!G147 -> सुधारीत अंदाज 2020-2021 | H4: ='Page 4'!H147 -> अर्थसंकल्पीय अंदाज 2021-2022 | L4: ='Page 4'!L147 -> मागील वर्षाच्या प्रत्यक्ष रक्कमा आणि चालु वर्षाच्या अर्थसंकल्पीय अंदाजाची तुलना करता आगामी वर्षासाठीच्या अंदाजातील वाढ किंवा घट यांच्या संबधातील स्पष्टीकरणे.
C5: ='Page 4'!C148 -> 2017-2018 | D5: ='Page 4'!D148 -> 2018-2019 | E5: ='Page 4'!E148 -> 2019-2020 | F5: ='Page 4'!F148 -> 2020-2021 | H5: ='Page 4'!H148 -> प्राकक्लन (एस्टिमेटिंग) अधिका-याचा | I5: ='Page 4'!I148 -> नियंत्रक अधिका-यांचा | J5: ='Page 4'!J148 -> प्रशासकीय विभागाचा | K5: ='Page 4'!K148 -> वित्त विभागाचा
A6: ='Page 4'!A149 -> 1 | B6: ='Page 4'!B149 -> 2 | C6: ='Page 4'!C149 -> 3 | D6: ='Page 4'!D149 -> 4 | E6: ='Page 4'!E149 -> 5 | F6: ='Page 4'!F149 -> 6 | G6: ='Page 4'!G149 -> 7 | H6: ='Page 4'!H149 -> 8 | ... L6: ='Page 4'!L149 -> 12
A7: 1 | B7: 01- वेतन | C7: ='Page 4'!C150 -> 28714 | D7: ='Page 4'!D150 -> 32127 | E7: ='Page 4'!E150 -> 41523 | F7: 56839 | G7: =SUM('Page 4'!G150) -> 47645 | I7: =SUM('Page 4'!H150) -> 59640 | L7: 01- वेतन:- या बाबीखाली चालु महागाई भत्ता दर आकारणी 25% प्रमाणे विचारात घेवून केली आहे.
A8: 2 | B8: 03 अति.भत्ता | C8: ='Page 4'!C151 -> 0 | D8: ='Page 4'!D151 -> 0 | E8: ='Page 4'!E151 -> 0 | F8: =SUM('Page 4'!F151) -> 0 | G8: =SUM('Page 4'!G151) -> 0 | I8: =SUM('Page 4'!H151) -> 0
A9: 3 | B9: 06- दूरध्वनी वीज,पाणी व शुल्क | C9: ='Page 4'!C152 -> 260 | D9: ='Page 4'!D152 -> 265 | E9: ='Page 4'!E152 -> 244 | F9: 1700 | G9: =SUM('Page 4'!G152) -> 1610 | I9: =SUM('Page 4'!H152) -> 1710 | L9: 06- दूरध्वनी, वीज पाणी व शुल्क:- भुसंपादन कार्यालयाकडील क्षेत्रीय कार्यालये व मुख्यालये यामध्ये दुरध्वनी खर्च तसेच वाढीव दराची वीज देयके अदा करणेकामी जादा अनुदानाची आवश्यकता आहे.
A10: 4 | B10: 11- देशातंर्गत प्रवास खर्च | C10: ='Page 4'!C153 -> 200 | D10: ='Page 4'!D153 -> 300 | E10: ='Page 4'!E153 -> 342 | F10: 1545 | G10: =SUM('Page 4'!G153) -> 1235 | I10: =SUM('Page 4'!H153) -> 1485 | L10: 11- देशातंर्गत प्रवास खर्च:- भुसंपादन कार्यालयाकडील कराव्या लागलेल्या फिरती बदली प्रवासभत्ता दैनिकभत्ता इत्यादीसाठी वाढीव महागाई दराच्या आधारावर जादा अनुदानाची आवश्यकता आहे.
A11: 5 | B11: 13- कार्यालयीन खर्च | C11: ='Page 4'!C154 -> 1014 | D11: ='Page 4'!D154 -> 1245 | E11: ='Page 4'!E154 -> 844 | F11: 2150 | G11: =SUM('Page 4'!G154) -> 1600 | I11: =SUM('Page 4'!H154) -> 1950 | L11: 13- कार्यालयीन खर्च :- सदर बाबीखाली कार्या.खर्चसाठी स्टेशनरी, जडसंग्रह वस्तु, झेरॉक्स यांच्या वाढीव दरामुळे तसेच अधिका-यांच्या साठी उपलब्ध असलेल्या शासकीय वाहनांची देखभाल, दुरुस्ती, पेट्रोल व डिझेल यांचे वाढीव दर यामुळे कार्यालयीन खर्च मोठया प्रमाणावर वाढला आहे. त्यामुळे वाढीव अनुदानाची मागणी केली आहे.
A12: 6 | B12: 14-भाडेपटटी व कर | C12: ='Page 4'!C155 -> 0 | D12: ='Page 4'!D155 -> 59 | E12: ='Page 4'!E155 -> 0 | F12: =SUM('Page 4'!F155) -> 860 | G12: =SUM('Page 4'!G155) -> 700 | I12: =SUM('Page 4'!H155) -> 700 | L12: 14-भाडेपट्टी व कर :- भूसंपादन कार्यालयाचे हिश्याचे वार्षीक मालमत्ता कराचे देयक अदा करण्याकरीता अनुदनाची आवश्यकता आहे.
A13: 7 | B13: 16- प्रकाशने | C13: ='Page 4'!C156 -> 0 | D13: ='Page 4'!D156 -> 0 | E13: ='Page 4'!E156 -> 0 | F13: =SUM('Page 4'!F156) -> 0 | G13: =SUM('Page 4'!G156) -> 0 | I13: =SUM('Page 4'!H156) -> 0
A14: 8 | B14: 17- संगणक खर्च | C14: ='Page 4'!C157 -> 273 | D14: ='Page 4'!D157 -> 467 | E14: ='Page 4'!E157 -> 249 | F14: 1220 | G14: =SUM('Page 4'!G157) -> 950 | I14: =SUM('Page 4'!H157) -> 1110 | L14: 17- संगणक खर्च :- सदर बाबीखाली सन 2010-2011 पासून मागणी करण्यात येत आहे. सदर उपशिर्षाखाली भुसंपादन कार्यालयास व क्षेत्रीय कार्यालयास पाठवावयाचे नियतकालीके अहवाल तयार करणे इ. कार्यालयीन कामे संगणकावर करावी लागतात. 2013-14 वित्‍त्तीय वर्षात सदर लेखाशिर्षातंर्गत नवीन बाब निर्माण करण्यांत आली आहे. मात्र अत्यल्प अनुदान उपलब्ध करुन देण्यांत आले. सबब या वित्तीय वर्षात सदर अनुदानाची तरतूद होण्यास विनंती आहे.
A15: 9 | B15: 24- इंधन खर्च | C15: ='Page 4'!C158 -> 0 | D15: ='Page 4'!D158 -> 19 | E15: ='Page 4'!E158 -> 0 | F15: =SUM('Page 4'!F158) -> 646 | G15: =SUM('Page 4'!G158) -> 446 | I15: =SUM('Page 4'!H158) -> 446 | L15: 24-इंधन खर्च:- भूसंपादन अधिका-यांच्या साठी उपलब्ध असलेल्या शासकीय वाहनांचे पेट्रोल व डिझेल यांचे वाढीव दर यामुळे इंधन खर्च मोठया प्रमाणावर वाढला आहे. त्यामुळे वाढीव अनुदानाची मागणी केली आहे.
A16: 10 | B16: 26- जाहीरात व प्रसिध्दी खर्च | C16: ='Page 4'!C159 -> 0 | D16: ='Page 4'!D159 -> 0 | E16: ='Page 4'!E159 -> 0 | F16: =SUM('Page 4'!F159) -> 0 | G16: =SUM('Page 4'!G159) -> 20 | I16: =SUM('Page 4'!H159) -> 20 | L16: 26-जाहिरात व प्रसिद्धी खर्च:- भूसंपादन कार्यालयातील विविध प्रकारच्या शासकीय जाहिराती प्रसिद्धी करणेकामी होणा-या खर्चाची देयके अदा करण्याकरीता अनुदानाची तरतुद होण्यास विनंती आहे.
B17: एकुण | C17: =SUM(C7:C16) -> 30461 | D17: =SUM(D7:D16) -> 34482 | E17: =SUM(E7:E16) -> 43202 | F17: =SUM(F7:F16) -> 64960 | G17: =SUM(G7:G16) -> 54206 | H17: =SUM(H7:H16) -> 0 | I17: =SUM(I7:I16) -> 67061 | J17: =SUM(J7:J16) -> 0 | K17: =SUM(K7:K16) -> 0
L19: (विनिता भूमकर)
L20: सहाय्यक संचालक(लेखा) कोकण विभाग

Sheet 4-12 TO 7-12 MES
A1: 2020-2021
A2: 4/2020-7/2020 Monthly Expenditure 20290182
C3: Mcity | D3: MSD | E3: PAO | F3: THANE | G3: PALGHAR | H3: RAIGAD | I3: RATNAGIRI | J3: SINDHUDURG | K3: DIV COMM | L3: AG | M3: TOTAL
A4: 1 | B4: Salary | C4: 0 | D4: 0 | E4: =SUM(C4:D4) -> 0 | F4: 1757 | G4: 410 | H4: 4156 | I4: 2310 | J4: 3353 | K4: 0 | L4: =SUM(F4:K4) -> 11986 | M4: =SUM(L4+E4) -> 11986
A5: 6 | B5: ELCT/WAT/TEL | E5: =SUM(C5:D5) -> 0 | H5: 4 | J5: 1 | L5: =SUM(F5:K5) -> 5 | M5: =SUM(E5:K5) -> 5
A6: 11 | B6: TE | E6: =SUM(C6:D6) -> 0 | H6: 11 | L6: =SUM(F6:K6) -> 11 | M6: =SUM(E6:K6) -> 11
A7: 13 | B7: OE | E7: =SUM(C7:D7) -> 0 | I7: 11 | J7: 22 | L7: =SUM(F7:K7) -> 33 | M7: =SUM(E7:K7) -> 33
A8: 14 | B8: Property Tax | E8: =SUM(C8:D8) -> 0 | L8: =SUM(F8:K8) -> 0 | M8: =SUM(E8:K8) -> 0
A9: 17 | B9: Computer | E9: =SUM(C9:D9) -> 0 | L9: =SUM(F9:K9) -> 0 | M9: =SUM(E9:K9) -> 0
A10: 24 | B10: Petrol-oil | E10: =SUM(C10:D10) -> 0 | L10: =SUM(F10:K10) -> 0 | M10: =SUM(E10:K10) -> 0
A11: 26 | B11: Advertisement & Publicity | E11: =SUM(C11:D11) -> 0 | L11: =SUM(F11:K11) -> 0 | M11: =SUM(E11:K11) -> 0
B12: Total | C12: =SUM(C4:C11) -> 0 | D12: =SUM(D4:D11) -> 0 | E12: =SUM(E4:E11) -> 0 | F12: =SUM(F4:F11) -> 1757 | G12: =SUM(G4:G11) -> 410 | H12: =SUM(H4:H11) -> 4171 | I12: =SUM(I4:I11) -> 2321 | J12: =SUM(J4:J11) -> 3376 | ... M12: =SUM(M4:M11) -> 12035
K15: (विनिता भूमकर)
K16: सहाय्यक संचालक (लेखा)
K17: कोकण विभाग

Sheet jodpatra d
A1: जोडपत्र-ड
A2: अर्थसंकल्पीय अंदाजपत्रक सन 2021-2022
A3: मागणी क्र.सी-1 2029 जमीन महसूल (20290182)
A4: कोकण विभाग संगर्व निहाय पदांची माहिती
A5: अ.क्र. | B5: संवर्ग | C5: मंजूर पदे | E5: भरलेली पदे | G5: रिक्त पदे
C6: स्थायी | D6: अस्थायी | E6: स्थायी | F6: अस्थायी | G6: स्थायी | H6: अस्थायी
A7: 1 | B7: वर्ग-1 | C7: 0 | D7: 9 | E7: =SUM('Page 3'!C133) -> 0 | F7: =SUM('Page 3'!E133) -> 9 | G7: =SUM('Page 3'!D133) -> 0 | H7: =SUM('Page 3'!F133) -> 0
A8: 2 | B8: वर्ग-2 | C8: 0 | D8: 1 | E8: =SUM('Page 3'!C134) -> 0 | F8: =SUM('Page 3'!E134) -> 1 | G8: =SUM('Page 3'!D134) -> 0 | H8: =SUM('Page 3'!F134) -> 0
A9: 3 | B9: वर्ग-3 | C9: =SUM('Page 1'!E264) -> 3 | D9: =SUM('Page 1'!E282) -> 47 | E9: =SUM('Page 3'!C135) -> 3 | F9: =SUM('Page 3'!E135) -> 39 | G9: =SUM('Page 3'!D135) -> 0 | H9: =SUM('Page 3'!F135) -> 8
A10: 4 | B10: वर्ग-4 | C10: =SUM('Page 1'!E266) -> 1 | D10: =SUM('Page 1'!E285) -> 11 | E10: =SUM('Page 3'!C136) -> 0 | F10: =SUM('Page 3'!E136) -> 6 | G10: =SUM('Page 3'!D136) -> 1 | H10: =SUM('Page 3'!F136) -> 5
B11: एकूण | C11: =SUM(C7:C10) -> 4 | D11: =SUM(D7:D10) -> 68 | E11: =SUM(E7:E10) -> 3 | F11: =SUM(F7:F10) -> 55 | G11: =SUM(G7:G10) -> 1 | H11: =SUM(H7:H10) -> 13
F14: (विनिता भूमकर)
F15: सहाय्यक संचालक(लेखा) कोकण विभाग

Sheet Sheet1
A1: अर्थसंकल्पीय अंदाजपत्रक सन 2017-2018 (जिल्हानिहाय)
A2: मागणी क्र.सी-1- लेखाशिर्ष : 20290182
A3: (आकडे हजारात)
A4: अ. क्र. | B4: उपलेखाशिर्ष | C4: मुंबई शहर | D4: मुंबई उपनगर | E4: ठाणे | F4: पालघर | G4: रायगड | H4: रत्नागिरी | I4: सिंधुदुर्ग | J4: मा.उप आयुक्त (सा.प्र.) | K4: एकूण
A5: 1 | B5: 01- वेतन | C5: =SUM('Page 4'!H7) -> 0 | D5: =SUM('Page 4'!H25) -> 0 | E5: =SUM('Page 4'!H43) -> 9714 | F5: =SUM('Page 4'!H60) -> 1791 | G5: =SUM('Page 4'!H78) -> 23626 | H5: =SUM('Page 4'!H96) -> 11912 | I5: =SUM('Page 4'!H114) -> 12597 | J5: =SUM('Page 4'!H132) -> 0 | K5: =SUM(C5:J5)-1 -> 59639
A6: 2 | B6: 03- अति.भत्ता | C6: =SUM('Page 4'!H8) -> 0 | D6: =SUM('Page 4'!H26) -> 0 | E6: =SUM('Page 4'!H44) -> 0 | F6: =SUM('Page 4'!H61) -> 0 | G6: =SUM('Page 4'!H79) -> 0 | H6: =SUM('Page 4'!H97) -> 0 | I6: =SUM('Page 4'!H115) -> 0 | J6: =SUM('Page 4'!H133) -> 0 | K6: =SUM(C6:J6) -> 0
A7: 3 | B7: 06- दूरध्वनी वीज,पाणी व शुल्क | C7: =SUM('Page 4'!H9) -> 0 | D7: =SUM('Page 4'!H27) -> 0 | E7: =SUM('Page 4'!H45) -> 500 | F7: =SUM('Page 4'!H62) -> 10 | G7: =SUM('Page 4'!H80) -> 950 | H7: =SUM('Page 4'!H98) -> 0 | I7: =SUM('Page 4'!H116) -> 250 | J7: =SUM('Page 4'!H134) -> 0 | K7: =SUM(C7:J7) -> 1710
A8: 4 | B8: 11- देशातंर्गत प्रवास खर्च | C8: =SUM('Page 4'!H10) -> 0 | D8: =SUM('Page 4'!H28) -> 0 | E8: =SUM('Page 4'!H46) -> 130 | F8: =SUM('Page 4'!H63) -> 75 | G8: =SUM('Page 4'!H81) -> 800 | H8: =SUM('Page 4'!H99) -> 200 | I8: =SUM('Page 4'!H117) -> 280 | J8: =SUM('Page 4'!H135) -> 0 | K8: =SUM(C8:J8) -> 1485
A9: 5 | B9: 13- कार्यालयीन खर्च | C9: =SUM('Page 4'!H11) -> 0 | D9: =SUM('Page 4'!H29) -> 0 | E9: =SUM('Page 4'!H47) -> 300 | F9: =SUM('Page 4'!H64) -> 100 | G9: =SUM('Page 4'!H82) -> 900 | H9: =SUM('Page 4'!H100) -> 250 | I9: =SUM('Page 4'!H118) -> 400 | J9: =SUM('Page 4'!H136) -> 0 | K9: =SUM(C9:J9) -> 1950
A10: 6 | B10: 14-भाडेपट्टी व कर | C10: =SUM('Page 4'!H12) -> 0 | D10: =SUM('Page 4'!H30) -> 0 | E10: =SUM('Page 4'!H48) -> 0 | F10: =SUM('Page 4'!H65) -> 0 | G10: =SUM('Page 4'!H83) -> 700 | H10: =SUM('Page 4'!H101) -> 0 | I10: =SUM('Page 4'!H119) -> 0 | J10: =SUM('Page 4'!H137) -> 0 | K10: =SUM(C10:J10) -> 700
A11: 7 | B11: 16-प्रकाशने | C11: =SUM('Page 4'!H13) -> 0 | D11: =SUM('Page 4'!H31) -> 0 | E11: =SUM('Page 4'!H49) -> 0 | F11: =SUM('Page 4'!H66) -> 0 | G11: =SUM('Page 4'!H84) -> 0 | H11: =SUM('Page 4'!H102) -> 0 | I11: =SUM('Page 4'!H120) -> 0 | J11: =SUM('Page 4'!H138) -> 0 | K11: =SUM(C11:J11) -> 0
A12: 8 | B12: 17- संगणक खर्च | C12: =SUM('Page 4'!H14) -> 0 | D12: =SUM('Page 4'!H32) -> 0 | E12: =SUM('Page 4'!H50) -> 150 | F12: =SUM('Page 4'!H67) -> 50 | G12: =SUM('Page 4'!H85) -> 600 | H12: =SUM('Page 4'!H103) -> 80 | I12: =SUM('Page 4'!H121) -> 230 | J12: =SUM('Page 4'!H139) -> 0 | K12: =SUM(C12:J12) -> 1110
A13: 9 | B13: 24- इंधन खर्च | C13: =SUM('Page 4'!H15) -> 0 | D13: =SUM('Page 4'!H33) -> 0 | E13: =SUM('Page 4'!H51) -> 46 | F13: =SUM('Page 4'!H68) -> 0 | G13: =SUM('Page 4'!H86) -> 400 | H13: =SUM('Page 4'!H104) -> 0 | I13: =SUM('Page 4'!H122) -> 0 | J13: =SUM('Page 4'!H140) -> 0 | K13: =SUM(C13:J13) -> 446
A14: 10 | B14: 26- जाहीरात व प्रसिध्दी खर्च | C14: =SUM('Page 4'!H16) -> 0 | D14: =SUM('Page 4'!H34) -> 0 | E14: =SUM('Page 4'!H52) -> 0 | F14: =SUM('Page 4'!H69) -> 20 | G14: =SUM('Page 4'!H87) -> 0 | H14: =SUM('Page 4'!H105) -> 0 | I14: =SUM('Page 4'!H123) -> 0 | J14: =SUM('Page 4'!H141) -> 0 | K14: =SUM(C14:J14) -> 20
A15: एकूण | C15: =SUM(C5:C14) -> 0 | D15: =SUM(D5:D14) -> 0 | E15: =SUM(E5:E14) -> 10840 | F15: =SUM(F5:F14) -> 2046 | G15: =SUM(G5:G14) -> 27976 | H15: =SUM(H5:H14) -> 12442 | I15: =SUM(I5:I14) -> 13757 | J15: =SUM(J5:J14) -> 0 | K15: =SUM(K5:K14) -> 67060
A17: प्रपत्र - अ - अर्थसंकल्पीय अंदाजपत्रक सन 2018-2019
A18: मागणी क्र.सी-1- लेखाशिर्ष : 20290182
A19: (आकडे हजारात)
A20: अ. क्र. | B20: उपलेखाशिर्ष | C20: मुंबई शहर | D20: मुंबई उपनगर | E20: ठाणे | F20: पालघर | G20: रायगड | H20: रत्नागिरी | I20: सिंधुदुर्ग | J20: मा.उप आयुक्त (सा.प्र.) | K20: एकूण
A21: 1 | B21: 01- वेतन | C21: =SUM((C5/K5)*100) -> 0 | D21: =SUM((D5/K5)*100) -> 0 | E21: =SUM((E5/K5)*100) -> 16.287999 | F21: =SUM((F5/K5)*100) -> 3.0030685 | G21: =SUM((G5/K5)*100) -> 39.615017 | H21: =SUM((H5/K5)*100) -> 19.973507 | I21: =SUM((I5/K5)*100) -> 21.122085 | J21: =SUM((J5/K5)*100) -> 0 | K21: 42782 | L21: =SUM(C21:J21) -> 100.00168
A22: 2 | B22: 03- अति.भत्ता | C22: =SUM((C6/K6)*100) -> #DIV/0! | D22: =SUM((D6/K6)*100) -> #DIV/0! | E22: =SUM((E6/K6)*100) -> #DIV/0! | F22: =SUM((F6/K6)*100) -> #DIV/0! | G22: =SUM((G6/K6)*100) -> #DIV/0! | H22: =SUM((H6/K6)*100) -> #DIV/0! | I22: =SUM((I6/K6)*100) -> #DIV/0! | J22: =SUM((J6/K6)*100) -> #DIV/0! | K22: 0 | L22: =SUM(C22:J22) -> #DIV/0!
A23: 3 | B23: 06- दूरध्वनी वीज,पाणी व शुल्क | C23: =SUM((C7/K7)*100) -> 0 | D23: =SUM((D7/K7)*100) -> 0 | E23: =SUM((E7/K7)*100) -> 29.239766 | F23: =SUM((F7/K7)*100) -> 0.58479532 | G23: =SUM((G7/K7)*100) -> 55.555556 | H23: =SUM((H7/K7)*100) -> 0 | I23: =SUM((I7/K7)*100) -> 14.619883 | J23: =SUM((J7/K7)*100) -> 0 | K23: 1450 | L23: =SUM(C23:J23) -> 100
A24: 4 | B24: 11- देशातंर्गत प्रवास खर्च | C24: =SUM((C8/K8)*100) -> 0 | D24: =SUM((D8/K8)*100) -> 0 | E24: =SUM((E8/K8)*100) -> 8.7542088 | F24: =SUM((F8/K8)*100) -> 5.0505051 | G24: =SUM((G8/K8)*100) -> 53.872054 | H24: =SUM((H8/K8)*100) -> 13.468013 | I24: =SUM((I8/K8)*100) -> 18.855219 | J24: =SUM((J8/K8)*100) -> 0 | K24: 1520 | L24: =SUM(C24:J24) -> 100
A25: 5 | B25: 13- कार्यालयीन खर्च | C25: =SUM((C9/K9)*100) -> 0 | D25: =SUM((D9/K9)*100) -> 0 | E25: =SUM((E9/K9)*100) -> 15.384615 | F25: =SUM((F9/K9)*100) -> 5.1282051 | G25: =SUM((G9/K9)*100) -> 46.153846 | H25: =SUM((H9/K9)*100) -> 12.820513 | I25: =SUM((I9/K9)*100) -> 20.512821 | J25: =SUM((J9/K9)*100) -> 0 | K25: 1920 | L25: =SUM(C25:J25) -> 100
A26: 6 | B26: 14-भाडेपट्टी व कर | C26: =SUM((C10/K10)*100) -> 0 | D26: =SUM((D10/K10)*100) -> 0 | E26: =SUM((E10/K10)*100) -> 0 | F26: =SUM((F10/K10)*100) -> 0 | G26: =SUM((G10/K10)*100) -> 100 | H26: =SUM((H10/K10)*100) -> 0 | I26: =SUM((I10/K10)*100) -> 0 | J26: =SUM((J10/K10)*100) -> 0 | K26: 760 | L26: =SUM(C26:J26) -> 100
A27: 7 | B27: 16-प्रकाशने | C27: =SUM((C11/K11)*100) -> #DIV/0! | D27: =SUM((D11/K11)*100) -> #DIV/0! | E27: =SUM((E11/K11)*100) -> #DIV/0! | F27: =SUM((F11/K11)*100) -> #DIV/0! | G27: =SUM((G11/K11)*100) -> #DIV/0! | H27: =SUM((H11/K11)*100) -> #DIV/0! | I27: =SUM((I11/K11)*100) -> #DIV/0! | J27: =SUM((J11/K11)*100) -> #DIV/0! | K27: 0 | L27: =SUM(C27:J27) -> #DIV/0!
A28: 8 | B28: 17- संगणक खर्च | C28: =SUM((C12/K12)*100) -> 0 | D28: =SUM((D12/K12)*100) -> 0 | E28: =SUM((E12/K12)*100) -> 13.513514 | F28: =SUM((F12/K12)*100) -> 4.5045045 | G28: =SUM((G12/K12)*100) -> 54.054054 | H28: =SUM((H12/K12)*100) -> 7.2072072 | I28: =SUM((I12/K12)*100) -> 20.720721 | J28: =SUM((J12/K12)*100) -> 0 | K28: 965 | L28: =SUM(C28:J28) -> 100
A29: 9 | B29: 24- इंधन खर्च | C29: =SUM((C13/K13)*100) -> 0 | D29: =SUM((D13/K13)*100) -> 0 | E29: =SUM((E13/K13)*100) -> 10.313901 | F29: =SUM((F13/K13)*100) -> 0 | G29: =SUM((G13/K13)*100) -> 89.686099 | H29: =SUM((H13/K13)*100) -> 0 | I29: =SUM((I13/K13)*100) -> 0 | J29: =SUM((J13/K13)*100) -> 0 | K29: 580 | L29: =SUM(C29:J29) -> 100
A30: 10 | B30: 26- जाहीरात व प्रसिध्दी खर्च | C30: =SUM((C14/K14)*100) -> 0 | D30: =SUM((D14/K14)*100) -> 0 | E30: =SUM((E14/K14)*100) -> 0 | F30: =SUM((F14/K14)*100) -> 100 | G30: =SUM((G14/K14)*100) -> 0 | H30: =SUM((H14/K14)*100) -> 0 | I30: =SUM((I14/K14)*100) -> 0 | J30: =SUM((J14/K14)*100) -> 0 | K30: 0 | L30: =SUM(C30:J30) -> 100
A31: एकूण | C31: =SUM((C15/K15)*100) -> 0 | D31: =SUM((D15/K15)*100) -> 0 | E31: =SUM((E15/K15)*100) -> 16.164629 | F31: =SUM((F15/K15)*100) -> 3.0509991 | G31: =SUM((G15/K15)*100) -> 41.717865 | H31: =SUM((H15/K15)*100) -> 18.553534 | I31: =SUM((I15/K15)*100) -> 20.514465 | J31: =SUM((J15/K15)*100) -> 0 | K31: 37141 | L31: =SUM(C31:J31) -> 100.00149
