Workbook

Sheet 0029 Budget Dist
A1: अर्थसंकल्पीय अंदाजपत्रक सन 2021-2022
A2: मुख्य लेखाशिर्ष 0029 जमीन महसूल
A3: (आकडे हजारात)
A4: अ. क्र. | B4: उपलेखाशिर्ष | C4: प्रत्यक्ष रक्कमा (जमा) | F4: अर्थसंकल्पीय जमा अंदाज | G4: सुधारीत जमा अंदाज | H4: अर्थसंकल्पीय जमा अंदाजपत्रक
C5: 2017-2018 | D5: 2018-2019 | E5: 2019-2020 | F5: 2020-2021 | G5: 2020-2021 | H5: 2021-2022
A6: 1 | B6: 2 | C6: 3 | D6: 4 | E6: 5 | F6: 6 | G6: 7 | H6: 8
A7: 1 | B7: 101 जमीन महसूल /कर 101 (01) सर्वसाधारण वसूली (01) (01) (00290258)
B8: मुंबई शहर | C8: 162431 | D8: 277827 | E8: 402747 | F8: 336169 | G8: 443021 | H8: 487323
B9: मुंबई उपनगर | C9: 2712388 | D9: 1029827 | E9: 1139021 | F9: 1135384 | G9: 1031002 | H9: 1082552
B10: ठाणे | C10: 6160 | D10: 6468 | E10: 23231 | F10: 7629.1 | G10: 8010.555 | H10: 8392.01
B11: पालघर | C11: 36532 | D11: 22629 | E11: 15937 | F11: 22666 | G11: 23799 | H11: 23799
B12: रायगड | C12: 17947 | D12: 17911.81 | E12: 18014.53 | F12: 23280.89 | G12: 20595.48 | H12: 21625.26
B13: रत्नागिरी | C13: 3819 | D13: 6586 | E13: 9498 | F13: 6852.07 | G13: 9687.96 | H13: 9881.72
B14: सिुधुदर्ग | C14: 2094 | D14: 2730 | E14: 2594 | F14: 3000 | G14: 2600 | H14: 3000
B15: एकूण कोकण विभाग | C15: =SUM(C8:C14) -> 2941371 | D15: =SUM(D8:D14) -> 1363978.8 | E15: =SUM(E8:E14) -> 1611042.5 | F15: =SUM(F8:F14) -> 1534981.1 | G15: =SUM(G8:G14) -> 1538716 | H15: =SUM(H8:H14) -> 1636573
A17: 2 | B17: (101) (02) रोजगार हमी योजनेकरीता जमीन महसूलातील वाढ (02) (01)(00290311)
B18: मुंबई शहर | C18: 0 | D18: 0 | E18: 2 | F18: 0 | G18: 0 | H18: 0
B19: मुंबई उपनगर | C19: 0 | D19: 0 | E19: 0 | F19: 0 | G19: 0 | H19: 0
B20: ठाणे | C20: 3171 | D20: 3330 | E20: 3252 | F20: 3909.78 | G20: 4105.269 | H20: 4300.758
B21: पालघर | C21: 3478 | D21: 153 | E21: 0 | F21: 150 | G21: 157 | H21: 157
B22: रायगड | C22: 3113 | D22: 1985 | E22: 1507.22 | F22: 22724.47 | G22: 22724.47 | H22: 23860.69
B23: रत्नागिरी | C23: 3020 | D23: 4866 | E23: 3306 | F23: 5062.59 | G23: 3372.12 | H23: 3439.56
B24: सिुधुदर्ग | C24: 418 | D24: 968 | E24: 1224 | F24: 1530 | G24: 1400 | H24: 1000
B25: एकूण कोकण विभाग | C25: =SUM(C18:C24) -> 13200 | D25: =SUM(D18:D24) -> 11302 | E25: =SUM(E18:E24) -> 9291.22 | F25: =SUM(F18:F24) -> 33376.84 | G25: =SUM(G18:G24) -> 31758.859 | H25: =SUM(H18:H24) -> 32758.008
A27: 3 | B27: 103(01)जमिनीवरील पट्टी व उपकर(01)महाराष्ट्र जिल्हापरिषद आणि पंचायत समिती अधिनियम 1961 खाली तरतुदीनुसार जमा केलेला जमीन महसूलावरील उपकर(01)(01)(00290383)
B28: मुंबई शहर | C28: 0 | D28: 0 | E28: 2 | F28: 0 | G28: 0 | H28: 0
B29: मुंबई उपनगर | C29: 0 | D29: 0 | E29: 0 | F29: 0 | G29: 0 | H29: 0
B30: ठाणे | C30: 35289 | D30: 37053 | E30: 37567 | F30: 43710.57 | G30: 45896.099 | H30: 48081.627
B31: पालघर | C31: 60576 | D31: 53428 | E31: 41284 | F31: 53366 | G31: 56034 | H31: 56034
B32: रायगड | C32: 131136 | D32: 112518.45 | E32: 112218.45 | F32: 178844.56 | G32: 177844.56 | H32: 186736.79
B33: रत्नागिरी | C33: 72342 | D33: 70895 | E33: 73758 | F33: 73759.16 | G33: 75233.16 | H33: 76737.82
B34: सिुधुदर्ग | C34: 22430 | D34: 37921 | E34: 35605 | F34: 35000 | G34: 33000 | H34: 35000
B35: एकूण कोकण विभाग | C35: =SUM(C28:C34) -> 321773 | D35: =SUM(D28:D34) -> 311815.45 | E35: =SUM(E28:E34) -> 300434.45 | F35: =SUM(F28:F34) -> 384680.29 | G35: =SUM(G28:G34) -> 388007.82 | H35: =SUM(H28:H34) -> 402590.24
A37: 4 | B37: (02) मुंबई ग्रामपंचायत अधिनियम 1958 उप विभाग 127 खाली वसूल केलेल्या जमीन महसूलावरील उपकर (02) (01) (00290445)
B38: मुंबई शहर | C38: 0 | D38: 0 | E38: 1 | F38: 0 | G38: 0 | H38: 0
B39: मुंबई उपनगर | C39: 0 | D39: 0 | E39: 0 | F39: 0 | G39: 0 | H39: 0
B40: ठाणे | C40: 6662 | D40: 6995 | E40: 4789 | F40: 7128.34 | G40: 7484.757 | H40: 7841.174
B41: पालघर | C41: 10500 | D41: 7976 | E41: 7331 | F41: 7712 | G41: 8097 | H41: 8097
B42: रायगड | C42: 20987 | D42: 17231.79 | E42: 18804.72 | F42: 29735.14 | G42: 29735.14 | H42: 31221.9
B43: रत्नागिरी | C43: 10515 | D43: 10567 | E43: 10674 | F43: 10993.91 | G43: 10887.48 | H43: 11105.23
...

Sheet 0029 Budget Division
A1: ='0029 Budget Dist'!$A$1 -> अर्थसंकल्पीय अंदाजपत्रक सन 2021-2022
A2: मुख्य लेखाशिर्ष 0029 जमीन महसूल
A3: (आकडे हजारात)
A4: अ. क्र. | B4: उपलेखाशिर्ष | C4: प्रत्यक्ष रक्कमा (जमा) | F4: अर्थसंकल्पीय जमा अंदाज | G4: सुधारीत जमा अंदाज | H4: अर्थसंकल्पीय जमा अंदाजपत्रक
C5: ='0029 Budget Dist'!C5 -> 2017-2018 | D5: ='0029 Budget Dist'!D5 -> 2018-2019 | E5: ='0029 Budget Dist'!E5 -> 2019-2020 | F5: ='0029 Budget Dist'!F5 -> 2020-2021 | G5: ='0029 Budget Dist'!G5 -> 2020-2021 | H5: ='0029 Budget Dist'!H5 -> 2021-2022
A6: 1 | B6: 2 | C6: 3 | D6: 4 | E6: 5 | F6: 6 | G6: 7 | H6: 8
A7: 1 | B7: 101- जमीन महसूल /कर 101 (01) सर्वसाधारण वसूली (01) (01) (00290258) | C7: ='0029 Budget Dist'!C15 -> 2941371 | D7: ='0029 Budget Dist'!D15 -> 1363978.8 | E7: ='0029 Budget Dist'!E15 -> 1611042.5 | F7: ='0029 Budget Dist'!F15 -> 1534981.1 | G7: ='0029 Budget Dist'!G15 -> 1538716 | H7: ='0029 Budget Dist'!H15 -> 1636573
A8: 2 | B8: (101) (02) रोजगार हमी योजनेकरीता जमीन महसूलातील वाढ (02) (01)(00290311) | C8: ='0029 Budget Dist'!C25 -> 13200 | D8: ='0029 Budget Dist'!D25 -> 11302 | E8: ='0029 Budget Dist'!E25 -> 9291.22 | F8: ='0029 Budget Dist'!F25 -> 33376.84 | G8: ='0029 Budget Dist'!G25 -> 31758.859 | H8: ='0029 Budget Dist'!H25 -> 32758.008
A9: 3 | B9: 103 (01) जमिनीवरील पट्टी व उपकर (01) महाराष्ट्र जिल्हा परिषद आणि पंचायत समिती अधिनियम 1961 खाली तरतुदीनुसार जमा केलेला जमीन महसूलावरील उपकर (01) (01) (00290383) | C9: ='0029 Budget Dist'!C35 -> 321773 | D9: ='0029 Budget Dist'!D35 -> 311815.45 | E9: ='0029 Budget Dist'!E35 -> 300434.45 | F9: ='0029 Budget Dist'!F35 -> 384680.29 | G9: ='0029 Budget Dist'!G35 -> 388007.82 | H9: ='0029 Budget Dist'!H35 -> 402590.24
A10: 4 | B10: (02) मुंबई ग्रामपंचायत अधिनियम 1958 उप विभाग 127 खाली वसूल केलेल्या जमीन महसूलावरील उपकर (02) (01) (00290445) | C10: ='0029 Budget Dist'!C45 -> 51863 | D10: ='0029 Budget Dist'!D45 -> 48271.79 | E10: ='0029 Budget Dist'!E45 -> 46778.72 | F10: ='0029 Budget Dist'!F45 -> 60569.39 | G10: ='0029 Budget Dist'!G45 -> 60704.377 | H10: ='0029 Budget Dist'!H45 -> 62765.304
A11: 5 | B11: (03) जमिनीवरील इतर पट्टी व उपकर (02) (01) (00290507) | C11: ='0029 Budget Dist'!C55 -> 3314 | D11: ='0029 Budget Dist'!D55 -> 1953.15 | E11: ='0029 Budget Dist'!E55 -> 6351.72 | F11: ='0029 Budget Dist'!F55 -> 9179.862 | G11: ='0029 Budget Dist'!G55 -> 13257.187 | H11: ='0029 Budget Dist'!H55 -> 13919.532
A12: 6 | B12: 104 भूतपूर्व जमीनदारीच्या मालमत्ता व्यवस्थापनापासून मिळणा-या जमा रकमा (01) जमिनीवरील इतर पट्टी व उपकर (01) (01) (00290572) | C12: ='0029 Budget Dist'!C65 -> 90724 | D12: ='0029 Budget Dist'!D65 -> 73776.95 | E12: ='0029 Budget Dist'!E65 -> 115683.11 | F12: ='0029 Budget Dist'!F65 -> 31200 | G12: ='0029 Budget Dist'!G65 -> 33504.71 | H12: ='0029 Budget Dist'!H65 -> 33722.79
A13: 7 | B13: 105 शासकीय मालमत्तेच्या विक्रीपासून मिळणा-या जमा रकमा (01) शासकीय मालमत्तेच्या विक्रीपासून मिळणा-या जमा रकमा (01) (01) (00290641) | C13: ='0029 Budget Dist'!C75 -> 681320 | D13: ='0029 Budget Dist'!D75 -> 3817169 | E13: ='0029 Budget Dist'!E75 -> 1213600.5 | F13: ='0029 Budget Dist'!F75 -> 3860482.2 | G13: ='0029 Budget Dist'!G75 -> 891467.6 | H13: ='0029 Budget Dist'!H75 -> 935943.1
A14: 8 | B14: 107 पडीत जमिनीच्या विक्री पासून मिळणारे उत्पन्न व भूमी विमोचन कर (01) शासकीय मालमत्तेच्या विक्रीपासून मिळणा-या जमा रकमा (01) (01) (00290712) | C14: ='0029 Budget Dist'!C85 -> 37 | D14: ='0029 Budget Dist'!D85 -> 0 | E14: ='0029 Budget Dist'!E85 -> 18.43 | F14: ='0029 Budget Dist'!F85 -> 0 | G14: ='0029 Budget Dist'!G85 -> 0 | H14: ='0029 Budget Dist'!H85 -> 0
A15: 9 | B15: (00) (01) मुंबई स्पेशल इकॉनॉमिक झोन प्रायव्हेट लिमीटेड मुंबई या कंपनीसाठी केलेल्या भूसंपादनाच्या कामासाठी कार्यरत असणा-या पदाच्या खर्चाची प्रतिपूर्ती (00290249) | C15: =SUM('0029 Budget Dist'!C95) -> 0 | D15: =SUM('0029 Budget Dist'!D95) -> 0 | E15: =SUM('0029 Budget Dist'!E95) -> 0 | F15: =SUM('0029 Budget Dist'!F95) -> 0 | G15: =SUM('0029 Budget Dist'!G95) -> 0 | H15: =SUM('0029 Budget Dist'!H95) -> 0
A16: 10 | B16: 501, सेवा व सेवा फी (01) (01) (00290786) | C16: =SUM('0029 Budget Dist'!C105) -> 301624 | D16: =SUM('0029 Budget Dist'!D105) -> 113380.9 | E16: =SUM('0029 Budget Dist'!E105) -> 28031.64 | F16: =SUM('0029 Budget Dist'!F105) -> 22 | G16: =SUM('0029 Budget Dist'!G105) -> 39990 | H16: =SUM('0029 Budget Dist'!H105) -> 1
A17: 11 | B17: 800 इतर जमा रकमा 800 (01) सर्वेक्षण व जमाबंदी कामाबाबतचे उत्पन्न (01) (01) (00290866) | C17: ='0029 Budget Dist'!C115 -> 121274 | D17: ='0029 Budget Dist'!D115 -> 74426 | E17: ='0029 Budget Dist'!E115 -> 132748 | F17: ='0029 Budget Dist'!F115 -> 87768.27 | G17: ='0029 Budget Dist'!G115 -> 92171.134 | H17: ='0029 Budget Dist'!H115 -> 96527.497
A18: 12 | B18: 800 (02) सीमा स्तंभाच्या परिक्षण खर्चाची वसूली (02) (01) (00290937) | C18: ='0029 Budget Dist'!C125 -> 9 | D18: ='0029 Budget Dist'!D125 -> 6 | E18: ='0029 Budget Dist'!E125 -> 0 | F18: ='0029 Budget Dist'!F125 -> 9 | G18: ='0029 Budget Dist'!G125 -> 9 | H18: ='0029 Budget Dist'!H125 -> 9
A19: 13 | B19: 800 (05) इतर बाबी (05) (01) (00291111) | C19: ='0029 Budget Dist'!C135 -> 1234947 | D19: ='0029 Budget Dist'!D135 -> 2608365.5 | E19: ='0029 Budget Dist'!E135 -> 3668336.8 | F19: ='0029 Budget Dist'!F135 -> 2866529.3 | G19: ='0029 Budget Dist'!G135 -> 3344438.5 | H19: ='0029 Budget Dist'!H135 -> 3641491.5
A20: 14 | B20: 800 (06) पोटहिस्सा भूमापन कामावरील वसूली (06) (01) (00291174) | C20: ='0029 Budget Dist'!C145 -> 248 | D20: ='0029 Budget Dist'!D145 -> 171.29 | E20: ='0029 Budget Dist'!E145 -> 3015 | F20: ='0029 Budget Dist'!F145 -> 250 | G20: ='0029 Budget Dist'!G145 -> 200 | H20: ='0029 Budget Dist'!H145 -> 200
A21: 15 | B21: 800 (09)सीमा चिन्हांच्या खर्चामुळे मिळणा-या वसुलीच्या रकमा (09)(01)(00291245) | C21: ='0029 Budget Dist'!C155 -> 7323 | D21: ='0029 Budget Dist'!D155 -> 7500 | E21: ='0029 Budget Dist'!E155 -> 2010 | F21: ='0029 Budget Dist'!F155 -> 8526.37 | G21: ='0029 Budget Dist'!G155 -> 8952.289 | H21: ='0029 Budget Dist'!H155 -> 9294.207
A22: 16 | B22: 800 (10) अतिप्रदानामुळे मिळणा-या वसूलीच्या रकमा (10) (01) (00291307) | C22: ='0029 Budget Dist'!C165 -> 253 | D22: ='0029 Budget Dist'!D165 -> 12.14 | E22: ='0029 Budget Dist'!E165 -> 23 | F22: ='0029 Budget Dist'!F165 -> 20 | G22: ='0029 Budget Dist'!G165 -> 44.46 | H22: ='0029 Budget Dist'!H165 -> 44.93
A23: 17 | B23: 800 (11) अधिकाराभिलेखामुळे मिळणा-या वसूलीच्या रकमा (11) (01) (00291361) | C23: ='0029 Budget Dist'!C175 -> 7428 | D23: ='0029 Budget Dist'!D175 -> 10562.06 | E23: ='0029 Budget Dist'!E175 -> 4482.05 | F23: ='0029 Budget Dist'!F175 -> 12901.41 | G23: ='0029 Budget Dist'!G175 -> 11160.53 | H23: ='0029 Budget Dist'!H175 -> 11363.39
A24: 18 | B24: 800 (14) भाडे, दंड व जप्तीच्या रकमा (14) (01) (00291541) | C24: ='0029 Budget Dist'!C185 -> 56617 | D24: ='0029 Budget Dist'!D185 -> 26219.21 | E24: ='0029 Budget Dist'!E185 -> 23459.82 | F24: ='0029 Budget Dist'!F185 -> 66300.93 | G24: ='0029 Budget Dist'!G185 -> 65278.12 | H24: ='0029 Budget Dist'!H185 -> 68538.92
A25: 19 | B25: 800 (15) जमीन महसूलीच्या थकबाकीवरील व्याज (15) (01) (00291601) | C25: ='0029 Budget Dist'!C195 -> 14625 | D25: ='0029 Budget Dist'!D195 -> 15285 | E25: ='0029 Budget Dist'!E195 -> 148538 | F25: ='0029 Budget Dist'!F195 -> 18399 | G25: ='0029 Budget Dist'!G195 -> 5800 | H25: ='0029 Budget Dist'!H195 -> 13838.5
A26: 20 | B26: 800 (16) संकिर्ण (16) (01) (00291666) | C26: ='0029 Budget Dist'!C205 -> 5981939 | D26: ='0029 Budget Dist'!D205 -> 6347835.3 | E26: ='0029 Budget Dist'!E205 -> 4151968.4 | F26: ='0029 Budget Dist'!F205 -> 7709331.1 | G26: ='0029 Budget Dist'!G205 -> 1787727.4 | H26: ='0029 Budget Dist'!H205 -> 8466711
A27: 21 | B27: 800 (03) (01) रजा व वेतन अंशदाने (00290991) | C27: ='0029 Budget Dist'!C215 -> 0 | D27: ='0029 Budget Dist'!D215 -> 9 | E27: ='0029 Budget Dist'!E215 -> 20.4 | F27: ='0029 Budget Dist'!F215 -> 0 | G27: ='0029 Budget Dist'!G215 -> 0 | H27: ='0029 Budget Dist'!H215 -> 0
A28: 22 | B28: 800 (04) (01) रद्दी कागद व इतर वस्तू यांचे विक्रीचे उत्पन्न (00291058) | C28: ='0029 Budget Dist'!C225 -> 8 | D28: ='0029 Budget Dist'!D225 -> 0 | E28: ='0029 Budget Dist'!E225 -> 0 | F28: ='0029 Budget Dist'!F225 -> 0 | G28: ='0029 Budget Dist'!G225 -> 0 | H28: ='0029 Budget Dist'!H225 -> 0
A29: 23 | B29: 800(12)(01) केंद्र सरकार कडून मिळणा-या वसुलीच्या रकमा (00291423) | C29: ='0029 Budget Dist'!C235 -> 3 | D29: ='0029 Budget Dist'!D235 -> 3 | E29: ='0029 Budget Dist'!E235 -> 4.86 | F29: ='0029 Budget Dist'!F235 -> 1 | G29: ='0029 Budget Dist'!G235 -> 1 | H29: ='0029 Budget Dist'!H235 -> 1
A30: 24 | B30: 800(13)(01) चावडी मुळे स्थानिक संस्थांकडून मिळणा-या अंशदानाच्या रकमा (00291488) | C30: ='0029 Budget Dist'!C245 -> 0 | D30: ='0029 Budget Dist'!D245 -> 50 | E30: ='0029 Budget Dist'!E245 -> 0 | F30: ='0029 Budget Dist'!F245 -> 1 | G30: ='0029 Budget Dist'!G245 -> 1 | H30: ='0029 Budget Dist'!H245 -> 1
A31: 25 | B31: 800 (17) (01) अकृषिक आकारणी (00291728) | C31: ='0029 Budget Dist'!C255 -> 321335 | D31: ='0029 Budget Dist'!D255 -> 311309.47 | E31: ='0029 Budget Dist'!E255 -> 280422.27 | F31: ='0029 Budget Dist'!F255 -> 367390.5 | G31: ='0029 Budget Dist'!G255 -> 277227.79 | H31: ='0029 Budget Dist'!H255 -> 287297.63
A32: 26 | B32: 800 (18) बिनशेती परवानगीसाठी करावयाच्या अर्जामुळे मिळणा-या रकमा (00290231) | C32: =SUM('0029 Budget Dist'!C265) -> 0 | D32: =SUM('0029 Budget Dist'!D265) -> 0 | E32: =SUM('0029 Budget Dist'!E265) -> 24 | F32: =SUM('0029 Budget Dist'!F265) -> 0 | G32: =SUM('0029 Budget Dist'!G265) -> 0 | H32: =SUM('0029 Budget Dist'!H265) -> 0
A33: 27 | B33: 501 सेवा व सेवा फी, 501 (01) केलेल्या सेवांकरीता प्रदानांची वसुली वजा वसुली (00290857) | C33: =SUM('0029 Budget Dist'!C275) -> 528081 | D33: =SUM('0029 Budget Dist'!D275) -> 158367 | E33: =SUM('0029 Budget Dist'!E275) -> 2568 | F33: =SUM('0029 Budget Dist'!F275) -> 67020 | G33: =SUM('0029 Budget Dist'!G275) -> 40000 | H33: =SUM('0029 Budget Dist'!H275) -> 30000
A34: 28 | B34: 101 (03) महाराष्ट्र धारण जमिनीचे तुकडे पाडण्यास प्रतिबंध करण्याबाबत व त्याचे एकत्रिकरण करण्याबाबत अधिनियम 1947 च्या कलम 9 मध्ये महाराष्ट्र अधिनियम क्र.58/2017 (03)(01)(00291782) | C34: =SUM('0029 Budget Dist'!C285) -> 0 | D34: =SUM('0029 Budget Dist'!D285) -> 0 | E34: =SUM('0029 Budget Dist'!E285) -> 66 | F34: =SUM('0029 Budget Dist'!F285) -> 0 | G34: =SUM('0029 Budget Dist'!G285) -> 0 | H34: =SUM('0029 Budget Dist'!H285) -> 0
A35: 29 | B35: इतर | C35: =SUM('0029 Budget Dist'!C294) -> 0 | D35: =SUM('0029 Budget Dist'!D294) -> 0 | E35: =SUM('0029 Budget Dist'!E294) -> 3039 | F35: =SUM('0029 Budget Dist'!F294) -> 0 | G35: =SUM('0029 Budget Dist'!G294) -> 5569.39 | H35: =SUM('0029 Budget Dist'!H294) -> 5755.78
B36: कोकण विभाग एकूण (1 ते 29 बाबी) | C36: =SUM(C7:C35) -> 12679316 | D36: =SUM(D7:D35) -> 15301769 | E36: =SUM(E7:E35) -> 11751958 | F36: =SUM(F7:F35) -> 17118940 | G36: =SUM(G7:G35) -> 8635987.1 | H36: =SUM(H7:H35) -> 15749347
A38: मा.उप आयुक्त (महसूल) कोकण विभाग यांची स्थळप्रतीवर स्वाक्षरी असे )
F39: (विनिता भूमकर)
F40: सहाय्यक संचालक (लेखा) कोकण विभाग
