Workbook

Sheet Page-1
A1: अर्थसंकल्पीय अंदाजपत्रक सन 2025-2026
A2: मागणी क्र.सी- 1- लेखाशिर्ष 20530028
A3: जिल्हा मुंबई शहर | O3: (आकडे हजारात)
A4: अ. क्र. | B4: वर्ग | C4: पद | D4: मंजूर पदे | E4: मंजूर पदे | F4: विशेष वेतन | G4: मुळ वेतन | H4: ग्रेड वेतन | I4: एकूण | J4: महागाई भत्ता 64% | K4: स्थानिक पुरक भत्ता | L4: घर भाडे भत्ता | M4: वाहन भत्ता | N4: धूलाई भत्ता | O4: रोख भत्ता | P4: चप्पल भत्ता/ इतर | Q4: एकूण
D5: 2024-25 | E5: 2025-26
C6: स्थायी
A7: 1 | B7: वर्ग-1 व 2 | C7: जिल्हाधिकारी | D7: 1 | E7: 1 | F7: 0 | G7: 2442 | H7: 0 | I7: =SUM(G7:H7) -> 2442 | J7: =ROUND(I7*0.64,0) -> 1563 | K7: 4 | L7: 0 | M7: 0 | N7: 0 | O7: 0 | P7: 0 | Q7: =SUM(F7+I7+J7+K7+L7+M7+N7+O7+P7) -> 4009
C8: अपर जिल्हाधिकारी | D8: 0 | E8: 0 | F8: 0 | G8: 0 | H8: 0 | I8: =SUM(G8:H8) -> 0 | J8: =ROUND(I8*0.64,0) -> 0 | K8: 0 | L8: =ROUND(I8*0.3,0) -> 0 | M8: 0 | N8: 0 | O8: 0 | P8: 0 | Q8: =SUM(F8+I8+J8+K8+L8+M8+N8+O8+P8) -> 0
C9: उपजिल्हाधिकारी | D9: 1 | E9: 1 | F9: 0 | G9: 1253 | H9: 0 | I9: =SUM(G9:H9) -> 1253 | J9: =ROUND(I9*0.64,0) -> 802 | K9: 4 | L9: =ROUND(I9*0.3,0) -> 376 | M9: 65 | N9: 0 | O9: 0 | P9: 0 | Q9: =SUM(F9+I9+J9+K9+L9+M9+N9+O9+P9) -> 2500
C10: तहसिलदार/अप्पर तहसिलदार/चिटणीस | D10: 1 | E10: 1 | F10: 0 | G10: 768 | H10: 0 | I10: =SUM(G10:H10) -> 768 | J10: =ROUND(I10*0.64,0) -> 492 | K10: 3 | L10: =ROUND(I10*0.3,0) -> 230 | M10: 65 | N10: 0 | O10: 0 | P10: 0 | Q10: =SUM(F10+I10+J10+K10+L10+M10+N10+O10+P10) -> 1558
C11: नायब तहसिलदार | D11: 0 | E11: 0 | F11: 0 | G11: 0 | H11: 0 | I11: =SUM(G11:H11) -> 0 | J11: =ROUND(I11*0.64,0) -> 0 | K11: 0 | L11: =ROUND(I11*0.3,0) -> 0 | M11: 0 | N11: 0 | O11: 0 | P11: 0 | Q11: =SUM(F11+I11+J11+K11+L11+M11+N11+O11+P11) -> 0
C12: लेखाधिकारी | D12: 0 | E12: 0 | F12: 0 | G12: 0 | H12: 0 | I12: =SUM(G12:H12) -> 0 | J12: =ROUND(I12*0.64,0) -> 0 | K12: 0 | L12: =ROUND(I12*0.3,0) -> 0 | M12: 0 | N12: 0 | O12: 0 | P12: 0 | Q12: =SUM(F12+I12+J12+K12+L12+M12+N12+O12+P12) -> 0
C13: सहा. लेखाधिकारी | D13: 0 | E13: 0 | F13: 0 | G13: 0 | H13: 0 | I13: =SUM(G13:H13) -> 0 | J13: =ROUND(I13*0.64,0) -> 0 | K13: 0 | L13: =ROUND(I13*0.3,0) -> 0 | M13: 0 | N13: 0 | O13: 0 | P13: 0 | Q13: =SUM(F13+I13+J13+K13+L13+M13+N13+O13+P13) -> 0
A14: 2 | B14: वर्ग-3 | C14: उपलेखापाल | D14: 0 | E14: 0 | F14: 0 | G14: 0 | H14: 0 | I14: =SUM(G14:H14) -> 0 | J14: =ROUND(I14*0.64,0) -> 0 | K14: 0 | L14: =ROUND(I14*0.3,0) -> 0 | M14: 0 | N14: 0 | O14: 0 | P14: 0 | Q14: =SUM(F14+I14+J14+K14+L14+M14+N14+O14+P14) -> 0
C15: लघुलेखक (उच्च) | D15: 1 | E15: 1 | F15: 0 | G15: 758 | H15: 0 | I15: =SUM(G15:H15) -> 758 | J15: =ROUND(I15*0.64,0) -> 485 | K15: 3 | L15: 228 | M15: 32 | N15: 0 | O15: 0 | P15: 0 | Q15: =SUM(F15+I15+J15+K15+L15+M15+N15+O15+P15) -> 1506
C16: लघुलेखक(निम्न)/परिक्षण भूमापक/आरेखक/ शिरस्तेदार | D16: 0 | E16: 0 | F16: 0 | G16: 0 | H16: 0 | I16: =SUM(G16:H16) -> 0 | J16: =ROUND(I16*0.64,0) -> 0 | K16: 0 | L16: =ROUND(I16*0.3,0) -> 0 | M16: 0 | N16: 0 | O16: 0 | P16: 0 | Q16: =SUM(F16+I16+J16+K16+L16+M16+N16+O16+P16) -> 0
C17: अव्वल कारकून | D17: 2 | E17: 2 | F17: 0 | G17: 867 | H17: 0 | I17: =SUM(G17:H17) -> 867 | J17: =ROUND(I17*0.64,0) -> 555 | K17: 8 | L17: =ROUND(I17*0.3,0) -> 260 | M17: 65 | N17: 0 | O17: 17 | P17: 0 | Q17: =SUM(F17+I17+J17+K17+L17+M17+N17+O17+P17) -> 1772
C18: लिपिक | D18: 23 | E18: 23 | F18: 0 | G18: 6637 | H18: 0 | I18: =SUM(G18:H18) -> 6637 | J18: =ROUND(I18*0.64,0) -> 4248 | K18: 55 | L18: 1992 | M18: 439 | N18: 0 | O18: 0 | P18: 0 | Q18: =SUM(F18+I18+J18+K18+L18+M18+N18+O18+P18) -> 13371
C19: वाहन चालक | D19: 0 | E19: 0 | F19: 0 | G19: 0 | H19: 0 | I19: =SUM(G19:H19) -> 0 | J19: =ROUND(I19*0.64,0) -> 0 | K19: 0 | L19: =ROUND(I19*0.3,0) -> 0 | M19: 0 | N19: 0 | O19: 0 | P19: 0 | Q19: =SUM(F19+I19+J19+K19+L19+M19+N19+O19+P19) -> 0
A20: 3 | B20: वर्ग-4 | C20: शिपाई/नाईक/हवालदार/वॉचमन/स्वच्छक | D20: 32 | E20: 32 | F20: 0 | G20: 8953 | H20: 0 | I20: =SUM(G20:H20) -> 8953 | J20: =ROUND(I20*0.64,0) -> 5730 | K20: 49 | L20: =ROUND(I20*0.3,0) -> 2686 | M20: 552 | N20: 96 | O20: 0 | P20: 0 | Q20: =SUM(F20+I20+J20+K20+L20+M20+N20+O20+P20) -> 18066
A21: -- | B21: -- | C21: एकूण | D21: =SUM(D7:D20) -> 61 | E21: =SUM(E7:E20) -> 61 | F21: =SUM(F7:F20) -> 0 | G21: =SUM(G7:G20) -> 21678 | H21: =SUM(H7:H20) -> 0 | I21: =SUM(I7:I20) -> 21678 | J21: =SUM(J7:J20) -> 13875 | K21: =SUM(K7:K20) -> 126 | ... Q21: =SUM(Q7:Q20) -> 42782
D22: =E6+E7+E8+E9+E10+E11 -> 3 | E22: =E14+E15+E16+E17+E18+E19 -> 26
A23: अर्थसंकल्पीय अंदाजपत्रक सन 2025-2026
A24: मागणी क्र.सी- 1- लेखाशिर्ष 20530028
A25: जिल्हा मुंबई शहर | O25: (आकडे हजारात)
A26: अ. क्र. | B26: वर्ग | C26: पद | D26: मंजूर पदे | E26: मंजूर पदे | F26: विशेष वेतन | G26: मुळ वेतन | H26: ग्रेड वेतन | I26: एकूण | J26: महागाई भत्ता 64% | K26: स्थानिक पुरक भत्ता | L26: घर भाडे भत्ता | M26: वाहन भत्ता | N26: धूलाई भत्ता | O26: रोख भत्ता | P26: चप्पल भत्ता/ इतर | Q26: एकूण
D27: 2024-25 | E27: 2025-26
C28: अस्थायी
A29: 1 | B29: वर्ग-1 व 2 | C29: जिल्हाधिकारी | D29: 0 | E29: 0 | F29: 0 | G29: 0 | H29: 0 | I29: =SUM(G29:H29) -> 0 | J29: =ROUND(I29*0.64,0) -> 0 | K29: 0 | L29: =ROUND(I29*0.3,0) -> 0 | M29: 0 | N29: 0 | O29: 0 | P29: 0 | Q29: =SUM(F29+I29+J29+K29+L29+M29+N29+O29+P29) -> 0
C30: अपर जिल्हाधिकारी | D30: 1 | E30: 1 | F30: 0 | G30: 1390 | H30: 0 | I30: =SUM(G30:H30) -> 1390 | J30: =ROUND(I30*0.64,0) -> 890 | K30: 4 | L30: =ROUND(I30*0.3,0) -> 417 | M30: 0 | N30: 0 | O30: 0 | P30: 0 | Q30: =SUM(F30+I30+J30+K30+L30+M30+N30+O30+P30) -> 2701
C31: उपजिल्हाधिकारी/परिविक्षाधीन उपजिल्हाधिकारी | D31: 1 | E31: 1 | F31: 0 | G31: 1049 | H31: 0 | I31: =SUM(G31:H31) -> 1049 | J31: =ROUND(I31*0.64,0) -> 671 | K31: 4 | L31: =ROUND(I31*0.3,0) -> 315 | M31: 65 | N31: 0 | O31: 0 | P31: 0 | Q31: =SUM(F31+I31+J31+K31+L31+M31+N31+O31+P31) -> 2104
C32: तहसिलदार/अप्पर तहसिलदार/चिटणीस/ परिविक्षाधीन तहसिलदार | D32: 2 | E32: 2 | F32: 0 | G32: 1583 | H32: 0 | I32: =SUM(G32:H32) -> 1583 | J32: =ROUND(I32*0.64,0) -> 1013 | K32: 8 | L32: 475 | M32: 130 | N32: 0 | O32: 0 | P32: 0 | Q32: =SUM(F32+I32+J32+K32+L32+M32+N32+O32+P32) -> 3209
C33: नायब तहसिलदार/परिविक्षाधीन ना.तहसिलदार | D33: 0 | E33: 0 | F33: 0 | G33: 0 | H33: 0 | I33: =SUM(G33:H33) -> 0 | J33: =ROUND(I33*0.64,0) -> 0 | K33: 0 | L33: =ROUND(I33*0.3,0) -> 0 | M33: 0 | N33: 0 | O33: 0 | P33: 0 | Q33: =SUM(F33+I33+J33+K33+L33+M33+N33+O33+P33) -> 0
C34: लेखाधिकारी | D34: 2 | E34: 2 | F34: 0 | G34: 1560 | H34: 0 | I34: =SUM(G34:H34) -> 1560 | J34: 999 | K34: 6 | L34: =ROUND(I34*0.3,0) -> 468 | M34: 65 | N34: 0 | O34: 0 | P34: 0 | Q34: =SUM(F34+I34+J34+K34+L34+M34+N34+O34+P34) -> 3098
C35: सहा. लेखाधिकारी | D35: 1 | E35: 1 | F35: 0 | G35: 636 | H35: 0 | I35: =SUM(G35:H35) -> 636 | J35: =ROUND(I35*0.64,0) -> 407 | K35: 3 | L35: =ROUND(I35*0.3,0) -> 191 | M35: 32 | N35: 0 | O35: 0 | P35: 0 | Q35: =SUM(F35+I35+J35+K35+L35+M35+N35+O35+P35) -> 1269
C36: विधी अधिकारी (मानधन) | D36: 1 | E36: 1 | F36: 0 | G36: 0 | H36: 0 | I36: =SUM(G36:H36) -> 0 | J36: =ROUND(I36*0.64,0) -> 0 | K36: 0 | L36: =ROUND(I36*0.3,0) -> 0 | M36: 0 | N36: 0 | O36: 0 | P36: 0 | Q36: =SUM(F36+I36+J36+K36+L36+M36+N36+O36+P36) -> 0
A37: 2 | B37: वर्ग-3 | C37: उपलेखापाल | D37: 1 | E37: 1 | F37: 0 | G37: 571 | H37: 0 | I37: =SUM(G37:H37) -> 571 | J37: 366 | K37: 4 | L37: =ROUND(I37*0.3,0) -> 171 | M37: 32 | N37: 0 | O37: 0 | P37: 0 | Q37: =SUM(F37+I37+J37+K37+L37+M37+N37+O37+P37) -> 1144
C38: अव्वल कारकून/उपलेखापाल | D38: 21 | E38: 20 | F38: 0 | G38: 9452 | H38: 0 | I38: =SUM(G38:H38) -> 9452 | J38: 6050 | K38: 72 | L38: =ROUND(I38*0.3,0) -> 2836 | M38: 648 | N38: 0 | O38: 168 | P38: 0 | Q38: =SUM(F38+I38+J38+K38+L38+M38+N38+O38+P38) -> 19226
C39: मंडळ अधिकारी | D39: 0 | E39: 0 | F39: 0 | G39: 0 | H39: 0 | I39: =SUM(G39:H39) -> 0 | J39: =ROUND(I39*0.64,0) -> 0 | K39: 0 | L39: =ROUND(I39*0.3,0) -> 0 | M39: 0 | N39: 0 | O39: 0 | P39: 0 | Q39: =SUM(F39+I39+J39+K39+L39+M39+N39+O39+P39) -> 0
C40: लिपिक/भूमापक/वसूली कारकून | D40: 14 | E40: 14 | F40: 0 | G40: 4732 | H40: 0 | I40: =SUM(G40:H40) -> 4732 | J40: =ROUND(I40*0.64,0) -> 3028 | K40: 34 | L40: =ROUND(I40*0.3,0) -> 1420 | M40: 311 | N40: 0 | O40: 0 | P40: 0 | Q40: =SUM(F40+I40+J40+K40+L40+M40+N40+O40+P40) -> 9525
...

Sheet Page-2
A1: अर्थसंकल्पीय अंदाजपत्रक सन 2025-2026
A2: मागणी क्र.सी- 1- लेखाशिर्ष 20530028
A3: (आकडे हजारात)
A4: जिल्हा | B4: स्थायी पदे
C5: भरलेली पदे | G5: रिक्त पदे | K5: एकूण
A6: मुंबई शहर | B6: वर्ग | C6: वर्ग-1 व 2 | D6: वर्ग-3 | E6: वर्ग-4 | F6: एकूण | G6: वर्ग-1 व 2 | H6: वर्ग-3 | I6: वर्ग-4 | J6: एकूण | K6: एकूण
B7: पदे | C7: 3 | D7: 25 | E7: 21 | F7: =SUM(C7:E7) -> 49 | G7: 0 | H7: 1 | I7: 11 | J7: =SUM(G7:I7) -> 12 | K7: =SUM(J7,F7) -> 61
B8: वेतन | C8: 4463 | D8: 7950 | E8: 5442 | F8: =SUM(C8:E8) -> 17855 | G8: 0 | H8: 312 | I8: 3511 | J8: =SUM(G8:I8) -> 3823 | K8: =SUM(J8,F8) -> 21678
B9: ग्रेड पे | C9: 0 | D9: 0 | E9: 0 | F9: =SUM(C9:E9) -> 0 | G9: 0 | H9: 0 | I9: 0 | J9: =SUM(G9:I9) -> 0 | K9: =SUM(J9,F9) -> 0
B10: एकूण | C10: =SUM(C8:C9) -> 4463 | D10: =SUM(D8:D9) -> 7950 | E10: =SUM(E8:E9) -> 5442 | F10: =SUM(C10:E10) -> 17855 | G10: =SUM(G8:G9) -> 0 | H10: =SUM(H8:H9) -> 312 | I10: =SUM(I8:I9) -> 3511 | J10: =SUM(J8:J9) -> 3823 | K10: =SUM(K8:K9) -> 21678
B11: विशेष वेतन | C11: 0 | D11: 0 | E11: 0 | F11: =SUM(C11:E11) -> 0 | G11: 0 | H11: 0 | I11: 0 | J11: =SUM(G11:I11) -> 0 | K11: =SUM(J11,F11) -> 0
B12: महा.भत्ता | C12: 2857 | D12: 5088 | E12: 3483 | F12: =SUM(C12:E12) -> 11428 | G12: 0 | H12: 200 | I12: 2247 | J12: =SUM(G12:I12) -> 2447 | K12: =SUM(J12,F12) -> 13875
B13: स्था.पु.भ. | C13: 11 | D13: 64 | E13: 32 | F13: =SUM(C13:E13) -> 107 | G13: 0 | H13: 2 | I13: 17 | J13: =SUM(G13:I13) -> 19 | K13: =SUM(J13,F13) -> 126
B14: घरभाडे | C14: 606 | D14: 2386 | E14: 1633 | F14: =SUM(C14:E14) -> 4625 | G14: 0 | H14: 94 | I14: 1053 | J14: =SUM(G14:I14) -> 1147 | K14: =SUM(J14,F14) -> 5772
B15: प्रवास भत्ता | C15: 130 | D15: 504 | E15: 298 | F15: =SUM(C15:E15) -> 932 | G15: 0 | H15: 32 | I15: 254 | J15: =SUM(G15:I15) -> 286 | K15: =SUM(J15,F15) -> 1218
B16: इतर | C16: 0 | D16: 17 | E16: 63 | F16: =SUM(C16:E16) -> 80 | G16: 0 | H16: 0 | I16: 33 | J16: =SUM(G16:I16) -> 33 | K16: =SUM(J16,F16) -> 113
B17: एकूण | C17: =SUM(C10:C16) -> 8067 | D17: =SUM(D10:D16) -> 16009 | E17: =SUM(E10:E16) -> 10951 | F17: =SUM(F10:F16) -> 35027 | G17: =SUM(G10:G16) -> 0 | H17: =SUM(H10:H16) -> 640 | I17: =SUM(I10:I16) -> 7115 | J17: =SUM(J10:J16) -> 7755 | K17: =SUM(K10:K16) -> 42782
A19: जिल्हा | B19: अस्थायी पदे | M19: सर्व वर्ग पदे
C20: भरलेली पदे | G20: रिक्त पदे | K20: एकूण | M20: वर्ग | N20: स्थायी पदे | O20: अस्थायी पदे | P20: एकूण
A21: मुंबई शहर | B21: वर्ग | C21: वर्ग-1 व 2 | D21: वर्ग-3 | E21: वर्ग-4 | F21: एकूण | G21: वर्ग-1 व 2 | H21: वर्ग-3 | I21: वर्ग-4 | J21: एकूण | K21: एकूण | M21: पदे | N21: =K7 -> 61 | O21: =K22 -> 51 | P21: =SUM(N21:O21) -> 112
B22: पदे | C22: 8 | D22: 35 | E22: 2 | F22: =SUM(C22:E22) -> 45 | G22: 0 | H22: 5 | I22: 1 | J22: =SUM(G22:I22) -> 6 | K22: =SUM(J22,F22) -> 51 | M22: वेतन | N22: =K8 -> 21678 | O22: =K23 -> 24289 | P22: =SUM(N22:O22) -> 45967
B23: वेतन | C23: 6218 | D23: 15085 | E23: 674 | F23: =SUM(C23:E23) -> 21977 | G23: 0 | H23: 2120 | I23: 192 | J23: =SUM(G23:I23) -> 2312 | K23: =SUM(J23,F23) -> 24289 | M23: ग्रेड पे | N23: =K9 -> 0 | O23: =K24 -> 0 | P23: =SUM(N23:O23) -> 0
B24: ग्रेड पे | C24: 0 | D24: 0 | E24: 0 | F24: =SUM(C24:E24) -> 0 | G24: 0 | H24: 0 | I24: 0 | J24: =SUM(G24:I24) -> 0 | K24: =SUM(J24,F24) -> 0 | M24: एकूण | N24: =K10 -> 21678 | O24: =K25 -> 24289 | P24: =SUM(N24:O24) -> 45967
B25: एकूण | C25: =SUM(C23:C24) -> 6218 | D25: =SUM(D23:D24) -> 15085 | E25: =SUM(E23:E24) -> 674 | F25: =SUM(C25:E25) -> 21977 | G25: =SUM(G23:G24) -> 0 | H25: =SUM(H23:H24) -> 2120 | I25: =SUM(I23:I24) -> 192 | J25: =SUM(J23:J24) -> 2312 | K25: =SUM(K23:K24) -> 24289 | M25: विशेष वेतन | N25: =K11 -> 0 | O25: =K26 -> 0 | P25: =SUM(N25:O25) -> 0
B26: विशेष वेतन | C26: 0 | D26: 0 | E26: 0 | F26: =SUM(C26:E26) -> 0 | G26: 0 | H26: 0 | I26: 0 | J26: =SUM(G26:I26) -> 0 | K26: =SUM(J26,F26) -> 0 | M26: महा.भत्ता | N26: =K12 -> 13875 | O26: =K27 -> 15547 | P26: =SUM(N26:O26) -> 29422
B27: महा.भत्ता | C27: 3980 | D27: 9655 | E27: 432 | F27: =SUM(C27:E27) -> 14067 | G27: 0 | H27: 1357 | I27: 123 | J27: =SUM(G27:I27) -> 1480 | K27: =SUM(J27,F27) -> 15547 | M27: स्था.पु.भ. | N27: =K13 -> 126 | O27: =K28 -> 157 | P27: =SUM(N27:O27) -> 283
B28: स्था.पु.भ. | C28: 25 | D28: 108 | E28: 4 | F28: =SUM(C28:E28) -> 137 | G28: 0 | H28: 18 | I28: 2 | J28: =SUM(G28:I28) -> 20 | K28: =SUM(J28,F28) -> 157 | M28: घरभाडे | N28: =K14 -> 5772 | O28: =K29 -> 7288 | P28: =SUM(N28:O28) -> 13060
B29: घरभाडे | C29: 1866 | D29: 4526 | E29: 202 | F29: =SUM(C29:E29) -> 6594 | G29: 0 | H29: 636 | I29: 58 | J29: =SUM(G29:I29) -> 694 | K29: =SUM(J29,F29) -> 7288 | M29: प्रवास भत्ता | N29: =K15 -> 1218 | O29: =K30 -> 1566 | P29: =SUM(N29:O29) -> 2784
B30: प्रवास भत्ता | C30: 292 | D30: 1056 | E30: 44 | F30: =SUM(C30:E30) -> 1392 | G30: 0 | H30: 162 | I30: 12 | J30: =SUM(G30:I30) -> 174 | K30: =SUM(J30,F30) -> 1566 | M30: इतर | N30: =K16 -> 113 | O30: =K31 -> 179 | P30: =SUM(N30:O30) -> 292
B31: इतर | C31: 0 | D31: 136 | E31: 6 | F31: =SUM(C31:E31) -> 142 | G31: 0 | H31: 34 | I31: 3 | J31: =SUM(G31:I31) -> 37 | K31: =SUM(J31,F31) -> 179 | M31: एकूण | N31: =SUM(N24:N30) -> 42782 | O31: =SUM(O24:O30) -> 49026 | P31: =SUM(P24:P30) -> 91808
B32: एकूण | C32: =SUM(C25:C31) -> 12381 | D32: =SUM(D25:D31) -> 30566 | E32: =SUM(E25:E31) -> 1362 | F32: =SUM(F25:F31) -> 44309 | G32: =SUM(G25:G31) -> 0 | H32: =SUM(H25:H31) -> 4327 | I32: =SUM(I25:I31) -> 390 | J32: =SUM(J25:J31) -> 4717 | K32: =SUM(K25:K31) -> 49026
A34: अर्थसंकल्पीय अंदाजपत्रक सन 2025-2026
A35: मागणी क्र.सी- 1- लेखाशिर्ष 20530028
A36: (आकडे हजारात)
A37: जिल्हा | B37: स्थायी पदे
C38: भरलेली पदे | G38: रिक्त पदे | K38: एकूण
A39: मुंबई उपनगर | B39: वर्ग | C39: वर्ग-1 व 2 | D39: वर्ग-3 | E39: वर्ग-4 | F39: एकूण | G39: वर्ग-1 व 2 | H39: वर्ग-3 | I39: वर्ग-4 | J39: एकूण | K39: एकूण
B40: पदे | C40: 11 | D40: 29 | E40: 15 | F40: =SUM(C40:E40) -> 55 | G40: 0 | H40: 5 | I40: 12 | J40: =SUM(G40:I40) -> 17 | K40: =SUM(J40,F40) -> 72
B41: वेतन | C41: 11050 | D41: 15810 | E41: 5921 | F41: =SUM(C41:E41) -> 32781 | G41: 0 | H41: 2340 | I41: 3029 | J41: =SUM(G41:I41) -> 5369 | K41: =SUM(J41,F41) -> 38150
B42: ग्रेड पे | C42: 0 | D42: 0 | E42: 0 | F42: =SUM(C42:E42) -> 0 | G42: 0 | H42: 0 | I42: 0 | J42: =SUM(G42:I42) -> 0 | K42: =SUM(J42,F42) -> 0
...

Sheet Page-3
A1: अर्थसंकल्पीय अंदाजपत्रक सन 2025-2026
A2: मागणी क्र.सी- 1- लेखाशिर्ष 20530028
A3: मंजूर पदे
A4: अ.क्र. | B4: वर्ग | C4: स्थायी | E4: अस्थायी | G4: एकूण
C5: भरलेली पदे | D5: रिक्त पदे | E5: भरलेली पदे | F5: रिक्त पदे
A6: 1 | B6: 1 | C6: 3 | D6: 0 | E6: 4 | F6: 0 | G6: =SUM(C6:F6) -> 7
A7: 2 | B7: 2 | C7: 0 | D7: 0 | E7: 4 | F7: 0 | G7: =SUM(C7:F7) -> 4
A8: 3 | B8: 3 | C8: 25 | D8: 1 | E8: 35 | F8: 5 | G8: =SUM(C8:F8) -> 66
A9: 4 | B9: 4 | C9: 21 | D9: 11 | E9: 2 | F9: 1 | G9: =SUM(C9:F9) -> 35
A10: -- | B10: एकूण | C10: =SUM(C6:C9) -> 49 | D10: =SUM(D6:D9) -> 12 | E10: =SUM(E6:E9) -> 45 | F10: =SUM(F6:F9) -> 6 | G10: =SUM(G6:G9) -> 112
F13: (आकडे हजारात)
A14: अ.क्र. | B14: जिल्हा / विभाग | C14: वैद्यकिय खर्च | D14: उत्सव/सण अग्रिम | E14: स्वग्राम/महाराष्ट्र दर्शन | F14: 7 व्या वेतन आयोग फरक+ NPS | G14: इतर | H14: एकूण
A15: 1 | B15: मुंबई शहर | C15: 1600 | D15: 1375 | E15: 1600 | F15: 120000 | G15: 5000 | H15: =SUM(C15:G15) -> 129575
A17: अर्थसंकल्पीय अंदाजपत्रक सन 2025-2026
A18: मागणी क्र.सी- 1- लेखाशिर्ष 20530028
A19: मंजूर पदे
A20: अ.क्र. | B20: वर्ग | C20: स्थायी | E20: अस्थायी | G20: एकूण
C21: भरलेली पदे | D21: रिक्त पदे | E21: भरलेली पदे | F21: रिक्त पदे
A22: 1 | B22: 1 | C22: 7 | D22: 0 | E22: 7 | F22: 2 | G22: =SUM(C22:F22) -> 16
A23: 2 | B23: 2 | C23: 4 | D23: 0 | E23: 6 | F23: 3 | G23: =SUM(C23:F23) -> 13
A24: 3 | B24: 3 | C24: 29 | D24: 5 | E24: 99 | F24: 16 | G24: =SUM(C24:F24) -> 149
A25: 4 | B25: 4 | C25: 15 | D25: 12 | E25: 25 | F25: 17 | G25: =SUM(C25:F25) -> 69
A26: -- | B26: एकूण | C26: =SUM(C22:C25) -> 55 | D26: =SUM(D22:D25) -> 17 | E26: =SUM(E22:E25) -> 137 | F26: =SUM(F22:F25) -> 38 | G26: =SUM(G22:G25) -> 247
F29: (आकडे हजारात)
A30: अ.क्र. | B30: जिल्हा / विभाग | C30: वैद्यकिय खर्च | D30: उत्सव/सण अग्रिम | E30: स्वग्राम/महाराष्ट्र दर्शन | F30: NPS | G30: इतर | H30: एकूण
A31: 1 | B31: मुंबई उपनगर | C31: 6000 | D31: 3100 | E31: 1000 | F31: 17000 | G31: 20000 | H31: =SUM(C31:G31) -> 47100
A33: अर्थसंकल्पीय अंदाजपत्रक सन 2025-2026
A34: मागणी क्र.सी- 1- लेखाशिर्ष 20530028
A35: मंजूर पदे
A36: अ.क्र. | B36: वर्ग | C36: स्थायी | E36: अस्थायी | G36: एकूण
C37: भरलेली पदे | D37: रिक्त पदे | E37: भरलेली पदे | F37: रिक्त पदे
A38: 1 | B38: 1 | C38: 13 | D38: 0 | E38: 5 | F38: 0 | G38: =SUM(C38:F38) -> 18
A39: 2 | B39: 2 | C39: 5 | D39: 1 | E39: 18 | F39: 0 | G39: =SUM(C39:F39) -> 24
A40: 3 | B40: 3 | C40: 67 | D40: 9 | E40: 121 | F40: 9 | G40: =SUM(C40:F40) -> 206
A41: 4 | B41: 4 | C41: 35 | D41: 8 | E41: 35 | F41: 6 | G41: =SUM(C41:F41) -> 84
A42: -- | B42: एकूण | C42: =SUM(C38:C41) -> 120 | D42: =SUM(D38:D41) -> 18 | E42: =SUM(E38:E41) -> 179 | F42: =SUM(F38:F41) -> 15 | G42: =SUM(G38:G41) -> 332
F45: (आकडे हजारात)
A46: अ.क्र. | B46: जिल्हा / विभाग | C46: वैद्यकिय खर्च | D46: उत्सव/सण अग्रिम | E46: स्वग्राम/महाराष्ट्र दर्शन | F46: 7 व्या वेतन आयोग फरक | G46: इतर | H46: एकूण
A47: 1 | B47: ठाणे | C47: 8500 | D47: 2000 | E47: 1500 | F47: 0 | G47: 11191 | H47: =SUM(C47:G47) -> 23191
A49: अर्थसंकल्पीय अंदाजपत्रक सन 2025-2026
...

Sheet Page-4
A1: अर्थसंकल्पीय अंदाजपत्रक सन 2025-2026
A2: मागणी क्र.सी- 1- लेखाशिर्ष 20530028
A3: जिल्हा मुंबई शहर | L3: (आकडे हजारात)
A4: अ. क्र. | B4: लेख्याची प्राथमिक आणि दुय्यम युनिट | C4: प्रत्यक्ष रक्कमा (खर्च) | F4: अर्थसंकल्पीय अंदाज | G4: सुधारीत अंदाज | H4: अर्थसंकल्पीय अंदाज 2025-2026 | L4: मागील वर्षाच्या प्रत्यक्ष रक्कमा आणि चालु वर्षाच्या अर्थसंकल्पीय अंदाजाची तुलना करता आगामी वर्षासाठीच्या अंदाजातील वाढ किंवा घट यांच्या संबंधातील स्पष्टीकरणे.
C5: 2021-2022 | D5: 2022-2023 | E5: 2023-2024 | F5: 2024-2025 | G5: 2024-2025 | H5: प्राकक्लन (एस्टिमेटिंग) अधिका-याचा | I5: नियंत्रक अधिका-यांचा | J5: प्रशासकीय विभागाचा | K5: वित्त विभागाचा
A6: 1 | B6: 2 | C6: 3 | D6: 4 | E6: 5 | F6: 6 | G6: 7 | H6: 8 | I6: 9 | J6: 10 | K6: 11 | L6: 12
A7: 1 | B7: 01- वेतन | C7: 61170 | D7: 76517 | E7: 71961 | F7: 229640 | G7: 229640 | H7: 221383 | I7: 0 | J7: 0 | K7: 0
A8: 2 | B8: 03- अति.भत्ता | C8: 103 | D8: 65 | E8: 102 | F8: 300 | G8: 300 | H8: 400 | I8: 0 | J8: 0 | K8: 0
A9: 3 | B9: 06- दूरध्वनी, वीज, पाणी व शुल्क | C9: 1571 | D9: 2279 | E9: 5470 | F9: 11922 | G9: 11922 | H9: 12922 | I9: 0 | J9: 0 | K9: 0
A10: 4 | B10: 10- कंत्राटी सेवा | C10: 0 | D10: 0 | E10: 341 | F10: 420 | G10: 420 | H10: 420 | I10: 0 | J10: 0 | K10: 0
A11: 5 | B11: 11- देशातंर्गत प्रवास खर्च | C11: 15 | D11: 14 | E11: 38 | F11: 600 | G11: 600 | H11: 700 | I11: 0 | J11: 0 | K11: 0
A12: 6 | B12: 13- कार्यालयीन खर्च | C12: 1239 | D12: 1845 | E12: 2987 | F12: 7481 | G12: 7481 | H12: 9081 | I12: 0 | J12: 0 | K12: 0
A13: 7 | B13: 14- भाडेपट्टी व कर | C13: 0 | D13: 0 | E13: 0 | F13: 0 | G13: 0 | H13: 0 | I13: 0 | J13: 0 | K13: 0
A14: 8 | B14: 16- प्रकाशने | C14: 0 | D14: 0 | E14: 0 | F14: 0 | G14: 0 | H14: 0 | I14: 0 | J14: 0 | K14: 0
A15: 9 | B15: 17- संगणक खर्च | C15: 14 | D15: 0 | E15: 33 | F15: 4000 | G15: 4000 | H15: 4500 | I15: 0 | J15: 0 | K15: 0
A16: 10 | B16: 20- इतर प्रशासकीय खर्च | C16: 0 | D16: 0 | E16: 0 | F16: 680 | G16: 680 | H16: 680 | I16: 0 | J16: 0 | K16: 0
A17: 11 | B17: 24- इंधन खर्च | C17: 316 | D17: 274 | E17: 302 | F17: 3000 | G17: 3000 | H17: 3050 | I17: 0 | J17: 0 | K17: 0
A18: 12 | B18: 26- जाहीरात व प्रसिध्दी खर्च | C18: 0 | D18: 16 | E18: 32 | F18: 1080 | G18: 1080 | H18: 1080 | I18: 0 | J18: 0 | K18: 0
... A21: 15 | B21: 51- मोटार वाहने | C21: 0 | D21: 0 | E21: 0 | F21: 0 | G21: 0 | H21: 0 | I21: 0 | J21: 0 | K21: 0
A22: -- | B22: एकूण | C22: =SUM(C7:C21) -> 64428 | D22: =SUM(D7:D21) -> 81010 | E22: =SUM(E7:E21) -> 81266 | F22: =SUM(F7:F21) -> 261053 | G22: =SUM(G7:G21) -> 261053 | H22: =SUM(H7:H21) -> 256146 | I22: =SUM(I7:I21) -> 0 | J22: =SUM(J7:J21) -> 0 | K22: =SUM(K7:K21) -> 0
A24: अर्थसंकल्पीय अंदाजपत्रक सन 2025-2026
A25: मागणी क्र.सी- 1- लेखाशिर्ष 20530028
A26: जिल्हा मुंबई उपनगर | L26: (आकडे हजारात)
A27: अ. क्र. | B27: लेख्याची प्राथमिक आणि दुय्यम युनिट | C27: प्रत्यक्ष रक्कमा (खर्च) | F27: अर्थसंकल्पीय अंदाज | G27: सुधारीत अंदाज | H27: अर्थसंकल्पीय अंदाज 2025-2026 | L27: मागील वर्षाच्या प्रत्यक्ष रक्कमा आणि चालु वर्षाच्या अर्थसंकल्पीय अंदाजाची तुलना करता आगामी वर्षासाठीच्या अंदाजातील वाढ किंवा घट यांच्या संबंधातील स्पष्टीकरणे.
C28: 2021-2022 | D28: 2022-2023 | E28: 2023-2024 | F28: 2024-2025 | G28: 2024-2025 | H28: प्राकक्लन (एस्टिमेटिंग) अधिका-याचा | I28: नियंत्रक अधिका-यांचा | J28: प्रशासकीय विभागाचा | K28: वित्त विभागाचा
A29: 1 | B29: 2 | C29: 3 | D29: 4 | E29: 5 | F29: 6 | G29: 7 | H29: 8 | I29: 9 | J29: 10 | K29: 11 | L29: 12
A30: 1 | B30: 01- वेतन | C30: 132538 | D30: 154229 | E30: 166870 | F30: 285029 | G30: 285029 | H30: 292560 | I30: 0 | J30: 0 | K30: 0
A31: 2 | B31: 03- अति.भत्ता | C31: 0 | D31: 0 | E31: 0 | F31: 370 | G31: 370 | H31: 370 | I31: 0 | J31: 0 | K31: 0
A32: 3 | B32: 06- दूरध्वनी, वीज, पाणी व शुल्क | C32: 1290 | D32: 1251 | E32: 1955 | F32: 7500 | G32: 7500 | H32: 7500 | I32: 0 | J32: 0 | K32: 0
A33: 4 | B33: 10- कंत्राटी सेवा | C33: 0 | D33: 0 | E33: 379 | F33: 500 | G33: 500 | H33: 500 | I33: 0 | J33: 0 | K33: 0
A34: 5 | B34: 11- देशातंर्गत प्रवास खर्च | C34: 109 | D34: 84 | E34: 132 | F34: 1000 | G34: 1000 | H34: 1000 | I34: 0 | J34: 0 | K34: 0
A35: 6 | B35: 13- कार्यालयीन खर्च | C35: 7154 | D35: 3735 | E35: 2090 | F35: 20000 | G35: 20000 | H35: 20000 | I35: 0 | J35: 0 | K35: 0
A36: 7 | B36: 14- भाडेपट्टी व कर | C36: 0 | D36: 0 | E36: 0 | F36: 0 | G36: 0 | H36: 0 | I36: 0 | J36: 0 | K36: 0
A37: 8 | B37: 16- प्रकाशने | C37: 0 | D37: 0 | E37: 0 | F37: 0 | G37: 0 | H37: 0 | I37: 0 | J37: 0 | K37: 0
A38: 9 | B38: 17- संगणक खर्च | C38: 11 | D38: 0 | E38: 5 | F38: 1000 | G38: 1000 | H38: 1000 | I38: 0 | J38: 0 | K38: 0
A39: 10 | B39: 20- इतर प्रशासकीय खर्च | C39: 0 | D39: 0 | E39: 0 | F39: 0 | G39: 0 | H39: 0 | I39: 0 | J39: 0 | K39: 0
A40: 11 | B40: 24- इंधन खर्च | C40: 106 | D40: 141 | E40: 135 | F40: 1000 | G40: 1000 | H40: 1000 | I40: 0 | J40: 0 | K40: 0
A41: 12 | B41: 26- जाहीरात व प्रसिध्दी खर्च | C41: 0 | D41: 252 | E41: 83 | F41: 670 | G41: 670 | H41: 670 | I41: 0 | J41: 0 | K41: 0
... A44: 15 | B44: 51- मोटार वाहने | C44: 0 | D44: 0 | E44: 0 | F44: 0 | G44: 0 | H44: 0 | I44: 0 | J44: 0 | K44: 0
A45: -- | B45: एकूण | C45: =SUM(C30:C44) -> 141208 | D45: =SUM(D30:D44) -> 159692 | E45: =SUM(E30:E44) -> 171649 | F45: =SUM(F30:F44) -> 317069 | G45: =SUM(G30:G44) -> 317069 | H45: =SUM(H30:H44) -> 324600 | I45: =SUM(I30:I44) -> 0 | J45: =SUM(J30:J44) -> 0 | K45: =SUM(K30:K44) -> 0
...

Sheet Page-5
A1: अर्थसंकल्पीय अंदाजपत्रक सन 2025-2026
A2: मागणी क्र.सी- 1- लेखाशिर्ष 20530028
A3: कोकण विभाग | L3: (आकडे हजारात)
A4: अ. क्र. | B4: लेख्याची प्राथमिक आणि दुय्यम युनिट | C4: प्रत्यक्ष रक्कमा (खर्च) | F4: अर्थसंकल्पीय अंदाज | G4: सुधारीत अंदाज | H4: अर्थसंकल्पीय अंदाज 2025-2026 | L4: मागील वर्षाच्या प्रत्यक्ष रक्कमा आणि चालु वर्षाच्या अर्थसंकल्पीय अंदाजाची तुलना करता आगामी वर्षासाठीच्या अंदाजातील वाढ किंवा घट यांच्या संबंधातील स्पष्टीकरणे.
C5: 2020-2021 | D5: 2021-2022 | E5: 2022-2023 | F5: 2023-2024 | G5: 2023-2024 | H5: प्राकक्लन (एस्टिमेटिंग) अधिका-याचा | I5: नियंत्रक अधिका-यांचा | J5: प्रशासकीय विभागाचा | K5: वित्त विभागाचा
A6: 1 | B6: 2 | C6: 3 | D6: 4 | E6: 5 | F6: 6 | G6: 7 | H6: 8 | I6: 9 | J6: 10 | K6: 11 | L6: 12
A7: 1 | B7: 01- वेतन | C7: ='Page-4'!C191 -> 1062697 | D7: ='Page-4'!D191 -> 1286858 | E7: ='Page-4'!E191 -> 1347942 | F7: ='Page-4'!F191 -> 2479253 | G7: ='Page-4'!G191 -> 2499349 | H7: 0 | I7: ='Page-4'!H191 -> 2684990 | J7: 0 | K7: 0 | L7: 01- वेतन:- या बाबीखाली सातवा वेतन आयोग फरक, चालु महागाई भत्ता दर आकारणी 64% प्रमाणे विचारात घेवून केली आहे. वेळोवेळी होणारी वेतनवाढ व महागाई भत्ता दराप्रमाणे वाढीव अनुदान मिळणेस विनंती आहे.
A8: 2 | B8: 03 अति.भत्ता | C8: ='Page-4'!C192 -> 1043 | D8: ='Page-4'!D192 -> 893 | E8: ='Page-4'!E192 -> 979 | F8: ='Page-4'!F192 -> 5435 | G8: ='Page-4'!G192 -> 5435 | H8: 0 | I8: ='Page-4'!H192 -> 5640 | J8: 0 | K8: 0 | L8: 03- अति. भत्ता:-शासनाने ठरवून दिलेल्या वाढीव महसूल उद्दिष्टपूर्तताबाबत विभागीय आयुक्त कोकण विभाग यांचे अधिनस्त 7 जिल्हाधिकारी व 50 तहसिलदार यांच्या सोबत त्यांचे वाहन चालकांना फिरती करावी लागते. सबब अतिकालिक भत्त्यात वाढ झाली आहे.
A9: 3 | B9: 06- दूरध्वनी वीज,पाणी व शुल्क | C9: ='Page-4'!C193 -> 17990 | D9: ='Page-4'!D193 -> 19296 | E9: ='Page-4'!E193 -> 24183 | F9: ='Page-4'!F193 -> 74334 | G9: ='Page-4'!G193 -> 74334 | H9: 0 | I9: ='Page-4'!H193 -> 75822 | J9: 0 | K9: 0 | L9: 06- दूरध्वनी, वीज पाणी व शुल्क:- (1)कोकण विभागांतर्गत एकूण 7 जिल्हाधिकारी कार्यालय व 50 तहसिल कार्यालय कार्यरत आहेत. (2)या बाबीखाली विभागात शासनाने ठरवून दिलेल्या जमीन महसूल कर वसुलीच्या वाढीव उद्दिष्टपूर्तता बाबत प्रशासकिय, विभागीय, जिल्हा, उपविभागीय व तहसिल कार्यालयांशी मोठया प्रमाणावर संपर्क साधण्यासाठी दूरध्वनीचा वापर, वीजेचे वाढलेले दर व पाणीपट्टीची वाढीव देयके यासाठी वाढीव अनुदानाची गरज आहे. (2)उपरोक्त सर्व पार्श्वभुमीवर मागणी व प्रत्यक्ष खर्चाचे प्रमाणे अनुदान मंजूर व्हावे ही विनंती.
A10: 4 | B10: 10- कंत्राटी सेवा | C10: ='Page-4'!C194 -> 793 | D10: ='Page-4'!D194 -> 1257 | E10: ='Page-4'!E194 -> 2769 | F10: ='Page-4'!F194 -> 4330 | G10: ='Page-4'!G194 -> 4330 | H10: 0 | I10: ='Page-4'!H194 -> 7770 | J10: ='[1]Page 4'!J186 -> 0 | K10: ='[1]Page 4'!K186 -> 0 | L10: 10- कंत्राटी सेवा:- 1) शासन वित्त विभाग शासन परिपत्रक क्र. संकीर्ण-2019/प्र.क्र.22/कोषा प्रशा-4, दि.29/01/2020 अन्वये विधी अधिकारी या (कंत्राटी) पदाच्या मानधनाकरीता तरतुद करण्यात आली आहे. विभागीय आयुक्त कोकण विभाग यांचे अधिनस्त सर्व जिल्हाधिकारी व तहसिल कार्यालयांतील कंत्राटी पध्दतीने विविध सेवा देणा-या कर्मचा-यांची देयके अदा करण्याकरीता तरतुद करण्यात आली आहे.
A11: 5 | B11: 11- देशांतर्गत प्रवास खर्च | C11: ='Page-4'!C195 -> 2308 | D11: ='Page-4'!D195 -> 2170 | E11: ='Page-4'!E195 -> 2604 | F11: ='Page-4'!F195 -> 17825 | G11: ='Page-4'!G195 -> 18000 | H11: 0 | I11: ='Page-4'!H195 -> 19470 | J11: 0 | K11: 0 | L11: 11- देशांतर्गत प्रवास खर्च:-अपु-या अनुदानामुळे कोकण विभागाचे अधिनस्त 7 जिल्हाधिकारी व 50 तहसिलदार कार्यालयांमध्ये गैरसाय निर्माण होत आहे.सबब कोकण विभागातील अधिकारी/कर्मचारी यांचे मागणी प्रमाणे पुरेसे अनुदान मंजूर होणेस सविनय विनंती आहे.
A12: 6 | B12: 13- कार्यालयीन खर्च | C12: ='Page-4'!C196 -> 40775 | D12: ='Page-4'!D196 -> 32492 | E12: ='Page-4'!E196 -> 30533 | F12: ='Page-4'!F196 -> 94371 | G12: ='Page-4'!G196 -> 94981 | H12: 0 | I12: ='Page-4'!H196 -> 110181 | J12: 0 | K12: 0 | L12: 13-कार्यालयीन खर्च:-कार्यालयीन खर्चामध्ये होणारी दरवाढ, प्रलंबित देयके, स्टेशनरीमधील दरवाढ तसेच गतवर्षांत सातत्याने अत्यल्प अनुदान मंजूर होत असल्याने अंदाजपत्रकीय मागणीप्रमाणे अनुदान मंजूर होणेंस विनंती आहे. वित्तीय अधिकारी नियम पुस्तिकेतील सुधारीत वित्तीय नियमानुसार वित्तीय मर्यादेत वाढ झाल्याने वाढीव अनुदानाची आवश्यकता आहे.
A13: 7 | B13: 14-भाडेपट्टी व कर | C13: ='Page-4'!C197 -> 5835 | D13: ='Page-4'!D197 -> 3648 | E13: ='Page-4'!E197 -> 2163 | F13: ='Page-4'!F197 -> 14342 | G13: ='Page-4'!G197 -> 14347 | H13: 0 | I13: ='Page-4'!H197 -> 15400 | J13: 0 | K13: 0 | L13: 14-भाडेपट्टी व कर:- विभागीय आयुक्त कोकण विभाग यांचे अधिनस्त काही जिल्हाधिकारी व तहसिल कार्यालये ही भाडे‍ तत्वावर असल्याने तसेच भविष्यातील भाडेवाढ लक्षात घेता अधिनस्त जिल्हाधिकारी कार्यालयाकडील अंदाजपत्रकीय अनुदान मागणीनुसार अनुदान मंजूर होणेंस विनंती आहे.
A14: 8 | B14: 16- प्रकाशने | C14: ='Page-4'!C198 -> 0 | D14: ='Page-4'!D198 -> 0 | E14: ='Page-4'!E198 -> 0 | F14: ='Page-4'!F198 -> 800 | G14: ='Page-4'!G198 -> 800 | H14: 0 | I14: ='Page-4'!H198 -> 300 | J14: ='[1]Page 4'!J190 -> 0 | K14: ='[1]Page 4'!K190 -> 0 | L14: 16- प्रकाशने:- विभागीय आयुक्त कोकण विभाग यांचे अधिनस्त सर्व जिल्हाधिकारी व तहसिल कार्यालयांतील विविध प्रकारच्या छपाईची देयके अदा करण्याकरीता नवीन बाब निर्माण करण्यासाठी टोकन रक्कमेची आवश्यक आहे.
A15: 9 | B15: 17- संगणक खर्च | C15: ='Page-4'!C199 -> 33 | D15: ='Page-4'!D199 -> 44 | E15: ='Page-4'!E199 -> 101 | F15: ='Page-4'!F199 -> 16605 | G15: ='Page-4'!G199 -> 16610 | H15: 0 | I15: ='Page-4'!H199 -> 44540 | J15: 0 | K15: 0 | L15: 17-संगणक खर्च:- E-Office, कार्यालयीन कामकाजातील संगणकाचा वाढता वापर या पार्श्वभूमीवर संगणक खर्च अनुदानात वाढ होणे अत्यावश्यक आहे. संपूर्ण कोकण विभागातील 7 जिल्हयांतील कार्यालयास आवश्यक संगणक खर्चाकरिता वाढीव अनुदान मंजूर होणे आवश्यक आहे.
A16: 10 | B16: 20- इतर प्रशासकीय खर्च | C16: ='Page-4'!C200 -> 0 | D16: ='Page-4'!D200 -> 0 | E16: ='Page-4'!E200 -> 0 | F16: ='Page-4'!F200 -> 680 | G16: ='Page-4'!G200 -> 680 | H16: 0 | I16: ='Page-4'!H200 -> 680 | J16: ='[1]Page 4'!J192 -> 0 | K16: ='[1]Page 4'!K192 -> 0 | L16: 20- इतर प्रशासकीय खर्च:- विभागीय आयुक्त कोकण विभाग यांचे अधिनस्त सर्व जिल्हाधिकारी व तहसिलदार कार्यालयांत आयोजित विविध प्रकारच्या बैठका आयोजित केल्या जातात. त्यावेळी उपस्थितांकरीता चहा, नास्ता इत्यादी मागविण्यात येतो. सदर खर्चाची देयके अदा करण्याकरीता नवीन बाब निर्माण करण्यासाठी जिल्हाधिकारी कार्यालयांचे मागणीनुसार अनुदान मंजूर होणेंस विनंती आहे.
A17: 11 | B17: 24- इंधन खर्च | C17: ='Page-4'!C201 -> 5221 | D17: ='Page-4'!D201 -> 4880 | E17: ='Page-4'!E201 -> 5291 | F17: ='Page-4'!F201 -> 29713 | G17: ='Page-4'!G201 -> 30000 | H17: 0 | I17: ='Page-4'!H201 -> 30350 | J17: 0 | K17: 0 | L17: 24-इंधन खर्च:- (1)लेखाशिर्ष 20530028 अंतर्गत जिल्हा प्रशासन तसेच तहसिलदार यांची एकूण 65 वाहनांची इंधन देयके अदा केली जातात. सबब एकूण 65 वाहनांकरीता 297 लाख एवढे अनुदान आवश्यक आहे. (2)कृपया वाढीव इंधन दराच्या पार्श्वभूमीवर वाढीव अनुदान प्राप्त होणेंस विनंती आहे.
A18: 12 | B18: 26- जाहीरात व प्रसिध्दी खर्च | C18: ='Page-4'!C202 -> 0 | D18: ='Page-4'!D202 -> 1121 | E18: ='Page-4'!E202 -> 564 | F18: ='Page-4'!F202 -> 17195 | G18: ='Page-4'!G202 -> 17195 | H18: 0 | I18: ='Page-4'!H202 -> 17402 | J18: 0 | K18: 0 | L18: 26-जाहीरात व प्रसिध्दी खर्च:- जिल्हाधिकारी कार्यालयांचे आवश्यकतेप्रमाणे अनुदान मंजूर होणेंस विनंती आहे.
A19: 13 | B19: 36- लहान बांधकाम | C19: ='Page-4'!C203 -> 0 | D19: ='Page-4'!D203 -> 0 | E19: ='Page-4'!E203 -> 0 | F19: ='Page-4'!F203 -> 1280 | G19: ='Page-4'!G203 -> 1280 | H19: 0 | I19: ='Page-4'!H203 -> 1280 | J19: 0 | K19: 0 | L19: 36-लहान बांधकाम:-जिल्हाधिकारी कार्यालय मुंबई शहरशी संबंधित प्रस्तावित लहान बांधकामाचे कामकाजाकरीता रु. 12.80 लाखाची अंदाजित तरतूद करण्यात आली आहे.
A20: 14 | B20: 50-इतर खर्च | C20: ='Page-4'!C204 -> 0 | D20: ='Page-4'!D204 -> 0 | E20: ='Page-4'!E204 -> 0 | F20: ='Page-4'!F204 -> 4550 | G20: ='Page-4'!G204 -> 4550 | H20: 0 | I20: ='Page-4'!H204 -> 30250 | J20: 0 | K20: 0 | L20: 50-इतर खर्च:- विभागीय आयुक्त कार्यालयाचे सादर अंदाजपत्रकामध्ये नमूद बाबींव्यतिरिक्त विभागीय आयुक्त यांचे अधिनस्त जिल्हाधिकारी व तहसिलदार कार्यालयांत करण्यात येणा-या खर्चाकरीता नवीन बाब निर्माण करण्यासाठी जिल्हाधिकारी कार्यालयांचे आवश्यकतेप्रमाणे अनुदान मंजूर होणेंस विनंती आहे.
A21: 15 | B21: 51- मोटार वाहने | C21: ='Page-4'!C205 -> 261 | D21: ='Page-4'!D205 -> 109 | E21: ='Page-4'!E205 -> 302 | F21: ='Page-4'!F205 -> 5960 | G21: ='Page-4'!G205 -> 6060 | H21: 0 | I21: ='Page-4'!H205 -> 7870 | J21: 0 | K21: 0 | L21: 51-मोटार वाहने:- जिल्हाधिकारी कार्यालयांचे मागणीनुसार वाहन दुरुस्ती व देखभालकरीता अनुदान मंजूर होणेंस विनंती आहे.
A22: -- | B22: एकूण | C22: =SUM(C7:C21) -> 1136956 | D22: =SUM(D7:D21) -> 1352768 | E22: =SUM(E7:E21) -> 1417431 | F22: =SUM(F7:F21) -> 2766673 | G22: =SUM(G7:G21) -> 2787951 | H22: =SUM(H7:H21) -> 0 | I22: =SUM(I7:I21) -> 3051945 | J22: =SUM(J7:J21) -> 0 | K22: =SUM(K7:K21) -> 0 | L22: --
J27: सहायक संचालक (लेखा) कोकण विभाग

Sheet Distrs.wise Abstract
A1: अर्थसंकल्पीय अंदाजपत्रक सन 2025-2026 (जिल्हानिहाय)
A2: मागणी क्र.सी-1- लेखाशिर्ष : 20530028
A3: (आकडे हजारात)
A4: अ. क्र. | B4: उपलेखाशिर्ष | C4: मुंबई शहर | D4: मुंबई उपनगर | E4: ठाणे | F4: पालघर | G4: रायगड | H4: रत्नागिरी | I4: सिंधुदुर्ग | J4: एकूण
A5: 1 | B5: 01- वेतन | C5: ='Page-4'!H7 -> 221383 | D5: ='Page-4'!H30 -> 292560 | E5: ='Page-4'!H53 -> 311464 | F5: ='Page-4'!H76 -> 487692 | G5: ='Page-4'!H99 -> 612773 | H5: ='Page-4'!H122 -> 490948 | I5: ='Page-4'!H145 -> 268170 | J5: =C5+D5+E5+F5+G5+H5+I5 -> 2684990
A6: 2 | B6: 03- अति.भत्ता | C6: ='Page-4'!H8 -> 400 | D6: ='Page-4'!H31 -> 370 | E6: ='Page-4'!H54 -> 300 | F6: ='Page-4'!H77 -> 800 | G6: ='Page-4'!H100 -> 1800 | H6: ='Page-4'!H123 -> 1270 | I6: ='Page-4'!H146 -> 700 | J6: =C6+D6+E6+F6+G6+H6+I6 -> 5640
A7: 3 | B7: 06- दूरध्वनी, वीज, पाणी व शुल्क | C7: ='Page-4'!H9 -> 12922 | D7: ='Page-4'!H32 -> 7500 | E7: ='Page-4'!H55 -> 12500 | F7: ='Page-4'!H78 -> 10000 | G7: ='Page-4'!H101 -> 15600 | H7: ='Page-4'!H124 -> 10300 | I7: ='Page-4'!H147 -> 7000 | J7: =C7+D7+E7+F7+G7+H7+I7 -> 75822
A8: 4 | B8: 10- कंत्राटी सेवा | C8: ='Page-4'!H10 -> 420 | D8: ='Page-4'!H33 -> 500 | E8: ='Page-4'!H56 -> 1700 | F8: ='Page-4'!H79 -> 450 | G8: ='Page-4'!H102 -> 420 | H8: ='Page-4'!H125 -> 3800 | I8: ='Page-4'!H148 -> 480 | J8: =C8+D8+E8+F8+G8+H8+I8 -> 7770
A9: 5 | B9: 11- देशांतर्गत प्रवास खर्च | C9: ='Page-4'!H11 -> 700 | D9: ='Page-4'!H34 -> 1000 | E9: ='Page-4'!H57 -> 1200 | F9: ='Page-4'!H80 -> 4000 | G9: ='Page-4'!H103 -> 6000 | H9: ='Page-4'!H126 -> 4570 | I9: ='Page-4'!H149 -> 2000 | J9: =C9+D9+E9+F9+G9+H9+I9 -> 19470
A10: 6 | B10: 13- कार्यालयीन खर्च | C10: ='Page-4'!H12 -> 9081 | D10: ='Page-4'!H35 -> 20000 | E10: ='Page-4'!H58 -> 9600 | F10: ='Page-4'!H81 -> 10000 | G10: ='Page-4'!H104 -> 40000 | H10: ='Page-4'!H127 -> 12500 | I10: ='Page-4'!H150 -> 9000 | J10: =C10+D10+E10+F10+G10+H10+I10 -> 110181
A11: 7 | B11: 14- भाडेपट्टी व कर | C11: ='Page-4'!H13 -> 0 | D11: ='Page-4'!H36 -> 0 | E11: ='Page-4'!H59 -> 500 | F11: ='Page-4'!H82 -> 7500 | G11: ='Page-4'!H105 -> 4200 | H11: ='Page-4'!H128 -> 2350 | I11: ='Page-4'!H151 -> 850 | J11: =C11+D11+E11+F11+G11+H11+I11 -> 15400
A12: 8 | B12: 16- प्रकाशने | C12: ='Page-4'!H14 -> 0 | D12: ='Page-4'!H37 -> 0 | E12: ='Page-4'!H60 -> 0 | F12: ='Page-4'!H83 -> 0 | G12: ='Page-4'!H106 -> 0 | H12: ='Page-4'!H129 -> 300 | I12: ='Page-4'!H152 -> 0 | J12: =C12+D12+E12+F12+G12+H12+I12 -> 300
A13: 9 | B13: 17- संगणक खर्च | C13: ='Page-4'!H15 -> 4500 | D13: ='Page-4'!H38 -> 1000 | E13: ='Page-4'!H61 -> 2000 | F13: ='Page-4'!H84 -> 2000 | G13: ='Page-4'!H107 -> 2400 | H13: ='Page-4'!H130 -> 31840 | I13: ='Page-4'!H153 -> 800 | J13: =C13+D13+E13+F13+G13+H13+I13 -> 44540
A14: 10 | B14: 20- इतर प्रशासकीय खर्च | C14: ='Page-4'!H16 -> 680 | D14: ='Page-4'!H39 -> 0 | E14: ='Page-4'!H62 -> 0 | F14: ='Page-4'!H85 -> 0 | G14: ='Page-4'!H108 -> 0 | H14: ='Page-4'!H131 -> 0 | I14: ='Page-4'!H154 -> 0 | J14: =C14+D14+E14+F14+G14+H14+I14 -> 680
A15: 11 | B15: 24- इंधन खर्च | C15: ='Page-4'!H17 -> 3050 | D15: ='Page-4'!H40 -> 1000 | E15: ='Page-4'!H63 -> 1600 | F15: ='Page-4'!H86 -> 5000 | G15: ='Page-4'!H109 -> 14400 | H15: ='Page-4'!H132 -> 3300 | I15: ='Page-4'!H155 -> 2000 | J15: =C15+D15+E15+F15+G15+H15+I15 -> 30350
A16: 12 | B16: 26- जाहीरात व प्रसिध्दी खर्च | C16: ='Page-4'!H18 -> 1080 | D16: ='Page-4'!H41 -> 670 | E16: ='Page-4'!H64 -> 8500 | F16: ='Page-4'!H87 -> 2500 | G16: ='Page-4'!H110 -> 1800 | H16: ='Page-4'!H133 -> 1852 | I16: ='Page-4'!H156 -> 1000 | J16: =C16+D16+E16+F16+G16+H16+I16 -> 17402
... A19: 15 | B19: 51- मोटार वाहने | C19: ='Page-4'!H21 -> 0 | D19: ='Page-4'!H44 -> 0 | E19: ='Page-4'!H67 -> 1900 | F19: ='Page-4'!H90 -> 1000 | G19: ='Page-4'!H113 -> 2160 | H19: ='Page-4'!H136 -> 2810 | I19: ='Page-4'!H159 -> 0 | J19: =C19+D19+E19+F19+G19+H19+I19 -> 7870
A20: एकूण | C20: =C5+C6+C7+C9+C10+C11+C13+C14+C15+C16+C17+C18+C19 -> 255726 | D20: =D5+D6+D7+D9+D10+D11+D13+D14+D15+D16+D17+D18+D19 -> 324100 | E20: =E5+E6+E7+E9+E10+E11+E13+E14+E15+E16+E17+E18+E19 -> 349564 | F20: =F5+F6+F7+F9+F10+F11+F13+F14+F15+F16+F17+F18+F19 -> 530992 | G20: =G5+G6+G7+G9+G10+G11+G13+G14+G15+G16+G17+G18+G19 -> 702033 | H20: =H5+H6+H7+H9+H10+H11+H13+H14+H15+H16+H17+H18+H19 -> 589940 | I20: =I5+I6+I7+I9+I10+I11+I13+I14+I15+I16+I17+I18+I19 -> 291520 | J20: =C20+D20+E20+F20+G20+H20+I20 -> 3043875
J22: 2713607

Sheet Table-D
A2: जोडपत्र "ड"
A5: अर्थसंकल्पीय अंदाजपत्रक सन 2025-2026
A6: मागणी क्र.सी- 1- लेखाशिर्ष 20530028
A8: संवर्गनिहाय माहिती
A10: अ.क्र. | B10: संवर्ग | C10: मंजूर पदे | E10: भरलेली पदे | G10: रिक्त पदे | J10: संवर्ग | K10: मंजूर पदे
C11: स्थायी | D11: अस्थायी | E11: स्थायी | F11: अस्थायी | G11: स्थायी | H11: अस्थायी | K11: स्थायी | L11: अस्थायी
A12: 1 | B12: वर्ग-1 | C12: =E12+G12 -> 70 | D12: =F12+H12 -> 50 | E12: 67 | F12: 44 | G12: 3 | H12: 6 | J12: वर्ग-1 | K12: 59 | L12: 50 | M12: =K12+L12 -> 109 | N12: =C12+D12 -> 120
A13: 2 | B13: वर्ग-2 | C13: =E13+G13 -> 47 | D13: =F13+H13 -> 101 | E13: 44 | F13: 84 | G13: 3 | H13: 17 | J13: वर्ग-2 | K13: 58 | L13: 100 | M13: =K13+L13 -> 158 | N13: =C13+D13 -> 148
A14: 3 | B14: वर्ग-3 | C14: =E14+G14 -> 422 | D14: =F14+H14 -> 854 | E14: 343 | F14: 642 | G14: 79 | H14: 212 | J14: वर्ग-3 | K14: 422 | L14: 840 | M14: =K14+L14 -> 1262 | N14: =C14+D14 -> 1276
A15: 4 | B15: वर्ग-4 | C15: =E15+G15 -> 290 | D15: =F15+H15 -> 254 | E15: 204 | F15: 172 | G15: 86 | H15: 82 | J15: वर्ग-4 | K15: 295 | L15: 276 | M15: =K15+L15 -> 571 | N15: =C15+D15 -> 544
A16: -- | B16: एकूण | C16: =C12+C13+C14+C15 -> 829 | D16: =D12+D13+D14+D15 -> 1259 | E16: =E12+E13+E14+E15 -> 658 | F16: =F12+F13+F14+F15 -> 942 | G16: =G12+G13+G14+G15 -> 171 | H16: =H12+H13+H14+H15 -> 317 | J16: एकूण | K16: =K12+K13+K14+K15 -> 834 | L16: =L12+L13+L14+L15 -> 1266 | M16: =K16+L16 -> 2100 | N16: =N12+N13+N14+N15 -> 2088
E20: सहायक संचालक (लेखा) कोकण विभाग
