Workbook

Sheet 155 217 271 315  2461
A1: अर्थसंकल्पीय अंदाजपत्रक सन 2026-2027
A2: मागणी क्र.सी- 6 2245 नैसर्गिक आपत्तीच्या निवारणासाठी सहाय्य
A3: कोकण विभाग
A4: अ. क्र | B4: लेखाशिर्ष | C4: प्रत्यक्ष रक्कमा (खर्च) | F4: अर्थसंकल्पीय अंदाजपत्रक | G4: सुधारीत अंदाजपत्रक मागणी | H4: अर्थसंकल्पीय अंदाजपत्रक
C5: 2022-2023 | D5: 2023-2024 | E5: 2024-2025 | F5: 2025-2026 | G5: 2025-2026 | H5: 2026-2027
A6: 1 | B6: 2 | C6: 3 | D6: 4 | E6: 5 | F6: 6 | G6: 7 | H6: 8
A7: 1 | B7: 02 पूर चक्रीवादळे इत्यादी, 101 अनुग्रह सहाय्य, (91) राज्य आपत्ती प्रतिसाद निधीच्या मानकानुसार खर्च, (91)(01) रोख भत्ता, मृत व्यक्तींच्या कुटुंबियांना सहाय्य व जखमींना मदत, 31 सहायक अनुदाने (वेतनेत्तर) (22450155)
B8: मुंबई शहर | C8: 400 | D8: 1200 | E8: 0 | F8: 3000 | G8: 3000 | H8: 3000
B9: मुंबई उपनगर | C9: 208 | D9: 7237.3 | E9: 8081.9 | F9: 21000 | G9: 21000 | H9: 21000
B10: ठाणे | C10: 62891.4 | D10: 4048.2 | E10: 3605.4 | F10: 36000 | G10: 36000 | H10: 20000
B11: पालघर | C11: 3347.9 | D11: 29290 | E11: 3610.8 | F11: 149259 | G11: 0 | H11: 149259
B12: रायगड | C12: 1516.85 | D12: 40236.7 | E12: 8875.553 | F12: 5000 | G12: 10000 | H12: 5000
B13: रत्नागिरी | C13: 4022.7 | D13: 810.4 | E13: 2437 | F13: 5000 | G13: 5000 | H13: 5000
B14: सिंधुदुर्ग | C14: 1385 | D14: 810 | E14: 5306.975 | F14: 10000 | G14: 10000 | H14: 10000
B15: एकूण | C15: =SUM(C8:C14) -> 73771.85 | D15: =SUM(D8:D14) -> 83632.6 | E15: =SUM(E8:E14) -> 31917.628 | F15: =SUM(F8:F14) -> 229259 | G15: =SUM(G8:G14) -> 85000 | H15: =SUM(H8:H14) -> 213259
A16: 2 | B16: 02 पुर चक्रीवादळे इ., 101 अनुग्रह सहाय्य (93) इतर (03) पुरामुळे बाधीत झालेल्या व्यक्तींच्या पुनर्वसनाकरीता रस्ते व घरे इत्यादी बांधकामासाठी संपादन केलेल्या/अधिग्रहित केलेल्या जमिनी बद्दल नुकसान भरपाई देणे (अनिवार्य)31, सहायक अनुदाने (वेतनेत्तर) (22450182)
B17: मुंबई शहर | C17: 0 | D17: 0 | E17: 0 | F17: 0 | G17: 0 | H17: 0
B18: मुंबई उपनगर | C18: 0 | D18: 0 | E18: 0 | F18: 0 | G18: 0 | H18: 0
B19: ठाणे | C19: 0 | D19: 0 | E19: 0 | F19: 0 | G19: 0 | H19: 0
B20: पालघर | C20: 0 | D20: 0 | E20: 0 | F20: 0 | G20: 0 | H20: 0
B21: रायगड | C21: 19202.75 | D21: 0 | E21: 0 | F21: 1000 | G21: 1000 | H21: 1000
B22: रत्नागिरी | C22: 0 | D22: 0 | E22: 0 | F22: 0 | G22: 0 | H22: 0
B23: सिंधुदुर्ग | C23: 0 | D23: 0 | E23: 0 | F23: 0 | G23: 0 | H23: 0
B24: एकूण | C24: =SUM(C17:C23) -> 19202.75 | D24: =SUM(D17:D23) -> 0 | E24: =SUM(E17:E23) -> 0 | F24: =SUM(F17:F23) -> 1000 | G24: =SUM(G17:G23) -> 1000 | H24: =SUM(H17:H23) -> 1000
A25: 3 | B25: 02 पुर चक्रीवादळे इ., 101 अनुग्रह सहाय्य (93) इतर (03) पुरामुळे बाधीत झालेल्या व्यक्तींच्या गृहनिर्माणासाठी‍ जमिनीचा विकास करण्यावरील खर्च (अनिवार्य)31, सहायक अनुदाने (वेतनेत्तर) (22450191)
B26: मुंबई शहर | C26: 0 | D26: 0 | E26: 0 | F26: 0 | G26: 0 | H26: 0
B27: मुंबई उपनगर | C27: 0 | D27: 0 | E27: 0 | F27: 0 | G27: 0 | H27: 0
B28: ठाणे | C28: 0 | D28: 0 | E28: 0 | F28: 0 | G28: 0 | H28: 0
B29: पालघर | C29: 0 | D29: 0 | E29: 0 | F29: 0 | G29: 0 | H29: 0
B30: रायगड | C30: 0 | D30: 0 | E30: 0 | F30: 100 | G30: 100 | H30: 100
B31: रत्नागिरी | C31: 0 | D31: 0 | E31: 0 | F31: 0 | G31: 0 | H31: 0
B32: सिंधुदुर्ग | C32: 0 | D32: 0 | E32: 0 | F32: 0 | G32: 0 | H32: 0
B33: एकूण | C33: =SUM(C26:C32) -> 0 | D33: =SUM(D26:D32) -> 0 | E33: =SUM(E26:E32) -> 0 | F33: =SUM(F26:F32) -> 100 | G33: =SUM(G26:G32) -> 100 | H33: =SUM(H26:H32) -> 100
A34: 4 | B34: 02 पूर चक्रीवादळे इत्यादी, 101 अनुग्रह सहाय्य, (91) राज्य आपत्ती प्रतिसाद निधीच्या मानकानुसार खर्च, (91)(02) राहत केंद्रामध्ये निवारा, अन्न, वस्त्र, औषधे इत्यादी चा पुरवठा, 31 सहायक अनुदाने (वेतनेत्तर) (22450217)
B35: मुंबई शहर | C35: 0 | D35: 0 | E35: 0 | F35: 0 | G35: 0 | H35: 0
B36: मुंबई उपनगर | C36: 0 | D36: 0 | E36: 0 | F36: 0 | G36: 0 | H36: 0
B37: ठाणे | C37: 0 | D37: 0 | E37: 0 | F37: 180 | G37: 180 | H37: 190
B38: पालघर | C38: 0 | D38: 0 | E38: 0 | F38: 220 | G38: 0 | H38: 220
B39: रायगड | C39: 9.865 | D39: 2.497 | E39: 0 | F39: 1500 | G39: 5000 | H39: 1500
B40: रत्नागिरी | C40: 49.285 | D40: 39.454 | E40: 0 | F40: 500 | G40: 500 | H40: 500
...

Sheet Div com
A1: अर्थसंकल्पीय अंदाजपत्रक सन 2026-2027
A2: मागणी क्र.सी- 6 2245 नैसर्गिक आपत्तीच्या निवारणासाठी सहाय्य
A3: कोकण विभाग
A4: अ. क्र | B4: लेखाशिर्ष | C4: प्रत्यक्ष रक्कमा (खर्च) | F4: अर्थसंकल्पीय अंदाजपत्रक | G4: सुधारीत अंदाजपत्रक मागणी | H4: अर्थसंकल्पीय अंदाजपत्रक
C5: 2022-2023 | D5: 2023-2024 | E5: 2024-2025 | F5: 2025-2026 | G5: 2025-2026 | H5: 2026-2027
A6: 1 | B6: 2 | C6: 3 | D6: 4 | E6: 5 | F6: 6 | G6: 7 | H6: 8
A7: 1 | B7: ='155 217 271 315 2461'!$B$7 -> 02 पूर चक्रीवादळे इत्यादी, 101 अनुग्रह सहाय्य, (91) राज्य आपत्ती प्रतिसाद निधीच्या मानकानुसार खर्च, (91)(01) रोख भत्ता, मृत व्यक्तींच्या कुटुंबियांना सहाय्य व जखमींना मदत, 31 सहायक अनुदाने (वेतनेत्तर) (22450155) | C7: ='155 217 271 315 2461'!C15 -> 73771.85 | D7: ='155 217 271 315 2461'!D15 -> 83632.6 | E7: ='155 217 271 315 2461'!E15 -> 31917.628 | F7: ='155 217 271 315 2461'!F15 -> 229259 | G7: ='155 217 271 315 2461'!G15 -> 85000 | H7: ='155 217 271 315 2461'!H15 -> 213259
A8: 2 | B8: 02 पुर चक्रीवादळे इ., 101 अनुग्रह सहाय्य (93) इतर (03) पुरामुळे बाधीत झालेल्या व्यक्तींच्या पुनर्वसनाकरीता रस्ते व घरे इत्यादी बांधकामासाठी संपादन केलेल्या/अधिग्रहित केलेल्या जमिनी बद्दल नुकसान भरपाई देणे (अनिवार्य)31, सहायक अनुदाने (वेतनेत्तर) (22450182) | C8: ='155 217 271 315 2461'!C24 -> 19202.75 | D8: ='155 217 271 315 2461'!D24 -> 0 | E8: ='155 217 271 315 2461'!E24 -> 0 | F8: ='155 217 271 315 2461'!F24 -> 1000 | G8: ='155 217 271 315 2461'!G24 -> 1000 | H8: ='155 217 271 315 2461'!H24 -> 1000
A9: 3 | B9: 02 पुर चक्रीवादळे इ., 101 अनुग्रह सहाय्य (93) इतर (03) पुरामुळे बाधीत झालेल्या व्यक्तींच्या गृहनिर्माणासाठी‍ जमिनीचा विकास करण्यावरील खर्च (अनिवार्य)31, सहायक अनुदाने (वेतनेत्तर) (22450191) | C9: ='155 217 271 315 2461'!C33 -> 0 | D9: ='155 217 271 315 2461'!D33 -> 0 | E9: ='155 217 271 315 2461'!E33 -> 0 | F9: ='155 217 271 315 2461'!F33 -> 100 | G9: ='155 217 271 315 2461'!G33 -> 100 | H9: ='155 217 271 315 2461'!H33 -> 100
A10: 4 | B10: ='155 217 271 315 2461'!$B$34 -> 02 पूर चक्रीवादळे इत्यादी, 101 अनुग्रह सहाय्य, (91) राज्य आपत्ती प्रतिसाद निधीच्या मानकानुसार खर्च, (91)(02) राहत केंद्रामध्ये निवारा, अन्न, वस्त्र, औषधे इत्यादी चा पुरवठा, 31 सहायक अनुदाने (वेतनेत्तर) (22450217) | C10: ='155 217 271 315 2461'!C42 -> 59.15 | D10: ='155 217 271 315 2461'!D42 -> 41.951 | E10: ='155 217 271 315 2461'!E42 -> 0 | F10: ='155 217 271 315 2461'!F42 -> 3600 | G10: ='155 217 271 315 2461'!G42 -> 6880 | H10: ='155 217 271 315 2461'!H42 -> 3710
A11: 5 | B11: ='155 217 271 315 2461'!$B$43 -> 02 पूर चक्रीवादळे इत्यादी, 101 अनुग्रह सहाय्य, (91) राज्य आपत्ती प्रतिसाद निधीच्या मानका नुसार खर्च, (91)(04) इतर बाबी 31 सहाय्यक अनुदाने (वेतनेत्तर)(22450244) | C11: ='155 217 271 315 2461'!C51 -> 0.628 | D11: ='155 217 271 315 2461'!D51 -> 0 | E11: ='155 217 271 315 2461'!E51 -> 0 | F11: ='155 217 271 315 2461'!F51 -> 11210 | G11: ='155 217 271 315 2461'!G51 -> 21130 | H11: ='155 217 271 315 2461'!H51 -> 11820
A12: 6 | B12: ='155 217 271 315 2461'!$B$52 -> 02 पूर चक्रीवादळे इत्यादी, 113 घरांची दुरुस्ती/पुनर्बाधंणी यासाठी सहाय्य, (91) राज्य आपत्ती प्रतिसाद निधीच्या मानकानुसार खर्च, (91)(01) घरांची दुरुस्ती/पुर्नबांधणी यासाठी सहाय्य, 31 सहायक अनुदाने (वेतनेत्तर) (22450271) | C12: ='155 217 271 315 2461'!C60 -> 6949.435 | D12: ='155 217 271 315 2461'!D60 -> 26812.04 | E12: ='155 217 271 315 2461'!E60 -> 4596.969 | F12: ='155 217 271 315 2461'!F60 -> 179691 | G12: ='155 217 271 315 2461'!G60 -> 92451 | H12: ='155 217 271 315 2461'!H60 -> 179059
A13: 7 | B13: 02 पूर चक्रीवादळे इत्यादी, 115 जमिनीतील वाळू , चिकणमाती व क्षार काढून टाकण्यासाठी शेतकरी यांना सहाय्य (91) राज्य आपत्ती प्रतिसाद निधीच्या मानकानुसार खर्च, (91)(01) शेतकरी यांना जमिनीतील वाळू , चिकणमाती व क्षार काढून टाकण्यासाठी सहाय्य डोंगराळ भागातील शेतीवरील गाळ काढणे, मत्स्य संवर्धन क्षेत्रातील गाळ काढणे व ती पुर्ववत करुन त्याची दुरुस्ती करणे, 31 सहायक अनुदाने (वेतनेत्तर) 22450291 | C13: ='155 217 271 315 2461'!C69 -> 0 | D13: ='155 217 271 315 2461'!D69 -> 0 | E13: ='155 217 271 315 2461'!E69 -> 0 | F13: ='155 217 271 315 2461'!F69 -> 26748 | G13: ='155 217 271 315 2461'!G69 -> 16605 | H13: ='155 217 271 315 2461'!H69 -> 27748
A14: 8 | B14: ='155 217 271 315 2461'!$B$70 -> 2 पूर चक्रीवादळे इत्यादी, 117 पशुधन खरेदीसाठी शेतक-यांना सहाय्य, (91) राज्य आपत्ती प्रतिसाद निधीच्या मानकानुसार खर्च, (91)(01) मृत जनावरां ऐवजी पशुधन खरेदीसाठी अल्प व अत्यल्प भूधारक शेतक-यांना सहाय्य, 31 सहायक अनुदाने (वेतनेत्तर) (22450315) | C14: ='155 217 271 315 2461'!C78 -> 1705.1 | D14: ='155 217 271 315 2461'!D78 -> 4456.65 | E14: ='155 217 271 315 2461'!E78 -> 2644.7 | F14: ='155 217 271 315 2461'!F78 -> 14397 | G14: ='155 217 271 315 2461'!G78 -> 9820 | H14: ='155 217 271 315 2461'!H78 -> 14417
A15: 9 | B15: ='155 217 271 315 2461'!$B$79 -> 02 पुर चक्रीवादळे इत्यादी, 91 राज्य आपत्ती प्रतिसाद निधीच्या मानकानुसार खर्च, (91) (01) हानी पोहचलेल्या होडया व मासेमारी साधनसामग्री यांची दुरुस्ती / ती नव्याने पुरवणे यासाठी सहाय्य (22450324) | C15: ='155 217 271 315 2461'!C87 -> 191.25 | D15: ='155 217 271 315 2461'!D87 -> 1066 | E15: ='155 217 271 315 2461'!E87 -> 0 | F15: ='155 217 271 315 2461'!F87 -> 14791 | G15: ='155 217 271 315 2461'!G87 -> 15740 | H15: ='155 217 271 315 2461'!H87 -> 14801
A16: 10 | B16: ='155 217 271 315 2461'!$B$88 -> मागणी क्र.सी-6, 2245 नैसर्गिक आपत्तीच्या निवारणासाठी सहाय्य, 02 पुर चक्रीवादळे इ., 119 हानी पोहोचलेली हत्यारे व साधनसामग्री यांची दुरुस्ती/ती नव्याने पुरविणे यासाठी हस्तकला/हातमाग कारागिराना सहाय्य, (91) राज्य आपत्ती प्रतिसाद निधीच्या मानका नुसार खर्च, (91) (01) हानी पोहोचलेली हत्यारे व साधनसामग्री यांची दुरुस्ती/ती नव्याने पुरविणे तसेच कच्चा प्रक्रीयाधीन तयार मालाच्या नुकसानीसाठी कारागिराना सहाय्य, 31 सहायक अनुदाने (वेतनेत्तर) (22450333) | C16: ='155 217 271 315 2461'!C96 -> 0 | D16: ='155 217 271 315 2461'!D96 -> 0 | E16: ='155 217 271 315 2461'!E96 -> 0 | F16: ='155 217 271 315 2461'!F96 -> 0 | G16: ='155 217 271 315 2461'!G96 -> 0 | H16: ='155 217 271 315 2461'!H96 -> 0
A17: 11 | B17: 02 पुर चक्रीवादळे इ., 101 अनुग्रह सहाय्य (93) इतर (03) पुरामुळे बाधीत झालेल्या व्यक्तींच्या पुनर्वसनाकरीता रस्ते, पाणी पुरवठा, शाळा, चावडी, विद्युत पुरवठा इत्यादी नागरी सुविंधावरील खर्च (अनिवार्य)31, सहायक अनुदाने (वेतनेत्तर) (22450988) | C17: ='155 217 271 315 2461'!C105 -> 94610.308 | D17: ='155 217 271 315 2461'!D105 -> 0 | E17: ='155 217 271 315 2461'!E105 -> 0 | F17: ='155 217 271 315 2461'!F105 -> 20000 | G17: ='155 217 271 315 2461'!G105 -> 20000 | H17: ='155 217 271 315 2461'!H105 -> 20000
A18: 12 | B18: 02 पूर चक्रीवादळे इत्यादी, 101 अनुग्रह सहाय्य, (92) राज्य आपत्ती प्रतिसाद निधीच्या मानका व्यतिरीक्त खर्च, (91)(01) रोख भत्ता, मृत व्यक्तींच्या कुटुंबियांना सहाय्य व जखमींना मदत, 31 सहायक अनुदाने (वेतनेत्तर) (22452194) | C18: ='155 217 271 315 2461'!C114 -> 120755 | D18: ='155 217 271 315 2461'!D114 -> 105478.3 | E18: ='155 217 271 315 2461'!E114 -> 8121.745 | F18: ='155 217 271 315 2461'!F114 -> 1283645 | G18: ='155 217 271 315 2461'!G114 -> 96000 | H18: ='155 217 271 315 2461'!H114 -> 1265500
A19: 13 | B19: (02) पूर चक्रीवादळे, इ. 101, अनुग्रह सहाय्य (92) राज्य आपत्ती प्रतिसाद निधीच्या मानका व्यतिरीक्त खर्च (92) (06) राहत केंद्रामध्ये निवारा, अन्न, वस्त्र, औषधे इत्यादींचा पुरवठा (22452247) | C19: ='155 217 271 315 2461'!C123 -> 5973.435 | D19: ='155 217 271 315 2461'!D123 -> 0 | E19: ='155 217 271 315 2461'!E123 -> 0 | F19: ='155 217 271 315 2461'!F123 -> 11320 | G19: ='155 217 271 315 2461'!G123 -> 10000 | H19: ='155 217 271 315 2461'!H123 -> 11430
A20: 14 | B20: 02, पुर चक्रीवादळे इ.101, अनुग्रह सहाय्य (92) राज्य प्रतिसाद निधीच्या मानकानुसार खर्च (92) (12) पीक नुकसानीमुळे शेतक-यांना सहाय्य 31 सहाय्यक अनुदाने (वेतनेत्तर) (22452309) | C20: ='155 217 271 315 2461'!C132 -> 11714.804 | D20: ='155 217 271 315 2461'!D132 -> 0 | E20: ='155 217 271 315 2461'!E132 -> 0 | F20: ='155 217 271 315 2461'!F132 -> 176778 | G20: ='155 217 271 315 2461'!G132 -> 45000 | H20: ='155 217 271 315 2461'!H132 -> 176778
A21: 15 | B21: ='155 217 271 315 2461'!$B$133 -> 02 पुर चक्रीवादळे इ.,113 घरांची दुरुस्ती/पुनर्बांधणी यासाठी सहाय्य, (92) राज्य आपत्ती प्रतिसाद निधीच्या मानका व्यतिरीक्त खर्च, (92) (01) घरांची दुरुस्ती/पुनर्बांधणी यासाठी सहाय्य, 31 सहायक अनुदाने (वेतनेत्तर) (22452327) | C21: ='155 217 271 315 2461'!C141 -> 5280 | D21: ='155 217 271 315 2461'!D141 -> 39338.759 | E21: ='155 217 271 315 2461'!E141 -> 0 | F21: ='155 217 271 315 2461'!F141 -> 221697 | G21: ='155 217 271 315 2461'!G141 -> 50100 | H21: ='155 217 271 315 2461'!H141 -> 221741
A22: 16 | B22: 02 पूर चक्रीवादळे इत्यादी, 117 पशुधन खरेदीसाठी शेतकरी यांना सहाय्य, (92) राज्य आपत्ती प्रतिसाद निधीच्या मानका व्यतिरीक्त खर्च, (92)(01) मृत जनावरांऐवजी पशुधन खरेदीसाठी अल्प व अत्यल्प भूधारक शेतकरी यांना सहाय्य, 31 सहायक अनुदाने (22452363) | C22: ='155 217 271 315 2461'!C150 -> 0 | D22: ='155 217 271 315 2461'!D150 -> 0 | E22: ='155 217 271 315 2461'!E150 -> 0 | F22: ='155 217 271 315 2461'!F150 -> 0 | G22: ='155 217 271 315 2461'!G150 -> 0 | H22: ='155 217 271 315 2461'!H150 -> 20017
A23: 17 | B23: 02, पूर चक्रीवादळे इ., 118 हानी पोहोचलेल्या होडया व मासेमारी साधनसामग्री यांची दुरुस्ती / ती नव्याने पुरविणे यासाठी सहाय्य (92) राज्य आपत्ती प्रतिसाद निधीच्या मानकाव्यतिरिक्त खर्च (92) (01) हानी पोहोचलेल्या होडया व मासेमारी साधनसामग्री यांची दुरुस्ती / ती नव्याने पुरविणे तसेच मासे बियाणे यासाठी सहाय्य, 31 सहायक अनुदाने (वेतनेत्तर) (22452372) | C23: ='155 217 271 315 2461'!C159 -> 151.2 | D23: ='155 217 271 315 2461'!D159 -> 0 | E23: ='155 217 271 315 2461'!E159 -> 0 | F23: ='155 217 271 315 2461'!F159 -> 27902 | G23: ='155 217 271 315 2461'!G159 -> 26706 | H23: ='155 217 271 315 2461'!H159 -> 26457
A24: 18 | B24: ='155 217 271 315 2461'!$B$160 -> 02 पुर चक्रीवादळे इ., 119 हानी पोहोचलेली हत्यारे व साधनसामग्री यांची दुरुस्ती/ती नव्याने पुरविणे यासाठी हस्तकला/हातमाग कारागिराना सहाय्य, (91) राज्य आपत्ती प्रतिसाद निधीच्या मानका व्यतिरिक्त खर्च, (91) (01) हानी पोहोचलेली हत्यारे व साधनसामग्री यांची दुरुस्ती/ती नव्याने पुरविणे तसेच कच्चा प्रक्रीयाधीन तयार मालाच्या नुकसानीसाठी कारागिराना सहाय्य, 31 सहायक अनुदाने (वेतनेत्तर) (22452381) | C24: ='155 217 271 315 2461'!C168 -> 6986.625 | D24: ='155 217 271 315 2461'!D168 -> 28831.087 | E24: ='155 217 271 315 2461'!E168 -> 13805.65 | F24: ='155 217 271 315 2461'!F168 -> 50000 | G24: ='155 217 271 315 2461'!G168 -> 50000 | H24: ='155 217 271 315 2461'!H168 -> 75600
A25: 19 | B25: 02 पूर चक्रीवादळे इत्यादी, 800 इतर खर्च, (92) राज्य आपत्ती प्रतिसाद निधीच्या मानकाव्यतिरीक्त खर्च (92)(01) इतर खर्च 31 सहाय्यक अनुदाने (वेतनत्तेर) (22452407) दत्तमत | C25: ='155 217 271 315 2461'!C178 -> 0 | D25: ='155 217 271 315 2461'!D178 -> 0 | E25: ='155 217 271 315 2461'!E178 -> 0 | F25: ='155 217 271 315 2461'!F178 -> 62 | G25: ='155 217 271 315 2461'!G178 -> 0 | H25: ='155 217 271 315 2461'!H178 -> 62
A26: 20 | B26: 01 अवर्षण, (91)राज्य आपत्ती प्रतिसाद निधीच्या मानकांनुसार खर्च (91)(05) पीक नुकसानीमुळे शेतक-यांना मदत (22452434), 31 सहाय्यक अनुदाने | C26: ='155 217 271 315 2461'!C187 -> 0 | D26: ='155 217 271 315 2461'!D187 -> 0 | E26: ='155 217 271 315 2461'!E187 -> 0 | F26: ='155 217 271 315 2461'!F187 -> 330000 | G26: ='155 217 271 315 2461'!G187 -> 0 | H26: ='155 217 271 315 2461'!H187 -> 330000
A27: 21 | B27: ='155 217 271 315 2461'!$B$188 -> 02 पूर चक्रीवादळे इत्यादी, 101 अनुग्रह सहाय्य, (91) राज्य आपत्ती प्रतिसाद निधीच्या मानका नुसार खर्च, (91)(05) पिक नुकसानीमुळे शेतक-यांना मदत, 31 सहाय्य अनुदाने (वेतनेत्तर) (22452452) | C27: ='155 217 271 315 2461'!C196 -> 34737.214 | D27: ='155 217 271 315 2461'!D196 -> 0 | E27: ='155 217 271 315 2461'!E196 -> 0 | F27: ='155 217 271 315 2461'!F196 -> 200305 | G27: ='155 217 271 315 2461'!G196 -> 100000 | H27: ='155 217 271 315 2461'!H196 -> 200305
A28: 22 | B28: 02 पूर चक्रीवादळे इत्यादी, 101 अनुग्रह सहाय्य, (91) राज्य आपत्ती प्रतिसाद निधीच्या मानका नुसार खर्च, (91)(06) नैसर्गिक आपत्तीमुळे अनुज्ञेय विभागातील आपत्ती्‌ग्रस्त पायाभूत सुविधांच्या तातडीच्या स्वरुपाच्या दुरुस्ती / पुर्नस्थापनेसाठी खर्च,31सहायक अनुदाने(वेतनेत्तर)(22452461) | C28: ='155 217 271 315 2461'!C205 -> 118709 | D28: ='155 217 271 315 2461'!D205 -> 0 | E28: ='155 217 271 315 2461'!E205 -> 0 | F28: ='155 217 271 315 2461'!F205 -> 65255 | G28: ='155 217 271 315 2461'!G205 -> 65000 | H28: ='155 217 271 315 2461'!H205 -> 67255
A29: 23 | B29: 06 भूकंप, 101 अनग्रह सहाय्य, (91) राज्य आपत्ती प्रतिसाद निधीच्या मानकानुसार खर्च (91) (01) भूकंपग्रस्तांसाठी सहाय्य, 31 सहाय्यक अनुदाने (वेतनेत्तर) (22452472) | C29: ='155 217 271 315 2461'!C214 -> 0 | D29: ='155 217 271 315 2461'!D214 -> 0 | E29: ='155 217 271 315 2461'!E214 -> 0 | F29: ='155 217 271 315 2461'!F214 -> 32260 | G29: ='155 217 271 315 2461'!G214 -> 5000 | H29: ='155 217 271 315 2461'!H214 -> 32260
A30: 24 | B30: ='155 217 271 315 2461'!$B$215 -> 80 सर्वसाधारण, 800 इतर खर्च (91) राज्य आपत्ती प्रतिसाद निधीच्या मानकांनुसार खर्च (91)(01) शोध, बचाव कार्य, व लोकांना सुरक्षित स्थळी हलविण्यासाठी आपत्तीच्या प्रतिसादासाठी (संपर्कसाधनासह) खरेदी करावयाची साधनसामुग्री (आपत्ती प्रतिसाद निधीच्या 5 टक्के मर्यादेपर्यंत) 22452499 अंतर्गत, 31 सहाय्यक अनुदाने (वेतनेत्तर) | C30: ='155 217 271 315 2461'!C223 -> 13959.679 | D30: ='155 217 271 315 2461'!D223 -> 3350 | E30: ='155 217 271 315 2461'!E223 -> 0 | F30: ='155 217 271 315 2461'!F223 -> 11220 | G30: ='155 217 271 315 2461'!G223 -> 5500 | H30: ='155 217 271 315 2461'!H223 -> 11270
A31: 25 | B31: मागणी क्र.सी-6,नैसर्गिक आपत्तीच्या निवारणासाठी सहाय्य, 80 सर्व साधारण 102 आपत्तीप्रवण क्षेत्रामध्ये नैसर्गिक आपत्कालीन परिस्थितीबाबतच्या तातडीच्या योजनांचे व्यवस्थापन करणे (06) चक्रीवादळ रोधक बांधकाम करणे (06) (01) चक्रीवादळ रोधक बांधकाम करणे (75 टक्के केंद्र हिस्सा) (कार्यक्रम) (22452603) 31 सहाय्यक अनुदाने (वेतनेत्तर) | C31: =SUM('155 217 271 315 2461'!C232) -> 0 | D31: =SUM('155 217 271 315 2461'!D232) -> 0 | E31: =SUM('155 217 271 315 2461'!E232) -> 0 | F31: =SUM('155 217 271 315 2461'!F232) -> 0 | G31: =SUM('155 217 271 315 2461'!G232) -> 0 | H31: =SUM('155 217 271 315 2461'!H232) -> 0
A32: 26 | B32: 02 पूर चक्रीवादळे इत्यादी, 101 अनुग्रह सहाय्य, (91) राज्य आपत्ती प्रतिसाद निधीच्या मानका नुसार खर्च, (91)(04) इतर बाबी 31 सहाय्यक अनुदाने (वेतनेत्तर) (22454141) COVID-19 | C32: ='155 217 271 315 2461'!C243 -> 1076981.6 | D32: ='155 217 271 315 2461'!D243 -> 1025098.9 | E32: =SUM('155 217 271 315 2461'!E233) -> 0 | F32: ='155 217 271 315 2461'!F243 -> 525000 | G32: ='155 217 271 315 2461'!G243 -> 525000 | H32: ='155 217 271 315 2461'!H243 -> 275000
A33: 27 | B33: (91) (01) पूर्व तयारी व क्षमता बांधणी (वित्त आयोग) (अनिवार्य) (2245 4188) 31 सहायक अनुदाने | C33: =SUM('155 217 271 315 2461'!C253) -> 0 | D33: =SUM('155 217 271 315 2461'!D253) -> 3969.548 | E33: =SUM('155 217 271 315 2461'!E253) -> 1218.857 | F33: =SUM('155 217 271 315 2461'!F253) -> 18300 | G33: =SUM('155 217 271 315 2461'!G253) -> 36500 | H33: =SUM('155 217 271 315 2461'!H253) -> 25000
A34: 28 | B34: ='155 217 271 315 2461'!$B$254 -> 80 सर्वसाधारण-पंचवार्षिक योजनांतर्गत योजना राज्य योजनांतर्गत योजना-001 संचालन व प्रशासन (01) महाराष्ट्र राज्य आपत्ती व्यवस्थापन प्राधिकरणाचे कार्यालय स्थापन करणे व फर्निचर,साधनसामुग्रीसह सुसज्जीकरण करणे 22451761-10 - कंत्राटीसेवा | C34: ='155 217 271 315 2461'!C263 -> 3663.973 | D34: ='155 217 271 315 2461'!D263 -> 3411.644 | E34: ='155 217 271 315 2461'!E263 -> 3012.966 | F34: ='155 217 271 315 2461'!F263 -> 4154 | G34: ='155 217 271 315 2461'!G263 -> 5940 | H34: ='155 217 271 315 2461'!H263 -> 5940
A35: 29 | B35: ='155 217 271 315 2461'!$B$264 -> 80 सर्व साधारण (01) (01) महाराष्ट्र राज्य आपत्ती व्यवस्थापन प्राधिकरणाचे कार्यालय स्थापन करणे व फर्निचर व साधन सामुग्रीसह सुसज्जीकरण करणे (2245 1761) 11-देशांतर्गत प्रवास खर्च | C35: ='155 217 271 315 2461'!C273 -> 0 | D35: ='155 217 271 315 2461'!D273 -> 0 | E35: ='155 217 271 315 2461'!E273 -> 0 | F35: ='155 217 271 315 2461'!F273 -> 150 | G35: ='155 217 271 315 2461'!G273 -> 100 | H35: ='155 217 271 315 2461'!H273 -> 100
A36: 30 | B36: ='155 217 271 315 2461'!$B$274 -> 80 सर्व साधारण (01) (01) महाराष्ट्र राज्य आपत्ती व्यवस्थापन प्राधिकरणाचे कार्यालय स्थापन करणे व फर्निचर व साधन सामुग्रीसह सुसज्जीकरण करणे (2245 1761) 21-पुरवठा व सामुग्री | C36: ='155 217 271 315 2461'!C283 -> 0 | D36: ='155 217 271 315 2461'!D283 -> 0 | E36: ='155 217 271 315 2461'!E283 -> 0 | F36: ='155 217 271 315 2461'!F283 -> 21500 | G36: ='155 217 271 315 2461'!G283 -> 20000 | H36: ='155 217 271 315 2461'!H283 -> 20000
A37: 31 | B37: ='155 217 271 315 2461'!$B$284 -> 80 सर्व साधारण (01) (01) महाराष्ट्र राज्य आपत्ती व्यवस्थापन प्राधिकरणाचे कार्यालय स्थापन करणे व फर्निचर व साधन सामुग्रीसह सुसज्जीकरण करणे (2245 1761) 27-लहान बांधकामे | C37: ='155 217 271 315 2461'!C293 -> 0 | D37: ='155 217 271 315 2461'!D293 -> 0 | E37: ='155 217 271 315 2461'!E293 -> 0 | F37: ='155 217 271 315 2461'!F293 -> 2500 | G37: ='155 217 271 315 2461'!G293 -> 2500 | H37: ='155 217 271 315 2461'!H293 -> 2500
A38: 32 | B38: 80 सर्वसाधारण-पंचवार्षिक योजनांतर्गत योजना-राज्य योजनांतर्गत योजना-001 संचालन व प्रशासन-(01) महाराष्ट्र राज्य आपत्ती व्यवस्थापन प्राधिकरणाचे कार्यालय स्थापन करणे व फर्निचर,साधनसामुग्रीसह सुसज्जीकरण करणे 22451761-31, सहायक अनुदाने | C38: ='155 217 271 315 2461'!C303 -> 88694.524 | D38: ='155 217 271 315 2461'!D303 -> 114100 | E38: ='155 217 271 315 2461'!E303 -> 0 | F38: ='155 217 271 315 2461'!F303 -> 10800 | G38: ='155 217 271 315 2461'!G303 -> 7500 | H38: ='155 217 271 315 2461'!H303 -> 12000
A39: 33 | B39: ='155 217 271 315 2461'!$B$304 -> 80 सर्व साधारण (01) (01) महाराष्ट्र राज्य आपत्ती व्यवस्थापन प्राधिकरणाचे कार्यालय स्थापन करणे व फर्निचर व साधन सामुग्रीसह सुसज्जीकरण करणे (2245 1761) 52-यंत्र सामुग्री | C39: ='155 217 271 315 2461'!C313 -> 0 | D39: ='155 217 271 315 2461'!D313 -> 0 | E39: ='155 217 271 315 2461'!E313 -> 0 | F39: ='155 217 271 315 2461'!F313 -> 6000 | G39: ='155 217 271 315 2461'!G313 -> 3000 | H39: ='155 217 271 315 2461'!H313 -> 5000
B40: एकूण | C40: =SUM(C7:C39) -> 1684097.5 | D40: =SUM(D7:D39) -> 1439587.5 | E40: =SUM(E7:E39) -> 65318.515 | F40: =SUM(F7:F39) -> 3499644 | G40: =SUM(G7:G39) -> 1322572 | H40: =SUM(H7:H39) -> 3270129
...

Sheet 22450093 22452185
A1: ='155 217 271 315 2461'!A1 -> अर्थसंकल्पीय अंदाजपत्रक सन 2026-2027
A2: मागणी क्र.सी- 6, 2245 आणि मागणी क्र.वाय-2, 2215 अंतर्गत पाणी टंचाई निवारणासाठी सहाय्य
A3: कोकण विभाग
H4: (आकडे लाखात)
A5: ='155 217 271 315 2461'!A4 -> अ. क्र | B5: ='155 217 271 315 2461'!B4 -> लेखाशिर्ष | C5: जिल्हा कार्यालय | D5: प्रत्यक्ष रक्कमा (खर्च) | G5: अर्थसंकल्पीय अंदाजपत्रक | H5: सुधारीत अंदाजपत्रक मागणी | I5: अर्थसंकल्पीय अंदाजपत्रक
D6: 2022-2023 | E6: 2023-2024 | F6: 2024-2025 | G6: 2025-2026 | H6: 2025-2026 | I6: 2026-2027
A7: ='155 217 271 315 2461'!A6 -> 1 | B7: ='155 217 271 315 2461'!B6 -> 2 | D7: 3 | E7: 4 | F7: 5 | G7: 6 | H7: 7 | I7: 8
A8: 1 | B8: 2245-नैसर्गिक आपत्तीच्या निवारणासाठी सहाय्य-01-अवर्षण-102-पिण्याच्या पाण्याचा पुरवठा, (91)(01)पिण्याच्या पाण्याचा आकस्मिक निकडीचा पुरवठा 31 सहाय्यक अनुदाने (वेतनेत्तर)(22450093 ) | C8: जिल्हाधिकारी ठाणे | D8: 0 | E8: 0 | F8: 0 | G8: 0 | H8: 0 | I8: 0
C9: मुख्य कार्यकारी अधिकारी, जिल्हा परिषद ठाणे | D9: 31 | E9: 0 | F9: 0 | G9: 0 | H9: 0 | I9: 0
C10: जिल्हा- ठाणे | D10: =SUM(D8:D9) -> 31 | E10: =SUM(E8:E9) -> 0 | F10: =SUM(F8:F9) -> 0 | G10: =SUM(G8:G9) -> 0 | H10: =SUM(H8:H9) -> 0 | I10: =SUM(I8:I9) -> 0
C11: जिल्हाधिकारी पालघर | D11: 0 | E11: 0 | F11: 0 | G11: 0 | H11: 0 | I11: 0
C12: मुख्य कार्यकारी अधिकारी, जिल्हा परिषद पालघर | D12: 364.57 | E12: 0 | F12: 0 | G12: 0 | H12: 0 | I12: 0
C13: जिल्हा पालघर | D13: =SUM(D11:D12) -> 364.57 | E13: =SUM(E11:E12) -> 0 | F13: =SUM(F11:F12) -> 0 | G13: =SUM(G11:G12) -> 0 | H13: =SUM(H11:H12) -> 0 | I13: =SUM(I11:I12) -> 0
C14: रायगड | D14: 0 | E14: 0 | F14: 0 | G14: 0 | H14: 0 | I14: 0
C15: मुख्य कार्यकारी अधिकारी, जिल्हा परिषद रायगड | D15: 420.14 | E15: 0 | F15: 0 | G15: 0 | H15: 0 | I15: 0
C16: जिल्हा रायगड | D16: =SUM(D14:D15) -> 420.14 | E16: =SUM(E14:E15) -> 0 | F16: =SUM(F14:F15) -> 0 | G16: =SUM(G14:G15) -> 0 | H16: =SUM(H14:H15) -> 0 | I16: =SUM(I14:I15) -> 0
C17: जिल्हाधिकारी रत्नागिरी | D17: 0 | E17: 0 | F17: 0 | G17: 0 | H17: 0 | I17: 0
C18: मुख्य कार्यकारी अधिकारी, जिल्हा परिषद रत्नागिरी | D18: 100 | E18: 0 | F18: 0 | G18: 500 | H18: 0 | I18: 0
C19: जिल्हा रत्नागिरी | D19: =SUM(D17:D18) -> 100 | E19: =SUM(E17:E18) -> 0 | F19: =SUM(F17:F18) -> 0 | G19: =SUM(G17:G18) -> 500 | H19: =SUM(H17:H18) -> 0 | I19: =SUM(I17:I18) -> 0
C20: जिल्हाधिकारी सिंधुदुर्ग | D20: 0 | E20: 0 | F20: 0 | G20: 0 | H20: 0 | I20: 0
C21: मुख्य कार्यकारी अधिकारी, जिल्हा परिषद सिंधुदुर्ग | D21: 65.03 | E21: 0 | F21: 0 | G21: 0 | H21: 0 | I21: 0
C22: जिल्हा सिंधुदुर्ग | D22: =SUM(D20:D21) -> 65.03 | E22: =SUM(E20:E21) -> 0 | F22: =SUM(F20:F21) -> 0 | G22: =SUM(G20:G21) -> 0 | H22: =SUM(H20:H21) -> 0 | I22: =SUM(I20:I21) -> 0
B23: कोंकण विभाग | C23: एकूण-कोकण विभाग | D23: =SUM(D22,D19,D16,D13,D10) -> 980.74 | E23: =SUM(E22,E19,E16,E13,E10) -> 0 | F23: =SUM(F22,F19,F16,F13,F10) -> 0 | G23: =SUM(G22,G19,G16,G13,G10) -> 500 | H23: =SUM(H22,H19,H16,H13,H10) -> 0 | I23: =SUM(I22,I19,I16,I13,I10) -> 0
A25: 2 | B25: 2245-नैसर्गिक आपत्तीच्या निवारणा साठी सहाय्य-01- अवर्षण- 102-पिण्याच्या पाण्याचा पुरवठा, (92))(01) पिण्याच्या पाण्याचा आकस्मिक निकडीचा पुरवठा 31 सहाय्यक अनुदाने (वेतनेत्तर) (22452185 ) | C25: जिल्हाधिकारी ठाणे | D25: 0 | E25: 0 | F25: 0 | G25: 0 | H25: 0 | I25: 0
C26: मुख्य कार्यकारी अधिकारी, जिल्हा परिषद ठाणे | D26: 1450.87 | E26: 0 | F26: 0 | G26: 0 | H26: 0 | I26: 0
C27: जिल्हा- ठाणे | D27: =SUM(D25:D26) -> 1450.87 | E27: =SUM(E25:E26) -> 0 | F27: =SUM(F25:F26) -> 0 | G27: =SUM(G25:G26) -> 0 | H27: =SUM(H25:H26) -> 0 | I27: =SUM(I25:I26) -> 0
C28: जिल्हाधिकारी पालघर | D28: 0 | E28: 0 | F28: 0 | G28: 0 | H28: 0 | I28: 0
C29: मुख्य कार्यकारी अधिकारी, जिल्हा परिषद पालघर | D29: 418.2 | E29: 0 | F29: 0 | G29: 0 | H29: 0 | I29: 0
C30: जिल्हा पालघर | D30: =SUM(D28:D29) -> 418.2 | E30: =SUM(E28:E29) -> 0 | F30: =SUM(F28:F29) -> 0 | G30: =SUM(G28:G29) -> 0 | H30: =SUM(H28:H29) -> 0 | I30: =SUM(I28:I29) -> 0
C31: रायगड | D31: 0 | E31: 0 | F31: 0 | G31: 0 | H31: 0 | I31: 0
C32: मुख्य कार्यकारी अधिकारी, जिल्हा परिषद रायगड | D32: 295 | E32: 0 | F32: 0 | G32: 0 | H32: 0 | I32: 0
C33: जिल्हा रायगड | D33: =SUM(D31:D32) -> 295 | E33: =SUM(E31:E32) -> 0 | F33: =SUM(F31:F32) -> 0 | G33: =SUM(G31:G32) -> 0 | H33: =SUM(H31:H32) -> 0 | I33: =SUM(I31:I32) -> 0
C34: जिल्हाधिकारी रत्नागिरी | D34: 0 | E34: 0 | F34: 0 | G34: 0 | H34: 0 | I34: 0
C35: मुख्य कार्यकारी अधिकारी, जिल्हा परिषद रत्नागिरी | D35: 830.49 | E35: 0 | F35: 0 | G35: 0 | H35: 0 | I35: 0
C36: जिल्हा रत्नागिरी | D36: =SUM(D34:D35) -> 830.49 | E36: =SUM(E34:E35) -> 0 | F36: =SUM(F34:F35) -> 0 | G36: =SUM(G34:G35) -> 0 | H36: =SUM(H34:H35) -> 0 | I36: =SUM(I34:I35) -> 0
C37: जिल्हाधिकारी सिंधुदुर्ग | D37: 0 | E37: 0 | F37: 0 | G37: 0 | H37: 0 | I37: 0
C38: मुख्य कार्यकारी अधिकारी, जिल्हा परिषद सिंधुदुर्ग | D38: 627.91 | E38: 0 | F38: 0 | G38: 0 | H38: 0 | I38: 0
C39: जिल्हा सिंधुदुर्ग | D39: =SUM(D37:D38) -> 627.91 | E39: =SUM(E37:E38) -> 0 | F39: =SUM(F37:F38) -> 0 | G39: =SUM(G37:G38) -> 0 | H39: =SUM(H37:H38) -> 0 | I39: =SUM(I37:I38) -> 0
B40: कोंकण विभाग | C40: एकूण-कोकण विभाग | D40: =SUM(D39,D36,D33,D30,D27) -> 3622.47 | E40: =SUM(E39,E36,E33,E30,E27) -> 0 | F40: =SUM(F39,F36,F33,F30,F27) -> 0 | G40: =SUM(G39,G36,G33,G30,G27) -> 0 | H40: =SUM(H39,H36,H33,H30,H27) -> 0 | I40: =SUM(I39,I36,I33,I30,I27) -> 0
H42: (दिपक काटे)
...

Sheet 2215A195 2215A201
A1: ='155 217 271 315 2461'!A1 -> अर्थसंकल्पीय अंदाजपत्रक सन 2026-2027
A2: मागणी क्र.वाय-2, 2215 अंतर्गत पाणी टंचाई निवारणासाठी सहाय्य
A3: कोकण विभाग
H4: (आकडे लाखात)
A5: ='155 217 271 315 2461'!A4 -> अ. क्र | B5: ='155 217 271 315 2461'!B4 -> लेखाशिर्ष | C5: जिल्हा कार्यालय | D5: प्रत्यक्ष रक्कमा (खर्च) | G5: अर्थसंकल्पीय अंदाजपत्रक | H5: सुधारीत अंदाजपत्रक मागणी | I5: अर्थसंकल्पीय अंदाजपत्रक | J5: तरतूद अधिक (+) कमी(-)
D6: 2022-2023 | E6: 2023-2024 | F6: 2024-2025 | G6: 2025-2026 | H6: 2025-2026 | I6: 2026-2027
A7: ='155 217 271 315 2461'!A6 -> 1 | B7: ='155 217 271 315 2461'!B6 -> 2 | D7: 3 | E7: 4 | F7: 5 | G7: 6 | H7: 7 | I7: 8
A8: 3 | B8: मागणी क्र.वाय-2, मुख्यलेखाशीर्ष 2215 पाणी पुरवठा व स्वच्छता, 01, पाणी पुरवठा, 196 जिल्हा परिषद पंचायत / संस्थाना सहाय्य, 02 जिल्हा परिषदांना अनुदान, (02) (03) आकस्मिक पिण्याच्या पाण्याच्या टंचाई निवारणार्थ घेण्यात येणा-या तात्पुरत्या उपाय योजनांसाठी जिल्हा परिषदांना सहाय्यक अनुदान (अनिवार्य), 31, सहाय्यक अनुदाने (वेतनेत्तर) (2215 ए 195) | C8: मुख्य कार्यकारी अधिकारी, जिल्हा परिषद ठाणे | D8: 1641.58 | E8: 459 | F8: 667.59 | G8: 1000 | H8: 800 | I8: 1500 | J8: =SUM(I8-H8) -> 700
C9: मुख्य कार्यकारी अधिकारी, जिल्हा परिषद पालघर | D9: 938.25 | E9: 639.63 | F9: 0 | G9: 115.214 | H9: 126.735 | I9: 139.408 | J9: =SUM(I9-H9) -> 12.673
C10: मुख्य कार्यकारी अधिकारी, जिल्हा परिषद रायगड | D10: 200 | E10: 500 | F10: 495 | G10: 500 | H10: 300 | I10: 500 | J10: =SUM(I10-H10) -> 200
C11: मुख्य कार्यकारी अधिकारी, जिल्हा परिषद रत्नागिरी | D11: 150.4 | E11: 0 | F11: 0 | G11: 500 | H11: 500 | I11: 400 | J11: =SUM(I11-H11) -> -100
C12: मुख्य कार्यकारी अधिकारी, जिल्हा परिषद सिंधुदुर्ग | D12: 0 | E12: 330.78 | F12: 0 | G12: 0 | H12: 0 | I12: 0 | J12: =SUM(I12-H12) -> 0
B13: कोंकण विभाग | C13: एकूण-कोकण विभाग | D13: =SUM(D8:D12) -> 2930.23 | E13: =SUM(E8:E12) -> 1929.41 | F13: =SUM(F8:F12) -> 1162.59 | G13: =SUM(G8:G12) -> 2115.214 | H13: =SUM(H8:H12) -> 1726.735 | I13: =SUM(I8:I12) -> 2539.408 | J13: =SUM(J8:J12) -> 812.673
B15: 2215A201 (शहरी भागासाठी) पाणी टंचाई | C15: जिल्हाधिकारी ठाणे | D15: 0 | E15: 0 | F15: 0 | G15: 0 | H15: 0 | I15: 0 | J15: =SUM(I15-H15) -> 0
C16: जिल्हाधिकारी पालघर | D16: 0 | E16: 76.59 | F16: 0 | G16: 7 | H16: 8.5 | I16: 8.5 | J16: =SUM(I16-H16) -> 0
C17: जिल्हाधिकारी रायगड | D17: 0 | E17: 0 | F17: 0 | G17: 0 | H17: 0 | I17: 0 | J17: =SUM(I17-H17) -> 0
C18: जिल्हाधिकारी रत्नागिरी | D18: 0 | E18: 0 | F18: 0 | G18: 0 | H18: 0 | I18: 0 | J18: =SUM(I18-H18) -> 0
C19: जिल्हाधिकारी सिंधुदुर्ग | D19: 0 | E19: 0 | F19: 0 | G19: 0 | H19: 0 | I19: 0 | J19: =SUM(I19-H19) -> 0
B20: कोंकण विभाग | C20: एकूण-कोकण विभाग | D20: =SUM(D15:D19) -> 0 | E20: =SUM(E15:E19) -> 76.59 | F20: =SUM(F15:F19) -> 0 | G20: =SUM(G15:G19) -> 7 | H20: =SUM(H15:H19) -> 8.5 | I20: =SUM(I15:I19) -> 8.5 | J20: =SUM(J15:J19) -> 0
H24: (दिपक काटे) | J24: (व्हि.एम.गाडे)
H25: सहाय्यक संचालक(लेखा) | J25: सहाय्यक संचालक(लेखा)
H26: कोकण विभाग | J26: कोकण विभाग

Sheet Div Com WS
A1: ='155 217 271 315 2461'!A1 -> अर्थसंकल्पीय अंदाजपत्रक सन 2026-2027
A2: मागणी क्र.सी- 6, 2245 आणि मागणी क्र.वाय-2, 2215 अंतर्गत पाणी टंचाई निवारणासाठी सहाय्य
A3: कोकण विभाग
A4: ='155 217 271 315 2461'!A4 -> अ. क्र | B4: ='155 217 271 315 2461'!B4 -> लेखाशिर्ष | C4: कार्यालय / विभाग | D4: प्रत्यक्ष रक्कमा (खर्च) | G4: अर्थसंकल्पीय अंदाजपत्रक | H4: सुधारीत अंदाजपत्रक मागणी | I4: अर्थसंकल्पीय अंदाजपत्रक
D5: 2022-2023 | E5: 2023-2024 | F5: 2024-2025 | G5: 2025-2026 | H5: 2025-2026 | I5: 2026-2027
A6: ='155 217 271 315 2461'!A6 -> 1 | B6: ='155 217 271 315 2461'!B6 -> 2 | D6: 3 | E6: 4 | F6: 5 | G6: 6 | H6: 7 | I6: 8
A7: 1 | B7: 22450093 | C7: कोकण विभाग | D7: ='22450093 22452185'!D23 -> 980.74 | E7: ='22450093 22452185'!E23 -> 0 | F7: ='22450093 22452185'!F23 -> 0 | G7: ='22450093 22452185'!G23 -> 500 | H7: ='22450093 22452185'!H23 -> 0 | I7: ='22450093 22452185'!I23 -> 0
A8: 2 | B8: 22452185 | C8: कोकण विभाग | D8: ='22450093 22452185'!D40 -> 3622.47 | E8: ='22450093 22452185'!E40 -> 0 | F8: ='22450093 22452185'!F40 -> 0 | G8: ='22450093 22452185'!G40 -> 0 | H8: ='22450093 22452185'!H40 -> 0 | I8: ='22450093 22452185'!I40 -> 0
A9: 3 | B9: 2215A195 | C9: कोकण विभाग | D9: =SUM('2215A195 2215A201'!D13) -> 2930.23 | E9: =SUM('2215A195 2215A201'!E13) -> 1929.41 | F9: =SUM('2215A195 2215A201'!F13) -> 1162.59 | G9: =SUM('2215A195 2215A201'!G13) -> 2115.214 | H9: =SUM('2215A195 2215A201'!H13) -> 1726.735 | I9: =SUM('2215A195 2215A201'!I13) -> 2539.408
A10: 4 | B10: 2215A201 | C10: कोकण विभाग | D10: =SUM('2215A195 2215A201'!D20) -> 0 | E10: =SUM('2215A195 2215A201'!E20) -> 76.59 | F10: =SUM('2215A195 2215A201'!F20) -> 0 | G10: =SUM('2215A195 2215A201'!G20) -> 7 | H10: =SUM('2215A195 2215A201'!H20) -> 8.5 | I10: =SUM('2215A195 2215A201'!I20) -> 8.5
H13: दिपक काटे
H14: सहाय्यक संचालक(लेखा)
H15: कोकण विभाग
