Workbook

Sheet Page 1
A1: प्रपत्र - ड - अर्थसंकल्पीय अंदाजपत्रक सन 2021-2022
A2: मागणी क्र.सी- 1- लेखाशिर्ष 2029 0046
A3: जिल्हा मुंबई शहर | O3: (आकडे हजारात)
A4: अ क्र | B4: वर्ग | C4: पद | D4: मंजूर पदे | E4: मंजूर पदे | F4: विशेष वेतन | G4: मुळ वेतन | H4: ग्रेड वेतन | I4: एकूण | J4: महागाई भत्ता 25% | K4: स्थानिक पुरक भत्ता | L4: घर भाडे भत्ता | M4: वाहन भत्ता | N4: धूलाई भत्ता | O4: रोख भत्ता | P4: चप्पल भत्ता/ इतर | Q4: एकूण
D5: 2020-2021 | E5: 2021-2022
C6: स्थायी
A7: 1 | B7: वर्ग-1 व 2 | C7: उप जिल्हाधिकारी/ वि.भू.अधि. | D7: 0 | E7: 0 | F7: 0 | G7: 0 | H7: 0 | I7: =SUM(G7:H7) -> 0 | J7: =ROUND(I7*1.6,0) -> 0 | K7: 0 | L7: 0 | M7: 0 | N7: 0 | O7: 0 | P7: 0 | Q7: =SUM(I7:P7)+F7 -> 0
C8: एकूण वर्ग 1 2 | D8: =SUM(D7) -> 0 | E8: =SUM(E7) -> 0 | F8: =SUM(F7) -> 0 | G8: =SUM(G7) -> 0 | H8: =SUM(H7) -> 0 | I8: =SUM(I7) -> 0 | J8: =SUM(J7) -> 0 | K8: =SUM(K7) -> 0 | ... Q8: =SUM(Q7) -> 0
A9: 2 | B9: वर्ग-3 | C9: अव्वल कारकून | D9: 0 | E9: 0 | F9: 0 | G9: 0 | H9: 0 | I9: =SUM(G9:H9) -> 0 | J9: =ROUND(I9*1.6,0) -> 0 | K9: 0 | L9: 0 | M9: 0 | N9: 0 | O9: 0 | P9: 0 | Q9: =SUM(I9:P9)+F9 -> 0
C10: लिपिक | D10: 0 | E10: 0 | F10: 0 | G10: 0 | H10: 0 | I10: =SUM(G10:H10) -> 0 | J10: =ROUND(I10*1.6,0) -> 0 | K10: 0 | L10: 0 | M10: 0 | N10: 0 | O10: 0 | P10: 0 | Q10: =SUM(I10:P10)+F10 -> 0
C11: आरेखक | D11: 0 | E11: 0 | F11: 0 | G11: 0 | H11: 0 | I11: =SUM(G11:H11) -> 0 | J11: =ROUND(I11*1.6,0) -> 0 | K11: 0 | L11: 0 | M11: 0 | N11: 0 | O11: 0 | P11: 0 | Q11: =SUM(I11:P11)+F11 -> 0
C12: एकूण वर्ग 3 | D12: =SUM(D9:D11) -> 0 | E12: =SUM(E9:E11) -> 0 | F12: =SUM(F9:F11) -> 0 | G12: =SUM(G9:G11) -> 0 | H12: =SUM(H9:H11) -> 0 | I12: =SUM(I9:I11) -> 0 | J12: =ROUND(I12*1.6,0) -> 0 | K12: =SUM(K9:K11) -> 0 | L12: =SUM(L9:L11) -> 0 | M12: =SUM(M9:M11) -> 0 | N12: =SUM(N9:N11) -> 0 | O12: =SUM(O9:O11) -> 0 | P12: =SUM(P9:P11) -> 0 | Q12: =SUM(Q9:Q11) -> 0
A13: 3 | B13: वर्ग-4 | C13: नोटीस वाहक | D13: 0 | E13: 0 | F13: 0 | G13: 0 | H13: 0 | I13: =SUM(G13:H13) -> 0 | J13: =ROUND(I13*1.6,0) -> 0 | K13: 0 | L13: 0 | M13: 0 | N13: 0 | O13: 0 | P13: 0 | Q13: =SUM(I13:P13)+F13 -> 0
C14: शिपाई | D14: 0 | E14: 0 | F14: 0 | G14: 0 | H14: 0 | I14: =SUM(G14:H14) -> 0 | J14: =ROUND(I14*1.6,0) -> 0 | K14: 0 | L14: 0 | M14: 0 | N14: 0 | O14: 0 | P14: 0 | Q14: =SUM(I14:P14)+F14 -> 0
C15: एकूण वर्ग 4 | D15: =SUM(D13:D14) -> 0 | E15: =SUM(E13:E14) -> 0 | F15: =SUM(F13:F14) -> 0 | G15: =SUM(G13:G14) -> 0 | H15: =SUM(H13:H14) -> 0 | I15: =SUM(I13:I14) -> 0 | J15: =SUM(J13:J14) -> 0 | K15: =SUM(K13:K14) -> 0 | ... Q15: =SUM(Q13:Q14) -> 0
C16: एकूण वर्ग 1 2 3 4 | D16: =SUM(D15,D12,D8) -> 0 | E16: =SUM(E15,E12,E8) -> 0 | F16: =SUM(F15,F12,F8) -> 0 | G16: =SUM(G15,G12,G8) -> 0 | H16: =SUM(H15,H12,H8) -> 0 | I16: =SUM(I15,I12,I8) -> 0 | J16: =SUM(J15,J12,J8) -> 0 | K16: =SUM(K15,K12,K8) -> 0 | ... Q16: =SUM(Q15,Q12,Q8) -> 0
A18: अ क | B18: वर्ग | C18: पद | D18: =D4 -> मंजूर पदे | E18: =E4 -> मंजूर पदे | F18: =F4 -> विशेष वेतन | G18: =G4 -> मुळ वेतन | H18: =H4 -> ग्रेड वेतन | I18: =I4 -> एकूण | J18: =J4 -> महागाई भत्ता 25% | K18: स्थानिक पुरक भत्ता | L18: घर भाडे भत्ता | M18: वाहन भत्ता | N18: धूलाई भत्ता | O18: रोख भत्ता | P18: चप्पल भत्ता/ इतर | Q18: एकूण
D19: =D5 -> 2020-2021 | E19: =E5 -> 2021-2022
C20: अस्थायी
A21: 1 | B21: वर्ग-1 व 2 | C21: उप जिल्हाधिकारी/वि.भू.अधि | D21: 0 | E21: 0 | F21: 0 | G21: 0 | H21: 0 | I21: =SUM(G21:H21) -> 0 | J21: =ROUND(I21*1.6,0) -> 0 | K21: 0 | L21: 0 | M21: 0 | N21: 0 | O21: 0 | P21: 0 | Q21: =SUM(I21:P21)+F21 -> 0
C22: नगर रचनाकार | D22: 1 | E22: 1 | F22: 0 | G22: 673 | H22: 0 | I22: =SUM(G22:H22) -> 673 | J22: =ROUND(I22*0.25,0) -> 168 | K22: 4 | L22: 182 | M22: 29 | N22: 0 | O22: 0 | P22: 0 | Q22: =SUM(I22:P22)+F22 -> 1056
C23: सहाय्यक नगर रचनाकार | D23: 0 | E23: 0 | F23: 0 | G23: 0 | H23: 0 | I23: =SUM(G23:H23) -> 0 | J23: =ROUND(I23*1.6,0) -> 0 | K23: 0 | L23: 0 | M23: 0 | N23: 0 | O23: 0 | P23: 0 | Q23: =SUM(I23:P23)+F23 -> 0
C24: एकूण वर्ग 1 व 2 | D24: =SUM(D21:D23) -> 1 | E24: =SUM(E21:E23) -> 1 | F24: =SUM(F21:F23) -> 0 | G24: =SUM(G21:G23) -> 673 | H24: =SUM(H21:H23) -> 0 | I24: =SUM(I21:I23) -> 673 | J24: =SUM(J21:J23) -> 168 | K24: =SUM(K21:K23) -> 4 | ... Q24: =SUM(Q21:Q23) -> 1056
A25: 2 | B25: वर्ग-3 | C25: अव्वल कारकून | D25: 0 | E25: 0 | F25: 0 | G25: 0 | H25: 0 | I25: =SUM(G25:H25) -> 0 | J25: =ROUND(I25*1.6,0) -> 0 | K25: 0 | L25: 0 | M25: 0 | N25: 0 | O25: 0 | P25: 0 | Q25: =SUM(I25:P25)+F25 -> 0
C26: मंडळ अधिकारी | D26: 0 | E26: 0 | F26: 0 | G26: 0 | H26: 0 | I26: =SUM(G26:H26) -> 0 | J26: =ROUND(I26*1.6,0) -> 0 | K26: 0 | L26: 0 | M26: 0 | N26: 0 | O26: 0 | P26: 0 | Q26: =SUM(I26:P26)+F26 -> 0
C27: लिपिक | D27: 1 | E27: 1 | F27: 0 | G27: 487 | H27: 0 | I27: =SUM(G27:H27) -> 487 | J27: =ROUND(I27*0.25,0) -> 122 | K27: 2 | L27: 131 | M27: 5 | N27: 0 | O27: 0 | P27: 0 | Q27: =SUM(I27:P27)+F27 -> 747
C28: वाहन चालक | D28: 0 | E28: 0 | F28: 0 | G28: 0 | H28: 0 | I28: =SUM(G28:H28) -> 0 | J28: =ROUND(I28*1.6,0) -> 0 | K28: 0 | L28: 0 | M28: 0 | N28: 0 | O28: 0 | P28: 0 | Q28: =SUM(I28:P28)+F28 -> 0
C29: एकूण वर्ग 3 | D29: =SUM(D25:D28) -> 1 | E29: =SUM(E25:E28) -> 1 | F29: =SUM(F25:F28) -> 0 | G29: =SUM(G25:G28) -> 487 | H29: =SUM(H25:H28) -> 0 | I29: =SUM(I25:I28) -> 487 | J29: =SUM(J25:J28) -> 122 | K29: =SUM(K25:K28) -> 2 | ... Q29: =SUM(Q25:Q28) -> 747
A30: 3 | B30: वर्ग-4 | C30: शिपाई | D30: 0 | E30: 0 | F30: 0 | G30: 0 | H30: 0 | I30: 0 | J30: =ROUND(I30*1.6,0) -> 0 | K30: 0 | L30: 0 | M30: 0 | N30: 0 | O30: 0 | P30: 0 | Q30: 0
C31: एकूण वर्ग 4 | D31: =SUM(D30) -> 0 | E31: =SUM(E30) -> 0 | F31: =SUM(F30) -> 0 | G31: =SUM(G30) -> 0 | H31: =SUM(H30) -> 0 | I31: =SUM(I30) -> 0 | J31: =SUM(J30) -> 0 | K31: =SUM(K30) -> 0 | ... Q31: =SUM(Q30) -> 0
C32: एकुण वर्ग 1 2 3 4 | D32: =SUM(D31,D29,D24) -> 2 | E32: =SUM(E31,E29,E24) -> 2 | F32: =SUM(F31,F29,F24) -> 0 | G32: =SUM(G31,G29,G24) -> 1160 | H32: =SUM(H31,H29,H24) -> 0 | I32: =SUM(I31,I29,I24) -> 1160 | J32: =SUM(J31,J29,J24) -> 290 | K32: =SUM(K31,K29,K24) -> 6 | ... Q32: =SUM(Q31,Q29,Q24) -> 1803
A34: =$A$1 -> प्रपत्र - ड - अर्थसंकल्पीय अंदाजपत्रक सन 2021-2022
A35: मागणी क्र.सी- 1- लेखाशिर्ष 2029 0046
A36: जिल्हा मुंबई उपनगर जिल्हा | O36: (आकडे हजारात)
A37: अ क्र | B37: वर्ग | C37: पद | D37: =D4 -> मंजूर पदे | E37: =E4 -> मंजूर पदे | F37: =F4 -> विशेष वेतन | G37: =G4 -> मुळ वेतन | H37: =H4 -> ग्रेड वेतन | I37: =I4 -> एकूण | J37: =J4 -> महागाई भत्ता 25% | K37: स्थानिक पुरक भत्ता | L37: घर भाडे भत्ता | M37: वाहन भत्ता | N37: धूलाई भत्ता | O37: रोख भत्ता | P37: चप्पल भत्ता/ इतर | Q37: एकूण
D38: =D5 -> 2020-2021 | E38: =E5 -> 2021-2022
C39: स्थायी
A40: 1 | B40: वर्ग-1 व 2 | C40: उप जिल्हाधिकारी/ वि.भू.अधि. | D40: 1 | E40: 1 | G40: 904 | H40: 0 | I40: =SUM(G40:H40) -> 904 | J40: =ROUND(I40*0.25,0) -> 226 | K40: 4 | L40: 244 | M40: 29 | N40: 0 | O40: 0 | P40: 0 | Q40: =SUM(I40:P40) -> 1407
C41: एकूण वर्ग 1 2 | D41: =SUM(D40) -> 1 | E41: =SUM(E40) -> 1 | F41: =SUM(F40) -> 0 | G41: =SUM(G40) -> 904 | H41: =SUM(H40) -> 0 | I41: =SUM(I40) -> 904 | J41: =SUM(J40) -> 226 | K41: =SUM(K40) -> 4 | ... Q41: =SUM(Q40) -> 1407
A42: 2 | B42: वर्ग-3 | C42: अव्वल कारकून | D42: 1 | E42: 1 | G42: 504 | H42: 0 | I42: =SUM(G42:H42) -> 504 | J42: =ROUND(I42*0.25,0) -> 126 | K42: 4 | L42: 136 | M42: 5 | N42: 0 | O42: 0 | P42: 0 | Q42: =SUM(I42:P42) -> 775
...

Sheet Page 2
A1: प्रपत्र - क - अर्थसंकल्पीय अंदाजपत्रक सन 2021-2022
A2: मागणी क्र.सी- 1- लेखाशिर्ष 2029 0046
A3: (आकडे हजारात)
A4: जिल्हा | B4: स्थायी पदे
C5: भरलेली पदे | G5: रिक्त पदे | K5: एकुण
A6: मुंबई शहर | B6: वर्ग | C6: वर्ग-1 व 2 | D6: वर्ग-3 | E6: वर्ग-4 | F6: एकुण | G6: वर्ग-1 व 2 | H6: वर्ग-3 | I6: वर्ग-4 | J6: एकुण | K6: एकुण
B7: पदे | C7: 0 | D7: 0 | E7: 0 | F7: 0 | G7: 0 | H7: 0 | I7: 0 | J7: 0 | K7: 0
B8: वेतन | C8: 0 | D8: 0 | E8: 0 | F8: 0 | G8: 0 | H8: 0 | I8: 0 | J8: 0 | K8: 0
B9: ग्रेड पे | C9: 0 | D9: 0 | E9: 0 | F9: 0 | G9: 0 | H9: 0 | I9: 0 | J9: 0 | K9: 0
B10: एकुण | C10: 0 | D10: 0 | E10: 0 | F10: 0 | G10: 0 | H10: 0 | I10: 0 | J10: 0 | K10: 0
B11: विशेष वेतन | C11: 0 | D11: 0 | E11: 0 | F11: 0 | G11: 0 | H11: 0 | I11: 0 | J11: 0 | K11: 0
B12: महा.भत्ता | C12: 0 | D12: 0 | E12: 0 | F12: 0 | G12: 0 | H12: 0 | I12: 0 | J12: 0 | K12: 0
B13: स्था.पु.भ. | C13: 0 | D13: 0 | E13: 0 | F13: 0 | G13: 0 | H13: 0 | I13: 0 | J13: 0 | K13: 0
B14: घरभाडे | C14: 0 | D14: 0 | E14: 0 | F14: 0 | G14: 0 | H14: 0 | I14: 0 | J14: 0 | K14: 0
B15: प्रवास भत्ता | C15: 0 | D15: 0 | E15: 0 | F15: 0 | G15: 0 | H15: 0 | I15: 0 | J15: 0 | K15: 0
B16: इतर | C16: 0 | D16: 0 | E16: 0 | F16: 0 | G16: 0 | H16: 0 | I16: 0 | J16: 0 | K16: 0
B17: एकुण | C17: 0 | D17: 0 | E17: 0 | F17: 0 | G17: 0 | H17: 0 | I17: 0 | J17: 0 | K17: 0
A19: जिल्हा | B19: अस्थायी पदे | M19: सर्व वर्ग पदे
C20: भरलेली पदे | G20: रिक्त पदे | K20: एकुण | M20: वर्ग | N20: स्थायी पदे | O20: अस्थायी पदे | P20: एकुण
A21: मुंबई शहर | B21: वर्ग | C21: वर्ग-1 व 2 | D21: वर्ग-3 | E21: वर्ग-4 | F21: एकुण | G21: वर्ग-1 व 2 | H21: वर्ग-3 | I21: वर्ग-4 | J21: एकुण | M21: पदे | N21: 0 | O21: =SUM(K22) -> 2 | P21: =SUM(N21:O21) -> 2
B22: पदे | C22: 0 | D22: 1 | E22: 0 | F22: =SUM(C22:E22) -> 1 | G22: 1 | H22: 0 | I22: 0 | J22: =SUM(G22:I22) -> 1 | K22: =SUM(F22+J22) -> 2 | M22: वेतन | N22: 0 | O22: =SUM(K23) -> 1160 | P22: =SUM(N22:O22) -> 1160
B23: वेतन | C23: 0 | D23: 487 | E23: 0 | F23: =SUM(C23:E23) -> 487 | G23: 673 | H23: 0 | I23: 0 | J23: =SUM(G23:I23) -> 673 | K23: =SUM(F23+J23) -> 1160 | M23: ग्रेड पे | N23: 0 | O23: =SUM(K24) -> 0 | P23: =SUM(N23:O23) -> 0
B24: ग्रेड पे | C24: 0 | D24: 0 | E24: 0 | F24: =SUM(C24:E24) -> 0 | G24: 0 | H24: 0 | I24: 0 | J24: =SUM(G24:I24) -> 0 | K24: =SUM(F24+J24) -> 0 | M24: एकुण | N24: =SUM(N22:N23) -> 0 | O24: =SUM(O22:O23) -> 1160 | P24: =SUM(P22:P23) -> 1160
B25: एकुण | C25: =SUM(C23:C24) -> 0 | D25: =SUM(D23:D24) -> 487 | E25: =SUM(E23:E24) -> 0 | F25: =SUM(F23:F24) -> 487 | G25: =SUM(G23:G24) -> 673 | H25: =SUM(H23:H24) -> 0 | I25: =SUM(I23:I24) -> 0 | J25: =SUM(J23:J24) -> 673 | K25: =SUM(K23:K24) -> 1160 | M25: महा.भत्ता | N25: 0 | O25: =SUM(K27) -> 290 | P25: =SUM(N25:O25) -> 290
B26: विशेष वेतन | C26: 0 | D26: 0 | E26: 0 | F26: =SUM(C26:E26) -> 0 | G26: 0 | H26: 0 | I26: 0 | J26: =SUM(G26:I26) -> 0 | K26: =SUM(F26+J26) -> 0 | M26: विशेष वेतन | N26: 0 | O26: =SUM(K26) -> 0 | P26: =SUM(N26:O26) -> 0
B27: महा.भत्ता | C27: 0 | D27: 122 | E27: 0 | F27: =SUM(C27:E27) -> 122 | G27: 168 | H27: 0 | I27: 0 | J27: =SUM(G27:I27) -> 168 | K27: =SUM(F27+J27) -> 290 | M27: स्था.पु.भ. | N27: 0 | O27: =SUM(K28) -> 6 | P27: =SUM(N27:O27) -> 6
B28: स्था.पु.भ. | C28: 0 | D28: 2 | E28: 0 | F28: =SUM(C28:E28) -> 2 | G28: 4 | H28: 0 | I28: 0 | J28: =SUM(G28:I28) -> 4 | K28: =SUM(F28+J28) -> 6 | M28: घरभाडे | N28: 0 | O28: =SUM(K29) -> 313 | P28: =SUM(N28:O28) -> 313
B29: घरभाडे | C29: 0 | D29: 131 | E29: 0 | F29: =SUM(C29:E29) -> 131 | G29: 182 | H29: 0 | I29: 0 | J29: =SUM(G29:I29) -> 182 | K29: =SUM(F29+J29) -> 313 | M29: प्रवास भत्ता | N29: 0 | O29: =SUM(K30) -> 34 | P29: =SUM(N29:O29) -> 34
B30: प्रवास भत्ता | C30: 0 | D30: 5 | E30: 0 | F30: =SUM(C30:E30) -> 5 | G30: 29 | H30: 0 | I30: 0 | J30: =SUM(G30:I30) -> 29 | K30: =SUM(F30+J30) -> 34 | M30: इतर | N30: 0 | O30: =SUM(K31) -> 0 | P30: =SUM(N30:O30) -> 0
B31: इतर | C31: 0 | D31: 0 | E31: 0 | F31: =SUM(C31:E31) -> 0 | G31: 0 | H31: 0 | I31: 0 | J31: =SUM(G31:I31) -> 0 | K31: =SUM(F31+J31) -> 0 | M31: एकुण | N31: =SUM(N24:N30) -> 0 | O31: =SUM(O24:O30) -> 1803 | P31: =SUM(P24:P30) -> 1803
B32: एकुण | C32: =SUM(C25:C31) -> 0 | D32: =SUM(D25:D31) -> 747 | E32: =SUM(E25:E31) -> 0 | F32: =SUM(F25:F31) -> 747 | G32: =SUM(G25:G31) -> 1056 | H32: =SUM(H25:H31) -> 0 | I32: =SUM(I25:I31) -> 0 | J32: =SUM(J25:J31) -> 1056 | K32: =SUM(K25:K31) -> 1803
A34: =$A$1 -> प्रपत्र - क - अर्थसंकल्पीय अंदाजपत्रक सन 2021-2022
A35: मागणी क्र.सी- 1- लेखाशिर्ष 2029 0046
A36: (आकडे हजारात)
A37: जिल्हा | B37: स्थायी पदे
C38: भरलेली पदे | G38: रिक्त पदे | K38: एकुण
A39: मुंबई उपनगर | B39: वर्ग | C39: वर्ग-1 व 2 | D39: वर्ग-3 | E39: वर्ग-4 | F39: एकुण | G39: वर्ग-1 व 2 | H39: वर्ग-3 | I39: वर्ग-4 | J39: एकुण | K39: एकुण
B40: पदे | C40: 1 | D40: 2 | E40: 4 | F40: =SUM(C40:E40) -> 7 | G40: 0 | H40: 1 | I40: 1 | J40: =SUM(G40:I40) -> 2 | K40: =SUM(J40,F40) -> 9
B41: वेतन | C41: 904 | D41: 788 | E41: 900 | F41: =SUM(C41:E41) -> 2592 | G41: 0 | H41: 283 | I41: 580 | J41: =SUM(G41:I41) -> 863 | K41: =SUM(J41,F41) -> 3455
B42: ग्रेड पे | C42: 0 | D42: 0 | E42: 0 | F42: =SUM(C42:E42) -> 0 | G42: 0 | H42: 0 | I42: 0 | J42: =SUM(G42:I42) -> 0 | K42: =SUM(J42,F42) -> 0
...

Sheet Page 3
A1: प्रपत्र - ब - अर्थसंकल्पीय अंदाजपत्रक सन 2021-2022
A2: मागणी क्र.सी- 1- लेखाशिर्ष 2029 0046
A3: मंजुर पदे
A4: अ.क्र. | B4: वर्ग | C4: स्थायी | E4: अस्थायी | H4: एकुण
C5: भरलेली पदे | D5: रिक्त पदे | E5: भरलेली पदे | F5: रिक्त पदे
A6: 1 | B6: 1 | C6: 0 | D6: 0 | E6: 0 | F6: 1 | H6: =SUM(C6:F6) -> 1
A7: 2 | B7: 2 | C7: 0 | D7: 0 | E7: 0 | F7: 0 | H7: =SUM(C7:F7) -> 0
A8: 3 | B8: 3 | C8: 0 | D8: 0 | E8: 1 | F8: 0 | H8: =SUM(C8:F8) -> 1
A9: 4 | B9: 4 | C9: 0 | D9: 0 | E9: 0 | F9: 0 | H9: =SUM(C9:F9) -> 0
A10: एकुण | C10: =SUM(C6:C9) -> 0 | D10: =SUM(D6:D9) -> 0 | E10: =SUM(E6:E9) -> 1 | F10: =SUM(F6:F9) -> 1 | H10: =SUM(H6:H9) -> 2
F13: ( आकडे हजारात)
A14: अ.क्र. | B14: जिल्हा / विभाग | C14: वैद्यकिय खर्च | D14: उत्सव/सण अग्रिम | E14: स्वग्राम/महाराष्ट्र दर्शन | F14: 7 व्या वेतन आयोग फरक | G14: एनपीएस | H14: इतर | I14: एकुण
A15: 1 | B15: मुंबई शहर | C15: 325 | D15: 13 | E15: 60 | F15: 350 | G15: 500 | H15: 0 | I15: =SUM(C15:H15) -> 1248
A17: =$A$1 -> प्रपत्र - ब - अर्थसंकल्पीय अंदाजपत्रक सन 2021-2022
A18: मागणी क्र.सी- 1- लेखाशिर्ष 2029 0046
A19: मंजुर पदे
A20: अ.क्र. | B20: वर्ग | C20: स्थायी | E20: अस्थायी | H20: एकुण
C21: भरलेली पदे | D21: रिक्त पदे | E21: भरलेली पदे | F21: रिक्त पदे
A22: 1 | B22: 1 | C22: 1 | D22: 0 | E22: 0 | F22: 1 | H22: =SUM(C22:F22) -> 2
A23: 2 | B23: 2 | C23: 0 | D23: 0 | E23: 0 | F23: 0 | H23: =SUM(C23:F23) -> 0
A24: 3 | B24: 3 | C24: 2 | D24: 1 | E24: 4 | F24: 0 | H24: =SUM(C24:F24) -> 7
A25: 4 | B25: 4 | C25: 4 | D25: 1 | E25: 1 | F25: 0 | H25: =SUM(C25:F25) -> 6
A26: एकुण | C26: =SUM(C22:C25) -> 7 | D26: =SUM(D22:D25) -> 2 | E26: =SUM(E22:E25) -> 5 | F26: =SUM(F22:F25) -> 1 | H26: =SUM(H22:H25) -> 15
F29: ( आकडे हजारात)
A30: अ.क्र. | B30: जिल्हा / विभाग | C30: वैद्यकिय खर्च | D30: उत्सव/सण अग्रिम | E30: स्वग्राम/महाराष्ट्र दर्शन | F30: 7 व्या वेतन आयोग फरक | G30: एनपीएस | H30: इतर | I30: एकुण
A31: 1 | B31: मुंबई उपनगर | C31: 1000 | D31: 150 | E31: 50 | F31: 1000 | G31: 500 | H31: 1000 | I31: =SUM(C31:H31) -> 3700
A33: =$A$1 -> प्रपत्र - ब - अर्थसंकल्पीय अंदाजपत्रक सन 2021-2022
A34: मागणी क्र.सी- 1- लेखाशिर्ष 2029 0046
A35: मंजुर पदे
A36: अ.क्र. | B36: वर्ग | C36: स्थायी | E36: अस्थायी | H36: एकुण
C37: भरलेली पदे | D37: रिक्त पदे | E37: भरलेली पदे | F37: रिक्त पदे
A38: 1 | B38: 1 | C38: 0 | D38: 0 | E38: 1 | F38: 0 | H38: =SUM(C38:F38) -> 1
A39: 2 | B39: 2 | C39: 0 | D39: 0 | E39: 1 | F39: 0 | H39: =SUM(C39:F39) -> 1
A40: 3 | B40: 3 | C40: 2 | D40: 2 | E40: 0 | F40: 0 | H40: =SUM(C40:F40) -> 4
A41: 4 | B41: 4 | C41: 0 | D41: 0 | E41: 0 | F41: 2 | H41: =SUM(C41:F41) -> 2
A42: एकुण | C42: =SUM(C38:C41) -> 2 | D42: =SUM(D38:D41) -> 2 | E42: =SUM(E38:E41) -> 2 | F42: =SUM(F38:F41) -> 2 | H42: =SUM(H38:H41) -> 8
F45: ( आकडे हजारात)
A46: अ.क्र. | B46: जिल्हा / विभाग | C46: वैद्यकिय खर्च | D46: उत्सव/सण अग्रिम | E46: स्वग्राम/महाराष्ट्र दर्शन | F46: 7 व्या वेतन आयोग फरक | G46: एनपीएस | H46: इतर | I46: एकुण
A47: 1 | B47: ठाणे | C47: 400 | D47: 30 | E47: 30 | F47: 300 | G47: 0 | H47: 100 | I47: =SUM(C47:H47) -> 860
A48: =$A$1 -> प्रपत्र - ब - अर्थसंकल्पीय अंदाजपत्रक सन 2021-2022
...

Sheet Page 4
A1: प्रपत्र - अ - अर्थसंकल्पीय अंदाजपत्रक सन 2021-2022
A2: मागणी क्र.सी- 1- लेखाशिर्ष 2029 0046
A3: जिल्हा मुंबई शहर | L3: (आकडे हजारात)
A4: अ. क्र | B4: लेख्याची प्राथमिक आणि दुय्यम युनिट | C4: प्रत्यक्ष रक्कमा (खर्च) | F4: अर्थसंकल्पीय अंदाज | G4: सुधारीत अंदाज 2020-2021 | H4: अर्थसंकल्पीय अंदाज 2021-2022 | L4: मागील वर्षाच्या प्रत्यक्ष रक्कमा आणि चालु वर्षाच्या अर्थसंकल्पीय अंदाजाची तुलना करता आगामी वर्षासाठीच्या अंदाजातील वाढ किंवा घट यांच्या संबधातील स्पष्टीकरणे.
C5: 2017-2018 | D5: 2018-2019 | E5: 2019-2020 | F5: 2020-2021 | H5: प्राकक्लन (एस्टिमेटिंग) अधिका-याचा | I5: नियंत्रक अधिका-यांचा | J5: प्रशासकीय विभागाचा | K5: वित्त विभागाचा
A6: 1 | B6: 2 | C6: 3 | D6: 4 | E6: 5 | F6: 6 | G6: 7 | H6: 8 | I6: 9 | J6: 10 | K6: 11 | L6: 12
A7: 1 | B7: 01- वेतन | C7: 1676 | D7: 1762 | E7: 1156 | F7: 2966 | G7: 2966 | H7: 3051
A8: 2 | B8: 03 अति.भत्ता | C8: 0 | D8: 0 | E8: 0 | F8: 0 | G8: 0 | H8: 0
A9: 3 | B9: 06-दूरध्वनी वीज,पाणी व शुल्क | C9: 70 | D9: 142 | E9: 40 | F9: 220 | G9: 220 | H9: 240
A10: 4 | B10: 11- देशातंर्गत प्रवास खर्च | C10: 25 | D10: 0 | E10: 0 | F10: 50 | G10: 50 | H10: 55
A11: 4 | B11: 13- कार्यालयीन खर्च | C11: 80 | D11: 27 | E11: 49 | F11: 190 | G11: 190 | H11: 200
A12: 5 | B12: 14-भाडेपटटी व कर | C12: 0 | D12: 0 | E12: 0 | F12: 0 | G12: 0 | H12: 0
A13: 7 | B13: 17- संगणक खर्च | C13: 22 | D13: 0 | E13: 4 | F13: 95 | G13: 95 | H13: 110
A14: 8 | B14: 26- जाहीरात व प्रसिध्दी खर्च | C14: 0 | D14: 0 | E14: 0 | F14: 0 | G14: 0 | H14: 0
A15: 9 | B15: 51- मोटार वाहने | C15: 0 | D15: 0 | E15: 0 | F15: 0 | G15: 0 | H15: 0
B16: एकुण | C16: =SUM(C7:C15) -> 1873 | D16: =SUM(D7:D15) -> 1931 | E16: =SUM(E7:E15) -> 1249 | F16: =SUM(F7:F15) -> 3521 | G16: =SUM(G7:G15) -> 3521 | H16: =SUM(H7:H15) -> 3656 | I16: =SUM(I7:I15) -> 0 | J16: =SUM(J7:J15) -> 0 | K16: =SUM(K7:K15) -> 0
A18: =$A$1 -> प्रपत्र - अ - अर्थसंकल्पीय अंदाजपत्रक सन 2021-2022
A19: मागणी क्र.सी- 1- लेखाशिर्ष 2029 0046
A20: जिल्हा मुंबई उपनगर | L20: (आकडे हजारात)
A21: अ. क्र | B21: लेख्याची प्राथमिक आणि दुय्यम युनिट | C21: प्रत्यक्ष रक्कमा (खर्च) | F21: अर्थसंकल्पीय अंदाज | G21: सुधारीत अंदाज 2020-2021 | H21: अर्थसंकल्पीय अंदाज 2021-2022 | L21: मागील वर्षाच्या प्रत्यक्ष रक्कमा आणि चालु वर्षाच्या अर्थसंकल्पीय अंदाजाची तुलना करता आगामी वर्षासाठीच्या अंदाजातील वाढ किंवा घट यांच्या संबधातील स्पष्टीकरणे.
C22: 2017-2018 | D22: 2018-2019 | E22: 2019-2020 | F22: 2020-2021 | H22: प्राकक्लन (एस्टिमेटिंग) अधिका-याचा | I22: नियंत्रक अधिका-यांचा | J22: प्रशासकीय विभागाचा | K22: वित्त विभागाचा
A23: 1 | B23: 2 | C23: 3 | D23: 4 | E23: 5 | F23: 6 | G23: 7 | H23: 8 | I23: 9 | J23: 10 | K23: 11 | L23: 12
A24: 1 | B24: 01- वेतन | C24: 7308 | D24: 6505 | E24: 6982 | F24: 12736 | G24: 12736 | H24: 13114
A25: 2 | B25: 03 अति.भत्ता | C25: 0 | D25: 0 | E25: 0 | F25: 0 | G25: 0 | H25: 0
A26: 3 | B26: 06- दूरध्वनी वीज,पाणी व शुल्क | C26: 21 | D26: 23 | E26: 21 | F26: 26 | G26: 26 | H26: 40
A27: 4 | B27: 11- देशातंर्गत प्रवास खर्च | C27: 31 | D27: 29 | E27: 0 | F27: 83 | G27: 83 | H27: 83
A28: 4 | B28: 13- कार्यालयीन खर्च | C28: 99 | D28: 74 | E28: 20 | F28: 205 | G28: 205 | H28: 205
A29: 5 | B29: 14-भाडेपटटी व कर | C29: 0 | D29: 0 | E29: 0 | F29: 0 | G29: 0 | H29: 0
A30: 7 | B30: 17- संगणक खर्च | C30: 0 | D30: 0 | E30: 0 | F30: 0 | G30: 0 | H30: 5
A31: 8 | B31: 26- जाहीरात व प्रसिध्दी खर्च | C31: 0 | D31: 0 | E31: 0 | F31: 0 | G31: 0 | H31: 0
A32: 9 | B32: 51- मोटार वाहने | C32: 0 | D32: 0 | E32: 0 | F32: 0 | G32: 0 | H32: 0
B33: एकुण | C33: =SUM(C24:C32) -> 7459 | D33: =SUM(D24:D32) -> 6631 | E33: =SUM(E24:E32) -> 7023 | F33: =SUM(F24:F32) -> 13050 | G33: =SUM(G24:G32) -> 13050 | H33: =SUM(H24:H32) -> 13447 | I33: =SUM(I24:I32) -> 0 | J33: =SUM(J24:J32) -> 0 | ... L33: =SUM(L24:L32) -> 0
A35: =$A$1 -> प्रपत्र - अ - अर्थसंकल्पीय अंदाजपत्रक सन 2021-2022
A36: मागणी क्र.सी- 1- लेखाशिर्ष 2029 0046
A37: जिल्हा ठाणे | L37: (आकडे हजारात)
A38: अ. क्र | B38: लेख्याची प्राथमिक आणि दुय्यम युनिट | C38: प्रत्यक्ष रक्कमा (खर्च) | F38: अर्थसंकल्पीय अंदाज | G38: सुधारीत अंदाज 2020-2021 | H38: अर्थसंकल्पीय अंदाज 2021-2022 | L38: मागील वर्षाच्या प्रत्यक्ष रक्कमा आणि चालु वर्षाच्या अर्थसंकल्पीय अंदाजाची तुलना करता आगामी वर्षासाठीच्या अंदाजातील वाढ किंवा घट यांच्या संबधातील स्पष्टीकरणे.
C39: 2017-2018 | D39: 2018-2019 | E39: 2019-2020 | F39: 2020-2021 | H39: प्राकक्लन (एस्टिमेटिंग) अधिका-याचा | I39: नियंत्रक अधिका-यांचा | J39: प्रशासकीय विभागाचा | K39: वित्त विभागाचा
A40: 1 | B40: 2 | C40: 3 | D40: 4 | E40: 5 | F40: 6 | G40: 7 | H40: 8 | I40: 9 | J40: 10 | K40: 11 | L40: 12
A41: 1 | B41: 01- वेतन | C41: 3475 | D41: 3009 | E41: 3313 | F41: 6225 | G41: 6250 | H41: 6380
A42: 2 | B42: 03 अति.भत्ता | C42: 0 | D42: 0 | E42: 0 | F42: 0 | G42: 0 | H42: 0
...

Sheet Page 5
A1: ='Page 4'!$A$1 -> प्रपत्र - अ - अर्थसंकल्पीय अंदाजपत्रक सन 2021-2022
A2: मागणी क्र.सी- 1- लेखाशिर्ष 2029 0046
A3: कोकण विभाग | L3: (आकडे हजारात)
A4: अ. क्र | B4: लेख्याची प्राथमिक आणि दुय्यम युनिट | C4: ='Page 4'!C139 -> प्रत्यक्ष रक्कमा (खर्च) | F4: ='Page 4'!F139 -> अर्थसंकल्पीय अंदाज | G4: ='Page 4'!G139 -> सुधारीत अंदाज 2020-2021 | H4: ='Page 4'!H139 -> अर्थसंकल्पीय अंदाज 2021-2022 | L4: मागील वर्षाच्या प्रत्यक्ष रक्कमा आणि चालु वर्षाच्या अर्थसंकल्पीय अंदाजाची तुलना करता आगामी वर्षासाठीच्या अंदाजातील वाढ किंवा घट यांच्या संबधातील स्पष्टीकरणे.
C5: ='Page 4'!C140 -> 2017-2018 | D5: ='Page 4'!D140 -> 2018-2019 | E5: ='Page 4'!E140 -> 2019-2020 | F5: ='Page 4'!F140 -> 2020-2021 | H5: ='Page 4'!H140 -> प्राकक्लन (एस्टिमेटिंग) अधिका-याचा | I5: ='Page 4'!I140 -> नियंत्रक अधिका-यांचा | J5: ='Page 4'!J140 -> प्रशासकीय विभागाचा | K5: ='Page 4'!K140 -> वित्त विभागाचा
A6: 1 | B6: 2 | C6: 3 | D6: 4 | E6: 5 | F6: 6 | G6: 7 | H6: 8 | I6: 9 | J6: 10 | K6: 11 | L6: 12
A7: 1 | B7: 01- वेतन | C7: ='Page 4'!C142 -> 24360 | D7: ='Page 4'!D142 -> 24662 | E7: ='Page 4'!E142 -> 28259 | F7: ='Page 4'!F142 -> 48731 | G7: ='Page 4'!G142 -> 48793 | I7: =SUM('Page 4'!H142) -> 48557 | L7: 01- वेतन:- या बाबीखाली चालु महागाई भत्ता दर आकारणी 25% प्रमाणे विचारात घेवून केली आहे.
A8: 2 | B8: 03 अति.भत्ता | C8: ='Page 4'!C143 -> 0 | D8: ='Page 4'!D143 -> 0 | E8: ='Page 4'!E143 -> 0 | F8: ='Page 4'!F143 -> 0 | G8: ='Page 4'!G143 -> 0 | I8: =SUM('Page 4'!H143) -> 0
A9: 3 | B9: 06- दूरध्वनी वीज, पाणी व शुल्क | C9: ='Page 4'!C144 -> 168 | D9: ='Page 4'!D144 -> 271 | E9: ='Page 4'!E144 -> 108 | F9: ='Page 4'!F144 -> 1014 | G9: ='Page 4'!G144 -> 1014 | I9: =SUM('Page 4'!H144) -> 1182 | L9: 06- दूरध्वनी, वीज पाणी व शुल्क:- भुसंपादन कार्यालयाकडील क्षेत्रीय कार्यालये व मुख्यालये यामध्ये दुरध्वनी खर्च तसेच वाढीव दराची वीज देयके अदा करणेकामी जादा अनुदानाची आवश्यकता आहे.
A10: 4 | B10: 11- देशातंर्गत प्रवास खर्च | C10: ='Page 4'!C145 -> 164 | D10: ='Page 4'!D145 -> 94 | E10: ='Page 4'!E145 -> 121 | F10: ='Page 4'!F145 -> 853 | G10: ='Page 4'!G145 -> 853 | I10: =SUM('Page 4'!H145) -> 938 | L10: 11- देशातंर्गत प्रवास खर्च:- भुसंपादन कार्यालयाकडील कराव्या लागलेल्या फिरती बदली प्रवासभत्ता दैनिकभत्ता इत्यादीसाठी वाढीव महागाई दराच्या आधारावर जादा अनुदानाची आवश्यकता आहे.
A11: 5 | B11: 13- कार्यालयीन खर्च | C11: ='Page 4'!C146 -> 480 | D11: ='Page 4'!D146 -> 504 | E11: ='Page 4'!E146 -> 469 | F11: ='Page 4'!F146 -> 2035 | G11: ='Page 4'!G146 -> 2035 | I11: =SUM('Page 4'!H146) -> 2235 | L11: 13- कार्यालयीन खर्च :- सदर बाबीखाली कार्या.खर्चसाठी स्टेशनरी, जडसंग्रह वस्तु, झेरॉक्स यांच्या वाढीव दरामुळे तसेच अधिका-या यांच्या साठी उपलब्ध असलेल्या शासकीय वाहनांची देखभाल, दुरुस्ती, पेट्रोल व डिझेल यांचे वाढीव दर यामुळे कार्यालयीन खर्च मोठया प्रमाणावर वाढला आहे. त्यामुळे वाढीव अनुदानाची मागणी केली आहे.
A12: 6 | B12: 14-भाडेपटटी व कर | C12: ='Page 4'!C147 -> 2 | D12: ='Page 4'!D147 -> 1 | E12: ='Page 4'!E147 -> 2 | F12: ='Page 4'!F147 -> 55 | G12: ='Page 4'!G147 -> 55 | I12: =SUM('Page 4'!H147) -> 55 | L12: 14-भाडेपट्टी व कर :- भूसंपादन कार्यालयाचे हिश्याचे वार्षीक मालमत्ता कराचे देयक अदा करण्याकरीता अनुदनाची आवश्यकता आहे.
A13: 7 | B13: 17- संगणक खर्च | C13: ='Page 4'!C148 -> 22 | D13: ='Page 4'!D148 -> 39 | E13: ='Page 4'!E148 -> 13 | F13: ='Page 4'!F148 -> 665 | G13: ='Page 4'!G148 -> 625 | I13: =SUM('Page 4'!H148) -> 695 | L13: 17- संगणक खर्च :- सदर बाबीखाली सन 2010-2011 पासून मागणी करण्यात येत आहे. सदर उपशिर्षाखाली भुसंपादन कार्यालयास व क्षेत्रीय कार्यालयास पाठवावयाचे नियतकालीके अहवाल तयार करणे इ. कार्यालयीन कामे संगणकावर करावी लागतात. 2013-14 वित्‍त्तीय वर्षात सदर लेखाशिर्षातंर्गत नवीन बाब निर्माण करण्यांत आली आहे.मात्र अत्यल्प अनुदान उपलब्ध करुन देण्यांत आले. सबब या वित्तीय वर्षात सदर अनुदानाची तरतूद होण्यास विनंती आहे.
A14: 8 | B14: 20-इतर प्रशासकीय खर्च | C14: 0 | D14: 0 | E14: 0 | F14: 0 | G14: 0 | I14: 0 | L14: 20-इतर प्रशासकीय खर्च:-विभागीय आयुक्त कार्यालयात आयोजित विविध प्रकारच्या बैठका आयोजित केल्या जातात. त्यावेळी उपस्थीतांकरीता चहा, नाश्ता इत्यादी मागविण्यांत येतो. सदर खर्चाची देयके अदा करण्याकरीता नवीन बाब निर्माण करण्यासाठी टोकन रक्कमेची आवश्यकता आहे.
A15: 9 | B15: 26-जाहीरात व प्रसिध्दी खर्च | C15: ='Page 4'!C149 -> 0 | D15: ='Page 4'!D149 -> 0 | E15: ='Page 4'!E149 -> 0 | F15: ='Page 4'!F149 -> 0 | G15: ='Page 4'!G149 -> 0 | I15: =SUM('Page 4'!H149) -> 0
A16: 10 | B16: 51- मोटार वाहने | C16: ='Page 4'!C150 -> 0 | D16: ='Page 4'!D150 -> 0 | E16: ='Page 4'!E150 -> 0 | F16: ='Page 4'!F150 -> 0 | G16: ='Page 4'!G150 -> 20 | I16: =SUM('Page 4'!H150) -> 20
B17: एकुण | C17: =SUM(C7:C16) -> 25196 | D17: =SUM(D7:D16) -> 25571 | E17: =SUM(E7:E16) -> 28972 | F17: =SUM(F7:F16) -> 53353 | G17: =SUM(G7:G16) -> 53395 | I17: =SUM(I7:I16) -> 53682
L20: (विनिता भूमकर)
L21: सहाय्यक संचालक (लेखा)
L22: कोकण विभाग

Sheet 4-12 TO 7-12 MES
A1: 2020-2021
A2: 4/2020-7/2020 Monthly Expenditure 20290046
A3: Sub Head | B3: Details | C3: Mcity | D3: MSD | E3: PAO | F3: THANE | G3: PALGHAR | H3: RAIGAD | I3: RATNAGIRI | J3: SINDHUDURG | K3: DIV COMM | L3: AG | M3: TOTAL
A4: 1 | B4: Salary | C4: 236 | D4: 2526 | E4: =SUM(C4:D4) -> 2762 | F4: 812 | G4: 1416 | H4: 2376 | I4: 0 | J4: 0 | K4: 1275 | L4: =SUM(F4:K4) -> 5879 | M4: =SUM(L4+E4) -> 8641
A5: 6 | B5: ELCT/WAT/TEL | E5: =SUM(C5:D5) -> 0 | G5: 0 | H5: 2 | K5: 8 | L5: =SUM(F5:K5) -> 10 | M5: =SUM(L5+E5) -> 10
A6: 11 | B6: TE | E6: =SUM(C6:D6) -> 0 | G6: 0 | L6: =SUM(F6:K6) -> 0 | M6: =SUM(L6+E6) -> 0
A7: 13 | B7: OE | E7: =SUM(C7:D7) -> 0 | G7: 0 | L7: =SUM(F7:K7) -> 0 | M7: =SUM(L7+E7) -> 0
A8: 14 | B8: Propert Tax | E8: =SUM(C8:D8) -> 0 | G8: 0 | L8: =SUM(F8:K8) -> 0 | M8: =SUM(L8+E8) -> 0
A9: 17 | B9: Computer Exp. | E9: =SUM(C9:D9) -> 0 | G9: 0 | L9: =SUM(F9:K9) -> 0 | M9: =SUM(L9+E9) -> 0
A10: 26 | B10: Advertisement & Publicity | E10: =SUM(C10:D10) -> 0 | G10: 0 | L10: =SUM(F10:K10) -> 0 | M10: =SUM(L10+E10) -> 0
A11: 51 | B11: Motor Car | E11: =SUM(C11:D11) -> 0 | G11: 0 | L11: =SUM(F11:K11) -> 0 | M11: =SUM(L11+E11) -> 0
C12: =SUM(C4:C11) -> 236 | D12: =SUM(D4:D11) -> 2526 | E12: =SUM(E4:E11) -> 2762 | F12: =SUM(F4:F11) -> 812 | G12: =SUM(G4:G11) -> 1416 | H12: =SUM(H4:H11) -> 2378 | I12: =SUM(I4:I11) -> 0 | J12: =SUM(J4:J11) -> 0 | ... M12: =SUM(M4:M11) -> 8651
K15: (विनिता भूमकर)
K16: सहाय्यक संचालक (लेखा)
K17: कोकण विभाग

Sheet jodpatra D
A1: जोडपत्र-ड
A2: अर्थसंकल्पीय अंदाजपत्रक सन 2021-2022
A3: मागणी क्र.सी-1 2029 जमीन महसूल (20290046)
A4: कोकण विभाग संगर्व निहाय पदांची माहिती
A5: अ.क्र. | B5: संवर्ग | C5: मंजूर पदे | E5: भरलेली पदे | G5: रिक्त पदे
C6: स्थायी | D6: अस्थायी | E6: स्थायी | F6: अस्थायी | G6: स्थायी | H6: अस्थायी
A7: 1 | B7: वर्ग-1 | C7: ='Page 1'!$E$270 -> 1 | D7: =SUM('Page 1'!E284:E285) -> 8 | E7: =SUM('Page 3'!C134) -> 1 | F7: =SUM('Page 3'!E134) -> 4 | G7: =SUM('Page 3'!D134) -> 0 | H7: =SUM('Page 3'!F134) -> 4
A8: 2 | B8: वर्ग-2 | C8: 0 | D8: =SUM('Page 1'!D286) -> 1 | E8: =SUM('Page 3'!C135) -> 0 | F8: =SUM('Page 3'!E135) -> 1 | G8: =SUM('Page 3'!D135) -> 0 | H8: =SUM('Page 3'!F135) -> 0
A9: 3 | B9: वर्ग-3 | C9: ='Page 1'!$E$275 -> 9 | D9: =SUM('Page 1'!E292) -> 20 | E9: =SUM('Page 3'!C136) -> 6 | F9: =SUM('Page 3'!E136) -> 17 | G9: =SUM('Page 3'!D136) -> 3 | H9: =SUM('Page 3'!F136) -> 3
A10: 4 | B10: वर्ग-4 | C10: ='Page 1'!$E$278 -> 8 | D10: =SUM('Page 1'!E294) -> 6 | E10: =SUM('Page 3'!C137) -> 7 | F10: =SUM('Page 3'!E137) -> 3 | G10: =SUM('Page 3'!D137) -> 1 | H10: =SUM('Page 3'!F137) -> 3
B11: एकूण | C11: =SUM(C7:C10) -> 18 | D11: =SUM(D7:D10) -> 35 | E11: =SUM(E7:E10) -> 14 | F11: =SUM(F7:F10) -> 25 | G11: =SUM(G7:G10) -> 4 | H11: =SUM(H7:H10) -> 10
F15: (विनिता भूमकर)
F16: सहाय्यक संचालक (लेखा)
F17: कोकण विभाग

Sheet Sheet1
A1: प्रपत्र - अ - अर्थसंकल्पीय अंदाजपत्रक सन 2018-2019
A2: मागणी क्र.सी-1- लेखाशिर्ष : 20290046
A3: (आकडे हजारात)
A4: अ. क्र. | B4: उपलेखाशिर्ष | C4: मुंबई शहर | D4: मुंबई उपनगर | E4: ठाणे | F4: पालघर | G4: रायगड | H4: रत्नागिरी | I4: सिंधुदुर्ग | J4: मा.उप आयुक्त (सा.प्र.) | K4: एकूण
A5: 1 | B5: 01- वेतन | C5: =SUM('Page 4'!H7) -> 3051 | D5: =SUM('Page 4'!H24) -> 13114 | E5: =SUM('Page 4'!H41) -> 6380 | F5: =SUM('Page 4'!H57) -> 8915 | G5: =SUM('Page 4'!H74) -> 10278 | H5: =SUM('Page 4'!H91) -> 0 | I5: =SUM('Page 4'!H108) -> 0 | J5: =SUM('Page 4'!H125) -> 6819 | K5: =SUM(C5:J5) -> 48557
A6: 2 | B6: 03- अति.भत्ता | C6: =SUM('Page 4'!H8) -> 0 | D6: =SUM('Page 4'!H25) -> 0 | E6: =SUM('Page 4'!H42) -> 0 | F6: =SUM('Page 4'!H58) -> 0 | G6: =SUM('Page 4'!H75) -> 0 | H6: =SUM('Page 4'!H92) -> 0 | I6: =SUM('Page 4'!H109) -> 0 | J6: =SUM('Page 4'!H126) -> 0 | K6: =SUM(C6:J6) -> 0
A7: 3 | B7: 06- दूरध्वनी वीज,पाणी व शुल्क | C7: =SUM('Page 4'!H9) -> 240 | D7: =SUM('Page 4'!H26) -> 40 | E7: =SUM('Page 4'!H43) -> 300 | F7: =SUM('Page 4'!H59) -> 60 | G7: =SUM('Page 4'!H76) -> 400 | H7: =SUM('Page 4'!H93) -> 0 | I7: =SUM('Page 4'!H110) -> 0 | J7: =SUM('Page 4'!H127) -> 142 | K7: =SUM(C7:J7) -> 1182
A8: 4 | B8: 11- देशातंर्गत प्रवास खर्च | C8: =SUM('Page 4'!H10) -> 55 | D8: =SUM('Page 4'!H27) -> 83 | E8: =SUM('Page 4'!H44) -> 200 | F8: =SUM('Page 4'!H60) -> 60 | G8: =SUM('Page 4'!H77) -> 450 | H8: =SUM('Page 4'!H94) -> 0 | I8: =SUM('Page 4'!H111) -> 0 | J8: =SUM('Page 4'!H128) -> 90 | K8: =SUM(C8:J8) -> 938
A9: 5 | B9: 13- कार्यालयीन खर्च | C9: =SUM('Page 4'!H11) -> 200 | D9: =SUM('Page 4'!H28) -> 205 | E9: =SUM('Page 4'!H45) -> 300 | F9: =SUM('Page 4'!H61) -> 80 | G9: =SUM('Page 4'!H78) -> 650 | H9: =SUM('Page 4'!H95) -> 0 | I9: =SUM('Page 4'!H112) -> 0 | J9: =SUM('Page 4'!H129) -> 800 | K9: =SUM(C9:J9) -> 2235
A10: 6 | B10: 14-भाडेपट्टी व कर | C10: =SUM('Page 4'!H12) -> 0 | D10: =SUM('Page 4'!H29) -> 0 | E10: =SUM('Page 4'!H46) -> 50 | F10: =SUM('Page 4'!H62) -> 0 | G10: =SUM('Page 4'!H79) -> 0 | H10: =SUM('Page 4'!H96) -> 0 | I10: =SUM('Page 4'!H113) -> 0 | J10: =SUM('Page 4'!H130) -> 5 | K10: =SUM(C10:J10) -> 55
A11: 7 | B11: 17- संगणक खर्च | C11: =SUM('Page 4'!H13) -> 110 | D11: =SUM('Page 4'!H30) -> 5 | E11: =SUM('Page 4'!H47) -> 160 | F11: =SUM('Page 4'!H63) -> 20 | G11: =SUM('Page 4'!H80) -> 250 | H11: =SUM('Page 4'!H97) -> 0 | I11: =SUM('Page 4'!H114) -> 0 | J11: =SUM('Page 4'!H131) -> 150 | K11: =SUM(C11:J11) -> 695
A12: 8 | B12: 20-इतर प्रशासकीय खर्च | C12: 0 | D12: 0 | E12: 0 | F12: 0 | G12: 0 | H12: 0 | I12: 0 | J12: 0 | K12: =SUM(C12:J12) -> 0
A13: 9 | B13: 26- जाहीरात व प्रसिध्दी खर्च | C13: =SUM('Page 4'!H14) -> 0 | D13: =SUM('Page 4'!H31) -> 0 | E13: =SUM('Page 4'!H48) -> 0 | F13: =SUM('Page 4'!H64) -> 0 | G13: =SUM('Page 4'!H81) -> 0 | H13: =SUM('Page 4'!H98) -> 0 | I13: =SUM('Page 4'!H115) -> 0 | J13: =SUM('Page 4'!H132) -> 0 | K13: =SUM(C13:J13) -> 0
A14: 10 | B14: 51- मोटार वाहने | C14: =SUM('Page 4'!H15) -> 0 | D14: =SUM('Page 4'!H32) -> 0 | E14: =SUM('Page 4'!H49) -> 0 | F14: =SUM('Page 4'!H65) -> 20 | G14: =SUM('Page 4'!H82) -> 0 | H14: =SUM('Page 4'!H99) -> 0 | I14: =SUM('Page 4'!H116) -> 0 | J14: =SUM('Page 4'!H133) -> 0 | K14: =SUM(C14:J14) -> 20
A15: एकूण | C15: =SUM(C5:C14) -> 3656 | D15: =SUM(D5:D14) -> 13447 | E15: =SUM(E5:E14) -> 7390 | F15: =SUM(F5:F14) -> 9155 | G15: =SUM(G5:G14) -> 12028 | H15: =SUM(H5:H14) -> 0 | I15: =SUM(I5:I14) -> 0 | J15: =SUM(J5:J14) -> 8006 | K15: =SUM(K5:K14) -> 53682
A17: प्रपत्र - अ - अर्थसंकल्पीय अंदाजपत्रक सन 2018-2019
A18: मागणी क्र.सी-1- लेखाशिर्ष : 20290046
A19: (आकडे हजारात)
A20: अ. क्र. | B20: उपलेखाशिर्ष | C20: मुंबई शहर | D20: मुंबई उपनगर | E20: ठाणे | F20: पालघर | G20: रायगड | H20: रत्नागिरी | I20: सिंधुदुर्ग | J20: मा.उप आयुक्त (सा.प्र.) | K20: एकूण
A21: 1 | B21: 01- वेतन | C21: =SUM((C5/K5)*100) -> 6.2833371 | D21: =SUM((D5/K5)*100) -> 27.007435 | E21: =SUM((E5/K5)*100) -> 13.139197 | F21: =SUM((F5/K5)*100) -> 18.359866 | G21: =SUM((G5/K5)*100) -> 21.166876 | H21: =SUM((H5/K5)*100) -> 0 | I21: =SUM((I5/K5)*100) -> 0 | J21: =SUM((J5/K5)*100) -> 14.043289 | K21: 32738 | L21: =SUM(C21:J21) -> 100
A22: 2 | B22: 03- अति.भत्ता | C22: =SUM((C6/K6)*100) -> #DIV/0! | D22: =SUM((D6/K6)*100) -> #DIV/0! | E22: =SUM((E6/K6)*100) -> #DIV/0! | F22: =SUM((F6/K6)*100) -> #DIV/0! | G22: =SUM((G6/K6)*100) -> #DIV/0! | H22: =SUM((H6/K6)*100) -> #DIV/0! | I22: =SUM((I6/K6)*100) -> #DIV/0! | J22: =SUM((J6/K6)*100) -> #DIV/0! | K22: 0 | L22: =SUM(C22:J22) -> #DIV/0!
A23: 3 | B23: 06- दूरध्वनी वीज,पाणी व शुल्क | C23: =SUM((C7/K7)*100) -> 20.304569 | D23: =SUM((D7/K7)*100) -> 3.3840948 | E23: =SUM((E7/K7)*100) -> 25.380711 | F23: =SUM((F7/K7)*100) -> 5.0761421 | G23: =SUM((G7/K7)*100) -> 33.840948 | H23: =SUM((H7/K7)*100) -> 0 | I23: =SUM((I7/K7)*100) -> 0 | J23: =SUM((J7/K7)*100) -> 12.013536 | K23: 1108 | L23: =SUM(C23:J23) -> 100
A24: 4 | B24: 11- देशातंर्गत प्रवास खर्च | C24: =SUM((C8/K8)*100) -> 5.8635394 | D24: =SUM((D8/K8)*100) -> 8.8486141 | E24: =SUM((E8/K8)*100) -> 21.321962 | F24: =SUM((F8/K8)*100) -> 6.3965885 | G24: =SUM((G8/K8)*100) -> 47.974414 | H24: =SUM((H8/K8)*100) -> 0 | I24: =SUM((I8/K8)*100) -> 0 | J24: =SUM((J8/K8)*100) -> 9.5948827 | K24: 800 | L24: =SUM(C24:J24) -> 100
A25: 5 | B25: 13- कार्यालयीन खर्च | C25: =SUM((C9/K9)*100) -> 8.9485459 | D25: =SUM((D9/K9)*100) -> 9.1722595 | E25: =SUM((E9/K9)*100) -> 13.422819 | F25: =SUM((F9/K9)*100) -> 3.5794183 | G25: =SUM((G9/K9)*100) -> 29.082774 | H25: =SUM((H9/K9)*100) -> 0 | I25: =SUM((I9/K9)*100) -> 0 | J25: =SUM((J9/K9)*100) -> 35.794183 | K25: 1820 | L25: =SUM(C25:J25) -> 100
A26: 6 | B26: 14-भाडेपट्टी व कर | C26: =SUM((C10/K10)*100) -> 0 | D26: =SUM((D10/K10)*100) -> 0 | E26: =SUM((E10/K10)*100) -> 90.909091 | F26: =SUM((F10/K10)*100) -> 0 | G26: =SUM((G10/K10)*100) -> 0 | H26: =SUM((H10/K10)*100) -> 0 | I26: =SUM((I10/K10)*100) -> 0 | J26: =SUM((J10/K10)*100) -> 9.0909091 | K26: 45 | L26: =SUM(C26:J26) -> 100
A27: 7 | B27: 17- संगणक खर्च | C27: =SUM((C11/K11)*100) -> 15.827338 | D27: =SUM((D11/K11)*100) -> 0.71942446 | E27: =SUM((E11/K11)*100) -> 23.021583 | F27: =SUM((F11/K11)*100) -> 2.8776978 | G27: =SUM((G11/K11)*100) -> 35.971223 | H27: =SUM((H11/K11)*100) -> 0 | I27: =SUM((I11/K11)*100) -> 0 | J27: =SUM((J11/K11)*100) -> 21.582734 | K27: 630 | L27: =SUM(C27:J27) -> 100
A28: 8 | B28: 20-इतर प्रशासकीय खर्च | C28: =SUM((C12/K12)*100) -> #DIV/0! | D28: =SUM((D12/K12)*100) -> #DIV/0! | E28: =SUM((E12/K12)*100) -> #DIV/0! | F28: =SUM((F12/K12)*100) -> #DIV/0! | G28: =SUM((G12/K12)*100) -> #DIV/0! | H28: =SUM((H12/K12)*100) -> #DIV/0! | I28: =SUM((I12/K12)*100) -> #DIV/0! | J28: =SUM((J12/K12)*100) -> #DIV/0! | K28: 0 | L28: =SUM(C28:J28) -> #DIV/0!
A29: 9 | B29: 26- जाहीरात व प्रसिध्दी खर्च | C29: =SUM((C13/K13)*100) -> #DIV/0! | D29: =SUM((D13/K13)*100) -> #DIV/0! | E29: =SUM((E13/K13)*100) -> #DIV/0! | F29: =SUM((F13/K13)*100) -> #DIV/0! | G29: =SUM((G13/K13)*100) -> #DIV/0! | H29: =SUM((H13/K13)*100) -> #DIV/0! | I29: =SUM((I13/K13)*100) -> #DIV/0! | J29: =SUM((J13/K13)*100) -> #DIV/0! | K29: 0 | L29: =SUM(C29:J29) -> #DIV/0!
A30: 10 | B30: 51- मोटार वाहने | C30: =SUM((C14/K14)*100) -> 0 | D30: =SUM((D14/K14)*100) -> 0 | E30: =SUM((E14/K14)*100) -> 0 | F30: =SUM((F14/K14)*100) -> 100 | G30: =SUM((G14/K14)*100) -> 0 | H30: =SUM((H14/K14)*100) -> 0 | I30: =SUM((I14/K14)*100) -> 0 | J30: =SUM((J14/K14)*100) -> 0 | K30: 0 | L30: =SUM(C30:J30) -> 100
A31: एकूण | C31: =SUM((C15/K15)*100) -> 6.8104765 | D31: =SUM((D15/K15)*100) -> 25.049365 | E31: =SUM((E15/K15)*100) -> 13.766253 | F31: =SUM((F15/K15)*100) -> 17.054134 | G31: =SUM((G15/K15)*100) -> 22.406021 | H31: =SUM((H15/K15)*100) -> 0 | I31: =SUM((I15/K15)*100) -> 0 | J31: =SUM((J15/K15)*100) -> 14.913751 | K31: 37141 | L31: =SUM(C31:J31) -> 100
